Workbook
Name _360EN: #REF!
Name _361EN: #REF!
Name _388EN: #REF!
Name _503EN: #REF!
Name _525EN: #REF!
Name _529EN: #REF!
Name _544EN: #REF!
Name _575D: #REF!
Name _577D: #REF!
Name _585EN: #REF!
Name _811EN: #REF!
Name _812EN: #REF!
Name _813EN: #REF!
Name _814EN: #REF!
Name _816EN: #REF!
Name _817EN: #REF!
Name _819EN: #REF!
Name ALCOHOL: #REF!
Name ALQ_LARRAZABAL: #REF!
Name ANHILINA: #REF!
Name Atriles10x15: #REF!
Name Atriles13x18: #REF!
Name BuiltIn_Print_Area: #REF!
Name BuiltIn_Print_Area___0: #REF!
Name BuiltIn_Print_Titles: #REF!
Name BuiltIn_Print_Titles___0: #REF!
Name CAJAS: #REF!
Name CARTON: #REF!
Name CHAPA: #REF!
Name CHAPADUR: #REF!
Name COLA: #REF!
Name CONTADOR1: #REF!
Name CORCHO: #REF!
Name CORTE_LASER: #REF!
Name CRAYOVAC: #REF!
Name DIOXIDO: #REF!
Name DOLAR: #REF!
Name Dólar: #REF!
Name Estimado: #REF!
Name Gananc._Chef: #REF!
Name GOMALACA: #REF!
Name Griego10x15: #REF!
Name Griego13x18: #REF!
Name Griego15x21: #REF!
Name HORA: #REF!
Name IB_3: #REF!
Name IG_35: #REF!
Name LA_015: #REF!
Name LA_052: #REF!
Name LA_053: #REF!
Name LA_070: #REF!
Name LA_071: #REF!
Name LA_072: #REF!
Name LA_113: #REF!
Name LA_114: #REF!
Name LA_115: #REF!
Name LA_117: #REF!
Name LA_119: #REF!
Name LA_195: #REF!
Name LA_196: #REF!

Sheet O.C. Rueda
A1: Loekemeyer Hnos. S.R.L | E1: ORDEN DE COMPRA
A2: CUIT: | C2: 30-51584245-0
A3: DIRECCION: | C3: Cervantes 2868
A4: LOCALIDAD: | C4: Villa Devoto, CABA | E4: FECHA PEDIDO: | G4: =+TODAY() -> 46008
A5: TELEFONO: | C5: 11 3118-1027
A7: RAZON SOCIAL: | C7: Rueda y Cia SRL | E7: COD PROV: | F7: 3372
A9: ENTREGA EN: | C9: Cervantes 2868
A12: Este pedido anula cualquier pedido anterior
A13: Rueda | C13: Fecha: | D13: =+TODAY() -> 46008
A14: Cód ISIS | B14: N° Ord | C14: Descripcion | D14: Pedido Damian Rollo | E14: Fecha Entrega | F14: Entrega Uni | G14: Entrega Fecha | H14: Entrega Uni | I14: Entrega Fecha
A15: 1165500 | C15: Tela Manga Repostera | D15: 2

Sheet O.C. Roosvelt
A1: Este pedido anula cualquier pedido anterior
A2: Roosvelt | C2: Fecha: | D2: =+TODAY() -> 46008
A3: Cód ISIS | B3: Descripcion | C3: Pedido Damian | D3: Orden Prioridad | F3: Fecha Entrega | H3: Entrega: | I3: Entrega: | J3: Entrega:
A4: 5161600 | B4: Resorte p/ Bombilla Niq

Sheet O.C. Resortes Charcas
A1: Este pedido anula cualquier pedido anterior
A2: =+TODAY() -> 46008 | C2: Resortes Charcas
A3: Cód ISIS | B3: N° Ord | C3: Descripcion | D3: Pedido Damian Uni | E3: Fecha Entrega | F3: Entrega Uni | G3: Entrega Fecha | H3: Entrega Uni | I3: Entrega Fecha
C4: Resorte p/Bombilla Autolimpiante
A6: 1111500 | C6: Resorte p/ Bombilla Crudo
A8: 1112500 | C8: Resorte Biconico
C10: Resorte Mini Batidor Pera
A12: 1114500 | C12: Resorte Batidor Pera

Sheet O.C. Colodis Kufo
A1: Este pedido anula cualquier pedido anterior
A2: Colodis Kufo | C2: Fecha: | D2: =+TODAY() -> 46008
A3: Cód ISIS | B3: Descripcion | C3: Pedido Damian | D3: Orden Prioridad | F3: Fecha Entrega | H3: Entrega: | I3: Entrega: | J3: Entrega:
A4: 5323600 | B4: Ralladores Cilindrico 14cm

Sheet O.C. Melinox
A1: Este pedido anula cualquier pedido anterior
A2: Melinox | C2: Fecha: | D2: =+TODAY() -> 46008
A3: Cód ISIS | B3: Descripcion | C3: Pedido Damian | D3: Orden Prioridad | F3: Fecha Entrega | H3: Entrega: | I3: Entrega: | J3: Entrega:
A4: 5312600 | B4: Pala de Torta

Sheet O.C. Rueda y Cia
A1: Este pedido anula cualquier pedido anterior
B2: Rueda y Cia | C2: Fecha: | D2: =+TODAY() -> 46008
A3: Cód ISIS | B3: Descripcion | C3: Pedido Damian | D3: Orden Prioridad | F3: Fecha Entrega | H3: Entrega: | I3: Entrega: | J3: Entrega:
A4: 1136500 | B4: Cerda P/Pincel Pastelero

Sheet O.C. Alambres Rumbo
A1: Este pedido anula cualquier pedido anterior
A2: Alambres Rumbo | C2: Fecha: | D2: =+TODAY() -> 46008
A3: Cód ISIS | B3: Descripcion | C3: Pedido Damian | D3: Orden Prioridad | F3: Fecha Entrega | H3: Entrega: | I3: Entrega: | J3: Entrega:
A4: 1182500 | B4: Alambre Corta Queso

Sheet O.C. Casa Landau
A1: Este pedido anula cualquier pedido anterior
A2: =+TODAY() -> 46008 | C2: Casa Landau
A3: Cód ISIS | B3: N° Ord | C3: Descripcion | D3: Pedido Damian Uni | E3: Fecha Entrega | F3: Entrega Uni | G3: Entrega Fecha | H3: Entrega Uni | I3: Entrega Fecha
A4: 1130500 | B4: 1 | C4: Aro p/Llavero Grande | D4: 2000
A6: 1168500 | B6: 2 | C6: {=+IFERROR(INDEX('[3]Pedido VACIO'!$C:$C,MATCH(1,('[3]Pedido VACIO'!$E:$E=$B16)*('[3]Pedido VACIO'!$A:$A="Casa Landau"),0)),"")}

Sheet O.C. Bella Vista
A1: Este pedido anula cualquier pedido anterior
B2: Bella Vista | C2: Fecha: | D2: =+TODAY() -> 46008
A3: Cód ISIS | B3: Descripcion | C3: Pedido Damian | D3: Orden Prioridad | F3: Fecha Entrega | H3: Entrega: | I3: Entrega: | J3: Entrega:
A4: 1078500 | B4: Cañito Pincel Pastelero
A5: 1106500 | B5: Tapita Aluminio

Sheet O.C. Giser
A1: Este pedido anula cualquier pedido anterior
A2: =+TODAY() -> 46008 | C2: Giser
A3: Cód ISIS | B3: N° Ord | C3: Descripcion | D3: Pedido Damian Uni | E3: Fecha Entrega | F3: Entrega Uni | G3: Entrega Fecha | H3: Entrega Uni | I3: Entrega Fecha
C4: Caño p/Sorbete Inox
A6: 1175500 | C6: Caño Inox 140 mm
A8: 1093500 | C8: Caño Inox 170 mm x 0.4mm x 7 Ø
A10: 1096500 | C10: Buje Bombilla Bronce
A12: 1095500 | C12: Adorno Bombilla Bronce

Sheet Conteo VACIO
B1: CONTEO BOMBILLA
C3: FECHA: | D3: 45796
C8: Este pedido anula cualquier pedido anterior
C9: Giser | D9: Fecha: | AA9: INFORMACION
B10: Cód ISIS | C10: Descripcion | D10: Pedido Damian | E10: Orden Prioridad | G10: % Ocup Relev | H10: % Ocup Total | J10: Max 3 Mes Uni/ KG | K10: Stock Uni/ KG | L10: Pedi Uni/ KG | N10: Stock Prov Serv Uni | O10: Stock Taller Uni | P10: Stock CD Uni | Q10: Stock Total Uni | S10: Max Taller Uni | T10: Max CD Uni | U10: Max Total Uni | W10: Sector | X10: Stock Bolsa/ Caj/ Rollo | Y10: Uni Suelta | AA10: Cons x Mes Uni | AB10: Cons x Mes Kg | AC10: Uni x B/C | AD10: Min Uni Compra | AE10: Prec x Uni | AF10: Min Kg Compra | AG10: Prec x Kg | AH10: KG x Uni | AI10: Prov | AJ10: Unidad de Medida Pedido | AK10: Max Mes
C11: Caño p/Sorbete Inox | D11: 0 | G11: =+IFERROR(K11/J11,0) -> 0 | H11: =+IFERROR(Q11/U11,0) -> 0 | J11: =AA11*AK11 -> 0 | K11: =(X11*AC11)+Y11 -> 4500 | L11: =+IF(K11-J11>0,0,J11-K11) -> 0 | N11: =+IFERROR(VLOOKUP(W11,'Stock Prov. Serv.'!A:D,4,0),0) -> 0 | O11: =+IFERROR(VLOOKUP(W11,'Stock Taller'!A:D,4,0),0) -> 0 | P11: =+SUMIF('Stock CD'!B:B,'Conteo VACIO'!W11,'Stock CD'!E:E) -> 0 | Q11: =+N11+O11+P11+K11 -> 4500 | S11: =+IFERROR(VLOOKUP(W11,'Stock Taller'!A:G,7,0),0) -> 0 | T11: =+IFERROR(SUMIF('Stock CD'!B:B,'Conteo VACIO'!W11,'Stock CD'!K:K),0) -> 0 | U11: =+S11+T11+J11 -> 0 | W11: BOM2 | X11: 9 | AA11: =+SUMIFS(Consumo!F:F,Consumo!D:D,'Conteo VACIO'!W11) -> 0 | AB11: =+AA11*AH11 -> 0 | AC11: 500 | AD11: 1000 | AE11: =+AH11*AG11 -> 0 | AF11: =+AD11*AH11 -> 9.5 | AG11: =AD11*BB11 -> 0 | AH11: 0.0095 | AI11: Giser | AJ11: Kilos | AK11: 3
B12: 1096500 | C12: Buje Bombilla Bronce | D12: 0 | G12: =+IFERROR(K12/J12,0) -> 2.115162 | H12: =+IFERROR(Q12/U12,0) -> 1.611552 | J12: =AA12*AK12 -> 3456 | K12: =(X12*AC12)+Y12 -> 7310 | L12: =+IF(K12-J12>0,0,J12-K12) -> 0 | N12: =+IFERROR(VLOOKUP(W12,'Stock Prov. Serv.'!A:D,4,0),0) -> 0 | O12: =+IFERROR(VLOOKUP(W12,'Stock Taller'!A:D,4,0),0) -> 0 | P12: =+SUMIF('Stock CD'!B:B,'Conteo VACIO'!W12,'Stock CD'!E:E) -> 0 | Q12: =+N12+O12+P12+K12 -> 7310 | S12: =+IFERROR(VLOOKUP(W12,'Stock Taller'!A:G,7,0),0) -> 0 | T12: =+IFERROR(SUMIF('Stock CD'!B:B,'Conteo VACIO'!W12,'Stock CD'!K:K),0) -> 1080 | U12: =+S12+T12+J12 -> 4536 | W12: BOM5 | X12: 1 | AA12: =+SUMIFS(Consumo!F:F,Consumo!D:D,'Conteo VACIO'!W12) -> 1152 | AB12: =+AA12*AH12 -> 3.2832 | AC12: 7310 | AD12: 3000 | AE12: 167 | AF12: =+AD12*AH12 -> 8.55 | AG12: =+AE12/AH12 -> 58596.491 | AH12: 0.00285 | AI12: Giser | AJ12: Unidad | AK12: 3
B13: 1095500 | C13: Adorno Bombilla Bronce | D13: 0 | G13: =+IFERROR(K13/J13,0) -> 0.5787037 | H13: =+IFERROR(Q13/U13,0) -> 0.44091711 | J13: =AA13*AK13 -> 3456 | K13: =(X13*AC13)+Y13 -> 2000 | L13: =+IF(K13-J13>0,0,J13-K13) -> 1456 | N13: =+IFERROR(VLOOKUP(W13,'Stock Prov. Serv.'!A:D,4,0),0) -> 0 | O13: =+IFERROR(VLOOKUP(W13,'Stock Taller'!A:D,4,0),0) -> 0 | P13: =+SUMIF('Stock CD'!B:B,'Conteo VACIO'!W13,'Stock CD'!E:E) -> 0 | Q13: =+N13+O13+P13+K13 -> 2000 | S13: =+IFERROR(VLOOKUP(W13,'Stock Taller'!A:G,7,0),0) -> 0 | T13: =+IFERROR(SUMIF('Stock CD'!B:B,'Conteo VACIO'!W13,'Stock CD'!K:K),0) -> 1080 | U13: =+S13+T13+J13 -> 4536 | W13: BOM6 | X13: 1 | AA13: =+SUMIFS(Consumo!F:F,Consumo!D:D,'Conteo VACIO'!W13) -> 1152 | AB13: =+AA13*AH13 -> 2.016 | AC13: 2000 | AD13: 3000 | AE13: 147 | AF13: =+AD13*AH13 -> 5.25 | AG13: =+AE13/AH13 -> 84000 | AH13: 0.00175 | AI13: Giser | AJ13: Unidad | AK13: 3
B14: 1175500 | C14: Caño Inox 140 mm | D14: 0 | G14: =+IFERROR(K14/J14,0) -> 0.80475537 | H14: =+IFERROR(Q14/U14,0) -> 0.016126243 | J14: =AB14*AK14 -> 81.7938 | K14: =+((X14*AC14)+Y14)*AH14 -> 65.824 | L14: =+IF(K14-J14>0,0,J14-K14) -> 15.9698 | N14: =+IFERROR(VLOOKUP(W14,'Stock Prov. Serv.'!A:D,4,0),0) -> 0 | O14: =+IFERROR(VLOOKUP(W14,'Stock Taller'!A:D,4,0),0) -> 0 | P14: =+SUMIF('Stock CD'!B:B,'Conteo VACIO'!W14,'Stock CD'!E:E) -> 0 | Q14: =+N14+O14+P14+K14 -> 65.824 | S14: =+IFERROR(VLOOKUP(W14,'Stock Taller'!A:G,7,0),0) -> 0 | T14: =+IFERROR(SUMIF('Stock CD'!B:B,'Conteo VACIO'!W14,'Stock CD'!K:K),0) -> 4000 | U14: =+S14+T14+J14 -> 4081.7938 | W14: BOM12 | X14: 4 | AA14: =+SUMIFS(Consumo!F:F,Consumo!D:D,'Conteo VACIO'!W14) -> 2916 | AB14: =+AA14*AH14 -> 27.2646 | AC14: 1760 | AD14: =+AF14/AH14 -> 1764.7059 | AE14: =+AH14*AG14 -> 171.666 | AF14: 16.5 | AG14: 18360 | AH14: 0.00935 | AI14: Giser/Ruffo | AJ14: Kilos | AK14: 3
B15: 1093500 | C15: Caño Inox 170 mm x 0.4mm x 7 Ø | D15: 0 | G15: =+IFERROR(K15/J15,0) -> 0.86805556 | H15: =+IFERROR(Q15/U15,0) -> 0.029905205 | J15: =AB15*AK15 -> 38.5344 | K15: =+((X15*AC15)+Y15)*AH15 -> 33.45 | L15: =+IF(K15-J15>0,0,J15-K15) -> 5.0844 | N15: =+IFERROR(VLOOKUP(W15,'Stock Prov. Serv.'!A:D,4,0),0) -> 0 | O15: =+IFERROR(VLOOKUP(W15,'Stock Taller'!A:D,4,0),0) -> 0 | P15: =+SUMIF('Stock CD'!B:B,'Conteo VACIO'!W15,'Stock CD'!E:E) -> 0 | Q15: =+N15+O15+P15+K15 -> 33.45 | S15: =+IFERROR(VLOOKUP(W15,'Stock Taller'!A:G,7,0),0) -> 0 | T15: =+IFERROR(SUMIF('Stock CD'!B:B,'Conteo VACIO'!W15,'Stock CD'!K:K),0) -> 1080 | U15: =+S15+T15+J15 -> 1118.5344 | W15: BOM14 | X15: 3 | AA15: =+SUMIFS(Consumo!F:F,Consumo!D:D,'Conteo VACIO'!W15) -> 1152 | AB15: =+AA15*AH15 -> 12.8448 | AC15: 1000 | AD15: =+AF15/AH15 -> 8968.6099 | AE15: =+AH15*AG15 -> 137.7025 | AF15: 100 | AG15: 12350 | AH15: 0.01115 | AI15: Giser/Ruffo | AJ15: Kilos | AK15: 3
C17: Este pedido anula cualquier pedido anterior
C18: Bella Vista | D18: Fecha: | AA18: INFORMACION
B19: Cód ISIS | C19: Descripcion | D19: Pedido Damian | E19: Orden Prioridad | G19: % Ocup Relev | H19: % Ocup Total | J19: Max 3 Mes Uni | K19: Stock Uni | L19: Pedi Uni | N19: Stock Prov Serv Uni | O19: Stock Taller Uni | P19: Stock CD Uni | Q19: Stock Total Uni | S19: Max Taller Uni | T19: Max CD Uni | U19: Max Total Uni | W19: Sector | X19: Stock Bolsa/ Caj/ Rollo | Y19: Uni Suelta | AA19: Cons x Mes Uni | AB19: Cons x Mes Kg | AC19: Uni x B/C | AD19: Min Uni Compra | AE19: Prec x Uni | AF19: Min Kg Compra | AG19: Prec x Kg | AH19: KG x Uni | AI19: Prov | AJ19: Unidad de Medida Pedido | AK19: Max Mes
B20: 1078500 | C20: Cañito Pincel Pastelero | D20: 0 | G20: =+IFERROR(K20/J20,0) -> 27.777778 | H20: =+IFERROR(Q20/U20,0) -> 4.5045045 | J20: =AA20*AK20 -> 144 | K20: =(X20*AC20)+Y20 -> 4000 | L20: =+IF(K20-J20>0,0,J20-K20) -> 0 | N20: =+IFERROR(VLOOKUP(W20,'Stock Prov. Serv.'!A:D,4,0),0) -> 0 | O20: =+IFERROR(VLOOKUP(W20,'Stock Taller'!A:D,4,0),0) -> 0 | P20: =+SUMIF('Stock CD'!B:B,'Conteo VACIO'!W20,'Stock CD'!E:E) -> 0 | Q20: =+N20+O20+P20+K20 -> 4000 | S20: =+IFERROR(VLOOKUP(W20,'Stock Taller'!A:G,7,0),0) -> 0 | T20: =+IFERROR(SUMIF('Stock CD'!B:B,'Conteo VACIO'!W20,'Stock CD'!K:K),0) -> 744 | U20: =+S20+T20+J20 -> 888 | W20: BOM9 | X20: 2 | AA20: =+SUMIFS(Consumo!F:F,Consumo!D:D,'Conteo VACIO'!W20) -> 48 | AB20: =+AA20*AH20 -> 0.1656 | AC20: 2000 | AD20: 1000 | AE20: 132.20677 | AF20: =+AD20*AH20 -> 3.45 | AG20: =+AE20/AH20 -> 38320.803 | AH20: 0.00345 | AI20: Bella Vista | AJ20: Unidad | AK20: 3
B21: 1106500 | C21: Tapita Aluminio | D21: 0 | G21: =+IFERROR(K21/J21,0) -> 2.55947 | H21: =+IFERROR(Q21/U21,0) -> 1.9096832 | J21: =AA21*AK21 -> 13284 | K21: =(X21*AC21)+Y21 -> 34000 | L21: =+IF(K21-J21>0,0,J21-K21) -> 0 | N21: =+IFERROR(VLOOKUP(W21,'Stock Prov. Serv.'!A:D,4,0),0) -> 0 | O21: =+IFERROR(VLOOKUP(W21,'Stock Taller'!A:D,4,0),0) -> 0 | P21: =+SUMIF('Stock CD'!B:B,'Conteo VACIO'!W21,'Stock CD'!E:E) -> 0 | Q21: =+N21+O21+P21+K21 -> 34000 | S21: =+IFERROR(VLOOKUP(W21,'Stock Taller'!A:G,7,0),0) -> 0 | T21: =+IFERROR(SUMIF('Stock CD'!B:B,'Conteo VACIO'!W21,'Stock CD'!K:K),0) -> 4520 | U21: =+S21+T21+J21 -> 17804 | W21: BOM11 | X21: 2 | AA21: =+SUMIFS(Consumo!F:F,Consumo!D:D,'Conteo VACIO'!W21) -> 4428 | AB21: =+AA21*AH21 -> 5.0922 | AC21: 17000 | AD21: 26000 | AE21: 3.52 | AF21: =+AD21*AH21 -> 29.9 | AG21: =AE21/AH21 -> 3060.8696 | AH21: 0.00115 | AI21: Bella Vista | AJ21: Kilos | AK21: 3
C23: Este pedido anula cualquier pedido anterior
C24: Casa Landau | D24: Fecha: | AA24: INFORMACION
B25: Cód ISIS | C25: Descripcion | D25: Pedido Damian | E25: Orden Prioridad | G25: % Ocup Relev | H25: % Ocup Total | J25: Max 4 Mes Uni | K25: Stock Uni | L25: Pedi Uni | N25: Stock Prov Serv Uni | O25: Stock Taller Uni | P25: Stock CD Uni | Q25: Stock Total Uni | S25: Max Taller Uni | T25: Max CD Uni | U25: Max Total Uni | W25: Sector | X25: Stock Bolsa/ Caj/ Rollo | Y25: Uni Suelta | AA25: Cons x Mes Uni | AB25: Cons x Mes Kg | AC25: Uni x B/C | AD25: Min Uni Compra | AE25: Prec x Uni | AF25: Min Kg Compra | AG25: Prec x Kg | AH25: KG x Uni | AI25: Prov | AJ25: Unidad de Medida Pedido | AK25: Max Mes
A26: Casa Landau | B26: 1130500 | C26: Aro p/Llavero Grande | D26: 2000 | E26: 1 | G26: =+IFERROR(K26/J26,0) -> 0.4553348 | H26: =+IFERROR(Q26/U26,0) -> 0.25869309 | J26: =AA26*AK26 -> 3552 | K26: =(X26*AC26)+Y26 -> 1617.3492 | L26: =+IF(K26-J26>0,0,J26-K26) -> 1934.6508 | N26: =+IFERROR(VLOOKUP(W26,'Stock Prov. Serv.'!A:D,4,0),0) -> 0 | O26: =+IFERROR(VLOOKUP(W26,'Stock Taller'!A:D,4,0),0) -> 0 | P26: =+SUMIF('Stock CD'!B:B,'Conteo VACIO'!W26,'Stock CD'!E:E) -> 0 | Q26: =+N26+O26+P26+K26 -> 1617.3492 | S26: =+IFERROR(VLOOKUP(W26,'Stock Taller'!A:G,7,0),0) -> 0 | T26: =+IFERROR(SUMIF('Stock CD'!B:B,'Conteo VACIO'!W26,'Stock CD'!K:K),0) -> 2700 | U26: =+S26+T26+J26 -> 6252 | W26: Z2S | X26: 1 | Y26: 411 | AA26: =+SUMIFS(Consumo!F:F,Consumo!D:D,'Conteo VACIO'!W26) -> 888 | AB26: =+AA26*AH26 -> 2.7972 | AC26: =3.8/AH26 -> 1206.3492 | AD26: 1000 | AE26: 29.06 | AF26: =+AD26*AH26 -> 3.15 | AG26: =AE26/AH26 -> 9225.3968 | AH26: =31.5/10/1000 -> 0.00315 | AI26: Casa Landau | AJ26: Unidad | AK26: 4
A27: Casa Landau | B27: 1168500 | C27: Argolla p/Llavero Chica | D27: 0 | G27: =+IFERROR(K27/J27,0) -> 26.388889 | H27: =+IFERROR(Q27/U27,0) -> 8.5585586 | J27: =AA27*AK27 -> 576 | K27: =(X27*AC27)+Y27 -> 15200 | L27: =+IF(K27-J27>0,0,J27-K27) -> 0 | N27: =+IFERROR(VLOOKUP(W27,'Stock Prov. Serv.'!A:D,4,0),0) -> 0 | O27: =+IFERROR(VLOOKUP(W27,'Stock Taller'!A:D,4,0),0) -> 0 | P27: =+SUMIF('Stock CD'!B:B,'Conteo VACIO'!W27,'Stock CD'!E:E) -> 0 | Q27: =+N27+O27+P27+K27 -> 15200 | S27: =+IFERROR(VLOOKUP(W27,'Stock Taller'!A:G,7,0),0) -> 0 | T27: =+IFERROR(SUMIF('Stock CD'!B:B,'Conteo VACIO'!W27,'Stock CD'!K:K),0) -> 1200 | U27: =+S27+T27+J27 -> 1776 | W27: Z2SB | X27: 2 | AA27: =+SUMIFS(Consumo!F:F,Consumo!D:D,'Conteo VACIO'!W27) -> 144 | AB27: =+AA27*AH27 -> 0.072 | AC27: =3.8/AH27 -> 7600 | AD27: 1000 | AE27: 15.47 | AF27: =+AD27*AH27 -> 0.5 | AG27: =AE27/AH27 -> 30940 | AH27: =0.5/1000 -> 0.0005 | AI27: Casa Landau | AJ27: Unidad | AK27: 4
C29: Este pedido anula cualquier pedido anterior
C30: Alambres Rumbo | D30: Fecha: | AA30: INFORMACION
B31: Cód ISIS | C31: Descripcion | D31: Pedido Damian | E31: Orden Prioridad | G31: % Ocup Relev | H31: % Ocup Total | J31: Max 3 Mes Uni | K31: Stock Uni | L31: Pedi Uni | N31: Stock Prov Serv Uni | O31: Stock Taller Uni | P31: Stock CD Uni | Q31: Stock Total Uni | S31: Max Taller Uni | T31: Max CD Uni | U31: Max Total Uni | W31: Sector | X31: Stock Bolsa/ Caj/ Rollo | Y31: Uni Suelta | AA31: Cons x Mes Uni | AB31: Cons x Mes Kg | AC31: Uni x B/C | AD31: Min Uni Compra | AE31: Prec x Uni | AF31: Min Kg Compra | AG31: Prec x Kg | AH31: KG x Uni | AI31: Prov | AJ31: Unidad de Medida Pedido | AK31: Max Mes
B32: 1182500 | C32: Alambre Corta Queso | D32: 0 | G32: =+IFERROR(K32/J32,0) -> 1.8343239 | H32: =+IFERROR(Q32/U32,0) -> 1.3461034 | J32: =AA32*AK32 -> 25488 | K32: =(X32*AC32)+Y32 -> 46753.247 | L32: =+IF(K32-J32>0,0,J32-K32) -> 0 | N32: =+IFERROR(VLOOKUP(W32,'Stock Prov. Serv.'!A:D,4,0),0) -> 0 | O32: =+IFERROR(VLOOKUP(W32,'Stock Taller'!A:D,4,0),0) -> 0 | P32: =+SUMIF('Stock CD'!B:B,'Conteo VACIO'!W32,'Stock CD'!E:E) -> 0 | Q32: =+N32+O32+P32+K32 -> 46753.247 | S32: =+IFERROR(VLOOKUP(W32,'Stock Taller'!A:G,7,0),0) -> 1264.2857 | T32: =+IFERROR(SUMIF('Stock CD'!B:B,'Conteo VACIO'!W32,'Stock CD'!K:K),0) -> 7980 | U32: =+S32+T32+J32 -> 34732.286 | W32: Z19A | X32: 3 | AA32: =+SUMIFS(Consumo!F:F,Consumo!D:D,'Conteo VACIO'!W32) -> 8496 | AB32: =+AA32*AH32 -> 2.9736 | AC32: =(6/AH32)/1.1 -> 15584.416 | AD32: =+AF32/AH32 -> 17142.857 | AE32: =+AH32*AG32 -> 11.27 | AF32: 6 | AG32: 32200 | AH32: 0.00035 | AI32: Alambres Rumbo | AJ32: Kilos | AK32: 3
C34: Este pedido anula cualquier pedido anterior
C35: Rueda y Cia | D35: Fecha: | AA35: INFORMACION
B36: Cód ISIS | C36: Descripcion | D36: Pedido Damian | E36: Orden Prioridad | G36: % Ocup Relev | H36: % Ocup Total | J36: Max 3 Mes Uni | K36: Stock Uni | L36: Pedi Uni | N36: Stock Prov Serv Uni | O36: Stock Taller Uni | P36: Stock CD Uni | Q36: Stock Total Uni | S36: Max Taller Uni | T36: Max CD Uni | U36: Max Total Uni | W36: Sector | X36: Stock Bolsa/ Caj/ Rollo | Y36: Uni Suelta | AA36: Cons x Mes Uni | AB36: Cons x Mes Kg | AC36: Uni x B/C | AD36: Min Uni Compra | AE36: Prec x Uni | AF36: Min Kg Compra | AG36: Prec x Kg | AH36: KG x Uni | AI36: Prov | AJ36: Unidad de Medida Pedido | AK36: Max Mes
B37: 1136500 | C37: Cerda P/Pincel Pastelero | D37: 0 | G37: =+IFERROR(K37/J37,0) -> 7.1319444 | H37: =+IFERROR(Q37/U37,0) -> 0.91463635 | J37: =AA37*AK37 -> 144 | K37: =(X37*AC37)+Y37 -> 1027 | L37: =+IF(K37-J37>0,0,J37-K37) -> 0 | N37: =+IFERROR(VLOOKUP(W37,'Stock Prov. Serv.'!A:D,4,0),0) -> 0 | O37: =+IFERROR(VLOOKUP(W37,'Stock Taller'!A:D,4,0),0) -> 0 | P37: =+SUMIF('Stock CD'!B:B,'Conteo VACIO'!W37,'Stock CD'!E:E) -> 0 | Q37: =+N37+O37+P37+K37 -> 1027 | S37: =+IFERROR(VLOOKUP(W37,'Stock Taller'!A:G,7,0),0) -> 234.85063 | T37: =+IFERROR(SUMIF('Stock CD'!B:B,'Conteo VACIO'!W37,'Stock CD'!K:K),0) -> 744 | U37: =+S37+T37+J37 -> 1122.8506 | W37: Z19B | X37: 2 | AA37: =+SUMIFS(Consumo!F:F,Consumo!D:D,'Conteo VACIO'!W37) -> 48 | AB37: =+AA37*AH37 -> 0.096 | AC37: =1.027/AH37 -> 513.5 | AD37: =+AF37/AH37 -> 543.5 | AE37: =+AH37*AG37 -> 0.365 | AF37: 1.087 | AG37: 182.5 | AH37: 0.002 | AI37: Raspa y Cia | AJ37: Kilos | AK37: 3
C39: Este pedido anula cualquier pedido anterior
C40: Melinox | D40: Fecha: | AA40: INFORMACION
B41: Cód ISIS | C41: Descripcion | D41: Pedido Damian | E41: Orden Prioridad | G41: % Ocup Relev | H41: % Ocup Total | J41: Max 3 Mes Uni | K41: Stock Uni | L41: Pedi Uni | N41: Stock Prov Serv Uni | O41: Stock Taller Uni | P41: Stock CD Uni | Q41: Stock Total Uni | S41: Max Taller Uni | T41: Max CD Uni | U41: Max Total Uni | W41: Sector | X41: Stock Bolsa/ Caj/ Rollo | Y41: Uni Suelta | AA41: Cons x Mes Uni | AB41: Cons x Mes Kg | AC41: Uni x B/C | AD41: Min Uni Compra | AE41: Prec x Uni | AF41: Min Kg Compra | AG41: Prec x Kg | AH41: KG x Uni | AI41: Prov | AJ41: Unidad de Medida Pedido | AK41: Max Mes
B42: 5312600 | C42: Pala de Torta | D42: 0 | G42: =+IFERROR(K42/J42,0) -> 0.33333333 | H42: =+IFERROR(Q42/U42,0) -> 0.1784235 | J42: =AA42*AK42 -> 900 | K42: =(X42*AC42)+Y42 -> 300 | L42: =+IF(K42-J42>0,0,J42-K42) -> 600 | N42: =+IFERROR(VLOOKUP(W42,'Stock Prov. Serv.'!A:D,4,0),0) -> 0 | O42: =+IFERROR(VLOOKUP(W42,'Stock Taller'!A:D,4,0),0) -> 0 | P42: =+SUMIF('Stock CD'!B:B,'Conteo VACIO'!W42,'Stock CD'!E:E) -> 0 | Q42: =+N42+O42+P42+K42 -> 300 | S42: =+IFERROR(VLOOKUP(W42,'Stock Taller'!A:G,7,0),0) -> 313.39286 | T42: =+IFERROR(SUMIF('Stock CD'!B:B,'Conteo VACIO'!W42,'Stock CD'!K:K),0) -> 468 | U42: =+S42+T42+J42 -> 1681.3929 | W42: Z22 | X42: 1 | AA42: =+SUMIFS(Consumo!F:F,Consumo!D:D,'Conteo VACIO'!W42) -> 300 | AB42: =+AA42*AH42 -> 11.2 | AC42: 300 | AD42: 1200 | AE42: 1100 | AF42: =+AD42*AH42 -> 44.8 | AG42: =AE42/AH42 -> 29464.286 | AH42: 0.037333333 | AI42: Melinox | AJ42: Unidad | AK42: 3
C44: Este pedido anula cualquier pedido anterior
C45: Colodis Kufo | D45: Fecha: | AA45: INFORMACION
B46: Cód ISIS | C46: Descripcion | D46: Pedido Damian | E46: Orden Prioridad | G46: % Ocup Relev | H46: % Ocup Total | J46: Max 3 Mes Uni | K46: Stock Uni | L46: Pedi Uni | N46: Stock Prov Serv Uni | O46: Stock Taller Uni | P46: Stock CD Uni | Q46: Stock Total Uni | S46: Max Taller Uni | T46: Max CD Uni | U46: Max Total Uni | W46: Sector | X46: Stock Bolsa/ Caj/ Rollo | Y46: Uni Suelta | AA46: Cons x Mes Uni | AB46: Cons x Mes Kg | AC46: Uni x B/C | AD46: Min Uni Compra | AE46: Prec x Uni | AF46: Min Kg Compra | AG46: Prec x Kg | AH46: KG x Uni | AI46: Prov | AJ46: Unidad de Medida Pedido | AK46: Max Mes
B47: 5323600 | C47: Ralladores Cilindrico 14cm | D47: 0 | G47: =+IFERROR(K47/J47,0) -> 0 | H47: =+IFERROR(Q47/U47,0) -> 0 | J47: =AA47*AK47 -> 1332 | K47: =(X47*AC47)+Y47 -> 0 | L47: =+IF(K47-J47>0,0,J47-K47) -> 1332 | N47: =+IFERROR(VLOOKUP(W47,'Stock Prov. Serv.'!A:D,4,0),0) -> 0 | O47: =+IFERROR(VLOOKUP(W47,'Stock Taller'!A:D,4,0),0) -> 0 | P47: =+SUMIF('Stock CD'!B:B,'Conteo VACIO'!W47,'Stock CD'!E:E) -> 0 | Q47: =+N47+O47+P47+K47 -> 0 | S47: =+IFERROR(VLOOKUP(W47,'Stock Taller'!A:G,7,0),0) -> 0 | T47: =+IFERROR(SUMIF('Stock CD'!B:B,'Conteo VACIO'!W47,'Stock CD'!K:K),0) -> 720 | U47: =+S47+T47+J47 -> 2052 | W47: AA6/ AE10 | AA47: =+SUMIFS(Consumo!F:F,Consumo!D:D,'Conteo VACIO'!W47) -> 444 | AB47: =+AA47*AH47 -> 20.0355 | AC47: 60 | AD47: =600000/AE47 -> 5854.8009 | AE47: 102.48 | AF47: =+AD47*AH47 -> 264.19789 | AG47: =AE47/AH47 -> 2271.0249 | AH47: =+(180.5/4)/1000 -> 0.045125 | AI47: Colodis Kufo | AJ47: Unidad | AK47: 3
C49: Este pedido anula cualquier pedido anterior
C50: Resortes Charcas | D50: Fecha: | AA50: INFORMACION
B51: Cód ISIS | C51: Descripcion | D51: Pedido Damian | E51: Orden Prioridad | G51: % Ocup Relev | H51: % Ocup Total | J51: Max 3 Mes Uni | K51: Stock Uni | L51: Pedi Uni | N51: Stock Prov Serv Uni | O51: Stock Taller Uni | P51: Stock CD Uni | Q51: Stock Total Uni | S51: Max Taller Uni | T51: Max CD Uni | U51: Max Total Uni | W51: Sector | X51: Stock Bolsa/ Caj/ Rollo | Y51: Uni Suelta | AA51: Cons x Mes Uni | AB51: Cons x Mes Kg | AC51: Uni x B/C | AD51: Min Uni Compra | AE51: Prec x Uni | AF51: Min Kg Compra | AG51: Prec x Kg | AH51: KG x Uni | AI51: Prov | AJ51: Unidad de Medida Pedido | AK51: Max Mes
C52: Resorte p/Bombilla Autolim. | D52: 0 | G52: =+IFERROR(K52/J52,0) -> 0.86805556 | H52: =+IFERROR(Q52/U52,0) -> 0.66137566 | J52: =AA52*AK52 -> 3456 | K52: =(X52*AC52)+Y52 -> 3000 | L52: =+IF(K52-J52>0,0,J52-K52) -> 456 | N52: =+IFERROR(VLOOKUP(W52,'Stock Prov. Serv.'!A:D,4,0),0) -> 0 | O52: =+IFERROR(VLOOKUP(W52,'Stock Taller'!A:D,4,0),0) -> 0 | P52: =+SUMIF('Stock CD'!B:B,'Conteo VACIO'!W52,'Stock CD'!E:E) -> 0 | Q52: =+N52+O52+P52+K52 -> 3000 | S52: =+IFERROR(VLOOKUP(W52,'Stock Taller'!A:G,7,0),0) -> 0 | T52: =+IFERROR(SUMIF('Stock CD'!B:B,'Conteo VACIO'!W52,'Stock CD'!K:K),0) -> 1080 | U52: =+S52+T52+J52 -> 4536 | W52: BOM4 | X52: 1 | AA52: =+SUMIFS(Consumo!F:F,Consumo!D:D,'Conteo VACIO'!W52) -> 1152 | AB52: =+AA52*AH52 -> 2.0736 | AC52: 3000 | AD52: 10000 | AE52: $ 0 | AF52: =+AD52*AH52 -> 18 | AG52: =+AE52/AH52 -> 0 | AH52: 0.0018 | AI52: Resorte Charcas | AJ52: Unidad | AK52: 3
...

Sheet Stock Prov. Serv.
A1: STOCK PROV SERV BOMBILLA | F1: INFORMACION
A2: Sector Proceso | B2: Descripción Parte | C2: Stock Cajon | D2: Stock Uni | F2: Max Prov Serv Cajon | G2: Kg x Uni | H2: Uni x Cajon | I2: KG x Cajon
A3: T1 | B3: Tornillos Corta Queso | D3: =+C3*H3 -> 0 | F3: 0 | G3: 0.00129 | H3: =1299*2 -> 2598 | I3: 3.35142
A4: Z19A | B4: Alambre Corta Queso | D4: =+C4*H4 -> 0 | F4: 10 | G4: 0.00216 | H4: 13888.889 | I4: =+G4*H4 -> 30
A5: Z19B | B5: Cerda p/ Pincel | D5: =+C5*H5 -> 0 | F5: 5 | G5: 0.002 | H5: 500 | I5: 1.0535
A6: Z22 | B6: Llavero Pie | D6: =+C6*H6 -> 0 | F6: 0 | G6: 0.023983333 | H6: 1250.8687 | I6: =+G6*H6 -> 30
A7: BOM18 | B7: Caño p/ Sorbete Inox | D7: =+C7*H7 -> 0 | F7: 0 | G7: 0.0095 | H7: 500 | I7: 7
A8: BOM3 | B8: Caño Alum Bombilla p/ Anodizar | D8: =+C8*H8 -> 0 | F8: 0 | G8: 0 | H8: 3100 | I8: 11
A9: BOM4 | B9: Resortes p/ bomb. Autoli. | D9: =+C9*H9 -> 0 | F9: 0
A10: BOM5 | B10: Buje Bombilla Bronce | D10: =+C10*H10 -> 0 | F10: 0 | G10: 0.00285 | H10: 5000 | I10: 14.25
A11: BOM6 | B11: Adorno Bombilla Bronce | D11: =+C11*H11 -> 0 | F11: 0 | G11: 0.00175 | H11: 5500 | I11: 11
A12: BOM7 | B12: Resorte p/ Bombilla Crudo | D12: =+C12*H12 -> 0 | F12: 0 | G12: 0.00525
A13: BOM8 | B13: Resorte p/ Bombilla 557/558 | D13: =+C13*H13 -> 0 | F13: 0 | G13: 0.00455 | H13: 500 | I13: 2.3
A14: BOM8B | B14: Tela Manga Repostera | D14: =+C14*H14 -> 0 | F14: 0 | G14: =+IFERROR((F14*J14)/H14,0) -> 0 | H14: 950 | I14: 0
A15: BOM9 | B15: Cañito Pincel Pastelero | D15: =+C15*H15 -> 0 | F15: 0 | G15: 0.00345 | H15: 2000 | I15: 7.2
A16: BOM10 | B16: Resorte Biconico | D16: =+C16*H16 -> 0 | F16: 0 | G16: 0.0075 | H16: 400 | I16: 11.4
A17: BOM11 | B17: Tapita Aluminio | D17: =+C17*H17 -> 0 | F17: 0 | G17: 0.00115 | H17: 2000 | I17: 18.8
A18: BOM12 | B18: Caño Inox 140 mm | D18: =+C18*H18 -> 0 | F18: 0 | G18: 0.00935 | H18: 4000 | I18: 17
A19: BOM14 | B19: Caño Inox 170 mm | D19: =+C19*H19 -> 0 | F19: 0 | G19: 0.01115

Sheet Stock Taller
A1: STOCK TALLERISTA BOMBILLA | F1: INFORMACION
A2: Sector Proceso | B2: Descripción Parte | C2: Conteo Cajon | D2: Conteo Uni | F2: Max Taller Cajon | G2: Max Taller Uni | H2: Kg x Uni | I2: Uni x Cajon | J2: KG x Cajon
A3: Z19A | B3: Alambre Corta Queso | F3: 0.091028571 | G3: =+IFERROR((F3*J3)/H3,0) -> 1264.2857 | H3: 0.00216 | I3: 13888.889 | J3: =+H3*I3 -> 30
A4: Z19B | B4: Cerda p/ Pincel | F4: 0.44584838 | G4: =+IFERROR((F4*J4)/H4,0) -> 234.85063 | H4: 0.002 | I4: =1/H4 -> 500 | J4: =1053.5/1000 -> 1.0535
A5: BOM18 | B5: Caño p/ Sorbete Inox | F5: 0 | G5: =+IFERROR((F5*J5)/H5,0) -> 0 | H5: 0.0095 | I5: 500 | J5: 7
A6: BOM3 | B6: Caño Alum Bombilla p/ Anodizar | F6: 0 | G6: =+IFERROR((F6*J6)/H6,0) -> 0 | H6: =+VLOOKUP(A6,'Conteo VACIO'!C:AJ,32,0) -> #N/A | I6: 3100 | J6: 11
A7: BOM5 | B7: Buje Bombilla Bronce | F7: 0.55310621 | G7: =+IFERROR((F7*J7)/H7,0) -> 0 | H7: =+VLOOKUP(A7,'Conteo VACIO'!C:AJ,32,0) -> #N/A | I7: 5000 | J7: =+I7*H7 -> #N/A
A8: BOM6 | B8: Adorno Bombilla Bronce | F8: 0.276 | G8: =+IFERROR((F8*J8)/H8,0) -> 0 | H8: =+VLOOKUP(A8,'Conteo VACIO'!C:AJ,32,0) -> #N/A | I8: 5500 | J8: 11
A9: BOM9 | B9: Cañito Pincel Pastelero | F9: 0.285 | G9: =+IFERROR((F9*J9)/H9,0) -> 0 | H9: =+VLOOKUP(A9,'Conteo VACIO'!C:AJ,32,0) -> #N/A | I9: 2000 | J9: 7.2
A10: BOM10 | B10: Resorte Biconico | F10: 0.274 | G10: =+IFERROR((F10*J10)/H10,0) -> 0 | H10: =+VLOOKUP(A10,'Conteo VACIO'!C:AJ,32,0) -> #N/A | I10: 400 | J10: 11.4
A11: BOM11 | B11: Tapita Aluminio | F11: 4.104 | G11: =+IFERROR((F11*J11)/H11,0) -> 0 | H11: =+VLOOKUP(A11,'Conteo VACIO'!C:AJ,32,0) -> #N/A | I11: 2000 | J11: 18.8
A12: BOM12 | B12: Caño Inox 140 mm | F12: 2.1590909 | G12: =+IFERROR((F12*J12)/H12,0) -> 0 | H12: =+VLOOKUP(A12,'Conteo VACIO'!C:AJ,32,0) -> #N/A | I12: 4000 | J12: 17
A13: BOM14 | B13: Caño Inox 170 mm | F13: 1.4790997 | G13: =+IFERROR((F13*J13)/H13,0) -> 0 | H13: =+VLOOKUP(A13,'Conteo VACIO'!C:AJ,32,0) -> #N/A
A14: BOM7 | B14: Resorte p/ Bombilla Crudo | F14: 0 | G14: =+IFERROR((F14*J14)/H14,0) -> 0 | H14: =+VLOOKUP(A14,'Conteo VACIO'!C:AJ,32,0) -> #N/A
A15: BOM8 | B15: Resorte p/ Bombilla Niq | F15: 0 | G15: =+IFERROR((F15*J15)/H15,0) -> 0 | H15: =+VLOOKUP(A15,'Conteo VACIO'!C:AJ,32,0) -> #N/A | I15: 500 | J15: 2.3
A16: BOM8B | B16: Tela Manga Repostera | F16: 0 | G16: =+IFERROR((F16*J16)/H16,0) -> 0 | H16: =+VLOOKUP(A16,'Conteo VACIO'!C:AJ,32,0) -> #N/A
A17: Z2S | B17: Aro p/Llavero Grande | F17: 0 | G17: =+IFERROR((F17*J17)/H17,0) -> 0 | H17: =+VLOOKUP(A17,'Conteo VACIO'!C:AJ,32,0) -> #N/A
A18: Z22 | B18: Pala de Torta | F18: 1.3 | G18: =+IFERROR((F18*J18)/H18,0) -> 313.39286 | H18: 0.037333333 | I18: 238 | J18: 9
A19: Z2SB | B19: Argolla p/Llavero Chica | F19: 0 | G19: =+IFERROR((F19*J19)/H19,0) -> 0 | H19: =+VLOOKUP(A19,'Conteo VACIO'!C:AJ,32,0) -> #N/A | I19: 8000 | J19: 3.4
A20: A1 | B20: Arandelas Corta Queso | F20: 0 | G20: =+IFERROR((F20*J20)/H20,0) -> 0 | H20: =+VLOOKUP(A20,'Conteo VACIO'!C:AJ,32,0) -> #N/A
A21: LLF8 | B21: Batidor Pera | F21: 17.2 | G21: =+IFERROR((F21*J21)/H21,0) -> 8600 | H21: 0.0355 | I21: 500 | J21: =500*H21 -> 17.75

Sheet Stock CD
A1: STOCK VIRGILIO BOMBILLA | I1: INFORMACION
A3: Descripción de Partes | B3: Sector Proce | C3: Cod Art | D3: Stock Cajas CD | E3: Stock Uni CD | F3: Parte x Uni | G3: KG x Uni | I3: Max Cajas CD | J3: Uni x Caja | K3: Max Uni CD | L3: Max KG CD | M3: Estad Madre Uni
A4: Tapita Aluminio | B4: BOM11 | C4: 557 | D4: =+IFERROR(VLOOKUP(C4,'Stock ISIS LK'!A:D,4,0),IFERROR(VLOOKUP(C4,'Stock ISIS CH'!A:D,4,0),0)) -> 0 | E4: =+D4*F4*J4 -> 0 | F4: 1 | G4: 0.013 | I4: 33.333333 | J4: =IFERROR(VLOOKUP(C4,[2]MADRE!A:D,4,0),0) -> 24 | K4: =+I4*J4*F4 -> 800 | L4: =+K4*G4 -> 10.4 | M4: =+IFERROR(VLOOKUP(C4,'Est Madre LK 10-25'!A:C,3),VLOOKUP(C4,'Est Madre CH 10-25'!A:C,3,0)) -> 1440
A5: Tapita Aluminio | B5: BOM11 | C5: 558 | D5: =+IFERROR(VLOOKUP(C5,'Stock ISIS LK'!A:D,4,0),IFERROR(VLOOKUP(C5,'Stock ISIS CH'!A:D,4,0),0)) -> 0 | E5: =+D5*F5*J5 -> 0 | F5: 1 | G5: 0.013 | I5: 108.33333 | J5: =IFERROR(VLOOKUP(C5,[2]MADRE!A:D,4,0),0) -> 24 | K5: =+I5*J5*F5 -> 2600 | L5: =+K5*G5 -> 33.8 | M5: =+IFERROR(VLOOKUP(C5,'Est Madre LK 10-25'!A:C,3),VLOOKUP(C5,'Est Madre CH 10-25'!A:C,3,0)) -> 1440
A6: Tapita Aluminio | B6: BOM11 | C6: 573 | D6: =+IFERROR(VLOOKUP(C6,'Stock ISIS LK'!A:D,4,0),IFERROR(VLOOKUP(C6,'Stock ISIS CH'!A:D,4,0),0)) -> 0 | E6: =+D6*F6*J6 -> 0 | F6: 1 | G6: 0.013 | I6: 16.666667 | J6: =IFERROR(VLOOKUP(C6,[2]MADRE!A:D,4,0),0) -> 24 | K6: =+I6*J6*F6 -> 400 | L6: =+K6*G6 -> 5.2 | M6: =+IFERROR(VLOOKUP(C6,'Est Madre LK 10-25'!A:C,3),VLOOKUP(C6,'Est Madre CH 10-25'!A:C,3,0)) -> 24
A7: Tapita Aluminio | B7: BOM11 | C7: 755 | D7: =+IFERROR(VLOOKUP(C7,'Stock ISIS LK'!A:D,4,0),IFERROR(VLOOKUP(C7,'Stock ISIS CH'!A:D,4,0),0)) -> 0 | E7: =+D7*F7*J7 -> 0 | F7: 1 | G7: 0.013 | I7: 15 | J7: =IFERROR(VLOOKUP(C7,[2]MADRE!A:D,4,0),0) -> 24 | K7: =+I7*J7*F7 -> 360 | L7: =+K7*G7 -> 4.68 | M7: =+IFERROR(VLOOKUP(C7,'Est Madre LK 10-25'!A:C,3),VLOOKUP(C7,'Est Madre CH 10-25'!A:C,3,0)) -> 2136
A8: Tapita Aluminio | B8: BOM11 | C8: 762 | D8: =+IFERROR(VLOOKUP(C8,'Stock ISIS LK'!A:D,4,0),IFERROR(VLOOKUP(C8,'Stock ISIS CH'!A:D,4,0),0)) -> 0 | E8: =+D8*F8*J8 -> 0 | F8: 1 | G8: 0.013 | I8: 5 | J8: =IFERROR(VLOOKUP(C8,[2]MADRE!A:D,4,0),0) -> 24 | K8: =+I8*J8*F8 -> 120 | L8: =+K8*G8 -> 1.56 | M8: =+IFERROR(VLOOKUP(C8,'Est Madre LK 10-25'!A:C,3),VLOOKUP(C8,'Est Madre CH 10-25'!A:C,3,0)) -> 2136
A9: Tapita Aluminio | B9: BOM11 | C9: 763 | D9: =+IFERROR(VLOOKUP(C9,'Stock ISIS LK'!A:D,4,0),IFERROR(VLOOKUP(C9,'Stock ISIS CH'!A:D,4,0),0)) -> 0 | E9: =+D9*F9*J9 -> 0 | F9: 1 | G9: 0.013 | I9: 10 | J9: =IFERROR(VLOOKUP(C9,[2]MADRE!A:D,4,0),0) -> 24 | K9: =+I9*J9*F9 -> 240 | L9: =+K9*G9 -> 3.12 | M9: =+IFERROR(VLOOKUP(C9,'Est Madre LK 10-25'!A:C,3),VLOOKUP(C9,'Est Madre CH 10-25'!A:C,3,0)) -> 2136
A10: Caño Inox 140 mm | B10: BOM12 | C10: 557 | D10: =+IFERROR(VLOOKUP(C10,'Stock ISIS LK'!A:D,4,0),IFERROR(VLOOKUP(C10,'Stock ISIS CH'!A:D,4,0),0)) -> 0 | E10: =+D10*F10*J10 -> 0 | F10: 1 | G10: 0.0095 | I10: 33.333333 | J10: =IFERROR(VLOOKUP(C10,[2]MADRE!A:D,4,0),0) -> 24 | K10: =+I10*J10*F10 -> 800 | L10: =+K10*G10 -> 7.6 | M10: =+IFERROR(VLOOKUP(C10,'Est Madre LK 10-25'!A:C,3),VLOOKUP(C10,'Est Madre CH 10-25'!A:C,3,0)) -> 1440
A11: Caño Inox 140 mm | B11: BOM12 | C11: 558 | D11: =+IFERROR(VLOOKUP(C11,'Stock ISIS LK'!A:D,4,0),IFERROR(VLOOKUP(C11,'Stock ISIS CH'!A:D,4,0),0)) -> 0 | E11: =+D11*F11*J11 -> 0 | F11: 1 | G11: 0.0095 | I11: 108.33333 | J11: =IFERROR(VLOOKUP(C11,[2]MADRE!A:D,4,0),0) -> 24 | K11: =+I11*J11*F11 -> 2600 | L11: =+K11*G11 -> 24.7 | M11: =+IFERROR(VLOOKUP(C11,'Est Madre LK 10-25'!A:C,3),VLOOKUP(C11,'Est Madre CH 10-25'!A:C,3,0)) -> 1440
A12: Caño Inox 140 mm | B12: BOM12 | C12: 655 | D12: =+IFERROR(VLOOKUP(C12,'Stock ISIS LK'!A:D,4,0),IFERROR(VLOOKUP(C12,'Stock ISIS CH'!A:D,4,0),0)) -> 0 | E12: =+D12*F12*J12 -> 0 | F12: 1 | G12: 0.0095 | I12: 10 | J12: =IFERROR(VLOOKUP(C12,[2]MADRE!A:D,4,0),0) -> 24 | K12: =+I12*J12*F12 -> 240 | L12: =+K12*G12 -> 2.28 | M12: =+IFERROR(VLOOKUP(C12,'Est Madre LK 10-25'!A:C,3),VLOOKUP(C12,'Est Madre CH 10-25'!A:C,3,0)) -> 2136
A13: Caño Inox 140 mm | B13: BOM12 | C13: 762 | D13: =+IFERROR(VLOOKUP(C13,'Stock ISIS LK'!A:D,4,0),IFERROR(VLOOKUP(C13,'Stock ISIS CH'!A:D,4,0),0)) -> 0 | E13: =+D13*F13*J13 -> 0 | F13: 1 | G13: 0.0095 | I13: 5 | J13: =IFERROR(VLOOKUP(C13,[2]MADRE!A:D,4,0),0) -> 24 | K13: =+I13*J13*F13 -> 120 | L13: =+K13*G13 -> 1.14 | M13: =+IFERROR(VLOOKUP(C13,'Est Madre LK 10-25'!A:C,3),VLOOKUP(C13,'Est Madre CH 10-25'!A:C,3,0)) -> 2136
A14: Caño Inox 140 mm | B14: BOM12 | C14: 763 | D14: =+IFERROR(VLOOKUP(C14,'Stock ISIS LK'!A:D,4,0),IFERROR(VLOOKUP(C14,'Stock ISIS CH'!A:D,4,0),0)) -> 0 | E14: =+D14*F14*J14 -> 0 | F14: 1 | G14: 0.0095 | I14: 10 | J14: =IFERROR(VLOOKUP(C14,[2]MADRE!A:D,4,0),0) -> 24 | K14: =+I14*J14*F14 -> 240 | L14: =+K14*G14 -> 2.28 | M14: =+IFERROR(VLOOKUP(C14,'Est Madre LK 10-25'!A:C,3),VLOOKUP(C14,'Est Madre CH 10-25'!A:C,3,0)) -> 2136
A15: Caño Inox 170 mm | B15: BOM14 | C15: 654 | D15: =+IFERROR(VLOOKUP(C15,'Stock ISIS LK'!A:D,4,0),IFERROR(VLOOKUP(C15,'Stock ISIS CH'!A:D,4,0),0)) -> 0 | E15: =+D15*F15*J15 -> 0 | F15: 1 | G15: 0.0113 | I15: 37.5 | J15: =IFERROR(VLOOKUP(C15,[2]MADRE!A:D,4,0),0) -> 24 | K15: =+I15*J15*F15 -> 900 | L15: =+K15*G15 -> 10.17 | M15: =+IFERROR(VLOOKUP(C15,'Est Madre LK 10-25'!A:C,3),VLOOKUP(C15,'Est Madre CH 10-25'!A:C,3,0)) -> 2136
... A34: Resorte Batidor Pera | B34: LLF8 | C34: 802 | D34: =+IFERROR(VLOOKUP(C34,'Stock ISIS LK'!A:D,4,0),IFERROR(VLOOKUP(C34,'Stock ISIS CH'!A:D,4,0),0)) -> 0 | E34: =+D34*F34*J34 -> 0 | F34: 1 | G34: 0.0355 | I34: 100 | J34: =IFERROR(VLOOKUP(C34,[2]MADRE!A:D,4,0),0) -> 12 | K34: =+I34*J34*F34 -> 1200 | L34: =+K34*G34 -> 42.6 | M34: =+IFERROR(VLOOKUP(C34,'Est Madre LK 10-25'!A:C,3),VLOOKUP(C34,'Est Madre CH 10-25'!A:C,3,0)) -> 2136
A35: Tela Manga Repostera | B35: BOM8B | C35: 280 | D35: =+IFERROR(VLOOKUP(C35,'Stock ISIS LK'!A:D,4,0),IFERROR(VLOOKUP(C35,'Stock ISIS CH'!A:D,4,0),0)) -> 0 | E35: =+D35*F35*J35 -> 0 | F35: 1 | I35: 100 | J35: =IFERROR(VLOOKUP(C35,[2]MADRE!A:D,4,0),0) -> 12 | K35: =+I35*J35*F35 -> 1200 | L35: =+K35*G35 -> 0 | M35: =+IFERROR(VLOOKUP(C35,'Est Madre LK 10-25'!A:C,3),VLOOKUP(C35,'Est Madre CH 10-25'!A:C,3,0)) -> #N/A
A36: Alambre Corta Queso | B36: Z19A | C36: 546 | D36: =+IFERROR(VLOOKUP(C36,'Stock ISIS LK'!A:D,4,0),IFERROR(VLOOKUP(C36,'Stock ISIS CH'!A:D,4,0),0)) -> 0 | E36: =+D36*F36*J36 -> 0 | F36: 1 | G36: 0.004 | I36: 530 | J36: =IFERROR(VLOOKUP(C36,[2]MADRE!A:D,4,0),0) -> 12 | K36: =+I36*J36*F36 -> 6360 | L36: =+K36*G36 -> 25.44 | M36: =+IFERROR(VLOOKUP(C36,'Est Madre LK 10-25'!A:C,3),VLOOKUP(C36,'Est Madre CH 10-25'!A:C,3,0)) -> 1440
A37: Alambre Corta Queso | B37: Z19A | C37: 809 | D37: =+IFERROR(VLOOKUP(C37,'Stock ISIS LK'!A:D,4,0),IFERROR(VLOOKUP(C37,'Stock ISIS CH'!A:D,4,0),0)) -> 0 | E37: =+D37*F37*J37 -> 0 | F37: 1 | G37: 0.004 | I37: 135 | J37: =IFERROR(VLOOKUP(C37,[2]MADRE!A:D,4,0),0) -> 12 | K37: =+I37*J37*F37 -> 1620 | L37: =+K37*G37 -> 6.48 | M37: =+IFERROR(VLOOKUP(C37,'Est Madre LK 10-25'!A:C,3),VLOOKUP(C37,'Est Madre CH 10-25'!A:C,3,0)) -> 2136
A38: Arandelas Corta Queso | B38: A1 | C38: 546 | D38: =+IFERROR(VLOOKUP(C38,'Stock ISIS LK'!A:D,4,0),IFERROR(VLOOKUP(C38,'Stock ISIS CH'!A:D,4,0),0)) -> 0 | E38: =+D38*F38*J38 -> 0 | F38: 2 | G38: 0.0001218 | I38: 530 | J38: =IFERROR(VLOOKUP(C38,[2]MADRE!A:D,4,0),0) -> 12 | K38: =+I38*J38*F38 -> 12720 | L38: =+K38*G38 -> 1.549296 | M38: =+IFERROR(VLOOKUP(C38,'Est Madre LK 10-25'!A:C,3),VLOOKUP(C38,'Est Madre CH 10-25'!A:C,3,0)) -> 1440
A39: Arandelas Corta Queso | B39: A1 | C39: 809 | D39: =+IFERROR(VLOOKUP(C39,'Stock ISIS LK'!A:D,4,0),IFERROR(VLOOKUP(C39,'Stock ISIS CH'!A:D,4,0),0)) -> 0 | E39: =+D39*F39*J39 -> 0 | F39: 2 | G39: 0.0001218 | I39: 135 | J39: =IFERROR(VLOOKUP(C39,[2]MADRE!A:D,4,0),0) -> 12 | K39: =+I39*J39*F39 -> 3240 | L39: =+K39*G39 -> 0.394632 | M39: =+IFERROR(VLOOKUP(C39,'Est Madre LK 10-25'!A:C,3),VLOOKUP(C39,'Est Madre CH 10-25'!A:C,3,0)) -> 2136
A40: Cerda p/ Pincel | B40: Z19B | C40: 548 | D40: =+IFERROR(VLOOKUP(C40,'Stock ISIS LK'!A:D,4,0),IFERROR(VLOOKUP(C40,'Stock ISIS CH'!A:D,4,0),0)) -> 0 | E40: =+D40*F40*J40 -> 0 | F40: 1 | G40: 0.0241 | I40: 25 | J40: =IFERROR(VLOOKUP(C40,[2]MADRE!A:D,4,0),0) -> 24 | K40: =+I40*J40*F40 -> 600 | L40: =+K40*G40 -> 14.46 | M40: =+IFERROR(VLOOKUP(C40,'Est Madre LK 10-25'!A:C,3),VLOOKUP(C40,'Est Madre CH 10-25'!A:C,3,0)) -> 1440
A41: Cerda p/ Pincel | B41: Z19B | C41: 864 | D41: =+IFERROR(VLOOKUP(C41,'Stock ISIS LK'!A:D,4,0),IFERROR(VLOOKUP(C41,'Stock ISIS CH'!A:D,4,0),0)) -> 0 | E41: =+D41*F41*J41 -> 0 | F41: 1 | G41: 0.0241 | I41: 12 | J41: =IFERROR(VLOOKUP(C41,[2]MADRE!A:D,4,0),0) -> 12 | K41: =+I41*J41*F41 -> 144 | L41: =+K41*G41 -> 3.4704 | M41: =+IFERROR(VLOOKUP(C41,'Est Madre LK 10-25'!A:C,3),VLOOKUP(C41,'Est Madre CH 10-25'!A:C,3,0)) -> 2136
A42: Aro p/Llavero Grande | B42: Z2S | C42: 57 | D42: =+IFERROR(VLOOKUP(C42,'Stock ISIS LK'!A:D,4,0),IFERROR(VLOOKUP(C42,'Stock ISIS CH'!A:D,4,0),0)) -> 0 | E42: =+D42*F42*J42 -> 0 | F42: 1 | G42: 0.00315 | I42: 100 | J42: =IFERROR(VLOOKUP(C42,[2]MADRE!A:D,4,0),0) -> 12 | K42: =+I42*J42*F42 -> 1200 | L42: =+K42*G42 -> 3.78 | M42: =+IFERROR(VLOOKUP(C42,'Est Madre LK 10-25'!A:C,3),VLOOKUP(C42,'Est Madre CH 10-25'!A:C,3,0)) -> #N/A
A43: Aro p/Llavero Grande | B43: Z2S | C43: 498 | D43: =+IFERROR(VLOOKUP(C43,'Stock ISIS LK'!A:D,4,0),IFERROR(VLOOKUP(C43,'Stock ISIS CH'!A:D,4,0),0)) -> 0 | E43: =+D43*F43*J43 -> 0 | F43: 1 | G43: 0.00315 | I43: 25 | J43: =IFERROR(VLOOKUP(C43,[2]MADRE!A:D,4,0),0) -> 12 | K43: =+I43*J43*F43 -> 300 | L43: =+K43*G43 -> 0.945 | M43: =+IFERROR(VLOOKUP(C43,'Est Madre LK 10-25'!A:C,3),VLOOKUP(C43,'Est Madre CH 10-25'!A:C,3,0)) -> #N/A
A44: Aro p/Llavero Grande | B44: Z2S | C44: 499 | D44: =+IFERROR(VLOOKUP(C44,'Stock ISIS LK'!A:D,4,0),IFERROR(VLOOKUP(C44,'Stock ISIS CH'!A:D,4,0),0)) -> 0 | E44: =+D44*F44*J44 -> 0 | F44: 1 | G44: 0.00315 | I44: 100 | J44: =IFERROR(VLOOKUP(C44,[2]MADRE!A:D,4,0),0) -> 12 | K44: =+I44*J44*F44 -> 1200 | L44: =+K44*G44 -> 3.78 | M44: =+IFERROR(VLOOKUP(C44,'Est Madre LK 10-25'!A:C,3),VLOOKUP(C44,'Est Madre CH 10-25'!A:C,3,0)) -> #N/A
A45: Argolla p/Llavero Chica | B45: Z2SB | C45: 499 | D45: =+IFERROR(VLOOKUP(C45,'Stock ISIS LK'!A:D,4,0),IFERROR(VLOOKUP(C45,'Stock ISIS CH'!A:D,4,0),0)) -> 0 | E45: =+D45*F45*J45 -> 0 | F45: 1 | G45: 0.0005 | I45: 100 | J45: =IFERROR(VLOOKUP(C45,[2]MADRE!A:D,4,0),0) -> 12 | K45: =+I45*J45*F45 -> 1200 | L45: =+K45*G45 -> 0.6 | M45: =+IFERROR(VLOOKUP(C45,'Est Madre LK 10-25'!A:C,3),VLOOKUP(C45,'Est Madre CH 10-25'!A:C,3,0)) -> #N/A
A46: Ralladores Cilindrico 14cm | B46: AA6/ AE10 | C46: 323 | D46: =+IFERROR(VLOOKUP(C46,'Stock ISIS LK'!A:D,4,0),IFERROR(VLOOKUP(C46,'Stock ISIS CH'!A:D,4,0),0)) -> 0 | E46: =+D46*F46*J46 -> 0 | F46: 1 | G46: 0.045125 | I46: 20 | J46: =IFERROR(VLOOKUP(C46,[2]MADRE!A:D,4,0),0) -> 12 | K46: =+I46*J46*F46 -> 240 | L46: =+K46*G46 -> 10.83 | M46: =+IFERROR(VLOOKUP(C46,'Est Madre LK 10-25'!A:C,3),VLOOKUP(C46,'Est Madre CH 10-25'!A:C,3,0)) -> #N/A
A47: Ralladores Cilindrico 14cm | B47: AA6/ AE10 | C47: 839 | D47: =+IFERROR(VLOOKUP(C47,'Stock ISIS LK'!A:D,4,0),IFERROR(VLOOKUP(C47,'Stock ISIS CH'!A:D,4,0),0)) -> 0 | E47: =+D47*F47*J47 -> 0 | F47: 1 | G47: 0.045125 | I47: 40 | J47: =IFERROR(VLOOKUP(C47,[2]MADRE!A:D,4,0),0) -> 12 | K47: =+I47*J47*F47 -> 480 | L47: =+K47*G47 -> 21.66 | M47: =+IFERROR(VLOOKUP(C47,'Est Madre LK 10-25'!A:C,3),VLOOKUP(C47,'Est Madre CH 10-25'!A:C,3,0)) -> 2136
... A49: Pala de Torta | B49: Z22 | C49: 856 | D49: =+IFERROR(VLOOKUP(C49,'Stock ISIS LK'!A:D,4,0),IFERROR(VLOOKUP(C49,'Stock ISIS CH'!A:D,4,0),0)) -> 0 | E49: =+D49*F49*J49 -> 0 | F49: 1 | G49: 0.037333333 | I49: 6 | J49: =IFERROR(VLOOKUP(C49,[2]MADRE!A:D,4,0),0) -> 24 | K49: =+I49*J49*F49 -> 144 | L49: =+K49*G49 -> 5.376 | M49: =+IFERROR(VLOOKUP(C49,'Est Madre LK 10-25'!A:C,3),VLOOKUP(C49,'Est Madre CH 10-25'!A:C,3,0)) -> 2136

Sheet Stock ISIS LK

Sheet Stock ISIS CH

Sheet Consumo
A1: Emp | B1: Cod | C1: Descripcion | D1: Sector | E1: Descripcion | F1: Vta
A2: Loeke | B2: 557 | C2: Bombilla Resorte Chata | D2: BOM7 | E2: Resorte p/ Bombilla Crudo | F2: =+IFERROR(IF(A2="Loeke",VLOOKUP(B2,'Est Madre LK 10-25'!A:C,3,),VLOOKUP(B2,'Est Madre CH 10-25'!A:C,3,)),0) -> 288
A3: Loeke | B3: 558 | C3: Bombilla Resorte Tradicio | D3: BOM7 | E3: Resorte p/ Bombilla Crudo | F3: =+IFERROR(IF(A3="Loeke",VLOOKUP(B3,'Est Madre LK 10-25'!A:C,3,),VLOOKUP(B3,'Est Madre CH 10-25'!A:C,3,)),0) -> 2124
A4: Loeke | B4: 573 | C4: Bombilla Colores Metaliza | D4: BOM7 | E4: Resorte p/ Bombilla Crudo | F4: =+IFERROR(IF(A4="Loeke",VLOOKUP(B4,'Est Madre LK 10-25'!A:C,3,),VLOOKUP(B4,'Est Madre CH 10-25'!A:C,3,)),0) -> 360
A5: Loeke | B5: 654 | C5: Bombilla Autolimpiante In | D5: BOM7 | E5: Resorte p/ Bombilla Crudo | F5: =+IFERROR(IF(A5="Loeke",VLOOKUP(B5,'Est Madre LK 10-25'!A:C,3,),VLOOKUP(B5,'Est Madre CH 10-25'!A:C,3,)),0) -> 912
A6: Loeke | B6: 557 | C6: Bombilla Resorte Chata | D6: BOM8 | E6: Resorte p/ Bombilla Niq | F6: =+IFERROR(IF(A6="Loeke",VLOOKUP(B6,'Est Madre LK 10-25'!A:C,3,),VLOOKUP(B6,'Est Madre CH 10-25'!A:C,3,)),0) -> 288
A7: Loeke | B7: 558 | C7: Bombilla Resorte Tradicio | D7: BOM8 | E7: Resorte p/ Bombilla Niq | F7: =+IFERROR(IF(A7="Loeke",VLOOKUP(B7,'Est Madre LK 10-25'!A:C,3,),VLOOKUP(B7,'Est Madre CH 10-25'!A:C,3,)),0) -> 2124
A8: Loeke | B8: 654 | C8: Bombilla Autolimpiante In | D8: BOM8 | E8: Resorte p/ Bombilla Niq | F8: =+IFERROR(IF(A8="Loeke",VLOOKUP(B8,'Est Madre LK 10-25'!A:C,3,),VLOOKUP(B8,'Est Madre CH 10-25'!A:C,3,)),0) -> 912
A9: Loeke | B9: 573 | C9: Bombilla Colores Metaliza | D9: BOM8 | E9: Resorte p/ Bombilla Niq | F9: =+IFERROR(IF(A9="Loeke",VLOOKUP(B9,'Est Madre LK 10-25'!A:C,3,),VLOOKUP(B9,'Est Madre CH 10-25'!A:C,3,)),0) -> 360
A10: Loeke | B10: 654 | C10: Bombilla Autolimpiante In | D10: BOM4 | E10: Resorte p/ Bombilla Autolimp. | F10: =+IFERROR(IF(A10="Loeke",VLOOKUP(B10,'Est Madre LK 10-25'!A:C,3,),VLOOKUP(B10,'Est Madre CH 10-25'!A:C,3,)),0) -> 912
A11: Loeke | B11: 548 | C11: Pincel Pastelero | D11: BOM9 | E11: Cañito Pincel Pastelero | F11: =+IFERROR(IF(A11="Loeke",VLOOKUP(B11,'Est Madre LK 10-25'!A:C,3,),VLOOKUP(B11,'Est Madre CH 10-25'!A:C,3,)),0) -> 0
A12: Loeke | B12: 557 | C12: Bombilla Resorte Chata | D12: BOM11 | E12: Tapita Aluminio | F12: =+IFERROR(IF(A12="Loeke",VLOOKUP(B12,'Est Madre LK 10-25'!A:C,3,),VLOOKUP(B12,'Est Madre CH 10-25'!A:C,3,)),0) -> 288
A13: Loeke | B13: 558 | C13: Bombilla Resorte Tradicio | D13: BOM11 | E13: Tapita Aluminio | F13: =+IFERROR(IF(A13="Loeke",VLOOKUP(B13,'Est Madre LK 10-25'!A:C,3,),VLOOKUP(B13,'Est Madre CH 10-25'!A:C,3,)),0) -> 2124
... A15: Loeke | B15: 654 | C15: Bombilla Autolimpiante In | D15: BOM11 | E15: Tapita Aluminio | F15: =+IFERROR(IF(A15="Loeke",VLOOKUP(B15,'Est Madre LK 10-25'!A:C,3,),VLOOKUP(B15,'Est Madre CH 10-25'!A:C,3,)),0) -> 912
A16: Loeke | B16: 552 | C16: 0 | D16: BOM6 | E16: Adorno Bombilla Bronce | F16: =+IFERROR(IF(A16="Loeke",VLOOKUP(B16,'Est Madre LK 10-25'!A:C,3,),VLOOKUP(B16,'Est Madre CH 10-25'!A:C,3,)),0) -> 0
A17: Loeke | B17: 553 | C17: 0 | D17: BOM6 | E17: Adorno Bombilla Bronce | F17: =+IFERROR(IF(A17="Loeke",VLOOKUP(B17,'Est Madre LK 10-25'!A:C,3,),VLOOKUP(B17,'Est Madre CH 10-25'!A:C,3,)),0) -> 0
A18: Loeke | B18: 654 | C18: Bombilla Autolimpiante In | D18: BOM6 | E18: Adorno Bombilla Bronce | F18: =+IFERROR(IF(A18="Loeke",VLOOKUP(B18,'Est Madre LK 10-25'!A:C,3,),VLOOKUP(B18,'Est Madre CH 10-25'!A:C,3,)),0) -> 912
A19: Loeke | B19: 654 | C19: Bombilla Autolimpiante In | D19: BOM5 | E19: Buje Bombilla Bronce | F19: =+IFERROR(IF(A19="Loeke",VLOOKUP(B19,'Est Madre LK 10-25'!A:C,3,),VLOOKUP(B19,'Est Madre CH 10-25'!A:C,3,)),0) -> 912
A20: Loeke | B20: 557 | C20: Bombilla Resorte Chata | D20: BOM12 | E20: Caño Inox 140 mm | F20: =+IFERROR(IF(A20="Loeke",VLOOKUP(B20,'Est Madre LK 10-25'!A:C,3,),VLOOKUP(B20,'Est Madre CH 10-25'!A:C,3,)),0) -> 288
A21: Loeke | B21: 655 | C21: Bombilla Eco Plastica | D21: BOM12 | E21: Caño Inox 140 mm | F21: =+IFERROR(IF(A21="Loeke",VLOOKUP(B21,'Est Madre LK 10-25'!A:C,3,),VLOOKUP(B21,'Est Madre CH 10-25'!A:C,3,)),0) -> 0
A22: Loeke | B22: 558 | C22: Bombilla Resorte Tradicio | D22: BOM12 | E22: Caño Inox 140 mm | F22: =+IFERROR(IF(A22="Loeke",VLOOKUP(B22,'Est Madre LK 10-25'!A:C,3,),VLOOKUP(B22,'Est Madre CH 10-25'!A:C,3,)),0) -> 2124
A23: Loeke | B23: 654 | C23: Bombilla Autolimpiante In | D23: BOM14 | E23: Caño Inox 170 mm | F23: =+IFERROR(IF(A23="Loeke",VLOOKUP(B23,'Est Madre LK 10-25'!A:C,3,),VLOOKUP(B23,'Est Madre CH 10-25'!A:C,3,)),0) -> 912
A24: Loeke | B24: 573 | C24: Bombilla Colores Metaliza | D24: BOM3 | E24: Caño Alum Bombilla p/ Anodizar | F24: =+IFERROR(IF(A24="Loeke",VLOOKUP(B24,'Est Madre LK 10-25'!A:C,3,),VLOOKUP(B24,'Est Madre CH 10-25'!A:C,3,)),0) -> 360
A25: Chef | B25: 755 | C25: Bomb. Resorte Color Metal | D25: BOM7 | E25: Resorte p/ Bombilla Crudo | F25: =+IFERROR(IF(A25="Loeke",VLOOKUP(B25,'Est Madre LK 10-25'!A:C,3,),VLOOKUP(B25,'Est Madre CH 10-25'!A:C,3,)),0) -> 0
A26: Chef | B26: 762 | C26: Bombilla Resorte Chata | D26: BOM7 | E26: Resorte p/ Bombilla Crudo | F26: =+IFERROR(IF(A26="Loeke",VLOOKUP(B26,'Est Madre LK 10-25'!A:C,3,),VLOOKUP(B26,'Est Madre CH 10-25'!A:C,3,)),0) -> 24
A27: Chef | B27: 763 | C27: Bombilla Resorte Tradicio | D27: BOM7 | E27: Resorte p/ Bombilla Crudo | F27: =+IFERROR(IF(A27="Loeke",VLOOKUP(B27,'Est Madre LK 10-25'!A:C,3,),VLOOKUP(B27,'Est Madre CH 10-25'!A:C,3,)),0) -> 480
A28: Chef | B28: 769 | C28: Bomb. Autolimpiante Ac. I | D28: BOM7 | E28: Resorte p/ Bombilla Crudo | F28: =+IFERROR(IF(A28="Loeke",VLOOKUP(B28,'Est Madre LK 10-25'!A:C,3,),VLOOKUP(B28,'Est Madre CH 10-25'!A:C,3,)),0) -> 240
A29: Chef | B29: 755 | C29: Bomb. Resorte Color Metal | D29: BOM8 | E29: Resorte p/ Bombilla Niq | F29: =+IFERROR(IF(A29="Loeke",VLOOKUP(B29,'Est Madre LK 10-25'!A:C,3,),VLOOKUP(B29,'Est Madre CH 10-25'!A:C,3,)),0) -> 0
... A38: Chef | B38: 769 | C38: Bomb. Autolimpiante Ac. I | D38: BOM11 | E38: Tapita Aluminio | F38: =+IFERROR(IF(A38="Loeke",VLOOKUP(B38,'Est Madre LK 10-25'!A:C,3,),VLOOKUP(B38,'Est Madre CH 10-25'!A:C,3,)),0) -> 240
A39: Chef | B39: 766 | C39: 0 | D39: BOM6 | E39: Adorno Bombilla Bronce | F39: =+IFERROR(IF(A39="Loeke",VLOOKUP(B39,'Est Madre LK 10-25'!A:C,3,),VLOOKUP(B39,'Est Madre CH 10-25'!A:C,3,)),0) -> 0
A40: Chef | B40: 767 | C40: 0 | D40: BOM6 | E40: Adorno Bombilla Bronce | F40: =+IFERROR(IF(A40="Loeke",VLOOKUP(B40,'Est Madre LK 10-25'!A:C,3,),VLOOKUP(B40,'Est Madre CH 10-25'!A:C,3,)),0) -> 0
A41: Chef | B41: 769 | C41: Bomb. Autolimpiante Ac. I | D41: BOM6 | E41: Adorno Bombilla Bronce | F41: =+IFERROR(IF(A41="Loeke",VLOOKUP(B41,'Est Madre LK 10-25'!A:C,3,),VLOOKUP(B41,'Est Madre CH 10-25'!A:C,3,)),0) -> 240
A42: Chef | B42: 769 | C42: Bomb. Autolimpiante Ac. I | D42: BOM5 | E42: Buje Bombilla Bronce | F42: =+IFERROR(IF(A42="Loeke",VLOOKUP(B42,'Est Madre LK 10-25'!A:C,3,),VLOOKUP(B42,'Est Madre CH 10-25'!A:C,3,)),0) -> 240
A43: Chef | B43: 762 | C43: Bombilla Resorte Chata | D43: BOM12 | E43: Caño Inox 140 mm | F43: =+IFERROR(IF(A43="Loeke",VLOOKUP(B43,'Est Madre LK 10-25'!A:C,3,),VLOOKUP(B43,'Est Madre CH 10-25'!A:C,3,)),0) -> 24
A44: Chef | B44: 763 | C44: Bombilla Resorte Tradicio | D44: BOM12 | E44: Caño Inox 140 mm | F44: =+IFERROR(IF(A44="Loeke",VLOOKUP(B44,'Est Madre LK 10-25'!A:C,3,),VLOOKUP(B44,'Est Madre CH 10-25'!A:C,3,)),0) -> 480
A45: Chef | B45: 769 | C45: Bomb. Autolimpiante Ac. I | D45: BOM14 | E45: Caño Inox 170 mm | F45: =+IFERROR(IF(A45="Loeke",VLOOKUP(B45,'Est Madre LK 10-25'!A:C,3,),VLOOKUP(B45,'Est Madre CH 10-25'!A:C,3,)),0) -> 240
A46: Chef | B46: 755 | C46: Bomb. Resorte Color Metal | D46: BOM3 | E46: Caño Alum Bombilla p/ Anodizar | F46: =+IFERROR(IF(A46="Loeke",VLOOKUP(B46,'Est Madre LK 10-25'!A:C,3,),VLOOKUP(B46,'Est Madre CH 10-25'!A:C,3,)),0) -> 0
A47: Loeke | B47: 548 | C47: Pincel Pastelero | D47: Z19B | E47: Cerda P/Pincel Pastelero | F47: =+IFERROR(IF(A47="Loeke",VLOOKUP(B47,'Est Madre LK 10-25'!A:C,3,),VLOOKUP(B47,'Est Madre CH 10-25'!A:C,3,)),0) -> 0
A48: Chef | B48: 864 | C48: Pincel Pastelero | D48: Z19B | E48: Cerda P/Pincel Pastelero | F48: =+IFERROR(IF(A48="Loeke",VLOOKUP(B48,'Est Madre LK 10-25'!A:C,3,),VLOOKUP(B48,'Est Madre CH 10-25'!A:C,3,)),0) -> 48
A49: Loeke | B49: 396 | C49: Enrulador De Manteca | D49: Z31A | E49: Enrulador Largo | F49: =+IFERROR(IF(A49="Loeke",VLOOKUP(B49,'Est Madre LK 10-25'!A:C,3,),VLOOKUP(B49,'Est Madre CH 10-25'!A:C,3,)),0) -> 180
...

Sheet Est Madre LK 10-25
A5: Cod Nuevo Isis | B5: Descripcion | C5: USAR Sugerencia Uni x Mes
A6: 505 | B6: Pelador Mgo Plastico | C6: 30000
A7: 506 | B7: Abrelatas Uña | C7: 18840
A8: 513 | B8: Pelador Mgo Metalico | C8: 18204
A9: 31 | B9: Filtro De Cafe | C9: 18192
A10: 586 | B10: Pelapapas Mgo Ergonomico | C10: 6996
A11: 530 | B11: Sacacorcho Tipo Mozo Color | C11: 3600
A12: 546 | B12: Corta Queso | C12: 7200
A13: 544 | B13: Batidor Pera Alambre | C13: 7464
A14: 504 | B14: Afila Cuchillos | C14: 6996
A15: 501 | B15: Abrelatas A Manija | C15: 6912
A16: 502 | B16: Abrelatas A Mariposa | C16: 5796
A17: 321 | B17: Rallador Cilindrico | C17: 3120
... A25: 30 | B25: Colador N°20 | C25: 0
A26: 529E | B26: Sacacorcho Doble Impulso | C26: 2160
A27: 224 | B27: Cuchara Madera 30 Cm X 12 | C27: 588
A28: 29 | B28: Colador N°16 | C28: 0
A29: 558 | B29: Bombilla Resorte Tradicio | C29: 2124
A30: 523 | B30: Sacacorcho Doble Aleta | C30: 2112
A31: 512 | B31: Abrelata Mariposa Plastic | C31: 1656
A32: 521 | B32: Sacacorcho Combinado Crom | C32: 2220
A33: 581 | B33: Sacacorcho Cabo Plastico | C33: 768
A34: 531 | B34: Sacacorcho Combinado Color | C34: 1440
A35: 248 | B35: Cuchara De Cocina 33 Cm X 12 | C35: 924
A36: 555 | B36: Cepillo Limpia Bombilla | C36: 1800
A37: 575 | B37: Tapon De Vino/Cerv X1 Negro | C37: 1092
A38: 66 | B38: Abrelata Super Mariposa | C38: 2100
... A43: 562 | B43: Corta Pizza Mgo 6cm | C43: 1200
A44: 816E | B44: Pelador "V" Horizontal | C44: 1872
A45: 229 | B45: Ñoquera Madera | C45: 1008
A46: 500 | B46: Abrelata Uña Pie Color | C46: 1440
A47: 654 | B47: Bombilla Autolimpiante In | C47: 912
A48: 564 | B48: Corta Pizza Gastronomico | C48: 444
A49: 525 | B49: Sacacorcho Cabo De Madera | C49: 1392
A50: 560 | B50: Pinza Chica | C50: 660
A51: 225 | B51: Cuchara Madera 35 Cm X 12 | C51: 2400
A52: 518 | B52: Sacafuente Gastronomico | C52: 780
A53: 580 | B53: Batidor Mini | C53: 684
A54: 577 | B54: Tapon De Vino/Cerveza Premium | C54: 984
A55: 280 | B55: Manga Repostera + 4 Boqui | C55: 1300
...

Sheet Est Madre CH 10-25
A5: Cod.Art. | B5: Descripcion | C5: Prom Uni
A6: 43 | B6: Tres En Uno | C6: 240
A7: 52 | B7: Lavavajilla C/Mgo.Arte | C7: 24
A8: 53 | B8: Pinza De Fiambre*Arte* X 12 | C8: 48
A9: 54 | B9: Pinza De Ensaladas*Arte* X 12 | C9: 24
A10: 55 | B10: Pinza De Fideos*Arte* | C10: 96
A11: 61 | B11: Pinza Chica Detalles Bco Azul | C11: 0
A12: 97 | B12: Afila Cuchillo Con Base V | C12: 840
A13: 99 | B13: Pelapapas Mgo Plast Verde | C13: 2976
A14: 307 | B14: Limpia Mamadera A/I | C14: 360
A15: 453 | B15: Cuchara Fideos Nylon C/Mgo | C15: 0
A16: 454 | B16: Cucharon Nylon C/Mgo | C16: 0
A17: 455 | B17: Espatula Calada Nylon C/Mgo | C17: 0
... A106: 922 | B106: Cuchara Madera 25 Display X 12 | C106: 696
A107: 692E | B107: Pelador "V" Horizontal | C107: 240
A108: 702E | B108: Abrelatas Mariposa | C108: 1200
A109: 712E | B109: Pelador Mgo Plastico Econ | C109: 240
A110: 725E | B110: Sacacorcho Cabo De Madera | C110: 1080
A111: 727E | B111: Sacacorcho Doble Impulso | C111: 240
A112: 729E | B112: Sac Doble Aleta Fund Eco | C112: 276
A113: 733E | B113: Sacacorcho Doble Impulso | C113: 792
A114: 809E | B114: Corta Queso Blandos Mango Alambre | C114: 1680
A115: 865E | B115: Rallador Plano A/I 3 Usos | C115: 120
A116: 868E | B116: Rallador 4 Lados A/I Mgo | C116: 0
A117: 877E | B117: Corta Pizza Con Mgo Chino | C117: 204
