Workbook

Sheet Planimetría & Nota de Ped.
B1: Fecha: | F1: Cotado Por:
B2: Listado Cartones Loekemeyer | I2: Stocks | L2: Pedido
B3: Tipo | C3: Ubic | D3: COD. | E3: Lin. | F3: Cartón | G3: ART. | H3: Vta. 2017 | I3: Stock Max | J3: Stock Min | K3: Stock Real | L3: Ped. | M3: Ped Correg
B4: Bolsa | C4: A2 | D4: 031D | E4: Lk | F4: Bolsa | G4: Filtro De Cafe | H4: 12813.714 | I4: =+J4*2 -> 25627.429 | J4: =+H4 -> 12813.714
C5: A2 | D5: 034D | E5: Lk | F5: Bolsa | G5: Filtro De Cafe Gastronomico | H5: 970.28571 | I5: =+J5*2 -> 1940.5714 | J5: =+H5 -> 970.28571
C6: A2 | D6: 516S | E6: Lk | F6: Bolsa | G6: Destapacorona Suelto | H6: 305 | I6: =+J6*2 -> 610 | J6: =+H6 -> 305
C7: A2 | D7: 35 | E7: P.P | F7: Bolsa | G7: Filtro De Cafe | H7: 1356 | I7: =+J7*2 -> 2712 | J7: =+H7 -> 1356
B8: Linea Lkmeyer / Aro | C8: B1 | D8: 324D | E8: Lk | F8: Pliegos Utensilios | G8: Pinche De Choclo X4 | H8: 42
C9: B1 | D9: 322D | E9: Lk | F9: Pliegos Utensilios | G9: Tenedor De Copetin X6 Unid | H9: 130.28571
C10: B1 | E10: Lk | F10: Pliegos Utensilios | H10: =SUM(H8:H9) -> 172.28571 | I10: =+J10*2 -> 344.57143 | J10: =+H10 -> 172.28571
C11: B1 | D11: 552D | E11: Lk | F11: Pliegos x 16 | G11: Bombilla Sup Niq Larga Recta | H11: 258
C12: B1 | D12: 553D | E12: Lk | F12: Pliegos x 16 | G12: Bombilla Super Niq Larga Curva | H12: 244
C13: B1 | D13: 554D | E13: Lk | F13: Pliegos x 16 | G13: Cucharita Matera | H13: 243.42857
C14: B1 | D14: 555D | E14: Lk | F14: Pliegos x 16 | G14: Cepillo Limpia Bombilla | H14: 1163.4286
C15: B1 | D15: 557D | E15: Lk | F15: Pliegos x 16 | G15: Bombilla Resorte Chata | H15: 230.85714
C16: B1 | D16: 558D | E16: Lk | F16: Pliegos x 16 | G16: Bombilla Resorte Tradicio | H16: 208
C17: B1 | D17: 654D | E17: Lk | F17: Pliegos x 16 | G17: Bombilla Autolimpiante Inox | H17: 788.57143
C18: B1 | D18: 657D | E18: Lk | F18: Pliegos x 16 | G18: Bombilla Autolimpiante Niq | H18: 526.28571
C19: B1 | D19: 658D | E19: Lk | F19: Pliegos x 16 | G19: Bombilla Basica Larga Recta | H19: 126.85714
C20: B1 | D20: 659D | E20: Lk | F20: Pliegos x 16 | G20: Bombilla Basica Larga Curva | H20: 248
C21: B1 | D21: 573D | E21: Lk | F21: Pliegos x 16 | G21: Bombilla Colores Metaliza | H21: 277.71429
C22: B1 | E22: Lk | F22: Pliegos x 16 | H22: =SUM(H11:H21) -> 4315.1429 | I22: =+J22*2 -> 8630.2857 | J22: =+H22 -> 4315.1429
C23: B2 | D23: 506D | E23: Lk | F23: Pliego Uña x 12 | G23: Abrelatas Uña | H23: 22355.286 | I23: =+H23 -> 22355.286 | J23: =+I23/2 -> 11177.643
C24: B3 | D24: 537D | E24: Lk | F24: Carton Propio | G24: Pela Y Pica Ajo De Acero | H24: 385.71429 | I24: =+J24*2 -> 771.42857 | J24: =+H24 -> 385.71429
C25: B3 | D25: 542D | E25: Lk | F25: Carton Propio | G25: Ahueca Papas | H25: 462.85714 | I25: =+J25*2 -> 925.71429 | J25: =+H25 -> 462.85714
C26: B3 | D26: 543D | E26: Lk | F26: Cart Prop. | G26: Ahueca Frutas | H26: 368.57143 | I26: =+J26*2 -> 737.14286 | J26: =+H26 -> 368.57143
C27: B4 | D27: 029D | E27: Lk | F27: Corbata Propia | G27: Colador N°16 | H27: 1107.7143 | I27: =+J27*2 -> 2215.4286 | J27: =+H27 -> 1107.7143
C28: B4 | D28: 315D | E28: Lk | F28: Corb. Prop | G28: Pisa Papas Inox | H28: 1563.4286 | I28: =+J28*2 -> 3126.8571 | J28: =+H28 -> 1563.4286
C29: B4 | D29: 325D | E29: Lk | F29: Corb. Prop | G29: Espat. Repost Plast 1 Pza. | H29: 3252 | I29: =+J29*2 -> 6504 | J29: =+H29 -> 3252
C30: B4 | D30: 333D | E30: Lk | F30: Corbata Propia | G30: Espumadera Ac.Inox. | H30: 594.85714 | I30: =+J30*2 -> 1189.7143 | J30: =+H30 -> 594.85714
C31: B5 | D31: 230D | E31: Lk | F31: Bandita | G31: Palo De Amasar 30 Cm
C32: B5 | D32: 231D | E32: Lk | F32: Bandita | G32: Palo De Amasar 40 Cm
C33: B5 | D33: 233D | E33: Lk | F33: Bandita | G33: Palo De Amasar 50 Cm
C34: B5 | D34: 246D | E34: Lk | F34: Bandita | G34: Prensa Matambre | H34: 103.71429
C35: B5 | D35: 247D | E35: Lk | F35: Bandita | G35: Plato De Picada P.P 21 Cm | H35: 51
C36: B5 | D36: 323D | E36: Lk | F36: Bandita | G36: Rallador Cilindrico Chico | H36: 958.28571
C37: B5 | D37: 328D | E37: Lk | F37: Bandita | G37: Rallador 3 Usos Marco Plast | H37: 1150.2857
C38: B5 | D38: 329D | E38: Lk | F38: Bandita | G38: Rallador Queso Marco Plast | H38: 82.285714
C39: B5 | D39: 695D | E39: Lk | F39: Bandita | G39: Posa Pava Alambre | H39: 0
C40: B5 | D40: 36 | E40: P.P | F40: Bandita | G40: Rallador Cilindrico | H40: 384
...

Sheet Planimetría & Nota de Pedido
A1: Listado Cartones Loekemeyer | K1: Stocks
A2: Tipo | B2: Ubic | C2: COD. | D2: Lin. | E2: Tipo Carton | F2: ART. | G2: Ubic | H2: COD. | I2: Vta. 2017 | K2: Stock Max | L2: Stock Min | M2: Stock Actual | N2: Pedido
A3: Bolsa | B3: A2 | C3: 031D | D3: Lk | E3: Bolsa | F3: FILTRO DE CAFE | G3: A2 | H3: 031D | I3: 12813.714 | K3: =+L3*2 -> 25627.429 | L3: =+I3 -> 12813.714 | M3: 18500 | N3: =+K3+K4+K5+K6-M3 -> 12390
B4: A2 | C4: 034D | D4: Lk | E4: Bolsa | F4: FILTRO DE CAFE GASTRONOMICO | G4: A2 | H4: 034D | I4: 970.28571 | K4: =+L4*2 -> 1940.5714 | L4: =+I4 -> 970.28571
B5: A2 | C5: 516S | D5: Lk | E5: Bolsa | F5: DESTAPACORONA SUELTO | G5: A2 | H5: 516S | I5: 305 | K5: =+L5*2 -> 610 | L5: =+I5 -> 305
B6: A2 | C6: 35 | D6: P.P | E6: Bolsa | F6: FILTRO DE CAFE | G6: A2 | H6: 35 | I6: 1356 | K6: =+L6*2 -> 2712 | L6: =+I6 -> 1356
A7: Linea Lkmeyer / Aro | B7: B1 | C7: 324D | D7: Lk | E7: Pliegos Utensilios | F7: PINCHE DE CHOCLO X4 | G7: B1 | H7: 324D | I7: 42
B8: B1 | C8: 322D | D8: Lk | E8: Pliegos Utensilios | F8: TENEDOR DE COPETIN x6 UNID | G8: B1 | H8: 322D | I8: 130.28571
B9: B1 | D9: Lk | E9: Pliegos Utensilios | G9: B1 | I9: =SUM(I7:I8) -> 172.28571 | K9: =+L9*2 -> 344.57143 | L9: =+I9 -> 172.28571 | M9: 2000 | N9: =+K9-M9 -> -1655.4286
B10: B1 | C10: 552D | D10: Lk | E10: Pliegos x 16 | F10: BOMBILLA SUP NIQ LARGA RECTA | G10: B1 | H10: 552D | I10: 258
B11: B1 | C11: 553D | D11: Lk | E11: Pliegos x 16 | F11: BOMBILLA SUPER NIQ LARGA CURVA | G11: B1 | H11: 553D | I11: 244
B12: B1 | C12: 554D | D12: Lk | E12: Pliegos x 16 | F12: CUCHARITA MATERA | G12: B1 | H12: 554D | I12: 243.42857
B13: B1 | C13: 555D | D13: Lk | E13: Pliegos x 16 | F13: CEPILLO LIMPIA BOMBILLA | G13: B1 | H13: 555D | I13: 1163.4286
B14: B1 | C14: 557D | D14: Lk | E14: Pliegos x 16 | F14: BOMBILLA RESORTE CHATA | G14: B1 | H14: 557D | I14: 230.85714
B15: B1 | C15: 558D | D15: Lk | E15: Pliegos x 16 | F15: BOMBILLA RESORTE tradicio | G15: B1 | H15: 558D | I15: 208
B16: B1 | C16: 654D | D16: Lk | E16: Pliegos x 16 | F16: BOMBILLA AUTOLIMPIANTE INOX | G16: B1 | H16: 654D | I16: 788.57143
B17: B1 | C17: 657D | D17: Lk | E17: Pliegos x 16 | F17: BOMBILLA AUTOLIMPIANTE NIQ | G17: B1 | H17: 657D | I17: 526.28571
B18: B1 | C18: 658D | D18: Lk | E18: Pliegos x 16 | F18: BOMBILLA BASICA LARGA RECTA | G18: B1 | H18: 658D | I18: 126.85714
B19: B1 | C19: 659D | D19: Lk | E19: Pliegos x 16 | F19: BOMBILLA BASICA LARGA CURVA | G19: B1 | H19: 659D | I19: 248
B20: B1 | C20: 573D | D20: Lk | E20: Pliegos x 16 | F20: BOMBILLA COLORES METALIZA | G20: B1 | H20: 573D | I20: 277.71429
B21: B1 | D21: Lk | E21: Pliegos x 16 | G21: B1 | I21: =SUM(I10:I20) -> 4315.1429 | K21: =+L21*2 -> 8630.2857 | L21: =+I21 -> 4315.1429 | M21: 12800 | N21: =+K21-M21 -> -4169.7143
B22: B3 | C22: 537D | D22: Lk | E22: Carton Propio | F22: PELA Y PICA AJO DE ACERO | G22: B3 | H22: 537D | I22: 385.71429 | K22: =+L22*2 -> 771.42857 | L22: =+I22 -> 385.71429 | M22: 1100 | N22: =+K22-M22 -> -328.57143
B23: B3 | C23: 542D | D23: Lk | E23: Carton Propio | F23: AHUECA PAPAS | G23: B3 | H23: 542D | I23: 462.85714 | K23: =+L23*2 -> 925.71429 | L23: =+I23 -> 462.85714 | M23: 510 | N23: =+K23-M23 -> 415.71429
B24: B3 | C24: 543D | D24: Lk | E24: Carton Propio | F24: AHUECA FRUTAS | G24: B3 | H24: 543D | I24: 368.57143 | K24: =+L24*2 -> 737.14286 | L24: =+I24 -> 368.57143 | M24: 550 | N24: =+K24-M24 -> 187.14286
B25: B3 | C25: 580D | D25: Lk | E25: Carton Propio | F25: MINI BATIDOR X 1 | G25: B3 | H25: 580D | I25: 185.71429 | K25: =+L25*2 -> 371.42857 | L25: =+I25 -> 185.71429 | M25: 735 | N25: =+K25-M25 -> -363.57143
B26: B4 | C26: 029D | D26: Lk | E26: Corbata Propia | F26: COLADOR N°16 | G26: B4 | H26: 029D | I26: 1107.7143 | K26: =+L26*2 -> 2215.4286 | L26: =+I26 -> 1107.7143 | M26: 500 | N26: =+K26-M26 -> 1715.4286
B27: B4 | C27: 315D | D27: Lk | E27: Corbata Propia | F27: PISA PAPAS ACERO INOX | G27: B4 | H27: 315D | I27: 1563.4286 | K27: =+L27*2 -> 3126.8571 | L27: =+I27 -> 1563.4286 | M27: 100 | N27: =+K27-M27 -> 3026.8571
B28: B4 | C28: 325D | D28: Lk | E28: Corbata Propia | F28: ESPATULA REPOSTERA PLAST 1 PZA | G28: B4 | H28: 325D | I28: 3252 | K28: =+L28*2 -> 6504 | L28: =+I28 -> 3252 | M28: 1569 | N28: =+K28-M28 -> 4935
B29: B4 | C29: 333D | D29: Lk | E29: Corbata Propia | F29: espumadera ac.inox. | G29: B4 | H29: 333D | I29: 594.85714 | K29: =+L29*2 -> 1189.7143 | L29: =+I29 -> 594.85714 | M29: 400 | N29: =+K29-M29 -> 789.71429
B30: B5 | C30: 230D | D30: Lk | E30: Bandita | F30: PALO DE AMASAR 30 CM | G30: B5 | H30: 230D | I30: 147
B31: B5 | C31: 231D | D31: Lk | E31: Bandita | F31: PALO DE AMASAR 40 CM | G31: B5 | H31: 231D | I31: 478.28571
B32: B5 | C32: 233D | D32: Lk | E32: Bandita | F32: PALO DE AMASAR 50 CM | G32: B5 | H32: 233D | I32: 237
B33: B5 | C33: 246D | D33: Lk | E33: Bandita | F33: PRENSA MATAMBRE | G33: B5 | H33: 246D | I33: 103.71429
B34: B5 | C34: 247D | D34: Lk | E34: Bandita | F34: PLATO DE PICADA P.P 21 CM | G34: B5 | H34: 247D | I34: 51
B35: B5 | C35: 323D | D35: Lk | E35: Bandita | F35: RALLADOR CILINDRICO CHICO | G35: B5 | H35: 323D | I35: 958.28571
B36: B5 | C36: 328D | D36: Lk | E36: Bandita | F36: RALLADOR 3 USOS MARCO PLAST | G36: B5 | H36: 328D | I36: 1150.2857
B37: B5 | C37: 329D | D37: Lk | E37: Bandita | F37: RALLADOR QUESO MARCO PLAST | G37: B5 | H37: 329D | I37: 82.285714
B38: B5 | C38: 695D | D38: Lk | E38: Bandita | F38: POSA PAVA ALAMBRE | G38: B5 | H38: 695D | I38: 0
B39: B5 | C39: 36 | D39: P.P | E39: Bandita | F39: RALLADOR CILINDRICO | G39: B5 | H39: 36 | I39: 384
B40: B5 | D40: Lk | E40: Bandita | G40: B5 | I40: =SUM(I30:I39) -> 3591.8571 | K40: =+L40*2 -> 7183.7143 | L40: =+I40 -> 3591.8571 | M40: 48000 | N40: =+K40-M40 -> -40816.286
...

Sheet O.C. Roster
A1: Loekemeyer Hnos. S.R.L | D1: ORDEN DE COMPRA
A2: CUIT: | C2: 30-51584245-0
A3: DIRECCION: | C3: Cervantes 2868
A4: LOCALIDAD: | C4: Villa Devoto, CABA | D4: FECHA PEDIDO: | F4: =+TODAY() -> 46052
A5: TELEFONO: | C5: 11 3118-1027
A7: RAZON SOCIAL: | C7: ROSTER | D7: COD PROV: | E7: 3847
A9: ENTREGA EN: | C9: Cervantes 2868
A11: ESTE PEDIDO ANULA CUALQUIER PEDIDO ANTERIOR
A12: Cód ISIS | B12: N° Ord | C12: Descripción | D12: Pedido Damian Uni | E12: Fecha Entrega | F12: Entrega Uni | G12: Entrega Fecha | H12: Entrega Uni | I12: Entrega Fecha | J12: Entrega Uni | K12: Entrega Fecha
A13: 6005600 | C13: Cepillo Limpia Bombilla LK | D13: 5400
A15: 6010600 | C15: Cepillo Limpia Mamadera LK | D15: 4800
A17: 6015600 | C17: Cepillo Limpia Vajilla LK | D17: 400
A20: Chef S.R.L | D20: ORDEN DE COMPRA
A21: CUIT: | C21: 30-68575625-7
A22: DIRECCION: | C22: Virgilio 2788
A23: LOCALIDAD: | C23: Villa Devoto, CABA | D23: FECHA PEDIDO: | F23: =+TODAY() -> 46052
A24: TELEFONO: | C24: 11 3118-1027
A26: RAZON SOCIAL: | C26: ROSTER | D26: COD PROV: | E26: 3724
A28: ENTREGA EN: | C28: Cervantes 2868
A30: ESTE PEDIDO ANULA CUALQUIER PEDIDO ANTERIOR
A31: Cód ISIS | B31: N° Ord | C31: Descripción | D31: Pedido Damian Uni | E31: Fecha Entrega | F31: Entrega Uni | G31: Entrega Fecha | H31: Entrega Uni | I31: Entrega Fecha | J31: Entrega Uni | K31: Entrega Fecha
A32: 5150600 | C32: Cepillo Limpia Bombilla CH | D32: 1600
A34: 5154600 | C34: Cepillo Limpia Mamadera CH | D34: 1200
A36: 5157600 | C36: Cepillo Limpia Vajilla CH | D36: 200

Sheet O.C. Cia Integral Etiquetas
A1: Loekemeyer Hnos. S.R.L | F1: Chef SRL
A2: CUIT: | C2: 30-51584245-0 | F2: CUIT: | H2: 30-68575625-7
A3: DIRECCION: | C3: Cervantes 2868 | F3: DIRECCION: | H3: Virgilio 2788
A4: LOCALIDAD: | C4: Villa Devoto, CABA | F4: LOCALIDAD: | H4: Villa Real, CABA
A6: ORDEN DE COMPRA | F6: FECHA PEDIDO: | I6: =+TODAY() -> 46052
A8: RAZON SOCIAL: | C8: CIA INTEGRAL ETIQUETAS | D8: COD PROV: | F8: ENTREGA EN: | I8: Cervantes 2868
A10: FACTURAR Loekemeyer 70% Chef 30%
A12: ESTE PEDIDO ANULA CUALQUIER PEDIDO ANTERIOR
A13: Cód ISIS | B13: N° Ord | C13: Descripcion Material | D13: Pedido Rollo | E13: Emp | F13: Rollo a FC | G13: Fecha Pos Ent | H13: Fecha Ent | I13: Rollo Ent | J13: Fecha Ent | K13: Rollo Ent | L13: Fecha Ent | M13: Rollo Ent
A14: {=+IFERROR(INDEX('Pedido VACIO'!$C:$C,MATCH(1,('Pedido VACIO'!$I:$I=$B14)*('Pedido VACIO'!$A:$A="Cia Integral Etiquetas"),0)),"")} | B14: 1 | C14: {=+IFERROR(INDEX('Pedido VACIO'!$G:$G,MATCH(1,('Pedido VACIO'!$I:$I=$B14)*('Pedido VACIO'!$A:$A="Cia Integral Etiquetas"),0)),"")} | D14: {=+IFERROR(INDEX('Pedido VACIO'!$H:$H,MATCH(1,('Pedido VACIO'!$I:$I=$B14)*('Pedido VACIO'!$A:$A="Cia Integral Etiquetas"),0)),"")} | E14: =+IF(E13="LK","CH",IF(D14="","",IF(D14>0,"LK","CH"))) | F14: =+IF(OR(E14="LK"),ROUNDUP(D14*(VLOOKUP(B14,'Pedido VACIO'!$I:$AM,31,0)/1000),0)*10,IF(E14="CH",D13-F13,""))
E15: =+IF(E14="LK","CH",IF(D15="","",IF(D15>0,"LK","CH"))) | F15: =+IF(OR(E15="LK"),ROUNDUP(D15*(VLOOKUP(B15,'Pedido VACIO'!$I:$AM,31,0)/1000),0)*10,IF(E15="CH",D14-F14,""))
A16: {=+IFERROR(INDEX('Pedido VACIO'!$C:$C,MATCH(1,('Pedido VACIO'!$I:$I=$B16)*('Pedido VACIO'!$A:$A="Cia Integral Etiquetas"),0)),"")} | B16: =+B14+1 -> 2 | C16: {=+IFERROR(INDEX('Pedido VACIO'!$G:$G,MATCH(1,('Pedido VACIO'!$I:$I=$B16)*('Pedido VACIO'!$A:$A="Cia Integral Etiquetas"),0)),"")} | D16: {=+IFERROR(INDEX('Pedido VACIO'!$H:$H,MATCH(1,('Pedido VACIO'!$I:$I=$B16)*('Pedido VACIO'!$A:$A="Cia Integral Etiquetas"),0)),"")} | E16: =+IF(E15="LK","CH",IF(D16="","",IF(D16>0,"LK","CH"))) | F16: =+IF(OR(E16="LK"),ROUNDUP(D16*(VLOOKUP(B16,'Pedido VACIO'!$I:$AM,31,0)/1000),0)*10,IF(E16="CH",D15-F15,""))
E17: =+IF(E16="LK","CH",IF(D17="","",IF(D17>0,"LK","CH"))) | F17: =+IF(OR(E17="LK"),ROUNDUP(D17*(VLOOKUP(B17,'Pedido VACIO'!$I:$AM,31,0)/1000),0)*10,IF(E17="CH",D16-F16,""))
A18: {=+IFERROR(INDEX('Pedido VACIO'!$C:$C,MATCH(1,('Pedido VACIO'!$I:$I=$B18)*('Pedido VACIO'!$A:$A="Cia Integral Etiquetas"),0)),"")} | B18: =+B16+1 -> 3 | C18: {=+IFERROR(INDEX('Pedido VACIO'!$G:$G,MATCH(1,('Pedido VACIO'!$I:$I=$B18)*('Pedido VACIO'!$A:$A="Cia Integral Etiquetas"),0)),"")} | D18: {=+IFERROR(INDEX('Pedido VACIO'!$H:$H,MATCH(1,('Pedido VACIO'!$I:$I=$B18)*('Pedido VACIO'!$A:$A="Cia Integral Etiquetas"),0)),"")} | E18: =+IF(E17="LK","CH",IF(D18="","",IF(D18>0,"LK","CH"))) | F18: =+IF(OR(E18="LK"),ROUNDUP(D18*(VLOOKUP(B18,'Pedido VACIO'!$I:$AM,31,0)/1000),0)*10,IF(E18="CH",D17-F17,""))
E19: =+IF(E18="LK","CH",IF(D19="","",IF(D19>0,"LK","CH"))) | F19: =+IF(OR(E19="LK"),ROUNDUP(D19*(VLOOKUP(B19,'Pedido VACIO'!$I:$AM,31,0)/1000),0)*10,IF(E19="CH",D18-F18,""))
A20: {=+IFERROR(INDEX('Pedido VACIO'!$C:$C,MATCH(1,('Pedido VACIO'!$I:$I=$B20)*('Pedido VACIO'!$A:$A="Cia Integral Etiquetas"),0)),"")} | B20: =+B18+1 -> 4 | C20: {=+IFERROR(INDEX('Pedido VACIO'!$G:$G,MATCH(1,('Pedido VACIO'!$I:$I=$B20)*('Pedido VACIO'!$A:$A="Cia Integral Etiquetas"),0)),"")} | D20: {=+IFERROR(INDEX('Pedido VACIO'!$H:$H,MATCH(1,('Pedido VACIO'!$I:$I=$B20)*('Pedido VACIO'!$A:$A="Cia Integral Etiquetas"),0)),"")} | E20: =+IF(E19="LK","CH",IF(D20="","",IF(D20>0,"LK","CH"))) | F20: =+IF(OR(E20="LK"),ROUNDUP(D20*(VLOOKUP(B20,'Pedido VACIO'!$I:$AM,31,0)/1000),0)*10,IF(E20="CH",D19-F19,""))
E21: =+IF(E20="LK","CH",IF(D21="","",IF(D21>0,"LK","CH"))) | F21: =+IF(OR(E21="LK"),ROUNDUP(D21*(VLOOKUP(B21,'Pedido VACIO'!$I:$AM,31,0)/1000),0)*10,IF(E21="CH",D20-F20,""))
A22: {=+IFERROR(INDEX('Pedido VACIO'!$C:$C,MATCH(1,('Pedido VACIO'!$I:$I=$B22)*('Pedido VACIO'!$A:$A="Cia Integral Etiquetas"),0)),"")} | B22: =+B20+1 -> 5 | C22: {=+IFERROR(INDEX('Pedido VACIO'!$G:$G,MATCH(1,('Pedido VACIO'!$I:$I=$B22)*('Pedido VACIO'!$A:$A="Cia Integral Etiquetas"),0)),"")} | D22: {=+IFERROR(INDEX('Pedido VACIO'!$H:$H,MATCH(1,('Pedido VACIO'!$I:$I=$B22)*('Pedido VACIO'!$A:$A="Cia Integral Etiquetas"),0)),"")} | E22: =+IF(E21="LK","CH",IF(D22="","",IF(D22>0,"LK","CH"))) | F22: =+IF(OR(E22="LK"),ROUNDUP(D22*(VLOOKUP(B22,'Pedido VACIO'!$I:$AM,31,0)/1000),0)*10,IF(E22="CH",D21-F21,""))
E23: =+IF(E22="LK","CH",IF(D23="","",IF(D23>0,"LK","CH"))) | F23: =+IF(OR(E23="LK"),ROUNDUP(D23*(VLOOKUP(B23,'Pedido VACIO'!$I:$AM,31,0)/1000),0)*10,IF(E23="CH",D22-F22,""))
A24: {=+IFERROR(INDEX('Pedido VACIO'!$C:$C,MATCH(1,('Pedido VACIO'!$I:$I=$B24)*('Pedido VACIO'!$A:$A="Cia Integral Etiquetas"),0)),"")} | B24: =+B22+1 -> 6 | C24: {=+IFERROR(INDEX('Pedido VACIO'!$G:$G,MATCH(1,('Pedido VACIO'!$I:$I=$B24)*('Pedido VACIO'!$A:$A="Cia Integral Etiquetas"),0)),"")} | D24: {=+IFERROR(INDEX('Pedido VACIO'!$H:$H,MATCH(1,('Pedido VACIO'!$I:$I=$B24)*('Pedido VACIO'!$A:$A="Cia Integral Etiquetas"),0)),"")} | E24: =+IF(E23="LK","CH",IF(D24="","",IF(D24>0,"LK","CH"))) | F24: =+IF(OR(E24="LK"),ROUNDUP(D24*(VLOOKUP(B24,'Pedido VACIO'!$I:$AM,31,0)/1000),0)*10,IF(E24="CH",D23-F23,""))
E25: =+IF(E24="LK","CH",IF(D25="","",IF(D25>0,"LK","CH"))) | F25: =+IF(OR(E25="LK"),ROUNDUP(D25*(VLOOKUP(B25,'Pedido VACIO'!$I:$AM,31,0)/1000),0)*10,IF(E25="CH",D24-F24,""))
A26: {=+IFERROR(INDEX('Pedido VACIO'!$C:$C,MATCH(1,('Pedido VACIO'!$I:$I=$B26)*('Pedido VACIO'!$A:$A="Cia Integral Etiquetas"),0)),"")} | B26: =+B24+1 -> 7 | C26: {=+IFERROR(INDEX('Pedido VACIO'!$G:$G,MATCH(1,('Pedido VACIO'!$I:$I=$B26)*('Pedido VACIO'!$A:$A="Cia Integral Etiquetas"),0)),"")} | D26: {=+IFERROR(INDEX('Pedido VACIO'!$H:$H,MATCH(1,('Pedido VACIO'!$I:$I=$B26)*('Pedido VACIO'!$A:$A="Cia Integral Etiquetas"),0)),"")} | E26: =+IF(E25="LK","CH",IF(D26="","",IF(D26>0,"LK","CH"))) | F26: =+IF(OR(E26="LK"),ROUNDUP(D26*(VLOOKUP(B26,'Pedido VACIO'!$I:$AM,31,0)/1000),0)*10,IF(E26="CH",D25-F25,""))
E27: =+IF(E26="LK","CH",IF(D27="","",IF(D27>0,"LK","CH"))) | F27: =+IF(OR(E27="LK"),ROUNDUP(D27*(VLOOKUP(B27,'Pedido VACIO'!$I:$AM,31,0)/1000),0)*10,IF(E27="CH",D26-F26,""))
A28: {=+IFERROR(INDEX('Pedido VACIO'!$C:$C,MATCH(1,('Pedido VACIO'!$I:$I=$B28)*('Pedido VACIO'!$A:$A="Cia Integral Etiquetas"),0)),"")} | B28: =+B26+1 -> 8 | C28: {=+IFERROR(INDEX('Pedido VACIO'!$G:$G,MATCH(1,('Pedido VACIO'!$I:$I=$B28)*('Pedido VACIO'!$A:$A="Cia Integral Etiquetas"),0)),"")} | D28: {=+IFERROR(INDEX('Pedido VACIO'!$H:$H,MATCH(1,('Pedido VACIO'!$I:$I=$B28)*('Pedido VACIO'!$A:$A="Cia Integral Etiquetas"),0)),"")} | E28: =+IF(E27="LK","CH",IF(D28="","",IF(D28>0,"LK","CH"))) | F28: =+IF(OR(E28="LK"),ROUNDUP(D28*(VLOOKUP(B28,'Pedido VACIO'!$I:$AM,31,0)/1000),0)*10,IF(E28="CH",D27-F27,""))
E29: =+IF(E28="LK","CH",IF(D29="","",IF(D29>0,"LK","CH"))) | F29: =+IF(OR(E29="LK"),ROUNDUP(D29*(VLOOKUP(B29,'Pedido VACIO'!$I:$AM,31,0)/1000),0)*10,IF(E29="CH",D28-F28,""))
A30: {=+IFERROR(INDEX('Pedido VACIO'!$C:$C,MATCH(1,('Pedido VACIO'!$I:$I=$B30)*('Pedido VACIO'!$A:$A="Cia Integral Etiquetas"),0)),"")} | B30: =+B28+1 -> 9 | C30: {=+IFERROR(INDEX('Pedido VACIO'!$G:$G,MATCH(1,('Pedido VACIO'!$I:$I=$B30)*('Pedido VACIO'!$A:$A="Cia Integral Etiquetas"),0)),"")} | D30: {=+IFERROR(INDEX('Pedido VACIO'!$H:$H,MATCH(1,('Pedido VACIO'!$I:$I=$B30)*('Pedido VACIO'!$A:$A="Cia Integral Etiquetas"),0)),"")} | E30: =+IF(E29="LK","CH",IF(D30="","",IF(D30>0,"LK","CH"))) | F30: =+IF(OR(E30="LK"),ROUNDUP(D30*(VLOOKUP(B30,'Pedido VACIO'!$I:$AM,31,0)/1000),0)*10,IF(E30="CH",D29-F29,""))
E31: =+IF(E30="LK","CH",IF(D31="","",IF(D31>0,"LK","CH"))) | F31: =+IF(OR(E31="LK"),ROUNDUP(D31*(VLOOKUP(B31,'Pedido VACIO'!$I:$AM,31,0)/1000),0)*10,IF(E31="CH",D30-F30,""))
A32: {=+IFERROR(INDEX('Pedido VACIO'!$C:$C,MATCH(1,('Pedido VACIO'!$I:$I=$B32)*('Pedido VACIO'!$A:$A="Cia Integral Etiquetas"),0)),"")} | B32: =+B30+1 -> 10 | C32: {=+IFERROR(INDEX('Pedido VACIO'!$G:$G,MATCH(1,('Pedido VACIO'!$I:$I=$B32)*('Pedido VACIO'!$A:$A="Cia Integral Etiquetas"),0)),"")} | D32: {=+IFERROR(INDEX('Pedido VACIO'!$H:$H,MATCH(1,('Pedido VACIO'!$I:$I=$B32)*('Pedido VACIO'!$A:$A="Cia Integral Etiquetas"),0)),"")} | E32: =+IF(E31="LK","CH",IF(D32="","",IF(D32>0,"LK","CH"))) | F32: =+IF(OR(E32="LK"),ROUNDUP(D32*(VLOOKUP(B32,'Pedido VACIO'!$I:$AM,31,0)/1000),0)*10,IF(E32="CH",D31-F31,""))
E33: =+IF(E32="LK","CH",IF(D33="","",IF(D33>0,"LK","CH"))) | F33: =+IF(OR(E33="LK"),ROUNDUP(D33*(VLOOKUP(B33,'Pedido VACIO'!$I:$AM,31,0)/1000),0)*10,IF(E33="CH",D32-F32,""))
A34: {=+IFERROR(INDEX('Pedido VACIO'!$C:$C,MATCH(1,('Pedido VACIO'!$I:$I=$B34)*('Pedido VACIO'!$A:$A="Cia Integral Etiquetas"),0)),"")} | B34: =+B32+1 -> 11 | C34: {=+IFERROR(INDEX('Pedido VACIO'!$G:$G,MATCH(1,('Pedido VACIO'!$I:$I=$B34)*('Pedido VACIO'!$A:$A="Cia Integral Etiquetas"),0)),"")} | D34: {=+IFERROR(INDEX('Pedido VACIO'!$H:$H,MATCH(1,('Pedido VACIO'!$I:$I=$B34)*('Pedido VACIO'!$A:$A="Cia Integral Etiquetas"),0)),"")} | E34: =+IF(E33="LK","CH",IF(D34="","",IF(D34>0,"LK","CH"))) | F34: =+IF(OR(E34="LK"),ROUNDUP(D34*(VLOOKUP(B34,'Pedido VACIO'!$I:$AM,31,0)/1000),0)*10,IF(E34="CH",D33-F33,""))
E35: =+IF(E34="LK","CH",IF(D35="","",IF(D35>0,"LK","CH"))) | F35: =+IF(OR(E35="LK"),ROUNDUP(D35*(VLOOKUP(B35,'Pedido VACIO'!$I:$AM,31,0)/1000),0)*10,IF(E35="CH",D34-F34,""))
A36: {=+IFERROR(INDEX('Pedido VACIO'!$C:$C,MATCH(1,('Pedido VACIO'!$I:$I=$B36)*('Pedido VACIO'!$A:$A="Cia Integral Etiquetas"),0)),"")} | B36: =+B34+1 -> 12 | C36: {=+IFERROR(INDEX('Pedido VACIO'!$G:$G,MATCH(1,('Pedido VACIO'!$I:$I=$B36)*('Pedido VACIO'!$A:$A="Cia Integral Etiquetas"),0)),"")} | D36: {=+IFERROR(INDEX('Pedido VACIO'!$H:$H,MATCH(1,('Pedido VACIO'!$I:$I=$B36)*('Pedido VACIO'!$A:$A="Cia Integral Etiquetas"),0)),"")} | E36: =+IF(E35="LK","CH",IF(D36="","",IF(D36>0,"LK","CH"))) | F36: =+IF(OR(E36="LK"),ROUNDUP(D36*(VLOOKUP(B36,'Pedido VACIO'!$I:$AM,31,0)/1000),0)*10,IF(E36="CH",D35-F35,""))
E37: =+IF(E36="LK","CH",IF(D37="","",IF(D37>0,"LK","CH"))) | F37: =+IF(OR(E37="LK"),ROUNDUP(D37*(VLOOKUP(B37,'Pedido VACIO'!$I:$AM,31,0)/1000),0)*10,IF(E37="CH",D36-F36,""))
A38: {=+IFERROR(INDEX('Pedido VACIO'!$C:$C,MATCH(1,('Pedido VACIO'!$I:$I=$B38)*('Pedido VACIO'!$A:$A="Cia Integral Etiquetas"),0)),"")} | B38: =+B36+1 -> 13 | C38: {=+IFERROR(INDEX('Pedido VACIO'!$G:$G,MATCH(1,('Pedido VACIO'!$I:$I=$B38)*('Pedido VACIO'!$A:$A="Cia Integral Etiquetas"),0)),"")} | D38: {=+IFERROR(INDEX('Pedido VACIO'!$H:$H,MATCH(1,('Pedido VACIO'!$I:$I=$B38)*('Pedido VACIO'!$A:$A="Cia Integral Etiquetas"),0)),"")} | E38: =+IF(E37="LK","CH",IF(D38="","",IF(D38>0,"LK","CH"))) | F38: =+IF(OR(E38="LK"),ROUNDUP(D38*(VLOOKUP(B38,'Pedido VACIO'!$I:$AM,31,0)/1000),0)*10,IF(E38="CH",D37-F37,""))
E39: =+IF(E38="LK","CH",IF(D39="","",IF(D39>0,"LK","CH"))) | F39: =+IF(OR(E39="LK"),ROUNDUP(D39*(VLOOKUP(B39,'Pedido VACIO'!$I:$AM,31,0)/1000),0)*10,IF(E39="CH",D38-F38,""))
A40: {=+IFERROR(INDEX('Pedido VACIO'!$C:$C,MATCH(1,('Pedido VACIO'!$I:$I=$B40)*('Pedido VACIO'!$A:$A="Cia Integral Etiquetas"),0)),"")} | B40: =+B38+1 -> 14 | C40: {=+IFERROR(INDEX('Pedido VACIO'!$G:$G,MATCH(1,('Pedido VACIO'!$I:$I=$B40)*('Pedido VACIO'!$A:$A="Cia Integral Etiquetas"),0)),"")} | D40: {=+IFERROR(INDEX('Pedido VACIO'!$H:$H,MATCH(1,('Pedido VACIO'!$I:$I=$B40)*('Pedido VACIO'!$A:$A="Cia Integral Etiquetas"),0)),"")} | E40: =+IF(E39="LK","CH",IF(D40="","",IF(D40>0,"LK","CH"))) | F40: =+IF(OR(E40="LK"),ROUNDUP(D40*(VLOOKUP(B40,'Pedido VACIO'!$I:$AM,31,0)/1000),0)*10,IF(E40="CH",D39-F39,""))
E41: =+IF(E40="LK","CH",IF(D41="","",IF(D41>0,"LK","CH"))) | F41: =+IF(OR(E41="LK"),ROUNDUP(D41*(VLOOKUP(B41,'Pedido VACIO'!$I:$AM,31,0)/1000),0)*10,IF(E41="CH",D40-F40,""))
A42: {=+IFERROR(INDEX('Pedido VACIO'!$C:$C,MATCH(1,('Pedido VACIO'!$I:$I=$B42)*('Pedido VACIO'!$A:$A="Cia Integral Etiquetas"),0)),"")} | B42: =+B40+1 -> 15 | C42: {=+IFERROR(INDEX('Pedido VACIO'!$G:$G,MATCH(1,('Pedido VACIO'!$I:$I=$B42)*('Pedido VACIO'!$A:$A="Cia Integral Etiquetas"),0)),"")} | D42: {=+IFERROR(INDEX('Pedido VACIO'!$H:$H,MATCH(1,('Pedido VACIO'!$I:$I=$B42)*('Pedido VACIO'!$A:$A="Cia Integral Etiquetas"),0)),"")} | E42: =+IF(E41="LK","CH",IF(D42="","",IF(D42>0,"LK","CH"))) | F42: =+IF(OR(E42="LK"),ROUNDUP(D42*(VLOOKUP(B42,'Pedido VACIO'!$I:$AM,31,0)/1000),0)*10,IF(E42="CH",D41-F41,""))
E43: =+IF(E42="LK","CH",IF(D43="","",IF(D43>0,"LK","CH"))) | F43: =+IF(OR(E43="LK"),ROUNDUP(D43*(VLOOKUP(B43,'Pedido VACIO'!$I:$AM,31,0)/1000),0)*10,IF(E43="CH",D42-F42,""))
A44: {=+IFERROR(INDEX('Pedido VACIO'!$C:$C,MATCH(1,('Pedido VACIO'!$I:$I=$B44)*('Pedido VACIO'!$A:$A="Cia Integral Etiquetas"),0)),"")} | B44: =+B42+1 -> 16 | C44: {=+IFERROR(INDEX('Pedido VACIO'!$G:$G,MATCH(1,('Pedido VACIO'!$I:$I=$B44)*('Pedido VACIO'!$A:$A="Cia Integral Etiquetas"),0)),"")} | D44: {=+IFERROR(INDEX('Pedido VACIO'!$H:$H,MATCH(1,('Pedido VACIO'!$I:$I=$B44)*('Pedido VACIO'!$A:$A="Cia Integral Etiquetas"),0)),"")} | E44: =+IF(E43="LK","CH",IF(D44="","",IF(D44>0,"LK","CH"))) | F44: =+IF(OR(E44="LK"),ROUNDUP(D44*(VLOOKUP(B44,'Pedido VACIO'!$I:$AM,31,0)/1000),0)*10,IF(E44="CH",D43-F43,""))
...

Sheet O.C. Sumatik
A1: Loekemeyer Hnos. S.R.L | D1: ORDEN DE COMPRA
A2: CUIT: | C2: 30-51584245-0
A3: DIRECCION: | C3: Cervantes 2868
A4: LOCALIDAD: | C4: Villa Devoto, CABA | D4: FECHA PEDIDO: | F4: =+TODAY() -> 46052
A5: TELEFONO: | C5: 11 3118-1027
A7: RAZON SOCIAL: | C7: SUMATIK | D7: COD PROV: | E7: 2119
A9: ENTREGA EN: | C9: Cervantes 2868
A11: ESTE PEDIDO ANULA CUALQUIER PEDIDO ANTERIOR
A12: Cód ISIS | B12: N° Ord | C12: Descripción | D12: Pedido Damian Rollo | E12: Fecha Entrega | F12: Entrega Rollo | G12: Entrega Fecha | H12: Entrega Rollo | I12: Entrega Fecha | J12: Entrega Rollo | K12: Entrega Fecha
A13: 1256700 | C13: Etiqueta 49 x 25
A15: 1255700 | C15: Etiqueta 38 x 20
A17: 1258700 | C17: Etiqueta 100 x 35
A19: 1257700 | C19: Etiqueta 100 x 65
A21: 1254700 | C21: Ribbon Cera 102 x 450 Negro
A24: Chef S.R.L | D24: ORDEN DE COMPRA
A25: CUIT: | C25: 30-68575625-7
A26: DIRECCION: | C26: Virgilio 2788
A27: LOCALIDAD: | C27: Villa Devoto, CABA | D27: FECHA PEDIDO: | F27: =+TODAY() -> 46052
A28: TELEFONO: | C28: 11 3118-1027
A30: RAZON SOCIAL: | C30: SUMATIK | D30: COD PROV: | E30: 1575
A32: ENTREGA EN: | C32: Cervantes 2868
A34: ESTE PEDIDO ANULA CUALQUIER PEDIDO ANTERIOR
A35: Cód ISIS | B35: N° Ord | C35: Descripción | D35: Pedido Damian Rollo | E35: Fecha Entrega | F35: Entrega Rollo | G35: Entrega Fecha | H35: Entrega Rollo | I35: Entrega Fecha | J35: Entrega Rollo | K35: Entrega Fecha
A36: 2335700 | C36: Etiqueta 49 x 25
A38: 2338700 | C38: Etiqueta 38 x 20
A40: 2336700 | C40: Etiqueta 100 x 35
A42: 2333700 | C42: Etiqueta 100 x 65
A44: 2334700 | C44: Ribbon Cera 102 x 450 Negro

Sheet O.C. Packaging y Servicios
D1: Este pedido anula cualquier pedido anterior
D2: Packaging y Servicios | E2: Fecha: | F2: =+TODAY() -> 46052
A3: Cód ISIS | B3: Cod | D3: Sunchos | E3: Pedido Damian Rollos | F3: Orden Prioridad | H3: Fecha Entrega | J3: Entrega: | K3: Entrega: | L3: Entrega:
A4: 1251700 | B4: Varios | D4: Film Strecht Virgen
A5: 1252700 | B5: Varios | D5: Fleje Prolipropileno 11.5 mm | E5: 10

Sheet O.C. Precinter
A1: Loekemeyer Hnos. S.R.L | D1: ORDEN DE COMPRA
A2: CUIT: | B2: 30-51584245-0
A3: DIRECCION: | B3: Cervantes 2868
A4: LOCALIDAD: | B4: Villa Devoto, CABA | D4: FECHA PEDIDO: | F4: =+TODAY() -> 46052
A5: TELEFONO: | B5: 11 3118-1027
A7: RAZON SOCIAL: | B7: PRECINTER | D7: COD PROV: | E7: 4227
A9: ENTREGA EN: | B9: Cervantes 2868
A11: ESTE PEDIDO ANULA CUALQUIER PEDIDO ANTERIOR
A12: Cód ISIS | B12: N° Ord | C12: Descripción | D12: Pedido Damian Uni | E12: Fecha Entrega | F12: Entrega Uni | G12: Entrega Fecha | H12: Entrega Uni | I12: Entrega Fecha | J12: Entrega Uni | K12: Entrega Fecha
A13: 1249700 | C13: Prescintos Negros N° 8 | D13: =50000*0.7 -> 35000
A15: 1247700 | C15: Prescintos Negros N° 12 | D15: =20000*0.7 -> 14000
A17: 1248700 | C17: Prescintos Negros N° 10 | D17: =150000*0.7 -> 105000
A19: 1246700 | C19: Prescintos Negros N° 14 | D19: =10000*0.7 -> 7000
A21: 1284700 | C21: Prescintos Negros N° 16 | D21: =10000*0.7 -> 7000
A24: Chef S.R.L | D24: ORDEN DE COMPRA
A25: CUIT: | B25: 30-68575625-7
A26: DIRECCION: | B26: Virgilio 2788
A27: LOCALIDAD: | B27: Villa Devoto, CABA | D27: FECHA PEDIDO: | F27: =+TODAY() -> 46052
A28: TELEFONO: | B28: 11 3118-1027
A30: RAZON SOCIAL: | B30: PRECINTER | D30: COD PROV: | E30: 3921
A32: ENTREGA EN: | B32: Cervantes 2868
A34: ESTE PEDIDO ANULA CUALQUIER PEDIDO ANTERIOR
A35: Cód ISIS | B35: N° Ord | C35: Descripción | D35: Pedido Damian Uni | E35: Fecha Entrega | F35: Entrega Uni | G35: Entrega Fecha | H35: Entrega Uni | I35: Entrega Fecha | J35: Entrega Uni | K35: Entrega Fecha
A36: 2350700 | C36: Prescintos Negros N° 8 | D36: =50000*0.3 -> 15000
A38: 2329700 | C38: Prescintos Negros N° 12 | D38: =20000*0.3 -> 6000
A40: 2328700 | C40: Prescintos Negros N° 10 | D40: =150000*0.3 -> 45000
A42: 2330700 | C42: Prescintos Negros N° 14 | D42: =10000*0.3 -> 3000
A44: 2400700 | C44: Prescintos Negros N° 16 | D44: =10000*0.3 -> 3000

Sheet O.C. Envases Vihal
D1: Este pedido anula cualquier pedido anterior
D2: Envases Vihal | E2: Fecha: | F2: =+TODAY() -> 46052
A3: Cód ISIS | B3: Cod | C3: L | D3: Bolsas | E3: Pedido Damian | F3: Orden Prioridad | H3: Fecha Entrega | J3: Entrega: | K3: Entrega: | L3: Entrega:
A4: 1203700 | B4: 31 | C4: LK | D4: Bolsa Filtro Café LK | E4: 30000
A5: 2314700 | B5: 836 | C5: LK | D5: Bolsa Filtro Café CH
A6: 1204700 | B6: 715 | C6: CH | D6: Bolsa Cierra Bolsa

Sheet O.C. Papelera 9 de Julio
D1: Este pedido anula cualquier pedido anterior
D2: Papelera 9 de Julio | E2: Fecha: | F2: =+TODAY() -> 46052
A3: Cód ISIS | B3: Cod | C3: L | D3: Bolsas | E3: Pedido Damian | F3: Orden Prioridad | H3: Fecha Entrega | J3: Entrega: | K3: Entrega: | L3: Entrega:
A4: 1314700 | B4: 34 | C4: LK | D4: Bolsa Filtro Café Gast LK
B5: 867 | C5: CH | D5: Bolsa Filtro Café Gast CH

Sheet O.C. AJ Adhesivos
D1: Este pedido anula cualquier pedido anterior
D2: AJ Adhesivos | E2: Fecha: | F2: =+TODAY() -> 46052
A3: Cód ISIS | B3: Cod | C3: L | D3: Pliegos Adhesivado | E3: Pedido Damian | F3: Orden Prioridad | H3: Fecha Entrega | J3: Entrega: | K3: Entrega: | L3: Entrega:
A4: 1259700 | B4: 500 | C4: LK | D4: Abrelata Uña Pie
A5: 1260700 | B5: 506 | C5: LK | D5: Abrelatas Uña
A6: 1279700 | B6: 510 | C6: LK | D6: Abrelata Uña Crom
A7: 2326700 | B7: 706 | C7: CH | D7: Abrelatas Uña 706 CH
A8: 1262700 | B8: 555 | C8: LK | D8: Cepillo Limpia Bombilla
A9: 1262700 | B9: 557 | C9: LK | D9: Bombilla Resorte Chata
A10: 1262700 | B10: 558 | C10: LK | D10: Bombilla Resorte Tradici
A11: 1262700 | B11: 654 | C11: LK | D11: Bombilla AutoLimp
A12: 2326700 | B12: Varios | C12: CH | D12: Bombilla Chef

Sheet O.C. Grafica Pol
A1: Loekemeyer Hnos. S.R.L | E1: ORDEN DE COMPRA
A2: CUIT: | B2: 30-51584245-0
A3: DIRECCION: | B3: Cervantes 2868
A4: LOCALIDAD: | B4: Villa Devoto, CABA | E4: FECHA PEDIDO: | G4: =+TODAY() -> 46052
A5: TELEFONO: | B5: 11 3118-1027
A7: RAZON SOCIAL: | B7: TALLER GRAFICA POL | E7: COD PROV: | F7: 2147
A9: ENTREGA EN: | B9: Cervantes 2868
A11: ESTE PEDIDO ANULA CUALQUIER PEDIDO ANTERIOR
A12: Cód ISIS | B12: Cod | C12: N° Ord | D12: Descripcion | E12: Pedido Damian Uni | F12: Fecha Entrega | G12: Entrega Uni | H12: Entrega Fecha | I12: Entrega Uni | J12: Entrega Fecha | K12: Entrega Uni | L12: Entrega Fecha
A13: 1208700 | B13: 280 | D13: Manga Repostera + 4 Boquillas
A15: 1206700 | B15: 512 | D15: Abrelatas Mariposa Capuchon Rojo
A17: 1206700 | B17: 501 | D17: Abrelatas A Manija
A19: 1206700 | B19: 502 | D19: Abrelatas Mariposa Cromado
A21: 1217700 | B21: 222 | D21: Bate Bife Madera
A23: 1206700 | B23: 395 | D23: Descorazonador De Manzana
A25: 1206700 | B25: 570 | D25: Pala De Canelones
A27: 1206700 | B27: 559 | D27: Corta Ravioles c/Mango Loeke
A29: 1206700 | B29: 562 | D29: Corta Pizza 6cm Mgo LK
A31: 1206700 | B31: 548 | D31: Pincel Pastelero
A33: 1214700 | B33: 575 | D33: Tapon De Vino/Cerveza x1 Negro
A35: 1217700 | B35: 312 | D35: Pala De Torta Acero Inox
... A99: 1206700 | B99: 544 | D99: Batidor Pera Alambre
A101: 1217700 | B101: Varios | D101: Corbata Generica LK
A103: 1217700 | B103: 248 | D103: Cuchara Nylon Reforzada
A105: 1217700 | B105: 29 | D105: Colador Ø 16cm
A107: 1217700 | B107: 333 | D107: Espumadera Ac.Inox.
A109: 1217700 | B109: 30 | D109: Colador Ø 20cm
A111: 1217700 | B111: 26 | D111: Colador Ø 8cm
A113: 1217700 | B113: 27 | D113: Colador Ø 10cm
A115: 1217700 | B115: 225 | D115: Cuchara Madera 35 Cm
A117: 1217700 | B117: 332 | D117: Espatula Calada Ac. Inox.
A119: 1217700 | B119: 334 | D119: Cuchara Salsera Inox
A121: 1217700 | B121: 335 | D121: Cuchara Calada Ac.Inox.
A123: 1217700 | B123: 336 | D123: Cucharon Ac.Inox.
A125: 1217700 | B125: 337 | D125: Pinche Ac.Inox.
... A179: 1267700 | B179: 517 | D179: Pinza Gastronomica 25cm
A181: 1216700 | B181: Varios | D181: Bandita LK
B183: 515 | D183: Batidor Resorte
A185: Cód ISIS | B185: Cod | C185: N° Ord | D185: Pliegos SIN Adhesivar | E185: Pedido Damian Paquete | F185: Fecha Entrega | G185: Entrega Paquete | H185: Entrega Fecha | I185: Entrega Paquete | J185: Entrega Fecha | K185: Entrega Paquete | L185: Entrega Fecha
A186: 1259700 | B186: 500 | D186: Abrelata Uña Pie
...

Sheet Pedido VACIO
D1: CONTEO CARTONES Y PLIEGOS
G4: Este pedido anula cualquier pedido anterior
C5: Grafica Pol | G5: Fecha Pedido:
C7: Loekemeyer Hnos. S.R.L
C8: Tipo C - Pliego 1 Abrelatas - Troquel Abrelatas (Mariposa 12)
C9: Cód ISIS | D9: Cod | E9: Sector | F9: L | G9: Descripcion | H9: Pedido Damian Uni | I9: Orden Priori | L9: % Ocup Conteo | M9: % Ocup Virgilio | O9: Pedido Uni | P9: Max Cons 3 Mes Uni | Q9: Stock Uni | R9: Pedido Pend Uni | T9: Stock CD Uni | U9: Stock Total Uni | W9: Max CD Uni | X9: Max Total Uni | Z9: Conteo Paquete | AA9: Uni Suelta | AB9: Uni x Paq | AD9: Prov | AE9: Cons x Mes | AF9: Pedi Min Uni | AG9: Cant x Pliego | AH9: Precio Uni | AI9: Tipo de Cartón | AJ9: Agrup | AK9: Max x Mes
A10: Grafica Pol | C10: 1206700 | D10: 502 | E10: =+VLOOKUP(D10,'Conteo VACIO'!$A$8:$D$226,4,0) -> D3 | F10: LK | G10: Abrelata Mariposa Cromado | L10: =+IFERROR(Q10/P10,0) -> 0.5726363 | M10: =+IFERROR(U10/X10,0) -> 0.5726363 | O10: =IF(P10-Q10-R10<0,0,P10-Q10-R10) -> 7431 | P10: =+IFERROR(AE10*AK10,0) -> 17388 | Q10: =+(Z10*AB10)+AA10 -> 9957 | T10: =+IFERROR(SUMIFS('Stock CD'!D:D,D25,'Stock CD'!C:C),0) -> 0 | U10: =+T10+Q10 -> 9957 | W10: =+IFERROR(VLOOKUP(D10,'Stock CD'!B:I,8,0),0) -> 0 | X10: =+W10+P10 -> 17388 | Z10: =+SUMIFS('Conteo VACIO'!F:F,'Conteo VACIO'!$A:$A,$D10) -> 8 | AA10: =+SUMIFS('Conteo VACIO'!G:G,'Conteo VACIO'!$A:$A,$D10) -> 1957 | AB10: 1000 | AD10: Grafica Pol | AE10: =IF(D10="Corb-LK",SUMIFS('Est Madre LK 10-25'!C:C,'Est Madre LK 10-25'!D:D,"si"),IF(D10="Corb-CH",SUMIFS('Est Madre CH 10-25'!C:C,'Est Madre CH 10-25'!D:D,"si"),0)+IFERROR(VLOOKUP(D10,'Est Madre LK 10-25'!$A:$C,3,),IFERROR(VLOOKUP(D10,'Est Madre CH 10-25'!$A:$C,3,),0))) -> 5796 | AF10: 12000 | AG10: 6 | AH10: 68.57028 | AI10: Tipo C | AJ10: AB | AK10: 3
A11: Grafica Pol | C11: 1206700 | D11: 512 | E11: =+VLOOKUP(D11,'Conteo VACIO'!$A$8:$D$226,4,0) -> D1B | F11: LK | G11: Abrelata Mariposa Pintado | L11: =+IFERROR(Q11/P11,0) -> 1.3687601 | M11: =+IFERROR(U11/X11,0) -> 1.3687601 | O11: =IF(P11-Q11-R11<0,0,P11-Q11-R11) -> 0 | P11: =+IFERROR(AE11*AK11,0) -> 4968 | Q11: =+(Z11*AB11)+AA11 -> 6800 | T11: =+IFERROR(SUMIFS('Stock CD'!D:D,D27,'Stock CD'!C:C),0) -> 0 | U11: =+T11+Q11 -> 6800 | W11: =+IFERROR(VLOOKUP(D11,'Stock CD'!B:I,8,0),0) -> 0 | X11: =+W11+P11 -> 4968 | Z11: =+SUMIFS('Conteo VACIO'!F:F,'Conteo VACIO'!$A:$A,$D11) -> 5 | AA11: =+SUMIFS('Conteo VACIO'!G:G,'Conteo VACIO'!$A:$A,$D11) -> 1800 | AB11: 1000 | AD11: Grafica Pol | AE11: =IF(D11="Corb-LK",SUMIFS('Est Madre LK 10-25'!C:C,'Est Madre LK 10-25'!D:D,"si"),IF(D11="Corb-CH",SUMIFS('Est Madre CH 10-25'!C:C,'Est Madre CH 10-25'!D:D,"si"),0)+IFERROR(VLOOKUP(D11,'Est Madre LK 10-25'!$A:$C,3,),IFERROR(VLOOKUP(D11,'Est Madre CH 10-25'!$A:$C,3,),0))) -> 1656 | AF11: 12000 | AG11: 6 | AH11: 68.57028 | AI11: Tipo C | AJ11: AB | AK11: 3
A12: Grafica Pol | C12: 1206700 | D12: 66 | E12: =+VLOOKUP(D12,'Conteo VACIO'!$A$8:$D$226,4,0) -> D1A | F12: LK | G12: Abrelata Super Mariposa | L12: =+IFERROR(Q12/P12,0) -> 1.8079365 | M12: =+IFERROR(U12/X12,0) -> 1.8079365 | O12: =IF(P12-Q12-R12<0,0,P12-Q12-R12) -> 0 | P12: =+IFERROR(AE12*AK12,0) -> 6300 | Q12: =+(Z12*AB12)+AA12 -> 11390 | T12: =+IFERROR(SUMIFS('Stock CD'!D:D,D40,'Stock CD'!C:C),0) -> 0 | U12: =+T12+Q12 -> 11390 | W12: =+IFERROR(VLOOKUP(D12,'Stock CD'!B:I,8,0),0) -> 0 | X12: =+W12+P12 -> 6300 | Z12: =+SUMIFS('Conteo VACIO'!F:F,'Conteo VACIO'!$A:$A,$D12) -> 10 | AA12: =+SUMIFS('Conteo VACIO'!G:G,'Conteo VACIO'!$A:$A,$D12) -> 1390 | AB12: 1000 | AD12: Grafica Pol | AE12: =IF(D12="Corb-LK",SUMIFS('Est Madre LK 10-25'!C:C,'Est Madre LK 10-25'!D:D,"si"),IF(D12="Corb-CH",SUMIFS('Est Madre CH 10-25'!C:C,'Est Madre CH 10-25'!D:D,"si"),0)+IFERROR(VLOOKUP(D12,'Est Madre LK 10-25'!$A:$C,3,),IFERROR(VLOOKUP(D12,'Est Madre CH 10-25'!$A:$C,3,),0))) -> 2100 | AF12: 12000 | AG12: 6 | AH12: 68.57028 | AI12: Tipo C | AJ12: AB | AK12: 3
A13: Grafica Pol | C13: 1206700 | D13: 501 | E13: =+VLOOKUP(D13,'Conteo VACIO'!$A$8:$D$226,4,0) -> D2 | F13: LK | G13: Abrelata A Manija | L13: =+IFERROR(Q13/P13,0) -> 0.27729552 | M13: =+IFERROR(U13/X13,0) -> 0.27729552 | O13: =IF(P13-Q13-R13<0,0,P13-Q13-R13) -> 14986 | P13: =+IFERROR(AE13*AK13,0) -> 20736 | Q13: =+(Z13*AB13)+AA13 -> 5750 | T13: =+IFERROR(SUMIFS('Stock CD'!D:D,D26,'Stock CD'!C:C),0) -> 0 | U13: =+T13+Q13 -> 5750 | W13: =+IFERROR(VLOOKUP(D13,'Stock CD'!B:I,8,0),0) -> 0 | X13: =+W13+P13 -> 20736 | Z13: =+SUMIFS('Conteo VACIO'!F:F,'Conteo VACIO'!$A:$A,$D13) -> 5 | AA13: =+SUMIFS('Conteo VACIO'!G:G,'Conteo VACIO'!$A:$A,$D13) -> 750 | AB13: 1000 | AD13: Grafica Pol | AE13: =IF(D13="Corb-LK",SUMIFS('Est Madre LK 10-25'!C:C,'Est Madre LK 10-25'!D:D,"si"),IF(D13="Corb-CH",SUMIFS('Est Madre CH 10-25'!C:C,'Est Madre CH 10-25'!D:D,"si"),0)+IFERROR(VLOOKUP(D13,'Est Madre LK 10-25'!$A:$C,3,),IFERROR(VLOOKUP(D13,'Est Madre CH 10-25'!$A:$C,3,),0))) -> 6912 | AF13: 12000 | AG13: 6 | AH13: 68.57028 | AI13: Tipo C | AJ13: AB | AK13: 3
O14: =+SUM(O10:O13) -> 22417
C15: Tipo C - Pliego 2 Pelador - Troquel Pelador
A16: Grafica Pol | C16: 1207700 | D16: 513 | E16: =+VLOOKUP(D16,'Conteo VACIO'!$A$8:$D$226,4,0) -> C1 | F16: LK | G16: Pelador Mgo Metalico | L16: =+IFERROR(Q16/P16,0) -> 0.64088479 | M16: =+IFERROR(U16/X16,0) -> 0.64088479 | O16: =IF(P16-Q16-R16<0,0,P16-Q16-R16) -> 19612 | P16: =+IFERROR(AE16*AK16,0) -> 54612 | Q16: =+(Z16*AB16)+AA16 -> 35000 | T16: =+IFERROR(SUMIFS('Stock CD'!D:D,D273,'Stock CD'!C:C),0) -> 0 | U16: =+T16+Q16 -> 35000 | W16: =+IFERROR(VLOOKUP(D16,'Stock CD'!B:I,8,0),0) -> 0 | X16: =+W16+P16 -> 54612 | Z16: =+SUMIFS('Conteo VACIO'!F:F,'Conteo VACIO'!$A:$A,$D16) -> 35 | AA16: =+SUMIFS('Conteo VACIO'!G:G,'Conteo VACIO'!$A:$A,$D16) -> 0 | AB16: 1000 | AD16: Grafica Pol | AE16: =IF(D16="Corb-LK",SUMIFS('Est Madre LK 10-25'!C:C,'Est Madre LK 10-25'!D:D,"si"),IF(D16="Corb-CH",SUMIFS('Est Madre CH 10-25'!C:C,'Est Madre CH 10-25'!D:D,"si"),0)+IFERROR(VLOOKUP(D16,'Est Madre LK 10-25'!$A:$C,3,),IFERROR(VLOOKUP(D16,'Est Madre CH 10-25'!$A:$C,3,),0))) -> 18204 | AF16: 12000 | AG16: 12 | AH16: 61.33671 | AI16: Tipo C | AJ16: PEL | AK16: 3
A17: Grafica Pol | C17: 1207700 | D17: 505 | E17: =+VLOOKUP(D17,'Conteo VACIO'!$A$8:$D$226,4,0) -> B1 | F17: LK | G17: Pelador Mgo Plastico | L17: =+IFERROR(Q17/P17,0) -> 0.39205556 | M17: =+IFERROR(U17/X17,0) -> 0.39205556 | O17: =IF(P17-Q17-R17<0,0,P17-Q17-R17) -> 54715 | P17: =+IFERROR(AE17*AK17,0) -> 90000 | Q17: =+(Z17*AB17)+AA17 -> 35285 | T17: =+IFERROR(SUMIFS('Stock CD'!D:D,D274,'Stock CD'!C:C),0) -> 0 | U17: =+T17+Q17 -> 35285 | W17: =+IFERROR(VLOOKUP(D17,'Stock CD'!B:I,8,0),0) -> 0 | X17: =+W17+P17 -> 90000 | Z17: =+SUMIFS('Conteo VACIO'!F:F,'Conteo VACIO'!$A:$A,$D17) -> 35 | AA17: =+SUMIFS('Conteo VACIO'!G:G,'Conteo VACIO'!$A:$A,$D17) -> 285 | AB17: 1000 | AD17: Grafica Pol | AE17: =IF(D17="Corb-LK",SUMIFS('Est Madre LK 10-25'!C:C,'Est Madre LK 10-25'!D:D,"si"),IF(D17="Corb-CH",SUMIFS('Est Madre CH 10-25'!C:C,'Est Madre CH 10-25'!D:D,"si"),0)+IFERROR(VLOOKUP(D17,'Est Madre LK 10-25'!$A:$C,3,),IFERROR(VLOOKUP(D17,'Est Madre CH 10-25'!$A:$C,3,),0))) -> 30000 | AF17: 12000 | AG17: 12 | AH17: 61.33671 | AI17: Tipo C | AJ17: PEL | AK17: 3
A18: Grafica Pol | C18: 1207700 | D18: 586 | E18: =+VLOOKUP(D18,'Conteo VACIO'!$A$8:$D$226,4,0) -> B3 | F18: LK | G18: Pelapapas Mgo Plast Ergo | L18: =+IFERROR(Q18/P18,0) -> 1.7605298 | M18: =+IFERROR(U18/X18,0) -> 1.7605298 | O18: =IF(P18-Q18-R18<0,0,P18-Q18-R18) -> 0 | P18: =+IFERROR(AE18*AK18,0) -> 20988 | Q18: =+(Z18*AB18)+AA18 -> 36950 | T18: =+IFERROR(SUMIFS('Stock CD'!D:D,D275,'Stock CD'!C:C),0) -> 0 | U18: =+T18+Q18 -> 36950 | W18: =+IFERROR(VLOOKUP(D18,'Stock CD'!B:I,8,0),0) -> 0 | X18: =+W18+P18 -> 20988 | Z18: =+SUMIFS('Conteo VACIO'!F:F,'Conteo VACIO'!$A:$A,$D18) -> 36 | AA18: =+SUMIFS('Conteo VACIO'!G:G,'Conteo VACIO'!$A:$A,$D18) -> 950 | AB18: 1000 | AD18: Grafica Pol | AE18: =IF(D18="Corb-LK",SUMIFS('Est Madre LK 10-25'!C:C,'Est Madre LK 10-25'!D:D,"si"),IF(D18="Corb-CH",SUMIFS('Est Madre CH 10-25'!C:C,'Est Madre CH 10-25'!D:D,"si"),0)+IFERROR(VLOOKUP(D18,'Est Madre LK 10-25'!$A:$C,3,),IFERROR(VLOOKUP(D18,'Est Madre CH 10-25'!$A:$C,3,),0))) -> 6996 | AF18: 12000 | AG18: 12 | AH18: 61.33671 | AI18: Tipo C | AJ18: PEL | AK18: 3
O19: =+SUM(O16:O18) -> 74327
C20: Tipo C - Pliego 5 Sacacorchos - Troquel Utensilios
A21: Grafica Pol | C21: 1261700 | D21: 525 | E21: =+VLOOKUP(D21,'Conteo VACIO'!$A$8:$D$226,4,0) -> E1B | F21: LK | G21: Sacacorcho Cabo De Madera | L21: =+IFERROR(Q21/P21,0) -> 1.2122845 | M21: =+IFERROR(U21/X21,0) -> 1.2122845 | O21: =IF(P21-Q21-R21<0,0,P21-Q21-R21) -> 0 | P21: =+IFERROR(AE21*AK21,0) -> 5568 | Q21: =+(Z21*AB21)+AA21 -> 6750 | T21: =+IFERROR(SUMIFS('Stock CD'!D:D,D306,'Stock CD'!C:C),0) -> 0 | U21: =+T21+Q21 -> 6750 | W21: =+IFERROR(VLOOKUP(D21,'Stock CD'!B:I,8,0),0) -> 0 | X21: =+W21+P21 -> 5568 | Z21: =+SUMIFS('Conteo VACIO'!F:F,'Conteo VACIO'!$A:$A,$D21) -> 6 | AA21: =+SUMIFS('Conteo VACIO'!G:G,'Conteo VACIO'!$A:$A,$D21) -> 750 | AB21: 1000 | AD21: Grafica Pol | AE21: =IF(D21="Corb-LK",SUMIFS('Est Madre LK 10-25'!C:C,'Est Madre LK 10-25'!D:D,"si"),IF(D21="Corb-CH",SUMIFS('Est Madre CH 10-25'!C:C,'Est Madre CH 10-25'!D:D,"si"),0)+IFERROR(VLOOKUP(D21,'Est Madre LK 10-25'!$A:$C,3,),IFERROR(VLOOKUP(D21,'Est Madre CH 10-25'!$A:$C,3,),0))) -> 1392 | AF21: 12000 | AG21: 12 | AH21: 0 | AI21: Tipo C | AJ21: UT | AK21: 4
A22: Grafica Pol | C22: 1261700 | D22: 531 | E22: =+VLOOKUP(D22,'Conteo VACIO'!$A$8:$D$226,4,0) -> E4B | F22: LK | G22: Sacacorcho Combinado Color | L22: =+IFERROR(Q22/P22,0) -> 0.75520833 | M22: =+IFERROR(U22/X22,0) -> 0.75520833 | O22: =IF(P22-Q22-R22<0,0,P22-Q22-R22) -> 1410 | P22: =+IFERROR(AE22*AK22,0) -> 5760 | Q22: =+(Z22*AB22)+AA22 -> 4350 | T22: =+IFERROR(SUMIFS('Stock CD'!D:D,D307,'Stock CD'!C:C),0) -> 0 | U22: =+T22+Q22 -> 4350 | W22: =+IFERROR(VLOOKUP(D22,'Stock CD'!B:I,8,0),0) -> 0 | X22: =+W22+P22 -> 5760 | Z22: =+SUMIFS('Conteo VACIO'!F:F,'Conteo VACIO'!$A:$A,$D22) -> 4 | AA22: =+SUMIFS('Conteo VACIO'!G:G,'Conteo VACIO'!$A:$A,$D22) -> 350 | AB22: 1000 | AD22: Grafica Pol | AE22: =IF(D22="Corb-LK",SUMIFS('Est Madre LK 10-25'!C:C,'Est Madre LK 10-25'!D:D,"si"),IF(D22="Corb-CH",SUMIFS('Est Madre CH 10-25'!C:C,'Est Madre CH 10-25'!D:D,"si"),0)+IFERROR(VLOOKUP(D22,'Est Madre LK 10-25'!$A:$C,3,),IFERROR(VLOOKUP(D22,'Est Madre CH 10-25'!$A:$C,3,),0))) -> 1440 | AF22: 12000 | AG22: 12 | AH22: 0 | AI22: Tipo C | AJ22: UT | AK22: 4
A23: Grafica Pol | C23: 1261700 | D23: 521 | E23: =+VLOOKUP(D23,'Conteo VACIO'!$A$8:$D$226,4,0) -> E1A | F23: LK | G23: Sacacorcho Combinado Crom | L23: =+IFERROR(Q23/P23,0) -> 0.73198198 | M23: =+IFERROR(U23/X23,0) -> 0.73198198 | O23: =IF(P23-Q23-R23<0,0,P23-Q23-R23) -> 2380 | P23: =+IFERROR(AE23*AK23,0) -> 8880 | Q23: =+(Z23*AB23)+AA23 -> 6500 | T23: =+IFERROR(SUMIFS('Stock CD'!D:D,D308,'Stock CD'!C:C),0) -> 0 | U23: =+T23+Q23 -> 6500 | W23: =+IFERROR(VLOOKUP(D23,'Stock CD'!B:I,8,0),0) -> 0 | X23: =+W23+P23 -> 8880 | Z23: =+SUMIFS('Conteo VACIO'!F:F,'Conteo VACIO'!$A:$A,$D23) -> 6 | AA23: =+SUMIFS('Conteo VACIO'!G:G,'Conteo VACIO'!$A:$A,$D23) -> 500 | AB23: 1000 | AD23: Grafica Pol | AE23: =IF(D23="Corb-LK",SUMIFS('Est Madre LK 10-25'!C:C,'Est Madre LK 10-25'!D:D,"si"),IF(D23="Corb-CH",SUMIFS('Est Madre CH 10-25'!C:C,'Est Madre CH 10-25'!D:D,"si"),0)+IFERROR(VLOOKUP(D23,'Est Madre LK 10-25'!$A:$C,3,),IFERROR(VLOOKUP(D23,'Est Madre CH 10-25'!$A:$C,3,),0))) -> 2220 | AF23: 12000 | AG23: 12 | AH23: 0 | AI23: Tipo C | AJ23: UT | AK23: 4
A24: Grafica Pol | C24: 1261700 | D24: 523 | E24: =+VLOOKUP(D24,'Conteo VACIO'!$A$8:$D$226,4,0) -> E4A | F24: LK | G24: Sacacorcho Doble Aleta | L24: =+IFERROR(Q24/P24,0) -> 0.56463068 | M24: =+IFERROR(U24/X24,0) -> 0.56463068 | O24: =IF(P24-Q24-R24<0,0,P24-Q24-R24) -> 3678 | P24: =+IFERROR(AE24*AK24,0) -> 8448 | Q24: =+(Z24*AB24)+AA24 -> 4770 | T24: =+IFERROR(SUMIFS('Stock CD'!D:D,D309,'Stock CD'!C:C),0) -> 0 | U24: =+T24+Q24 -> 4770 | W24: =+IFERROR(VLOOKUP(D24,'Stock CD'!B:I,8,0),0) -> 0 | X24: =+W24+P24 -> 8448 | Z24: =+SUMIFS('Conteo VACIO'!F:F,'Conteo VACIO'!$A:$A,$D24) -> 4 | AA24: =+SUMIFS('Conteo VACIO'!G:G,'Conteo VACIO'!$A:$A,$D24) -> 770 | AB24: 1000 | AD24: Grafica Pol | AE24: =IF(D24="Corb-LK",SUMIFS('Est Madre LK 10-25'!C:C,'Est Madre LK 10-25'!D:D,"si"),IF(D24="Corb-CH",SUMIFS('Est Madre CH 10-25'!C:C,'Est Madre CH 10-25'!D:D,"si"),0)+IFERROR(VLOOKUP(D24,'Est Madre LK 10-25'!$A:$C,3,),IFERROR(VLOOKUP(D24,'Est Madre CH 10-25'!$A:$C,3,),0))) -> 2112 | AF24: 12000 | AG24: 12 | AH24: 0 | AI24: Tipo C | AJ24: UT | AK24: 4
A25: Grafica Pol | C25: 1261700 | D25: 581 | E25: =+VLOOKUP(D25,'Conteo VACIO'!$A$8:$D$226,4,0) -> E2B | F25: LK | G25: Sacacorcho Mgo Ergonomico | L25: =+IFERROR(Q25/P25,0) -> 2.6692708 | M25: =+IFERROR(U25/X25,0) -> 2.6692708 | O25: =IF(P25-Q25-R25<0,0,P25-Q25-R25) -> 0 | P25: =+IFERROR(AE25*AK25,0) -> 3072 | Q25: =+(Z25*AB25)+AA25 -> 8200 | T25: =+IFERROR(SUMIFS('Stock CD'!D:D,D310,'Stock CD'!C:C),0) -> 0 | U25: =+T25+Q25 -> 8200 | W25: =+IFERROR(VLOOKUP(D25,'Stock CD'!B:I,8,0),0) -> 0 | X25: =+W25+P25 -> 3072 | Z25: =+SUMIFS('Conteo VACIO'!F:F,'Conteo VACIO'!$A:$A,$D25) -> 8 | AA25: =+SUMIFS('Conteo VACIO'!G:G,'Conteo VACIO'!$A:$A,$D25) -> 200 | AB25: 1000 | AD25: Grafica Pol | AE25: =IF(D25="Corb-LK",SUMIFS('Est Madre LK 10-25'!C:C,'Est Madre LK 10-25'!D:D,"si"),IF(D25="Corb-CH",SUMIFS('Est Madre CH 10-25'!C:C,'Est Madre CH 10-25'!D:D,"si"),0)+IFERROR(VLOOKUP(D25,'Est Madre LK 10-25'!$A:$C,3,),IFERROR(VLOOKUP(D25,'Est Madre CH 10-25'!$A:$C,3,),0))) -> 768 | AF25: 12000 | AG25: 12 | AH25: 0 | AI25: Tipo C | AJ25: UT | AK25: 4
A26: Grafica Pol | C26: 1261700 | D26: 530 | E26: =+VLOOKUP(D26,'Conteo VACIO'!$A$8:$D$226,4,0) -> E3 | F26: LK | G26: Sacacorcho Tipo Mozo Color | L26: =+IFERROR(Q26/P26,0) -> 0.34375 | M26: =+IFERROR(U26/X26,0) -> 0.34375 | O26: =IF(P26-Q26-R26<0,0,P26-Q26-R26) -> 9450 | P26: =+IFERROR(AE26*AK26,0) -> 14400 | Q26: =+(Z26*AB26)+AA26 -> 4950 | T26: =+IFERROR(SUMIFS('Stock CD'!D:D,D311,'Stock CD'!C:C),0) -> 0 | U26: =+T26+Q26 -> 4950 | W26: =+IFERROR(VLOOKUP(D26,'Stock CD'!B:I,8,0),0) -> 0 | X26: =+W26+P26 -> 14400 | Z26: =+SUMIFS('Conteo VACIO'!F:F,'Conteo VACIO'!$A:$A,$D26) -> 4 | AA26: =+SUMIFS('Conteo VACIO'!G:G,'Conteo VACIO'!$A:$A,$D26) -> 950 | AB26: 1000 | AD26: Grafica Pol | AE26: =IF(D26="Corb-LK",SUMIFS('Est Madre LK 10-25'!C:C,'Est Madre LK 10-25'!D:D,"si"),IF(D26="Corb-CH",SUMIFS('Est Madre CH 10-25'!C:C,'Est Madre CH 10-25'!D:D,"si"),0)+IFERROR(VLOOKUP(D26,'Est Madre LK 10-25'!$A:$C,3,),IFERROR(VLOOKUP(D26,'Est Madre CH 10-25'!$A:$C,3,),0))) -> 3600 | AF26: 12000 | AG26: 12 | AH26: 0 | AI26: Tipo C | AJ26: UT | AK26: 4
A27: Grafica Pol | C27: 1261700 | D27: 520 | E27: =+VLOOKUP(D27,'Conteo VACIO'!$A$8:$D$226,4,0) -> E2A | F27: LK | G27: Sacacorcho Tipo Mozo Crom | L27: =+IFERROR(Q27/P27,0) -> 0.02588141 | M27: =+IFERROR(U27/X27,0) -> 0.02588141 | O27: =IF(P27-Q27-R27<0,0,P27-Q27-R27) -> 12157 | P27: =+IFERROR(AE27*AK27,0) -> 12480 | Q27: =+(Z27*AB27)+AA27 -> 323 | T27: =+IFERROR(SUMIFS('Stock CD'!D:D,D312,'Stock CD'!C:C),0) -> 0 | U27: =+T27+Q27 -> 323 | W27: =+IFERROR(VLOOKUP(D27,'Stock CD'!B:I,8,0),0) -> 0 | X27: =+W27+P27 -> 12480 | Z27: =+SUMIFS('Conteo VACIO'!F:F,'Conteo VACIO'!$A:$A,$D27) -> 0 | AA27: =+SUMIFS('Conteo VACIO'!G:G,'Conteo VACIO'!$A:$A,$D27) -> 323 | AB27: 1000 | AD27: Grafica Pol | AE27: =IF(D27="Corb-LK",SUMIFS('Est Madre LK 10-25'!C:C,'Est Madre LK 10-25'!D:D,"si"),IF(D27="Corb-CH",SUMIFS('Est Madre CH 10-25'!C:C,'Est Madre CH 10-25'!D:D,"si"),0)+IFERROR(VLOOKUP(D27,'Est Madre LK 10-25'!$A:$C,3,),IFERROR(VLOOKUP(D27,'Est Madre CH 10-25'!$A:$C,3,),0))) -> 3120 | AF27: 12000 | AG27: 12 | AH27: 0 | AI27: Tipo C | AJ27: UT | AK27: 4
O28: =+SUM(O21:O27) -> 29075
C29: Tipo C - Pliego 11 Afila - Troquel Utensilios
A30: Grafica Pol | C30: 1273700 | D30: 504 | E30: =+VLOOKUP(D30,'Conteo VACIO'!$A$8:$D$226,4,0) -> C3 | F30: LK | G30: Afila Cuchillos | L30: =+IFERROR(Q30/P30,0) -> 0.52101201 | M30: =+IFERROR(U30/X30,0) -> 0.52101201 | O30: =IF(P30-Q30-R30<0,0,P30-Q30-R30) -> 13404 | P30: =+IFERROR(AE30*AK30,0) -> 27984 | Q30: =+(Z30*AB30)+AA30 -> 14580 | T30: =+IFERROR(SUMIFS('Stock CD'!D:D,D42,'Stock CD'!C:C),0) -> 0 | U30: =+T30+Q30 -> 14580 | W30: =+IFERROR(VLOOKUP(D30,'Stock CD'!B:I,8,0),0) -> 0 | X30: =+W30+P30 -> 27984 | Z30: =+SUMIFS('Conteo VACIO'!F:F,'Conteo VACIO'!$A:$A,$D30) -> 13 | AA30: =+SUMIFS('Conteo VACIO'!G:G,'Conteo VACIO'!$A:$A,$D30) -> 1580 | AB30: 1000 | AD30: Grafica Pol | AE30: =IF(D30="Corb-LK",SUMIFS('Est Madre LK 10-25'!C:C,'Est Madre LK 10-25'!D:D,"si"),IF(D30="Corb-CH",SUMIFS('Est Madre CH 10-25'!C:C,'Est Madre CH 10-25'!D:D,"si"),0)+IFERROR(VLOOKUP(D30,'Est Madre LK 10-25'!$A:$C,3,),IFERROR(VLOOKUP(D30,'Est Madre CH 10-25'!$A:$C,3,),0))) -> 6996 | AF30: 12000 | AG30: 12 | AH30: 0 | AI30: Tipo C | AJ30: UT | AK30: 4
C32: Tipo C - Pliegos a definir - Troquel Utensilios
A33: Grafica Pol | C33: 1269700 | D33: 511 | E33: =+VLOOKUP(D33,'Conteo VACIO'!$A$8:$D$226,4,0) -> G3D | F33: LK | G33: Abrelata Uña 3 En 1 | L33: =+IFERROR(Q33/P33,0) -> 1.4772727 | M33: =+IFERROR(U33/X33,0) -> 1.4772727 | O33: =IF(P33-Q33-R33<0,0,P33-Q33-R33) -> 0 | P33: =+IFERROR(AE33*AK33,0) -> 1936 | Q33: =+(Z33*AB33)+AA33 -> 2860 | T33: =+IFERROR(SUMIFS('Stock CD'!D:D,D295,'Stock CD'!C:C),0) -> 0 | U33: =+T33+Q33 -> 2860 | W33: =+IFERROR(VLOOKUP(D33,'Stock CD'!B:I,8,0),0) -> 0 | X33: =+W33+P33 -> 1936 | Z33: =+SUMIFS('Conteo VACIO'!F:F,'Conteo VACIO'!$A:$A,$D33) -> 2 | AA33: =+SUMIFS('Conteo VACIO'!G:G,'Conteo VACIO'!$A:$A,$D33) -> 860 | AB33: 1000 | AD33: Grafica Pol | AE33: =IF(D33="Corb-LK",SUMIFS('Est Madre LK 10-25'!C:C,'Est Madre LK 10-25'!D:D,"si"),IF(D33="Corb-CH",SUMIFS('Est Madre CH 10-25'!C:C,'Est Madre CH 10-25'!D:D,"si"),0)+IFERROR(VLOOKUP(D33,'Est Madre LK 10-25'!$A:$C,3,),IFERROR(VLOOKUP(D33,'Est Madre CH 10-25'!$A:$C,3,),0))) -> 484 | AF33: 12000 | AG33: 12 | AH33: 0 | AI33: Tipo C | AJ33: UT | AK33: 4
A34: Grafica Pol | C34: 1206700 | D34: 58 | E34: =+VLOOKUP(D34,'Conteo VACIO'!$A$8:$D$226,4,0) -> G5C | F34: LK | G34: Cierra Bolsa x2 | L34: =+IFERROR(Q34/P34,0) -> 1.4423077 | M34: =+IFERROR(U34/X34,0) -> 1.4423077 | O34: =IF(P34-Q34-R34<0,0,P34-Q34-R34) -> 0 | P34: =+IFERROR(AE34*AK34,0) -> 1248 | Q34: =+(Z34*AB34)+AA34 -> 1800 | T34: =+IFERROR(SUMIFS('Stock CD'!D:D,D297,'Stock CD'!C:C),0) -> 0 | U34: =+T34+Q34 -> 1800 | W34: =+IFERROR(VLOOKUP(D34,'Stock CD'!B:I,8,0),0) -> 0 | X34: =+W34+P34 -> 1248 | Z34: =+SUMIFS('Conteo VACIO'!F:F,'Conteo VACIO'!$A:$A,$D34) -> 1 | AA34: =+SUMIFS('Conteo VACIO'!G:G,'Conteo VACIO'!$A:$A,$D34) -> 800 | AB34: 1000 | AD34: Grafica Pol | AE34: =IF(D34="Corb-LK",SUMIFS('Est Madre LK 10-25'!C:C,'Est Madre LK 10-25'!D:D,"si"),IF(D34="Corb-CH",SUMIFS('Est Madre CH 10-25'!C:C,'Est Madre CH 10-25'!D:D,"si"),0)+IFERROR(VLOOKUP(D34,'Est Madre LK 10-25'!$A:$C,3,),IFERROR(VLOOKUP(D34,'Est Madre CH 10-25'!$A:$C,3,),0))) -> 312 | AF34: 12000 | AG34: 12 | AH34: 68.57028 | AI34: Tipo C | AJ34: UT | AK34: 4
A35: Grafica Pol | C35: 1206700 | D35: 547 | E35: =+VLOOKUP(D35,'Conteo VACIO'!$A$8:$D$226,4,0) -> G7D | F35: LK | G35: Corta Torta | L35: =+IFERROR(Q35/P35,0) -> 0 | M35: =+IFERROR(U35/X35,0) -> 0 | O35: =IF(P35-Q35-R35<0,0,P35-Q35-R35) -> 96 | P35: =+IFERROR(AE35*AK35,0) -> 96 | Q35: =+(Z35*AB35)+AA35 -> 0 | T35: =+IFERROR(SUMIFS('Stock CD'!D:D,D298,'Stock CD'!C:C),0) -> 0 | U35: =+T35+Q35 -> 0 | W35: =+IFERROR(VLOOKUP(D35,'Stock CD'!B:I,8,0),0) -> 0 | X35: =+W35+P35 -> 96 | Z35: =+SUMIFS('Conteo VACIO'!F:F,'Conteo VACIO'!$A:$A,$D35) -> 0 | AA35: =+SUMIFS('Conteo VACIO'!G:G,'Conteo VACIO'!$A:$A,$D35) -> 0 | AB35: 500 | AD35: Grafica Pol | AE35: =IF(D35="Corb-LK",SUMIFS('Est Madre LK 10-25'!C:C,'Est Madre LK 10-25'!D:D,"si"),IF(D35="Corb-CH",SUMIFS('Est Madre CH 10-25'!C:C,'Est Madre CH 10-25'!D:D,"si"),0)+IFERROR(VLOOKUP(D35,'Est Madre LK 10-25'!$A:$C,3,),IFERROR(VLOOKUP(D35,'Est Madre CH 10-25'!$A:$C,3,),0))) -> 24 | AF35: 12000 | AG35: 12 | AH35: 68.57028 | AI35: Tipo C | AJ35: UT | AK35: 4
A36: Grafica Pol | C36: 1263700 | D36: 532 | E36: =+VLOOKUP(D36,'Conteo VACIO'!$A$8:$D$226,4,0) -> G2B | F36: LK | G36: Cuchara De Helado | L36: =+IFERROR(Q36/P36,0) -> 1.4022436 | M36: =+IFERROR(U36/X36,0) -> 1.4022436 | O36: =IF(P36-Q36-R36<0,0,P36-Q36-R36) -> 0 | P36: =+IFERROR(AE36*AK36,0) -> 1248 | Q36: =+(Z36*AB36)+AA36 -> 1750 | T36: =+IFERROR(SUMIFS('Stock CD'!D:D,D300,'Stock CD'!C:C),0) -> 0 | U36: =+T36+Q36 -> 1750 | W36: =+IFERROR(VLOOKUP(D36,'Stock CD'!B:I,8,0),0) -> 0 | X36: =+W36+P36 -> 1248 | Z36: =+SUMIFS('Conteo VACIO'!F:F,'Conteo VACIO'!$A:$A,$D36) -> 1 | AA36: =+SUMIFS('Conteo VACIO'!G:G,'Conteo VACIO'!$A:$A,$D36) -> 750 | AB36: 1000 | AD36: Grafica Pol | AE36: =IF(D36="Corb-LK",SUMIFS('Est Madre LK 10-25'!C:C,'Est Madre LK 10-25'!D:D,"si"),IF(D36="Corb-CH",SUMIFS('Est Madre CH 10-25'!C:C,'Est Madre CH 10-25'!D:D,"si"),0)+IFERROR(VLOOKUP(D36,'Est Madre LK 10-25'!$A:$C,3,),IFERROR(VLOOKUP(D36,'Est Madre CH 10-25'!$A:$C,3,),0))) -> 312 | AF36: 12000 | AG36: 12 | AH36: 0 | AI36: Tipo C | AJ36: UT | AK36: 4
A37: Grafica Pol | C37: 1281700 | D37: 551 | E37: =+VLOOKUP(D37,'Conteo VACIO'!$A$8:$D$226,4,0) -> G8A | F37: LK | G37: Cuchillo Untar Mgo Plast x 2 | L37: =+IFERROR(Q37/P37,0) -> 0.84935897 | M37: =+IFERROR(U37/X37,0) -> 0.84935897 | O37: =IF(P37-Q37-R37<0,0,P37-Q37-R37) -> 282 | P37: =+IFERROR(AE37*AK37,0) -> 1872 | Q37: =+(Z37*AB37)+AA37 -> 1590 | T37: =+IFERROR(SUMIFS('Stock CD'!D:D,D303,'Stock CD'!C:C),0) -> 0 | U37: =+T37+Q37 -> 1590 | W37: =+IFERROR(VLOOKUP(D37,'Stock CD'!B:I,8,0),0) -> 0 | X37: =+W37+P37 -> 1872 | Z37: =+SUMIFS('Conteo VACIO'!F:F,'Conteo VACIO'!$A:$A,$D37) -> 1 | AA37: =+SUMIFS('Conteo VACIO'!G:G,'Conteo VACIO'!$A:$A,$D37) -> 590 | AB37: 1000 | AD37: Grafica Pol | AE37: =IF(D37="Corb-LK",SUMIFS('Est Madre LK 10-25'!C:C,'Est Madre LK 10-25'!D:D,"si"),IF(D37="Corb-CH",SUMIFS('Est Madre CH 10-25'!C:C,'Est Madre CH 10-25'!D:D,"si"),0)+IFERROR(VLOOKUP(D37,'Est Madre LK 10-25'!$A:$C,3,),IFERROR(VLOOKUP(D37,'Est Madre CH 10-25'!$A:$C,3,),0))) -> 468 | AF37: 12000 | AG37: 10 | AH37: 68.57028 | AI37: Tipo C | AJ37: UT | AK37: 4
A38: Grafica Pol | C38: 1281700 | D38: 519 | E38: =+VLOOKUP(D38,'Conteo VACIO'!$A$8:$D$226,4,0) -> G5E | F38: LK | G38: Cuchillo Untar Mgo Madera x 2 | L38: =+IFERROR(Q38/P38,0) -> 0.83333333 | M38: =+IFERROR(U38/X38,0) -> 0.83333333 | O38: =IF(P38-Q38-R38<0,0,P38-Q38-R38) -> 400 | P38: =+IFERROR(AE38*AK38,0) -> 2400 | Q38: =+(Z38*AB38)+AA38 -> 2000 | T38: =+IFERROR(SUMIFS('Stock CD'!D:D,D304,'Stock CD'!C:C),0) -> 0 | U38: =+T38+Q38 -> 2000 | W38: =+IFERROR(VLOOKUP(D38,'Stock CD'!B:I,8,0),0) -> 0 | X38: =+W38+P38 -> 2400 | Z38: =+SUMIFS('Conteo VACIO'!F:F,'Conteo VACIO'!$A:$A,$D38) -> 2 | AA38: =+SUMIFS('Conteo VACIO'!G:G,'Conteo VACIO'!$A:$A,$D38) -> 0 | AB38: 1000 | AD38: Grafica Pol | AE38: =IF(D38="Corb-LK",SUMIFS('Est Madre LK 10-25'!C:C,'Est Madre LK 10-25'!D:D,"si"),IF(D38="Corb-CH",SUMIFS('Est Madre CH 10-25'!C:C,'Est Madre CH 10-25'!D:D,"si"),0)+IFERROR(VLOOKUP(D38,'Est Madre LK 10-25'!$A:$C,3,),IFERROR(VLOOKUP(D38,'Est Madre CH 10-25'!$A:$C,3,),0))) -> 600 | AF38: 12000 | AG38: 10 | AH38: 68.57028 | AI38: Tipo C | AJ38: UT | AK38: 4
A39: Grafica Pol | C39: 1206700 | D39: 395 | E39: =+VLOOKUP(D39,'Conteo VACIO'!$A$8:$D$226,4,0) -> G1C | F39: LK | G39: Descorazonador De Manzana | L39: =+IFERROR(Q39/P39,0) -> 0.59166667 | M39: =+IFERROR(U39/X39,0) -> 0.59166667 | O39: =IF(P39-Q39-R39<0,0,P39-Q39-R39) -> 980 | P39: =+IFERROR(AE39*AK39,0) -> 2400 | Q39: =+(Z39*AB39)+AA39 -> 1420 | T39: =+IFERROR(SUMIFS('Stock CD'!D:D,D302,'Stock CD'!C:C),0) -> 0 | U39: =+T39+Q39 -> 1420 | W39: =+IFERROR(VLOOKUP(D39,'Stock CD'!B:I,8,0),0) -> 0 | X39: =+W39+P39 -> 2400 | Z39: =+SUMIFS('Conteo VACIO'!F:F,'Conteo VACIO'!$A:$A,$D39) -> 1 | AA39: =+SUMIFS('Conteo VACIO'!G:G,'Conteo VACIO'!$A:$A,$D39) -> 420 | AB39: 1000 | AD39: Grafica Pol | AE39: =IF(D39="Corb-LK",SUMIFS('Est Madre LK 10-25'!C:C,'Est Madre LK 10-25'!D:D,"si"),IF(D39="Corb-CH",SUMIFS('Est Madre CH 10-25'!C:C,'Est Madre CH 10-25'!D:D,"si"),0)+IFERROR(VLOOKUP(D39,'Est Madre LK 10-25'!$A:$C,3,),IFERROR(VLOOKUP(D39,'Est Madre CH 10-25'!$A:$C,3,),0))) -> 600 | AF39: 12000 | AG39: 12 | AH39: 68.57028 | AI39: Tipo C | AJ39: UT | AK39: 4
A40: Grafica Pol | C40: 1206700 | D40: 57 | E40: =+VLOOKUP(D40,'Conteo VACIO'!$A$8:$D$226,4,0) -> G7A | F40: LK | G40: Destapa Corona x 1 Cromado | L40: =+IFERROR(Q40/P40,0) -> 0.84005376 | M40: =+IFERROR(U40/X40,0) -> 0.84005376 | O40: =IF(P40-Q40-R40<0,0,P40-Q40-R40) -> 476 | P40: =+IFERROR(AE40*AK40,0) -> 2976 | Q40: =+(Z40*AB40)+AA40 -> 2500 | T40: =+IFERROR(SUMIFS('Stock CD'!D:D,D303,'Stock CD'!C:C),0) -> 0 | U40: =+T40+Q40 -> 2500 | W40: =+IFERROR(VLOOKUP(D40,'Stock CD'!B:I,8,0),0) -> 0 | X40: =+W40+P40 -> 2976 | Z40: =+SUMIFS('Conteo VACIO'!F:F,'Conteo VACIO'!$A:$A,$D40) -> 2 | AA40: =+SUMIFS('Conteo VACIO'!G:G,'Conteo VACIO'!$A:$A,$D40) -> 500 | AB40: 1000 | AD40: Grafica Pol | AE40: =IF(D40="Corb-LK",SUMIFS('Est Madre LK 10-25'!C:C,'Est Madre LK 10-25'!D:D,"si"),IF(D40="Corb-CH",SUMIFS('Est Madre CH 10-25'!C:C,'Est Madre CH 10-25'!D:D,"si"),0)+IFERROR(VLOOKUP(D40,'Est Madre LK 10-25'!$A:$C,3,),IFERROR(VLOOKUP(D40,'Est Madre CH 10-25'!$A:$C,3,),0))) -> 744 | AF40: 12000 | AG40: 12 | AH40: 68.57028 | AI40: Tipo C | AJ40: UT | AK40: 4
A41: Grafica Pol | C41: 2374700 | D41: 550 | E41: =+VLOOKUP(D41,'Conteo VACIO'!$A$8:$D$226,4,0) -> G6B | F41: LK | G41: Filtro Para Bombillas | L41: =+IFERROR(Q41/P41,0) -> 0.22843567 | M41: =+IFERROR(U41/X41,0) -> 0.22843567 | O41: =IF(P41-Q41-R41<0,0,P41-Q41-R41) -> 4222 | P41: =+IFERROR(AE41*AK41,0) -> 5472 | Q41: =+(Z41*AB41)+AA41 -> 1250 | T41: =+IFERROR(SUMIFS('Stock CD'!D:D,D307,'Stock CD'!C:C),0) -> 0 | U41: =+T41+Q41 -> 1250 | W41: =+IFERROR(VLOOKUP(D41,'Stock CD'!B:I,8,0),0) -> 0 | X41: =+W41+P41 -> 5472 | Z41: =+SUMIFS('Conteo VACIO'!F:F,'Conteo VACIO'!$A:$A,$D41) -> 1 | AA41: =+SUMIFS('Conteo VACIO'!G:G,'Conteo VACIO'!$A:$A,$D41) -> 250 | AB41: 1000 | AD41: Grafica Pol | AE41: =IF(D41="Corb-LK",SUMIFS('Est Madre LK 10-25'!C:C,'Est Madre LK 10-25'!D:D,"si"),IF(D41="Corb-CH",SUMIFS('Est Madre CH 10-25'!C:C,'Est Madre CH 10-25'!D:D,"si"),0)+IFERROR(VLOOKUP(D41,'Est Madre LK 10-25'!$A:$C,3,),IFERROR(VLOOKUP(D41,'Est Madre CH 10-25'!$A:$C,3,),0))) -> 1368 | AF41: 12000 | AG41: 12 | AH41: 43.2693 | AI41: Tipo C | AJ41: UT | AK41: 4
