Workbook

Sheet Garage Vacio 2026
F4: =+TODAY() -> 46101
K5: Informacion Cajones Garage | S5: Cajones a Preparar | AA5: Informacion Partes
A6: Cod Prov | B6: Taller/ Prov | C6: Sector | D6: Cod Art | E6: Cod ISIS | F6: Descripcion | G6: Stock Actual Cajon | H6: Pedido Cajon | I6: % Ocup | K6: Max Entra Caj | L6: Kg x Cajon | M6: Max Uni | N6: KG x Uni | O6: Uni x Cajon | P6: Est Madre Uni | Q6: Stock Max Madre 3M | S6: Sector Garage | T6: Cod | U6: Descripcion | V6: Sector Parte | W6: Descrip | X6: Cajon/ Paq a Enviar | AA6: Kg x Uni | AB6: Kg x Cajon | AC6: Cajones Pedido | AD6: Uni x Cajon | AE6: Kg a Enviar
B7: Martin | C7: GRJ 1 | D7: 500 | F7: Uña 500 LK | H7: =+IF(G7="","",IF(G7-Q7>0,0,Q7-G7)) | I7: =+IFERROR(G7/K7,) -> 0 | K7: 5 | L7: 30 | M7: =+K7*O7 -> 4552.352 | N7: 0.03295 | O7: =+L7/N7 -> 910.47041 | P7: =IFERROR(VLOOKUP(D7,'Estadistica Madre CH 23-01'!A:C,3,0),+VLOOKUP(D7,'Estadistica Madre LK 23-01 '!A:C,3,0)) -> 1440 | Q7: =3*P7/O7 -> 4.7448 | S7: GRJ 1 | T7: 500 | U7: Uña 500 LK | V7: C1 | W7: Abrelata Pie Uña Serig | X7: =+AE7/AB7 -> 0 | AA7: 0.029343333 | AB7: 30 | AC7: =+SUMIFS(H:H,D:$D,T7) -> 0 | AD7: =+SUMIFS(O:O,D:D,T7) -> 910.47041 | AE7: =+(AD7*AC7)*AA7 -> 0
B8: Martin | C8: GRJ7/8 | D8: 506 | F8: Uña LK 506 | H8: =+IF(G8="","",IF(G8-Q8>0,0,Q8-G8)) | I8: =+IFERROR(G8/K8,) -> 0 | K8: 36 | L8: 30 | M8: =+K8*O8 -> 49202.733 | N8: 0.02195 | O8: =+L8/N8 -> 1366.7426 | P8: =IFERROR(VLOOKUP(D8,'Estadistica Madre CH 23-01'!A:C,3,0),+VLOOKUP(D8,'Estadistica Madre LK 23-01 '!A:C,3,0)) -> 18840 | Q8: =3*P8/O8 -> 41.3538 | S8: GRJ 1 | T8: 500 | U8: Uña 500 LK | V8: C10 | W8: Uñas Zinc. | X8: =+AE8/AB8 -> 0 | AA8: 0.00353 | AB8: 30 | AC8: =+SUMIFS(H:H,D:$D,T8) -> 0 | AD8: =+SUMIFS(O:O,D:D,T8) -> 910.47041 | AE8: =+(AD8*AC8)*AA8 -> 0
B9: Martin | C9: GRJ 4 | D9: 654 | F9: Bomb Autolimp. 654 | H9: =+IF(G9="","",IF(G9-Q9>0,0,Q9-G9)) | I9: =+IFERROR(G9/K9,) -> 0 | K9: 5 | L9: 15 | M9: =+K9*O9 -> 3488.3721 | N9: 0.0215 | O9: =+L9/N9 -> 697.67442 | P9: =IFERROR(VLOOKUP(D9,'Estadistica Madre CH 23-01'!A:C,3,0),+VLOOKUP(D9,'Estadistica Madre LK 23-01 '!A:C,3,0)) -> 912 | Q9: =3*P9/O9 -> 3.9216 | S9: GRJ7/8 | T9: 506 | U9: Uña LK 506 | V9: A10 | W9: Cpo Uña LK C/M Pint. | X9: =+AE9/AB9 -> 0 | AA9: 0.01796 | AB9: 30 | AC9: =+SUMIFS(H:H,D:$D,T9)*1/4 -> 0 | AD9: =+SUMIFS(O:O,D:D,T9) -> 2733.4852 | AE9: =+(AD9*AC9)*AA9 -> 0
B10: Martin | C10: GRJ 5 | D10: 558 | F10: Bomb. Tradicional 558 | H10: =+IF(G10="","",IF(G10-Q10>0,0,Q10-G10)) | I10: =+IFERROR(G10/K10,) -> 0 | K10: 10 | L10: 1.8 | M10: =+K10*O10 -> 1161.2903 | N10: 0.0155 | O10: =+L10/N10 -> 116.12903 | P10: =IFERROR(VLOOKUP(D10,'Estadistica Madre CH 23-01'!A:C,3,0),+VLOOKUP(D10,'Estadistica Madre LK 23-01 '!A:C,3,0)) -> 2124 | Q10: =3*P10/O10 -> 54.87 | S10: GRJ7/8 | T10: 506 | U10: Uña LK 506 | V10: C10 | W10: Uñas Zinc. | X10: =+AE10/AB10 -> 0 | AA10: 0.00353 | AB10: 30 | AC10: =+SUMIFS(H:H,D:$D,T10)*1/4 -> 0 | AD10: =+SUMIFS(O:O,D:D,T10) -> 2733.4852 | AE10: =+(AD10*AC10)*AA10 -> 0
B11: Fabrica | C11: GRJ 6 | D11: 557 | F11: Bomb. Tradicional 557 | H11: =+IF(G11="","",IF(G11-Q11>0,0,Q11-G11)) | I11: =+IFERROR(G11/K11,) -> 0 | K11: 1 | L11: 1.8 | M11: =+K11*O11 -> 113.20755 | N11: 0.0159 | O11: =+L11/N11 -> 113.20755 | P11: =IFERROR(VLOOKUP(D11,'Estadistica Madre CH 23-01'!A:C,3,0),+VLOOKUP(D11,'Estadistica Madre LK 23-01 '!A:C,3,0)) -> 1400 | Q11: =3*P11/O11 -> 37.1 | S11: GRJ 4 | T11: 654 | U11: Bomb Autolimp. 654 | X11: =+AE11/AB11 -> #DIV/0! | AC11: =+SUMIFS(H:H,D:$D,T11) -> 0 | AD11: =+SUMIFS(O:O,D:D,T11) -> 697.67442 | AE11: =+(AD11*AC11)*AA11 -> 0
B12: Cimarron | F12: Bomb. Pico de Loro | H12: =+IF(G12="","",IF(G12-Q12>0,0,Q12-G12)) | I12: =+IFERROR(G12/K12,) -> 0
B13: Fabrica | C13: GRJ9 | D13: 510 | F13: Uña Crom 510 | H13: =+IF(G13="","",IF(G13-Q13>0,0,Q13-G13)) | I13: =+IFERROR(G13/K13,) -> 0 | K13: 8 | L13: 30 | M13: =+K13*O13 -> 10909.091 | N13: 0.022 | O13: =+L13/N13 -> 1363.6364 | P13: =IFERROR(VLOOKUP(D13,'Estadistica Madre CH 23-01'!A:C,3,0),+VLOOKUP(D13,'Estadistica Madre LK 23-01 '!A:C,3,0)) -> 6456 | Q13: =3*P13/O13 -> 14.2032 | S13: GRJ 5 | T13: 558 | U13: Bomb. Tradicional 558 | X13: =+AE13/AB13 -> #DIV/0! | AC13: =+SUMIFS(H:H,D:$D,T13) -> 0 | AD13: =+SUMIFS(O:O,D:D,T13) -> 116.12903 | AE13: =+(AD13*AC13)*AA13 -> 0
B14: Fabrica | C14: GJR10 | D14: 544 | F14: Batidor Pera | H14: =+IF(G14="","",IF(G14-Q14>0,0,Q14-G14)) | I14: =+IFERROR(G14/K14,) -> 0 | K14: 54 | L14: 15.68 | M14: =+K14*O14 -> 8640 | N14: 0.098 | O14: =+L14/N14 -> 160 | P14: =IFERROR(VLOOKUP(D14,'Estadistica Madre CH 23-01'!A:C,3,0),+VLOOKUP(D14,'Estadistica Madre LK 23-01 '!A:C,3,0)) -> 7464 | Q14: =3*P14/O14 -> 139.95 | S14: GRJ 6 | T14: 557 | U14: Bomb. Tradicional 557 | X14: =+AE14/AB14 -> #DIV/0! | AC14: =+SUMIFS(H:H,D:$D,T14) -> 0 | AD14: =+SUMIFS(O:O,D:D,T14) -> 113.20755 | AE14: =+(AD14*AC14)*AA14 -> 0
B15: Carlos | C15: GRJ7/8 | D15: 506 | F15: Uña LK 506 | H15: =+IF(G15="","",IF(G15-Q15>0,0,Q15-G15)) | I15: =+IFERROR(G15/K15,) -> 0 | K15: 36 | L15: 30 | M15: =+K15*O15 -> 49202.733 | N15: 0.02195 | O15: =+L15/N15 -> 1366.7426 | P15: =IFERROR(VLOOKUP(D15,'Estadistica Madre CH 23-01'!A:C,3,0),+VLOOKUP(D15,'Estadistica Madre LK 23-01 '!A:C,3,0)) -> 18840 | Q15: =3*P15/O15 -> 41.3538 | S15: GRJ9 | T15: 510 | U15: Uña Crom 510 | V15: A15 | W15: Cpo Uña Crom. LK C/M | X15: =+AE15/AB15 -> 0 | AA15: 0.018013333 | AB15: 30 | AC15: =+SUMIFS(H:H,D:$D,T15) -> 0 | AD15: =+SUMIFS(O:O,D:D,T15) -> 1363.6364 | AE15: =+(AD15*AC15)*AA15 -> 0
B16: Jade | C16: GRJ15 | D16: 530-531-730-731-706-700 | F16: Pintura Azul Mate | H16: =+IF(G16="","",IF(G16-Q16>0,0,Q16-G16)) | I16: =+IFERROR(G16/K16,) -> 0 | K16: 20 | L16: =+K16*M16 -> 400 | M16: 20 | N16: 12.867568 | O16: =+SUMIFS('Consumo '!E:E,'Consumo '!A:A,'Garage Vacio 2026'!C16) -> 9224 | P16: =+N16*1.5 -> 19.301351 | Q16: =3*P16/O16 -> 0.0062775427 | S16: GRJ9 | T16: 510 | U16: Uña Crom 510 | V16: C10 | W16: Uñas Zinc. | X16: =+AE16/AB16 -> 0 | AA16: 0.00353 | AB16: 30 | AC16: =+SUMIFS(H:H,D:$D,T16) -> 0 | AD16: =+SUMIFS(O:O,D:D,T16) -> 1363.6364 | AE16: =+(AD16*AC16)*AA16 -> 0
B17: Carlos | I17: =+IFERROR(G17/K17,) -> 0 | S17: GJR10 | T17: 544 | U17: Batidor Pera | V17: LL9 | W17: Resorte Batidor Pera | X17: =+AE17/AB17 -> 0 | AA17: 0.0355 | AB17: 18 | AC17: =+SUMIFS(H:H,D:$D,T17) -> 0 | AD17: =+SUMIFS(O:O,D:D,T17) -> 160 | AE17: =+(AD17*AC17)*AA17 -> 0
B18: Carlos | I18: =+IFERROR(G18/K18,) -> 0 | S18: GJR10 | T18: 544 | U18: Batidor Pera | V18: LLF7B | W18: Arandela Batidor Pera | X18: =+AE18/AB18 -> 0 | AA18: 0.00159 | AB18: 32 | AC18: =+SUMIFS(H:H,D:$D,T18) -> 0 | AD18: =+SUMIFS(O:O,D:D,T18) -> 160 | AE18: =+(AD18*AC18)*AA18 -> 0
B19: Carlos | I19: =+IFERROR(G19/K19,) -> 0 | S19: GJR10 | T19: 544 | U19: Batidor Pera | V19: E4 | W19: Fleje Ø2 x 600 | X19: =+AE19/AB19 -> 0 | AA19: 0.046484375 | AB19: 14 | AC19: =+SUMIFS(H:H,D:$D,T19) -> 0 | AD19: =+SUMIFS(O:O,D:D,T19) -> 160 | AE19: =+(AD19*AC19)*AA19 -> 0
B20: Carlos | I20: =+IFERROR(G20/K20,) -> 0 | S20: GJR10 | T20: 544 | U20: Batidor Pera | V20: E5 | W20: Fleje Ø2 x 665 | X20: =+AE20/AB20 -> 0 | AA20: 0.015625 | AB20: 10 | AC20: =+SUMIFS(H:H,D:$D,T20) -> 0 | AD20: =+SUMIFS(O:O,D:D,T20) -> 160 | AE20: =+(AD20*AC20)*AA20 -> 0
B21: Carlos | I21: =+IFERROR(G21/K21,) -> 0 | S21: GRJ7/8 | T21: 506 | U21: Uña LK 506 | V21: A10 | W21: Cpo Uña LK C/M Pint. | X21: =+AE21/AB21 -> 0 | AA21: 0.01796 | AB21: 30 | AC21: =+SUMIFS(H:H,D:$D,T21)*3/4 -> 0 | AD21: =+SUMIFS(O:O,D:D,T21) -> 2733.4852 | AE21: =+(AD21*AC21)*AA21 -> 0
B22: Carlos | I22: =+IFERROR(G22/K22,) -> 0 | S22: GRJ7/8 | T22: 506 | U22: Uña LK 506 | V22: C10 | W22: Uñas Zinc. | X22: =+AE22/AB22 -> 0 | AA22: 0.00353 | AB22: 30 | AC22: =+SUMIFS(H:H,D:$D,T22)*3/4 -> 0 | AD22: =+SUMIFS(O:O,D:D,T22) -> 2733.4852 | AE22: =+(AD22*AC22)*AA22 -> 0
B23: Carlos | I23: =+IFERROR(G23/K23,) -> 0 | S23: GRJ15 | T23: 530-531-730-731-706-700 | U23: Pintura Azul Mate | X23: =+AE23/AB23 -> #DIV/0! | AC23: =+SUMIFS(H:H,D:$D,T23) -> 0 | AD23: =+SUMIFS(O:O,D:D,T23) -> 9224 | AE23: =+(AD23*AC23)*AA23 -> 0

Sheet Garage Vacio 20-03
D4: =+TODAY() -> 46101
I5: Informacion Cajones Garage | Q5: Cajones a Preparar | Y5: Informacion Partes
A6: Taller | B6: Sector | C6: Art | D6: Descripcion | E6: Stock Actual Cajon | F6: Pedido Cajon | G6: % Ocup | I6: Max Entra Caj | J6: Kg x Cajon | K6: Max Uni | L6: KG x Uni | M6: Uni x Cajon | N6: Est Madre Uni | O6: Stock Max Madre 3M | Q6: Sector Garage | R6: Cod | S6: Descripcion | T6: Sector Parte | U6: Descrip | V6: Cajon/ Paq a Enviar | Y6: Kg x Uni | Z6: Kg x Cajon | AA6: Cajones Pedido | AB6: Uni x Cajon | AC6: Kg a Enviar
A7: Martin | B7: GRJ 1 | C7: 500 | D7: Uña 500 LK | E7: 0 | F7: =+IF(E7="","",IF(E7-O7>0,0,O7-E7)) -> 5 | G7: =+IFERROR(E7/I7,) -> 0 | I7: 5 | J7: 30 | K7: =+I7*M7 -> 4552.352 | L7: 0.03295 | M7: =+J7/L7 -> 910.47041 | N7: =IFERROR(VLOOKUP(C7,'Estadistica Madre CH 23-01'!A:C,3,0),+VLOOKUP(C7,'Estadistica Madre LK 23-01 '!A:C,3,0)) -> 1440 | O7: 5 | Q7: GRJ 1 | R7: 500 | S7: Uña 500 LK | T7: C1 | U7: Abrelata Pie Uña Serig | V7: =+AC7/Z7 -> 4.4527061 | Y7: 0.029343333 | Z7: 30 | AA7: =+SUMIFS(F:F,C:$C,R7) -> 5 | AB7: =+SUMIFS(M:M,C:C,R7) -> 910.47041 | AC7: =+(AB7*AA7)*Y7 -> 133.58118
A8: Martin | B8: GRJ7/8 | C8: 506 | D8: Uña LK 506 | E8: 0 | F8: =+IF(E8="","",IF(E8-O8>0,0,O8-E8)) -> 36 | G8: =+IFERROR(E8/I8,) -> 0 | I8: 36 | J8: 30 | K8: =+I8*M8 -> 49202.733 | L8: 0.02195 | M8: =+J8/L8 -> 1366.7426 | N8: =IFERROR(VLOOKUP(C8,'Estadistica Madre CH 23-01'!A:C,3,0),+VLOOKUP(C8,'Estadistica Madre LK 23-01 '!A:C,3,0)) -> 18840 | O8: 36 | Q8: GRJ 1 | R8: 500 | S8: Uña 500 LK | T8: C10 | U8: Uñas Zinc. | V8: =+AC8/Z8 -> 0.53566009 | Y8: 0.00353 | Z8: 30 | AA8: =+SUMIFS(F:F,C:$C,R8) -> 5 | AB8: =+SUMIFS(M:M,C:C,R8) -> 910.47041 | AC8: =+(AB8*AA8)*Y8 -> 16.069803
A9: Martin | B9: GRJ 4 | C9: 654 | D9: Bomb Autolimp. 654 | E9: 0 | F9: =+IF(E9="","",IF(E9-O9>0,0,O9-E9)) -> 5 | G9: =+IFERROR(E9/I9,) -> 0 | I9: 5 | J9: 15 | K9: =+I9*M9 -> 3488.3721 | L9: 0.0215 | M9: =+J9/L9 -> 697.67442 | N9: =IFERROR(VLOOKUP(C9,'Estadistica Madre CH 23-01'!A:C,3,0),+VLOOKUP(C9,'Estadistica Madre LK 23-01 '!A:C,3,0)) -> 912 | O9: 5 | Q9: GRJ7/8 | R9: 506 | S9: Uña LK 506 | T9: A10 | U9: Cpo Uña LK C/M Pint. | V9: =+AC9/Z9 -> 29.456036 | Y9: 0.01796 | Z9: 30 | AA9: =+SUMIFS(F:F,C:$C,R9)*1/4 -> 18 | AB9: =+SUMIFS(M:M,C:C,R9) -> 2733.4852 | AC9: =+(AB9*AA9)*Y9 -> 883.68109
A10: Martin | B10: GRJ 5 | C10: 558 | D10: Bomb. Tradicional 558 | E10: 2 | F10: =+IF(E10="","",IF(E10-O10>0,0,O10-E10)) -> 8 | G10: =+IFERROR(E10/I10,) -> 0.2 | I10: 10 | J10: 1.8 | K10: =+I10*M10 -> 1161.2903 | L10: 0.0155 | M10: =+J10/L10 -> 116.12903 | N10: =IFERROR(VLOOKUP(C10,'Estadistica Madre CH 23-01'!A:C,3,0),+VLOOKUP(C10,'Estadistica Madre LK 23-01 '!A:C,3,0)) -> 2124 | O10: 10 | Q10: GRJ7/8 | R10: 506 | S10: Uña LK 506 | T10: C10 | U10: Uñas Zinc. | V10: =+AC10/Z10 -> 5.7895216 | Y10: 0.00353 | Z10: 30 | AA10: =+SUMIFS(F:F,C:$C,R10)*1/4 -> 18 | AB10: =+SUMIFS(M:M,C:C,R10) -> 2733.4852 | AC10: =+(AB10*AA10)*Y10 -> 173.68565
A11: Fabrica | B11: GRJ 6 | C11: 557 | D11: Bomb. Tradicional 557 | E11: 0 | F11: =+IF(E11="","",IF(E11-O11>0,0,O11-E11)) -> 8 | G11: =+IFERROR(E11/I11,) -> 0 | I11: 8 | J11: 1.8 | K11: =+I11*M11 -> 905.66038 | L11: 0.0159 | M11: =+J11/L11 -> 113.20755 | N11: =IFERROR(VLOOKUP(C11,'Estadistica Madre CH 23-01'!A:C,3,0),+VLOOKUP(C11,'Estadistica Madre LK 23-01 '!A:C,3,0)) -> 1400 | O11: 8 | Q11: GRJ 4 | R11: 654 | S11: Bomb Autolimp. 654 | V11: =+AC11/Z11 -> #DIV/0! | AA11: =+SUMIFS(F:F,C:$C,R11) -> 5 | AB11: =+SUMIFS(M:M,C:C,R11) -> 697.67442 | AC11: =+(AB11*AA11)*Y11 -> 0
A12: Cimarron | D12: Bomb. Pico de Loro | E12: 0 | F12: =+IF(E12="","",IF(E12-O12>0,0,O12-E12)) -> 0 | G12: =+IFERROR(E12/I12,) -> 0
A13: Fabrica | B13: GRJ9 | C13: 510 | D13: Uña Crom 510 | E13: 10 | F13: =+IF(E13="","",IF(E13-O13>0,0,O13-E13)) -> 0 | G13: =+IFERROR(E13/I13,) -> 1.25 | I13: 8 | J13: 30 | K13: =+I13*M13 -> 10909.091 | L13: 0.022 | M13: =+J13/L13 -> 1363.6364 | N13: =IFERROR(VLOOKUP(C13,'Estadistica Madre CH 23-01'!A:C,3,0),+VLOOKUP(C13,'Estadistica Madre LK 23-01 '!A:C,3,0)) -> 6456 | O13: 8 | Q13: GRJ 5 | R13: 558 | S13: Bomb. Tradicional 558 | V13: =+AC13/Z13 -> 8 | Y13: 0.0155 | Z13: 1.8 | AA13: =+SUMIFS(F:F,C:$C,R13) -> 8 | AB13: =+SUMIFS(M:M,C:C,R13) -> 116.12903 | AC13: =+(AB13*AA13)*Y13 -> 14.4
A14: Fabrica | B14: GJR10 | C14: 544 | D14: Batidor Pera | E14: 31 | F14: =+IF(E14="","",IF(E14-O14>0,0,O14-E14)) -> 23 | G14: =+IFERROR(E14/I14,) -> 0.57407407 | I14: 54 | J14: 15.68 | K14: =+I14*M14 -> 8640 | L14: 0.098 | M14: =+J14/L14 -> 160 | N14: =IFERROR(VLOOKUP(C14,'Estadistica Madre CH 23-01'!A:C,3,0),+VLOOKUP(C14,'Estadistica Madre LK 23-01 '!A:C,3,0)) -> 7464 | O14: 54 | Q14: GRJ 6 | R14: 557 | S14: Bomb. Tradicional 557 | T14: GRJ 6 | V14: =+AC14/Z14 -> 8 | Y14: 0.0159 | Z14: 1.8 | AA14: =+SUMIFS(F:F,C:$C,R14) -> 8 | AB14: =+SUMIFS(M:M,C:C,R14) -> 113.20755 | AC14: =+(AB14*AA14)*Y14 -> 14.4
A15: Carlos | B15: GRJ7/8 | C15: 506 | D15: Uña LK 506 | E15: 0 | F15: =+IF(E15="","",IF(E15-O15>0,0,O15-E15)) -> 36 | G15: =+IFERROR(E15/I15,) -> 0 | I15: 36 | J15: 30 | K15: =+I15*M15 -> 49202.733 | L15: 0.02195 | M15: =+J15/L15 -> 1366.7426 | N15: =IFERROR(VLOOKUP(C15,'Estadistica Madre CH 23-01'!A:C,3,0),+VLOOKUP(C15,'Estadistica Madre LK 23-01 '!A:C,3,0)) -> 18840 | O15: 36 | Q15: GRJ9 | R15: 510 | S15: Uña Crom 510 | T15: A15 | U15: Cpo Uña Crom. LK C/M | V15: =+AC15/Z15 -> 0 | Y15: 0.018013333 | Z15: 30 | AA15: =+SUMIFS(F:F,C:$C,R15) -> 0 | AB15: =+SUMIFS(M:M,C:C,R15) -> 1363.6364 | AC15: =+(AB15*AA15)*Y15 -> 0
A16: Carlos | B16: GRJ15 | C16: 530-531-730-731-706-700 | D16: Pintura Azul Mate | E16: 3 | F16: =+IF(E16="","",IF(E16-O16>0,0,O16-E16)) -> 17 | G16: =+IFERROR(E16/I16,) -> 0.15 | I16: 20 | J16: =+I16*K16 -> 400 | K16: 20 | L16: 12.867568 | M16: =+SUMIFS('Consumo '!E:E,'Consumo '!A:A,'Garage Vacio 20-03'!B16) -> 9224 | N16: =+L16*1.5 -> 19.301351 | O16: 20 | Q16: GRJ9 | R16: 510 | S16: Uña Crom 510 | T16: C10 | U16: Uñas Zinc. | V16: =+AC16/Z16 -> 0 | Y16: 0.00353 | Z16: 30 | AA16: =+SUMIFS(F:F,C:$C,R16) -> 0 | AB16: =+SUMIFS(M:M,C:C,R16) -> 1363.6364 | AC16: =+(AB16*AA16)*Y16 -> 0
A17: Carlos | Q17: GJR10 | R17: 544 | S17: Batidor Pera | T17: LL9 | U17: Resorte Batidor Pera | V17: =+AC17/Z17 -> 7.2577778 | Y17: 0.0355 | Z17: 18 | AA17: =+SUMIFS(F:F,C:$C,R17) -> 23 | AB17: =+SUMIFS(M:M,C:C,R17) -> 160 | AC17: =+(AB17*AA17)*Y17 -> 130.64
A18: Carlos | Q18: GJR10 | R18: 544 | S18: Batidor Pera | T18: LLF7B | U18: Arandela Batidor Pera | V18: =+AC18/Z18 -> 0.18285 | Y18: 0.00159 | Z18: 32 | AA18: =+SUMIFS(F:F,C:$C,R18) -> 23 | AB18: =+SUMIFS(M:M,C:C,R18) -> 160 | AC18: =+(AB18*AA18)*Y18 -> 5.8512
A19: Carlos | Q19: GJR10 | R19: 544 | S19: Batidor Pera | T19: E4 | U19: Fleje Ø2 x 600 | V19: =+AC19/Z19 -> 12.21875 | Y19: 0.046484375 | Z19: 14 | AA19: =+SUMIFS(F:F,C:$C,R19) -> 23 | AB19: =+SUMIFS(M:M,C:C,R19) -> 160 | AC19: =+(AB19*AA19)*Y19 -> 171.0625
A20: Carlos | Q20: GJR10 | R20: 544 | S20: Batidor Pera | T20: E5 | U20: Fleje Ø2 x 665 | V20: =+AC20/Z20 -> 5.75 | Y20: 0.015625 | Z20: 10 | AA20: =+SUMIFS(F:F,C:$C,R20) -> 23 | AB20: =+SUMIFS(M:M,C:C,R20) -> 160 | AC20: =+(AB20*AA20)*Y20 -> 57.5
A21: Carlos | Q21: GRJ7/8 | R21: 506 | S21: Uña LK 506 | T21: A10 | U21: Cpo Uña LK C/M Pint. | V21: =+AC21/Z21 -> 88.368109 | Y21: 0.01796 | Z21: 30 | AA21: =+SUMIFS(F:F,C:$C,R21)*3/4 -> 54 | AB21: =+SUMIFS(M:M,C:C,R21) -> 2733.4852 | AC21: =+(AB21*AA21)*Y21 -> 2651.0433
A22: Carlos | Q22: GRJ7/8 | R22: 506 | S22: Uña LK 506 | T22: C10 | U22: Uñas Zinc. | V22: =+AC22/Z22 -> 17.368565 | Y22: 0.00353 | Z22: 30 | AA22: =+SUMIFS(F:F,C:$C,R22)*3/4 -> 54 | AB22: =+SUMIFS(M:M,C:C,R22) -> 2733.4852 | AC22: =+(AB22*AA22)*Y22 -> 521.05695
A23: Jade | Q23: GRJ15 | R23: 530-531-730-731-706-700 | S23: Pintura Azul Mate | V23: =+AC23/Z23 -> #DIV/0! | AA23: =+SUMIFS(F:F,C:$C,R23) -> 17 | AB23: =+SUMIFS(M:M,C:C,R23) -> 9224 | AC23: =+(AB23*AA23)*Y23 -> 0

Sheet Garage Vacio 13-03
D4: =+TODAY() -> 46101
I5: Informacion Cajones Garage | Q5: Cajones a Preparar | Y5: Informacion Partes
A6: Taller | B6: Sector | C6: Art | D6: Descripcion | E6: Stock Actual Cajon | F6: Pedido Cajon | G6: % Ocup | I6: Max Entra Caj | J6: Kg x Cajon | K6: Max Uni | L6: KG x Uni | M6: Uni x Cajon | N6: Est Madre Uni | O6: Stock Max Madre 3M | Q6: Sector Garage | R6: Cod | S6: Descripcion | T6: Sector Parte | U6: Descrip | V6: Cajon/ Paq a Enviar | Y6: Kg x Uni | Z6: Kg x Cajon | AA6: Cajones Pedido | AB6: Uni x Cajon | AC6: Kg a Enviar
A7: Martin | B7: GRJ 1 | C7: 500 | D7: Uña 500 LK | E7: 0 | F7: =+IF(E7="","",IF(E7-O7>0,0,O7-E7)) -> 4.7448 | G7: =+IFERROR(E7/I7,) -> 0 | I7: 5 | J7: 30 | K7: =+I7*M7 -> 4552.352 | L7: 0.03295 | M7: =+J7/L7 -> 910.47041 | N7: =IFERROR(VLOOKUP(C7,'Estadistica Madre CH 23-01'!A:C,3,0),+VLOOKUP(C7,'Estadistica Madre LK 23-01 '!A:C,3,0)) -> 1440 | O7: =3*N7/M7 -> 4.7448 | Q7: GRJ 1 | R7: 500 | S7: Uña 500 LK | T7: C1 | U7: Abrelata Pie Uña Serig | V7: =+AC7/Z7 -> 4.22544 | Y7: 0.029343333 | Z7: 30 | AA7: =+SUMIFS(F:F,C:$C,R7) -> 4.7448 | AB7: =+SUMIFS(M:M,C:C,R7) -> 910.47041 | AC7: =+(AB7*AA7)*Y7 -> 126.7632
A8: Martin | B8: GRJ7/8 | C8: 506 | D8: Uña LK 506 | E8: 12 | F8: =+IF(E8="","",IF(E8-O8>0,0,O8-E8)) -> 29.3538 | G8: =+IFERROR(E8/I8,) -> 0.33333333 | I8: 36 | J8: 30 | K8: =+I8*M8 -> 49202.733 | L8: 0.02195 | M8: =+J8/L8 -> 1366.7426 | N8: =IFERROR(VLOOKUP(C8,'Estadistica Madre CH 23-01'!A:C,3,0),+VLOOKUP(C8,'Estadistica Madre LK 23-01 '!A:C,3,0)) -> 18840 | O8: =3*N8/M8 -> 41.3538 | Q8: GRJ 1 | R8: 500 | S8: Uña 500 LK | T8: C10 | U8: Uñas Zinc. | V8: =+AC8/Z8 -> 0.50832 | Y8: 0.00353 | Z8: 30 | AA8: =+SUMIFS(F:F,C:$C,R8) -> 4.7448 | AB8: =+SUMIFS(M:M,C:C,R8) -> 910.47041 | AC8: =+(AB8*AA8)*Y8 -> 15.2496
A9: Martin | B9: GRJ 4 | C9: 654 | D9: Bomb Autolimp. 654 | E9: 0 | F9: =+IF(E9="","",IF(E9-O9>0,0,O9-E9)) -> 3.9216 | G9: =+IFERROR(E9/I9,) -> 0 | I9: 5 | J9: 15 | K9: =+I9*M9 -> 3488.3721 | L9: 0.0215 | M9: =+J9/L9 -> 697.67442 | N9: =IFERROR(VLOOKUP(C9,'Estadistica Madre CH 23-01'!A:C,3,0),+VLOOKUP(C9,'Estadistica Madre LK 23-01 '!A:C,3,0)) -> 912 | O9: =3*N9/M9 -> 3.9216 | Q9: GRJ7/8 | R9: 506 | S9: Uña LK 506 | T9: A10 | U9: Cpo Uña LK C/M Pint. | V9: =+AC9/Z9 -> 24.017961 | Y9: 0.01796 | Z9: 30 | AA9: =+SUMIFS(F:F,C:$C,R9)*1/4 -> 14.6769 | AB9: =+SUMIFS(M:M,C:C,R9) -> 2733.4852 | AC9: =+(AB9*AA9)*Y9 -> 720.53884
A10: Martin | B10: GRJ 5 | C10: 558 | D10: Bomb. Tradicional 558 | E10: 0 | F10: =+IF(E10="","",IF(E10-O10>0,0,O10-E10)) -> 54.87 | G10: =+IFERROR(E10/I10,) -> 0 | I10: 10 | J10: 1.8 | K10: =+I10*M10 -> 1161.2903 | L10: 0.0155 | M10: =+J10/L10 -> 116.12903 | N10: =IFERROR(VLOOKUP(C10,'Estadistica Madre CH 23-01'!A:C,3,0),+VLOOKUP(C10,'Estadistica Madre LK 23-01 '!A:C,3,0)) -> 2124 | O10: =3*N10/M10 -> 54.87 | Q10: GRJ7/8 | R10: 506 | S10: Uña LK 506 | T10: C10 | U10: Uñas Zinc. | V10: =+AC10/Z10 -> 4.7206795 | Y10: 0.00353 | Z10: 30 | AA10: =+SUMIFS(F:F,C:$C,R10)*1/4 -> 14.6769 | AB10: =+SUMIFS(M:M,C:C,R10) -> 2733.4852 | AC10: =+(AB10*AA10)*Y10 -> 141.62038
A11: Fabrica | B11: GRJ 6 | C11: 557 | D11: Bomb. Tradicional 557 | E11: 2 | F11: =+IF(E11="","",IF(E11-O11>0,0,O11-E11)) -> 35.1 | G11: =+IFERROR(E11/I11,) -> 0.25 | I11: 8 | J11: 1.8 | K11: =+I11*M11 -> 905.66038 | L11: 0.0159 | M11: =+J11/L11 -> 113.20755 | N11: =IFERROR(VLOOKUP(C11,'Estadistica Madre CH 23-01'!A:C,3,0),+VLOOKUP(C11,'Estadistica Madre LK 23-01 '!A:C,3,0)) -> 1400 | O11: =3*N11/M11 -> 37.1 | Q11: GRJ 4 | R11: 654 | S11: Bomb Autolimp. 654 | V11: =+AC11/Z11 -> #DIV/0! | AA11: =+SUMIFS(F:F,C:$C,R11) -> 3.9216 | AB11: =+SUMIFS(M:M,C:C,R11) -> 697.67442 | AC11: =+(AB11*AA11)*Y11 -> 0
A12: Cimarron | D12: Bomb. Pico de Loro | E12: 0 | F12: =+IF(E12="","",IF(E12-O12>0,0,O12-E12)) -> 0 | G12: =+IFERROR(E12/I12,) -> 0
A13: Fabrica | B13: GRJ9 | C13: 510 | D13: Uña Crom 510 | E13: 10 | F13: =+IF(E13="","",IF(E13-O13>0,0,O13-E13)) -> 4.2032 | G13: =+IFERROR(E13/I13,) -> 1.25 | I13: 8 | J13: 30 | K13: =+I13*M13 -> 10909.091 | L13: 0.022 | M13: =+J13/L13 -> 1363.6364 | N13: =IFERROR(VLOOKUP(C13,'Estadistica Madre CH 23-01'!A:C,3,0),+VLOOKUP(C13,'Estadistica Madre LK 23-01 '!A:C,3,0)) -> 6456 | O13: =3*N13/M13 -> 14.2032 | Q13: GRJ 5 | R13: 558 | S13: Bomb. Tradicional 558 | V13: =+AC13/Z13 -> 54.87 | Y13: 0.0155 | Z13: 1.8 | AA13: =+SUMIFS(F:F,C:$C,R13) -> 54.87 | AB13: =+SUMIFS(M:M,C:C,R13) -> 116.12903 | AC13: =+(AB13*AA13)*Y13 -> 98.766
A14: Fabrica | B14: GJR10 | C14: 544 | D14: Batidor Pera | E14: 31 | F14: =+IF(E14="","",IF(E14-O14>0,0,O14-E14)) -> 62.3 | G14: =+IFERROR(E14/I14,) -> 0.57407407 | I14: 54 | J14: 15.68 | K14: =+I14*M14 -> 8640 | L14: 0.098 | M14: =+J14/L14 -> 160 | N14: =IFERROR(VLOOKUP(C14,'Estadistica Madre CH 23-01'!A:C,3,0),+VLOOKUP(C14,'Estadistica Madre LK 23-01 '!A:C,3,0)) -> 7464 | O14: =2*N14/M14 -> 93.3 | Q14: GRJ 6 | R14: 557 | S14: Bomb. Tradicional 557 | T14: GRJ 6 | V14: =+AC14/Z14 -> 35.1 | Y14: 0.0159 | Z14: 1.8 | AA14: =+SUMIFS(F:F,C:$C,R14) -> 35.1 | AB14: =+SUMIFS(M:M,C:C,R14) -> 113.20755 | AC14: =+(AB14*AA14)*Y14 -> 63.18
A15: Carlos | B15: GRJ7/8 | C15: 506 | D15: Uña LK 506 | E15: 12 | F15: =+IF(E15="","",IF(E15-O15>0,0,O15-E15)) -> 29.3538 | G15: =+IFERROR(E15/I15,) -> 0.33333333 | I15: 36 | J15: 30 | K15: =+I15*M15 -> 49202.733 | L15: 0.02195 | M15: =+J15/L15 -> 1366.7426 | N15: =IFERROR(VLOOKUP(C15,'Estadistica Madre CH 23-01'!A:C,3,0),+VLOOKUP(C15,'Estadistica Madre LK 23-01 '!A:C,3,0)) -> 18840 | O15: =3*N15/M15 -> 41.3538 | Q15: GRJ9 | R15: 510 | S15: Uña Crom 510 | T15: A15 | U15: Cpo Uña Crom. LK C/M | V15: =+AC15/Z15 -> 3.4415292 | Y15: 0.018013333 | Z15: 30 | AA15: =+SUMIFS(F:F,C:$C,R15) -> 4.2032 | AB15: =+SUMIFS(M:M,C:C,R15) -> 1363.6364 | AC15: =+(AB15*AA15)*Y15 -> 103.24588
A16: Carlos | B16: GRJ15 | C16: 530-531-730-731-706-700 | D16: Pintura Azul Mate | E16: 3 | F16: =+IF(E16="","",IF(E16-O16>0,0,O16-E16)) -> 0 | G16: =+IFERROR(E16/I16,) -> 0.15 | I16: 20 | J16: =+I16*K16 -> 400 | K16: 20 | L16: 12.867568 | M16: =+SUMIFS('Consumo '!E:E,'Consumo '!A:A,'Garage Vacio 13-03'!B16) -> 9224 | N16: =+L16*1.5 -> 19.301351 | O16: =3*N16/M16 -> 0.0062775427 | Q16: GRJ9 | R16: 510 | S16: Uña Crom 510 | T16: C10 | U16: Uñas Zinc. | V16: =+AC16/Z16 -> 0.67442255 | Y16: 0.00353 | Z16: 30 | AA16: =+SUMIFS(F:F,C:$C,R16) -> 4.2032 | AB16: =+SUMIFS(M:M,C:C,R16) -> 1363.6364 | AC16: =+(AB16*AA16)*Y16 -> 20.232676
A17: Carlos | Q17: GJR10 | R17: 544 | S17: Batidor Pera | T17: LL9 | U17: Resorte Batidor Pera | V17: =+AC17/Z17 -> 19.659111 | Y17: 0.0355 | Z17: 18 | AA17: =+SUMIFS(F:F,C:$C,R17) -> 62.3 | AB17: =+SUMIFS(M:M,C:C,R17) -> 160 | AC17: =+(AB17*AA17)*Y17 -> 353.864
A18: Carlos | Q18: GJR10 | R18: 544 | S18: Batidor Pera | T18: LLF7B | U18: Arandela Batidor Pera | V18: =+AC18/Z18 -> 0.495285 | Y18: 0.00159 | Z18: 32 | AA18: =+SUMIFS(F:F,C:$C,R18) -> 62.3 | AB18: =+SUMIFS(M:M,C:C,R18) -> 160 | AC18: =+(AB18*AA18)*Y18 -> 15.84912
A19: Carlos | Q19: GJR10 | R19: 544 | S19: Batidor Pera | T19: E4 | U19: Fleje Ø2 x 600 | V19: =+AC19/Z19 -> 33.096875 | Y19: 0.046484375 | Z19: 14 | AA19: =+SUMIFS(F:F,C:$C,R19) -> 62.3 | AB19: =+SUMIFS(M:M,C:C,R19) -> 160 | AC19: =+(AB19*AA19)*Y19 -> 463.35625
A20: Carlos | Q20: GJR10 | R20: 544 | S20: Batidor Pera | T20: E5 | U20: Fleje Ø2 x 665 | V20: =+AC20/Z20 -> 15.575 | Y20: 0.015625 | Z20: 10 | AA20: =+SUMIFS(F:F,C:$C,R20) -> 62.3 | AB20: =+SUMIFS(M:M,C:C,R20) -> 160 | AC20: =+(AB20*AA20)*Y20 -> 155.75
A21: Carlos | Q21: GRJ7/8 | R21: 506 | S21: Uña LK 506 | T21: A10 | U21: Cpo Uña LK C/M Pint. | V21: =+AC21/Z21 -> 72.053884 | Y21: 0.01796 | Z21: 30 | AA21: =+SUMIFS(F:F,C:$C,R21)*3/4 -> 44.0307 | AB21: =+SUMIFS(M:M,C:C,R21) -> 2733.4852 | AC21: =+(AB21*AA21)*Y21 -> 2161.6165
A22: Carlos | Q22: GRJ7/8 | R22: 506 | S22: Uña LK 506 | T22: C10 | U22: Uñas Zinc. | V22: =+AC22/Z22 -> 14.162038 | Y22: 0.00353 | Z22: 30 | AA22: =+SUMIFS(F:F,C:$C,R22)*3/4 -> 44.0307 | AB22: =+SUMIFS(M:M,C:C,R22) -> 2733.4852 | AC22: =+(AB22*AA22)*Y22 -> 424.86115
A23: Jade | Q23: GRJ15 | R23: 530-531-730-731-706-700 | S23: Pintura Azul Mate | V23: =+AC23/Z23 -> #DIV/0! | AA23: =+SUMIFS(F:F,C:$C,R23) -> 0 | AB23: =+SUMIFS(M:M,C:C,R23) -> 9224 | AC23: =+(AB23*AA23)*Y23 -> 0

Sheet Garage Vacio 06-03
D4: =+TODAY() -> 46101
I5: Informacion Cajones Garage | Q5: Cajones a Preparar | Y5: Informacion Partes
A6: Taller | B6: Sector | C6: Art | D6: Descripcion | E6: Stock Actual Cajon | F6: Pedido Cajon | G6: % Ocup | I6: Max Entra Caj | J6: Kg x Cajon | K6: Max Uni | L6: KG x Uni | M6: Uni x Cajon | N6: Est Madre Uni | O6: Stock Max Madre 3M | Q6: Sector Garage | R6: Cod | S6: Descripcion | T6: Sector Parte | U6: Descrip | V6: Cajon/ Paq a Enviar | Y6: Kg x Uni | Z6: Kg x Cajon | AA6: Cajones Pedido | AB6: Uni x Cajon | AC6: Kg a Enviar
A7: Martin | B7: GRJ 1 | C7: 500 | D7: Uña 500 LK | E7: 2 | F7: =+IF(E7="","",IF(E7-O7>0,0,O7-E7)) -> 2.7448 | G7: =+IFERROR(E7/I7,) -> 0.4 | I7: 5 | J7: 30 | K7: =+I7*M7 -> 4552.352 | L7: 0.03295 | M7: =+J7/L7 -> 910.47041 | N7: =IFERROR(VLOOKUP(C7,'Estadistica Madre CH 23-01'!A:C,3,0),+VLOOKUP(C7,'Estadistica Madre LK 23-01 '!A:C,3,0)) -> 1440 | O7: =3*N7/M7 -> 4.7448 | Q7: GRJ 1 | R7: 500 | S7: Uña 500 LK | T7: C1 | U7: Abrelata Pie Uña Serig | V7: =+AC7/Z7 -> 2.4443576 | Y7: 0.029343333 | Z7: 30 | AA7: =+SUMIFS(F:F,C:$C,R7) -> 2.7448 | AB7: =+SUMIFS(M:M,C:C,R7) -> 910.47041 | AC7: =+(AB7*AA7)*Y7 -> 73.330727
A8: Martin | B8: GRJ7/8 | C8: 506 | D8: Uña LK 506 | E8: 12 | F8: =+IF(E8="","",IF(E8-O8>0,0,O8-E8)) -> 29.3538 | G8: =+IFERROR(E8/I8,) -> 0.33333333 | I8: 36 | J8: 30 | K8: =+I8*M8 -> 49202.733 | L8: 0.02195 | M8: =+J8/L8 -> 1366.7426 | N8: =IFERROR(VLOOKUP(C8,'Estadistica Madre CH 23-01'!A:C,3,0),+VLOOKUP(C8,'Estadistica Madre LK 23-01 '!A:C,3,0)) -> 18840 | O8: =3*N8/M8 -> 41.3538 | Q8: GRJ 1 | R8: 500 | S8: Uña 500 LK | T8: C10 | U8: Uñas Zinc. | V8: =+AC8/Z8 -> 0.29405596 | Y8: 0.00353 | Z8: 30 | AA8: =+SUMIFS(F:F,C:$C,R8) -> 2.7448 | AB8: =+SUMIFS(M:M,C:C,R8) -> 910.47041 | AC8: =+(AB8*AA8)*Y8 -> 8.8216789
A9: Martin | B9: GRJ 4 | C9: 654 | D9: Bomb Autolimp. 654 | E9: 0 | F9: =+IF(E9="","",IF(E9-O9>0,0,O9-E9)) -> 3.9216 | G9: =+IFERROR(E9/I9,) -> 0 | I9: 5 | J9: 15 | K9: =+I9*M9 -> 3488.3721 | L9: 0.0215 | M9: =+J9/L9 -> 697.67442 | N9: =IFERROR(VLOOKUP(C9,'Estadistica Madre CH 23-01'!A:C,3,0),+VLOOKUP(C9,'Estadistica Madre LK 23-01 '!A:C,3,0)) -> 912 | O9: =3*N9/M9 -> 3.9216 | Q9: GRJ7/8 | R9: 506 | S9: Uña LK 506 | T9: A10 | U9: Cpo Uña LK C/M Pint. | V9: =+AC9/Z9 -> 24.017961 | Y9: 0.01796 | Z9: 30 | AA9: =+SUMIFS(F:F,C:$C,R9)*1/4 -> 14.6769 | AB9: =+SUMIFS(M:M,C:C,R9) -> 2733.4852 | AC9: =+(AB9*AA9)*Y9 -> 720.53884
A10: Martin | B10: GRJ 5 | C10: 558 | D10: Bomb. Tradicional 558 | E10: 0 | F10: =+IF(E10="","",IF(E10-O10>0,0,O10-E10)) -> 54.87 | G10: =+IFERROR(E10/I10,) -> 0 | I10: 10 | J10: 1.8 | K10: =+I10*M10 -> 1161.2903 | L10: 0.0155 | M10: =+J10/L10 -> 116.12903 | N10: =IFERROR(VLOOKUP(C10,'Estadistica Madre CH 23-01'!A:C,3,0),+VLOOKUP(C10,'Estadistica Madre LK 23-01 '!A:C,3,0)) -> 2124 | O10: =3*N10/M10 -> 54.87 | Q10: GRJ7/8 | R10: 506 | S10: Uña LK 506 | T10: C10 | U10: Uñas Zinc. | V10: =+AC10/Z10 -> 4.7206795 | Y10: 0.00353 | Z10: 30 | AA10: =+SUMIFS(F:F,C:$C,R10)*1/4 -> 14.6769 | AB10: =+SUMIFS(M:M,C:C,R10) -> 2733.4852 | AC10: =+(AB10*AA10)*Y10 -> 141.62038
A11: Fabrica | B11: GRJ 6 | C11: 557 | D11: Bomb. Tradicional 557 | E11: 0 | F11: =+IF(E11="","",IF(E11-O11>0,0,O11-E11)) -> 37.1 | G11: =+IFERROR(E11/I11,) -> 0 | I11: 8 | J11: 1.8 | K11: =+I11*M11 -> 905.66038 | L11: 0.0159 | M11: =+J11/L11 -> 113.20755 | N11: =IFERROR(VLOOKUP(C11,'Estadistica Madre CH 23-01'!A:C,3,0),+VLOOKUP(C11,'Estadistica Madre LK 23-01 '!A:C,3,0)) -> 1400 | O11: =3*N11/M11 -> 37.1 | Q11: GRJ 4 | R11: 654 | S11: Bomb Autolimp. 654 | V11: =+AC11/Z11 -> #DIV/0! | AA11: =+SUMIFS(F:F,C:$C,R11) -> 3.9216 | AB11: =+SUMIFS(M:M,C:C,R11) -> 697.67442 | AC11: =+(AB11*AA11)*Y11 -> 0
A12: Cimarron | D12: Bomb. Pico de Loro | E12: 0 | F12: =+IF(E12="","",IF(E12-O12>0,0,O12-E12)) -> 0 | G12: =+IFERROR(E12/I12,) -> 0
A13: Fabrica | B13: GRJ9 | C13: 510 | D13: Uña Crom 510 | E13: 10 | F13: =+IF(E13="","",IF(E13-O13>0,0,O13-E13)) -> 4.2032 | G13: =+IFERROR(E13/I13,) -> 1.25 | I13: 8 | J13: 30 | K13: =+I13*M13 -> 10909.091 | L13: 0.022 | M13: =+J13/L13 -> 1363.6364 | N13: =IFERROR(VLOOKUP(C13,'Estadistica Madre CH 23-01'!A:C,3,0),+VLOOKUP(C13,'Estadistica Madre LK 23-01 '!A:C,3,0)) -> 6456 | O13: =3*N13/M13 -> 14.2032 | Q13: GRJ 5 | R13: 558 | S13: Bomb. Tradicional 558 | V13: =+AC13/Z13 -> 54.87 | Y13: 0.0155 | Z13: 1.8 | AA13: =+SUMIFS(F:F,C:$C,R13) -> 54.87 | AB13: =+SUMIFS(M:M,C:C,R13) -> 116.12903 | AC13: =+(AB13*AA13)*Y13 -> 98.766
A14: Fabrica | B14: GJR10 | C14: 544 | D14: Batidor Pera | E14: 30 | F14: =+IF(E14="","",IF(E14-O14>0,0,O14-E14)) -> 63.3 | G14: =+IFERROR(E14/I14,) -> 0.55555556 | I14: 54 | J14: 15.68 | K14: =+I14*M14 -> 8640 | L14: 0.098 | M14: =+J14/L14 -> 160 | N14: =IFERROR(VLOOKUP(C14,'Estadistica Madre CH 23-01'!A:C,3,0),+VLOOKUP(C14,'Estadistica Madre LK 23-01 '!A:C,3,0)) -> 7464 | O14: =2*N14/M14 -> 93.3 | Q14: GRJ 6 | R14: 557 | S14: Bomb. Tradicional 557 | T14: GRJ 6 | V14: =+AC14/Z14 -> 37.1 | Y14: 0.0159 | Z14: 1.8 | AA14: =+SUMIFS(F:F,C:$C,R14) -> 37.1 | AB14: =+SUMIFS(M:M,C:C,R14) -> 113.20755 | AC14: =+(AB14*AA14)*Y14 -> 66.78
A15: Carlos | B15: GRJ7/8 | C15: 506 | D15: Uña LK 506 | E15: 12 | F15: =+IF(E15="","",IF(E15-O15>0,0,O15-E15)) -> 29.3538 | G15: =+IFERROR(E15/I15,) -> 0.33333333 | I15: 36 | J15: 30 | K15: =+I15*M15 -> 49202.733 | L15: 0.02195 | M15: =+J15/L15 -> 1366.7426 | N15: =IFERROR(VLOOKUP(C15,'Estadistica Madre CH 23-01'!A:C,3,0),+VLOOKUP(C15,'Estadistica Madre LK 23-01 '!A:C,3,0)) -> 18840 | O15: =3*N15/M15 -> 41.3538 | Q15: GRJ9 | R15: 510 | S15: Uña Crom 510 | T15: A15 | U15: Cpo Uña Crom. LK C/M | V15: =+AC15/Z15 -> 3.4415292 | Y15: 0.018013333 | Z15: 30 | AA15: =+SUMIFS(F:F,C:$C,R15) -> 4.2032 | AB15: =+SUMIFS(M:M,C:C,R15) -> 1363.6364 | AC15: =+(AB15*AA15)*Y15 -> 103.24588
A16: Carlos | B16: GRJ15 | C16: 530-531-730-731-706-700 | D16: Pintura Azul Mate | E16: 3 | F16: =+IF(E16="","",IF(E16-O16>0,0,O16-E16)) -> 0 | G16: =+IFERROR(E16/I16,) -> 0.15 | I16: 20 | J16: =+I16*K16 -> 400 | K16: 20 | L16: 12.867568 | M16: =+SUMIFS('Consumo '!E:E,'Consumo '!A:A,'Garage Vacio 06-03'!B16) -> 9224 | N16: =+L16*1.5 -> 19.301351 | O16: =3*N16/M16 -> 0.0062775427 | Q16: GRJ9 | R16: 510 | S16: Uña Crom 510 | T16: C10 | U16: Uñas Zinc. | V16: =+AC16/Z16 -> 0.67442255 | Y16: 0.00353 | Z16: 30 | AA16: =+SUMIFS(F:F,C:$C,R16) -> 4.2032 | AB16: =+SUMIFS(M:M,C:C,R16) -> 1363.6364 | AC16: =+(AB16*AA16)*Y16 -> 20.232676
A17: Carlos | Q17: GJR10 | R17: 544 | S17: Batidor Pera | T17: LL9 | U17: Resorte Batidor Pera | V17: =+AC17/Z17 -> 19.974667 | Y17: 0.0355 | Z17: 18 | AA17: =+SUMIFS(F:F,C:$C,R17) -> 63.3 | AB17: =+SUMIFS(M:M,C:C,R17) -> 160 | AC17: =+(AB17*AA17)*Y17 -> 359.544
A18: Carlos | Q18: GJR10 | R18: 544 | S18: Batidor Pera | T18: LLF7B | U18: Arandela Batidor Pera | V18: =+AC18/Z18 -> 0.503235 | Y18: 0.00159 | Z18: 32 | AA18: =+SUMIFS(F:F,C:$C,R18) -> 63.3 | AB18: =+SUMIFS(M:M,C:C,R18) -> 160 | AC18: =+(AB18*AA18)*Y18 -> 16.10352
A19: Carlos | Q19: GJR10 | R19: 544 | S19: Batidor Pera | T19: E4 | U19: Fleje Ø2 x 600 | V19: =+AC19/Z19 -> 33.628125 | Y19: 0.046484375 | Z19: 14 | AA19: =+SUMIFS(F:F,C:$C,R19) -> 63.3 | AB19: =+SUMIFS(M:M,C:C,R19) -> 160 | AC19: =+(AB19*AA19)*Y19 -> 470.79375
A20: Carlos | Q20: GJR10 | R20: 544 | S20: Batidor Pera | T20: E5 | U20: Fleje Ø2 x 665 | V20: =+AC20/Z20 -> 15.825 | Y20: 0.015625 | Z20: 10 | AA20: =+SUMIFS(F:F,C:$C,R20) -> 63.3 | AB20: =+SUMIFS(M:M,C:C,R20) -> 160 | AC20: =+(AB20*AA20)*Y20 -> 158.25
A21: Carlos | Q21: GRJ7/8 | R21: 506 | S21: Uña LK 506 | T21: A10 | U21: Cpo Uña LK C/M Pint. | V21: =+AC21/Z21 -> 72.053884 | Y21: 0.01796 | Z21: 30 | AA21: =+SUMIFS(F:F,C:$C,R21)*3/4 -> 44.0307 | AB21: =+SUMIFS(M:M,C:C,R21) -> 2733.4852 | AC21: =+(AB21*AA21)*Y21 -> 2161.6165
A22: Carlos | Q22: GRJ7/8 | R22: 506 | S22: Uña LK 506 | T22: C10 | U22: Uñas Zinc. | V22: =+AC22/Z22 -> 14.162038 | Y22: 0.00353 | Z22: 30 | AA22: =+SUMIFS(F:F,C:$C,R22)*3/4 -> 44.0307 | AB22: =+SUMIFS(M:M,C:C,R22) -> 2733.4852 | AC22: =+(AB22*AA22)*Y22 -> 424.86115
A23: Jade | Q23: GRJ15 | R23: 530-531-730-731-706-700 | S23: Pintura Azul Mate | V23: =+AC23/Z23 -> #DIV/0! | AA23: =+SUMIFS(F:F,C:$C,R23) -> 0 | AB23: =+SUMIFS(M:M,C:C,R23) -> 9224 | AC23: =+(AB23*AA23)*Y23 -> 0

Sheet Garage Vacio 27-02
C4: =+TODAY() -> 46101
H5: Informacion Cajones Garage | P5: Cajones a Preparar | Y5: Informacion Partes
A6: Sector | B6: Art | C6: Descripcion | D6: Stock Actual Cajon | E6: Pedido Cajon | F6: % Ocup | H6: Max Entra Caj | I6: Kg x Cajon | J6: Max Uni | K6: KG x Uni | L6: Uni x Cajon | M6: Est Madre Uni | N6: Stock Max Madre 3M | P6: Taller | Q6: Sector Garage | R6: Cod | S6: Descripcion | T6: Sector Parte | U6: Descrip | V6: Cajon/ Paq a Enviar | Y6: Kg x Uni | Z6: Kg x Cajon | AA6: Cajones Pedido | AB6: Uni x Cajon | AC6: Kg a Enviar
A7: GRJ 1 | B7: 500 | C7: Uña 500 LK | D7: 2 | E7: =+IF(D7="","",IF(D7-N7>0,0,N7-D7)) -> 2.7448 | F7: =+IFERROR(D7/H7,) -> 0.4 | H7: 5 | I7: 30 | J7: =+H7*L7 -> 4552.352 | K7: 0.03295 | L7: =+I7/K7 -> 910.47041 | M7: =IFERROR(VLOOKUP(B7,'Estadistica Madre CH 23-01'!A:C,3,0),+VLOOKUP(B7,'Estadistica Madre LK 23-01 '!A:C,3,0)) -> 1440 | N7: =3*M7/L7 -> 4.7448 | P7: Martin | Q7: GRJ 1 | R7: 500 | S7: Uña 500 LK | T7: C1 | U7: Abrelata Pie Uña Serig | V7: =+AC7/Z7 -> 2.4443576 | Y7: 0.029343333 | Z7: 30 | AA7: =+SUMIFS(E:E,B:$B,R7) -> 2.7448 | AB7: =+SUMIFS(L:L,B:B,R7) -> 910.47041 | AC7: =+(AB7*AA7)*Y7 -> 73.330727
A8: GRJ7/8 | B8: 506 | C8: Uña LK 506 | D8: 21 | E8: =+IF(D8="","",IF(D8-N8>0,0,N8-D8)) -> 20.3538 | F8: =+IFERROR(D8/H8,) -> 0.58333333 | H8: 36 | I8: 30 | J8: =+H8*L8 -> 49202.733 | K8: 0.02195 | L8: =+I8/K8 -> 1366.7426 | M8: =IFERROR(VLOOKUP(B8,'Estadistica Madre CH 23-01'!A:C,3,0),+VLOOKUP(B8,'Estadistica Madre LK 23-01 '!A:C,3,0)) -> 18840 | N8: =3*M8/L8 -> 41.3538 | P8: Martin | Q8: GRJ 1 | R8: 500 | S8: Uña 500 LK | T8: C10 | U8: Uñas Zinc. | V8: =+AC8/Z8 -> 0.29405596 | Y8: 0.00353 | Z8: 30 | AA8: =+SUMIFS(E:E,B:$B,R8) -> 2.7448 | AB8: =+SUMIFS(L:L,B:B,R8) -> 910.47041 | AC8: =+(AB8*AA8)*Y8 -> 8.8216789
A9: GRJ 4 | B9: 654 | C9: Bomb Autolimp. 654 | D9: 0 | E9: =+IF(D9="","",IF(D9-N9>0,0,N9-D9)) -> 3.9216 | F9: =+IFERROR(D9/H9,) -> 0 | H9: 5 | I9: 15 | J9: =+H9*L9 -> 3488.3721 | K9: 0.0215 | L9: =+I9/K9 -> 697.67442 | M9: =IFERROR(VLOOKUP(B9,'Estadistica Madre CH 23-01'!A:C,3,0),+VLOOKUP(B9,'Estadistica Madre LK 23-01 '!A:C,3,0)) -> 912 | N9: =3*M9/L9 -> 3.9216 | P9: Martin | Q9: GRJ7/8 | R9: 506 | S9: Uña LK 506 | T9: A10 | U9: Cpo Uña LK C/M Pint. | V9: =+AC9/Z9 -> 16.653952 | Y9: 0.01796 | Z9: 30 | AA9: =+SUMIFS(E:E,B:$B,R9)*1/4 -> 10.1769 | AB9: =+SUMIFS(L:L,B:B,R9) -> 2733.4852 | AC9: =+(AB9*AA9)*Y9 -> 499.61856
A10: GRJ 5 | B10: 558 | C10: Bomb. Tradicional 558 | D10: 0 | E10: =+IF(D10="","",IF(D10-N10>0,0,N10-D10)) -> 54.87 | F10: =+IFERROR(D10/H10,) -> 0 | H10: 10 | I10: 1.8 | J10: =+H10*L10 -> 1161.2903 | K10: 0.0155 | L10: =+I10/K10 -> 116.12903 | M10: =IFERROR(VLOOKUP(B10,'Estadistica Madre CH 23-01'!A:C,3,0),+VLOOKUP(B10,'Estadistica Madre LK 23-01 '!A:C,3,0)) -> 2124 | N10: =3*M10/L10 -> 54.87 | P10: Martin | Q10: GRJ7/8 | R10: 506 | S10: Uña LK 506 | T10: C10 | U10: Uñas Zinc. | V10: =+AC10/Z10 -> 3.273299 | Y10: 0.00353 | Z10: 30 | AA10: =+SUMIFS(E:E,B:$B,R10)*1/4 -> 10.1769 | AB10: =+SUMIFS(L:L,B:B,R10) -> 2733.4852 | AC10: =+(AB10*AA10)*Y10 -> 98.198971
A11: GRJ 6 | B11: 557 | C11: Bomb. Tradicional 557 | D11: 1 | E11: =+IF(D11="","",IF(D11-N11>0,0,N11-D11)) -> 36.1 | F11: =+IFERROR(D11/H11,) -> 0.125 | H11: 8 | I11: 1.8 | J11: =+H11*L11 -> 905.66038 | K11: 0.0159 | L11: =+I11/K11 -> 113.20755 | M11: =IFERROR(VLOOKUP(B11,'Estadistica Madre CH 23-01'!A:C,3,0),+VLOOKUP(B11,'Estadistica Madre LK 23-01 '!A:C,3,0)) -> 1400 | N11: =3*M11/L11 -> 37.1 | P11: Fabrica | Q11: GRJ 4 | R11: 654 | S11: Bomb Autolimp. 654 | V11: =+AC11/Z11 -> #DIV/0! | AA11: =+SUMIFS(E:E,B:$B,R11) -> 3.9216 | AB11: =+SUMIFS(L:L,B:B,R11) -> 697.67442 | AC11: =+(AB11*AA11)*Y11 -> 0
C12: Bomb. Pico de Loro | D12: 0 | F12: =+IFERROR(D12/H12,) -> 0
A13: GRJ9 | B13: 510 | C13: Uña Crom 510 | D13: 8 | E13: =+IF(D13="","",IF(D13-N13>0,0,N13-D13)) -> 6.2032 | F13: =+IFERROR(D13/H13,) -> 1 | H13: 8 | I13: 30 | J13: =+H13*L13 -> 10909.091 | K13: 0.022 | L13: =+I13/K13 -> 1363.6364 | M13: =IFERROR(VLOOKUP(B13,'Estadistica Madre CH 23-01'!A:C,3,0),+VLOOKUP(B13,'Estadistica Madre LK 23-01 '!A:C,3,0)) -> 6456 | N13: =3*M13/L13 -> 14.2032 | P13: Fabrica | Q13: GRJ 5 | R13: 558 | S13: Bomb. Tradicional 558 | V13: =+AC13/Z13 -> 54.87 | Y13: 0.0155 | Z13: 1.8 | AA13: =+SUMIFS(E:E,B:$B,R13) -> 54.87 | AB13: =+SUMIFS(L:L,B:B,R13) -> 116.12903 | AC13: =+(AB13*AA13)*Y13 -> 98.766
A14: GJR10 | B14: 544 | C14: Batidor Pera | D14: 31 | E14: =+IF(D14="","",IF(D14-N14>0,0,N14-D14)) -> 108.95 | F14: =+IFERROR(D14/H14,) -> 0.57407407 | H14: 54 | I14: 15.68 | J14: =+H14*L14 -> 8640 | K14: 0.098 | L14: =+I14/K14 -> 160 | M14: =IFERROR(VLOOKUP(B14,'Estadistica Madre CH 23-01'!A:C,3,0),+VLOOKUP(B14,'Estadistica Madre LK 23-01 '!A:C,3,0)) -> 7464 | N14: =3*M14/L14 -> 139.95 | P14: Fabrica | Q14: GRJ 6 | R14: 557 | S14: Bomb. Tradicional 557 | T14: GRJ 6 | V14: =+AC14/Z14 -> 36.1 | Y14: 0.0159 | Z14: 1.8 | AA14: =+SUMIFS(E:E,B:$B,R14) -> 36.1 | AB14: =+SUMIFS(L:L,B:B,R14) -> 113.20755 | AC14: =+(AB14*AA14)*Y14 -> 64.98
A15: GRJ7/8 | B15: 506 | C15: Uña LK 506 | D15: 21 | E15: =+IF(D15="","",IF(D15-N15>0,0,N15-D15)) -> 20.3538 | F15: =+IFERROR(D15/H15,) -> 0.58333333 | H15: 36 | I15: 30 | J15: =+H15*L15 -> 49202.733 | K15: 0.02195 | L15: =+I15/K15 -> 1366.7426 | M15: =IFERROR(VLOOKUP(B15,'Estadistica Madre CH 23-01'!A:C,3,0),+VLOOKUP(B15,'Estadistica Madre LK 23-01 '!A:C,3,0)) -> 18840 | N15: =3*M15/L15 -> 41.3538 | P15: Carlos | Q15: GRJ9 | R15: 510 | S15: Uña Crom 510 | T15: A15 | U15: Cpo Uña Crom. LK C/M | V15: =+AC15/Z15 -> 5.079105 | Y15: 0.018013333 | Z15: 30 | AA15: =+SUMIFS(E:E,B:$B,R15) -> 6.2032 | AB15: =+SUMIFS(L:L,B:B,R15) -> 1363.6364 | AC15: =+(AB15*AA15)*Y15 -> 152.37315
A16: GRJ15 | B16: 530-531-730-731-706-700 | C16: Pintura Azul Mate | D16: 0 | E16: =+IF(D16="","",IF(D16-N16>0,0,N16-D16)) -> 0.0062775427 | F16: =+IFERROR(D16/H16,) -> 0 | H16: 20 | I16: =+H16*J16 -> 400 | J16: 20 | K16: 12.867568 | L16: =+SUMIFS('Consumo '!E:E,'Consumo '!A:A,'Garage Vacio 27-02'!A16) -> 9224 | M16: =+K16*1.5 -> 19.301351 | N16: =3*M16/L16 -> 0.0062775427 | P16: Carlos | Q16: GRJ9 | R16: 510 | S16: Uña Crom 510 | T16: C10 | U16: Uñas Zinc. | V16: =+AC16/Z16 -> 0.99533164 | Y16: 0.00353 | Z16: 30 | AA16: =+SUMIFS(E:E,B:$B,R16) -> 6.2032 | AB16: =+SUMIFS(L:L,B:B,R16) -> 1363.6364 | AC16: =+(AB16*AA16)*Y16 -> 29.859949
P17: Carlos | Q17: GJR10 | R17: 544 | S17: Batidor Pera | T17: LL9 | U17: Resorte Batidor Pera | V17: =+AC17/Z17 -> 34.379778 | Y17: 0.0355 | Z17: 18 | AA17: =+SUMIFS(E:E,B:$B,R17) -> 108.95 | AB17: =+SUMIFS(L:L,B:B,R17) -> 160 | AC17: =+(AB17*AA17)*Y17 -> 618.836
P18: Carlos | Q18: GJR10 | R18: 544 | S18: Batidor Pera | T18: LLF7B | U18: Arandela Batidor Pera | V18: =+AC18/Z18 -> 0.8661525 | Y18: 0.00159 | Z18: 32 | AA18: =+SUMIFS(E:E,B:$B,R18) -> 108.95 | AB18: =+SUMIFS(L:L,B:B,R18) -> 160 | AC18: =+(AB18*AA18)*Y18 -> 27.71688
P19: Carlos | Q19: GJR10 | R19: 544 | S19: Batidor Pera | T19: E4 | U19: Fleje Ø2 x 600 | V19: =+AC19/Z19 -> 57.879687 | Y19: 0.046484375 | Z19: 14 | AA19: =+SUMIFS(E:E,B:$B,R19) -> 108.95 | AB19: =+SUMIFS(L:L,B:B,R19) -> 160 | AC19: =+(AB19*AA19)*Y19 -> 810.31562
P20: Carlos | Q20: GJR10 | R20: 544 | S20: Batidor Pera | T20: E5 | U20: Fleje Ø2 x 665 | V20: =+AC20/Z20 -> 27.2375 | Y20: 0.015625 | Z20: 10 | AA20: =+SUMIFS(E:E,B:$B,R20) -> 108.95 | AB20: =+SUMIFS(L:L,B:B,R20) -> 160 | AC20: =+(AB20*AA20)*Y20 -> 272.375
P21: Carlos | Q21: GRJ7/8 | R21: 506 | S21: Uña LK 506 | T21: A10 | U21: Cpo Uña LK C/M Pint. | V21: =+AC21/Z21 -> 49.961856 | Y21: 0.01796 | Z21: 30 | AA21: =+SUMIFS(E:E,B:$B,R21)*3/4 -> 30.5307 | AB21: =+SUMIFS(L:L,B:B,R21) -> 2733.4852 | AC21: =+(AB21*AA21)*Y21 -> 1498.8557
P22: Carlos | Q22: GRJ7/8 | R22: 506 | S22: Uña LK 506 | T22: C10 | U22: Uñas Zinc. | V22: =+AC22/Z22 -> 9.8198971 | Y22: 0.00353 | Z22: 30 | AA22: =+SUMIFS(E:E,B:$B,R22)*3/4 -> 30.5307 | AB22: =+SUMIFS(L:L,B:B,R22) -> 2733.4852 | AC22: =+(AB22*AA22)*Y22 -> 294.59691
P23: Jade | Q23: GRJ15 | R23: 530-531-730-731-706-700 | S23: Pintura Azul Mate | V23: =+AC23/Z23 -> #DIV/0! | AA23: =+SUMIFS(E:E,B:$B,R23) -> 0.0062775427 | AB23: =+SUMIFS(L:L,B:B,R23) -> 9224 | AC23: =+(AB23*AA23)*Y23 -> 0

Sheet Garage Vacio 20-02
C4: =+TODAY() -> 46101
H5: Informacion Cajones Garage | P5: Cajones a Preparar | Y5: Informacion Partes
A6: Sector | B6: Art | C6: Descripcion | D6: Stock Actual Cajon | E6: Pedido Cajon | F6: % Ocup | H6: Max Entra Caj | I6: Kg x Cajon | J6: Max Uni | K6: KG x Uni | L6: Uni x Cajon | M6: Est Madre Uni | N6: Stock Max Madre 3M | P6: Taller | Q6: Sector Garage | R6: Cod | S6: Descripcion | T6: Sector Parte | U6: Descrip | V6: Cajon/ Paq a Enviar | Y6: Kg x Uni | Z6: Kg x Cajon | AA6: Cajones Pedido | AB6: Uni x Cajon | AC6: Kg a Enviar
A7: GRJ 1 | B7: 500 | C7: Uña 500 LK | D7: 0 | E7: =+IF(D7="","",IF(D7-N7>0,0,N7-D7)) -> 4.7448 | F7: =+IFERROR(D7/H7,) -> 0 | H7: 5 | I7: 30 | J7: =+H7*L7 -> 4552.352 | K7: 0.03295 | L7: =+I7/K7 -> 910.47041 | M7: =IFERROR(VLOOKUP(B7,'Estadistica Madre CH 23-01'!A:C,3,0),+VLOOKUP(B7,'Estadistica Madre LK 23-01 '!A:C,3,0)) -> 1440 | N7: =3*M7/L7 -> 4.7448 | P7: Martin | Q7: GRJ 1 | R7: 500 | S7: Uña 500 LK | T7: C1 | U7: Abrelata Pie Uña Serig | V7: =+AC7/Z7 -> 4.22544 | Y7: 0.029343333 | Z7: 30 | AA7: =+SUMIFS(E:E,B:$B,R7) -> 4.7448 | AB7: =+SUMIFS(L:L,B:B,R7) -> 910.47041 | AC7: =+(AB7*AA7)*Y7 -> 126.7632
A8: GRJ7/8 | B8: 506 | C8: Uña LK 506 | D8: 0 | E8: =+IF(D8="","",IF(D8-N8>0,0,N8-D8)) -> 41.3538 | F8: =+IFERROR(D8/H8,) -> 0 | H8: 36 | I8: 30 | J8: =+H8*L8 -> 49202.733 | K8: 0.02195 | L8: =+I8/K8 -> 1366.7426 | M8: =IFERROR(VLOOKUP(B8,'Estadistica Madre CH 23-01'!A:C,3,0),+VLOOKUP(B8,'Estadistica Madre LK 23-01 '!A:C,3,0)) -> 18840 | N8: =3*M8/L8 -> 41.3538 | P8: Martin | Q8: GRJ 1 | R8: 500 | S8: Uña 500 LK | T8: C10 | U8: Uñas Zinc. | V8: =+AC8/Z8 -> 0.50832 | Y8: 0.00353 | Z8: 30 | AA8: =+SUMIFS(E:E,B:$B,R8) -> 4.7448 | AB8: =+SUMIFS(L:L,B:B,R8) -> 910.47041 | AC8: =+(AB8*AA8)*Y8 -> 15.2496
A9: GRJ 4 | B9: 654 | C9: Bomb Autolimp. 654 | D9: 0 | E9: =+IF(D9="","",IF(D9-N9>0,0,N9-D9)) -> 3.9216 | F9: =+IFERROR(D9/H9,) -> 0 | H9: 5 | I9: 15 | J9: =+H9*L9 -> 3488.3721 | K9: 0.0215 | L9: =+I9/K9 -> 697.67442 | M9: =IFERROR(VLOOKUP(B9,'Estadistica Madre CH 23-01'!A:C,3,0),+VLOOKUP(B9,'Estadistica Madre LK 23-01 '!A:C,3,0)) -> 912 | N9: =3*M9/L9 -> 3.9216 | P9: Martin | Q9: GRJ7/8 | R9: 506 | S9: Uña LK 506 | T9: A10 | U9: Cpo Uña LK C/M Pint. | V9: =+AC9/Z9 -> 33.83664 | Y9: 0.01796 | Z9: 30 | AA9: =+SUMIFS(E:E,B:$B,R9)*1/4 -> 20.6769 | AB9: =+SUMIFS(L:L,B:B,R9) -> 2733.4852 | AC9: =+(AB9*AA9)*Y9 -> 1015.0992
A10: GRJ 5 | B10: 558 | C10: Bomb. Tradicional 558 | D10: 0 | E10: =+IF(D10="","",IF(D10-N10>0,0,N10-D10)) -> 54.87 | F10: =+IFERROR(D10/H10,) -> 0 | H10: 10 | I10: 1.8 | J10: =+H10*L10 -> 1161.2903 | K10: 0.0155 | L10: =+I10/K10 -> 116.12903 | M10: =IFERROR(VLOOKUP(B10,'Estadistica Madre CH 23-01'!A:C,3,0),+VLOOKUP(B10,'Estadistica Madre LK 23-01 '!A:C,3,0)) -> 2124 | N10: =3*M10/L10 -> 54.87 | P10: Martin | Q10: GRJ7/8 | R10: 506 | S10: Uña LK 506 | T10: C10 | U10: Uñas Zinc. | V10: =+AC10/Z10 -> 6.65052 | Y10: 0.00353 | Z10: 30 | AA10: =+SUMIFS(E:E,B:$B,R10)*1/4 -> 20.6769 | AB10: =+SUMIFS(L:L,B:B,R10) -> 2733.4852 | AC10: =+(AB10*AA10)*Y10 -> 199.5156
A11: GRJ 6 | B11: 557 | C11: Bomb. Tradicional 557 | D11: 1 | E11: =+IF(D11="","",IF(D11-N11>0,0,N11-D11)) -> 36.1 | F11: =+IFERROR(D11/H11,) -> 0.125 | H11: 8 | I11: 1.8 | J11: =+H11*L11 -> 905.66038 | K11: 0.0159 | L11: =+I11/K11 -> 113.20755 | M11: =IFERROR(VLOOKUP(B11,'Estadistica Madre CH 23-01'!A:C,3,0),+VLOOKUP(B11,'Estadistica Madre LK 23-01 '!A:C,3,0)) -> 1400 | N11: =3*M11/L11 -> 37.1 | P11: Fabrica | Q11: GRJ 4 | R11: 654 | S11: Bomb Autolimp. 654 | V11: =+AC11/Z11 -> #DIV/0! | AA11: =+SUMIFS(E:E,B:$B,R11) -> 3.9216 | AB11: =+SUMIFS(L:L,B:B,R11) -> 697.67442 | AC11: =+(AB11*AA11)*Y11 -> 0
C12: Bomb. Pico de Loro | D12: 0 | F12: =+IFERROR(D12/H12,) -> 0
A13: GRJ9 | B13: 510 | C13: Uña Crom 510 | D13: 8 | E13: =+IF(D13="","",IF(D13-N13>0,0,N13-D13)) -> 6.2032 | F13: =+IFERROR(D13/H13,) -> 1 | H13: 8 | I13: 30 | J13: =+H13*L13 -> 10909.091 | K13: 0.022 | L13: =+I13/K13 -> 1363.6364 | M13: =IFERROR(VLOOKUP(B13,'Estadistica Madre CH 23-01'!A:C,3,0),+VLOOKUP(B13,'Estadistica Madre LK 23-01 '!A:C,3,0)) -> 6456 | N13: =3*M13/L13 -> 14.2032 | P13: Fabrica | Q13: GRJ 5 | R13: 558 | S13: Bomb. Tradicional 558 | V13: =+AC13/Z13 -> #DIV/0! | AA13: =+SUMIFS(E:E,B:$B,R13) -> 54.87 | AB13: =+SUMIFS(L:L,B:B,R13) -> 116.12903 | AC13: =+(AB13*AA13)*Y13 -> 0
A14: GJR10 | B14: 544 | C14: Batidor Pera | D14: 31 | E14: =+IF(D14="","",IF(D14-N14>0,0,N14-D14)) -> 108.95 | F14: =+IFERROR(D14/H14,) -> 0.57407407 | H14: 54 | I14: 15.68 | J14: =+H14*L14 -> 8640 | K14: 0.098 | L14: =+I14/K14 -> 160 | M14: =IFERROR(VLOOKUP(B14,'Estadistica Madre CH 23-01'!A:C,3,0),+VLOOKUP(B14,'Estadistica Madre LK 23-01 '!A:C,3,0)) -> 7464 | N14: =3*M14/L14 -> 139.95 | P14: Fabrica | Q14: GRJ 6 | R14: 557 | S14: Bomb. Tradicional 557 | V14: =+AC14/Z14 -> #DIV/0! | AA14: =+SUMIFS(E:E,B:$B,R14) -> 36.1 | AB14: =+SUMIFS(L:L,B:B,R14) -> 113.20755 | AC14: =+(AB14*AA14)*Y14 -> 0
A15: GRJ7/8 | B15: 506 | C15: Uña LK 506 | D15: 0 | E15: =+IF(D15="","",IF(D15-N15>0,0,N15-D15)) -> 41.3538 | F15: =+IFERROR(D15/H15,) -> 0 | H15: 36 | I15: 30 | J15: =+H15*L15 -> 49202.733 | K15: 0.02195 | L15: =+I15/K15 -> 1366.7426 | M15: =IFERROR(VLOOKUP(B15,'Estadistica Madre CH 23-01'!A:C,3,0),+VLOOKUP(B15,'Estadistica Madre LK 23-01 '!A:C,3,0)) -> 18840 | N15: =3*M15/L15 -> 41.3538 | P15: Carlos | Q15: GRJ9 | R15: 510 | S15: Uña Crom 510 | T15: A15 | U15: Cpo Uña Crom. LK C/M | V15: =+AC15/Z15 -> 5.079105 | Y15: 0.018013333 | Z15: 30 | AA15: =+SUMIFS(E:E,B:$B,R15) -> 6.2032 | AB15: =+SUMIFS(L:L,B:B,R15) -> 1363.6364 | AC15: =+(AB15*AA15)*Y15 -> 152.37315
A16: GRJ15 | B16: 530-531-730-731-706-700 | C16: Pintura Azul Mate | D16: 0 | E16: =+IF(D16="","",IF(D16-N16>0,0,N16-D16)) -> 0.0062775427 | F16: =+IFERROR(D16/H16,) -> 0 | H16: 20 | I16: =+H16*J16 -> 400 | J16: 20 | K16: 12.867568 | L16: =+SUMIFS('Consumo '!E:E,'Consumo '!A:A,'Garage Vacio 20-02'!A16) -> 9224 | M16: =+K16*1.5 -> 19.301351 | N16: =3*M16/L16 -> 0.0062775427 | P16: Carlos | Q16: GRJ9 | R16: 510 | S16: Uña Crom 510 | T16: C10 | U16: Uñas Zinc. | V16: =+AC16/Z16 -> 0.99533164 | Y16: 0.00353 | Z16: 30 | AA16: =+SUMIFS(E:E,B:$B,R16) -> 6.2032 | AB16: =+SUMIFS(L:L,B:B,R16) -> 1363.6364 | AC16: =+(AB16*AA16)*Y16 -> 29.859949
P17: Carlos | Q17: GJR10 | R17: 544 | S17: Batidor Pera | T17: LL9 | U17: Resorte Batidor Pera | V17: =+AC17/Z17 -> 34.379778 | Y17: 0.0355 | Z17: 18 | AA17: =+SUMIFS(E:E,B:$B,R17) -> 108.95 | AB17: =+SUMIFS(L:L,B:B,R17) -> 160 | AC17: =+(AB17*AA17)*Y17 -> 618.836
P18: Carlos | Q18: GJR10 | R18: 544 | S18: Batidor Pera | T18: LLF7B | U18: Arandela Batidor Pera | V18: =+AC18/Z18 -> 0.8661525 | Y18: 0.00159 | Z18: 32 | AA18: =+SUMIFS(E:E,B:$B,R18) -> 108.95 | AB18: =+SUMIFS(L:L,B:B,R18) -> 160 | AC18: =+(AB18*AA18)*Y18 -> 27.71688
P19: Carlos | Q19: GJR10 | R19: 544 | S19: Batidor Pera | T19: E4 | U19: Fleje Ø2 x 600 | V19: =+AC19/Z19 -> 57.879687 | Y19: 0.046484375 | Z19: 14 | AA19: =+SUMIFS(E:E,B:$B,R19) -> 108.95 | AB19: =+SUMIFS(L:L,B:B,R19) -> 160 | AC19: =+(AB19*AA19)*Y19 -> 810.31562
P20: Carlos | Q20: GJR10 | R20: 544 | S20: Batidor Pera | T20: E5 | U20: Fleje Ø2 x 665 | V20: =+AC20/Z20 -> 27.2375 | Y20: 0.015625 | Z20: 10 | AA20: =+SUMIFS(E:E,B:$B,R20) -> 108.95 | AB20: =+SUMIFS(L:L,B:B,R20) -> 160 | AC20: =+(AB20*AA20)*Y20 -> 272.375
P21: Carlos | Q21: GRJ7/8 | R21: 506 | S21: Uña LK 506 | T21: A10 | U21: Cpo Uña LK C/M Pint. | V21: =+AC21/Z21 -> 101.50992 | Y21: 0.01796 | Z21: 30 | AA21: =+SUMIFS(E:E,B:$B,R21)*3/4 -> 62.0307 | AB21: =+SUMIFS(L:L,B:B,R21) -> 2733.4852 | AC21: =+(AB21*AA21)*Y21 -> 3045.2976
P22: Carlos | Q22: GRJ7/8 | R22: 506 | S22: Uña LK 506 | T22: C10 | U22: Uñas Zinc. | V22: =+AC22/Z22 -> 19.95156 | Y22: 0.00353 | Z22: 30 | AA22: =+SUMIFS(E:E,B:$B,R22)*3/4 -> 62.0307 | AB22: =+SUMIFS(L:L,B:B,R22) -> 2733.4852 | AC22: =+(AB22*AA22)*Y22 -> 598.5468
P23: Jade | Q23: GRJ15 | R23: 530-531-730-731-706-700 | S23: Pintura Azul Mate | V23: =+AC23/Z23 -> #DIV/0! | AA23: =+SUMIFS(E:E,B:$B,R23) -> 0.0062775427 | AB23: =+SUMIFS(L:L,B:B,R23) -> 9224 | AC23: =+(AB23*AA23)*Y23 -> 0

Sheet Garage 06-02
C4: =+TODAY() -> 46101
H5: Informacion Cajones Garage | P5: Cajones a Preparar | Y5: Informacion Partes
A6: Sector | B6: Art | C6: Descripcion | D6: Stock Actual Cajon | E6: Pedido Cajon | F6: % Ocup | H6: Max Entra Caj | I6: Kg x Cajon | J6: Max Uni | K6: KG x Uni | L6: Uni x Cajon | M6: Est Madre Uni | N6: Stock Max Madre 3M | P6: Taller | Q6: Sector Garage | R6: Cod | S6: Descripcion | T6: Sector Parte | U6: Descrip | V6: Cajon/ Paq a Enviar | Y6: Kg x Uni | Z6: Kg x Cajon | AA6: Cajones Pedido | AB6: Uni x Cajon | AC6: Kg a Enviar
A7: GRJ 1 | B7: 500 | C7: Uña 500 LK | D7: 3 | E7: =+IF(D7="","",IF(D7-N7>0,0,N7-D7)) -> 1.7448 | F7: =+IFERROR(D7/H7,) -> 0.6 | H7: 5 | I7: 30 | J7: =+H7*L7 -> 4552.352 | K7: 0.03295 | L7: =+I7/K7 -> 910.47041 | M7: =IFERROR(VLOOKUP(B7,'Estadistica Madre CH 23-01'!A:C,3,0),+VLOOKUP(B7,'Estadistica Madre LK 23-01 '!A:C,3,0)) -> 1440 | N7: =3*M7/L7 -> 4.7448 | P7: Martin | Q7: GRJ 1 | R7: 500 | S7: Uña 500 LK | T7: C1 | U7: Abrelata Pie Uña Serig | V7: =+AC7/Z7 -> 1.5538163 | Y7: 0.029343333 | Z7: 30 | AA7: =+SUMIFS(E:E,B:$B,R7) -> 1.7448 | AB7: =+SUMIFS(L:L,B:B,R7) -> 910.47041 | AC7: =+(AB7*AA7)*Y7 -> 46.61449
A8: GRJ7/8 | B8: 506 | C8: Uña LK 506 | D8: 0 | E8: =+IF(D8="","",IF(D8-N8>0,0,N8-D8)) -> 41.3538 | F8: =+IFERROR(D8/H8,) -> 0 | H8: 36 | I8: 30 | J8: =+H8*L8 -> 49202.733 | K8: 0.02195 | L8: =+I8/K8 -> 1366.7426 | M8: =IFERROR(VLOOKUP(B8,'Estadistica Madre CH 23-01'!A:C,3,0),+VLOOKUP(B8,'Estadistica Madre LK 23-01 '!A:C,3,0)) -> 18840 | N8: =3*M8/L8 -> 41.3538 | P8: Martin | Q8: GRJ 1 | R8: 500 | S8: Uña 500 LK | T8: C10 | U8: Uñas Zinc. | V8: =+AC8/Z8 -> 0.18692395 | Y8: 0.00353 | Z8: 30 | AA8: =+SUMIFS(E:E,B:$B,R8) -> 1.7448 | AB8: =+SUMIFS(L:L,B:B,R8) -> 910.47041 | AC8: =+(AB8*AA8)*Y8 -> 5.6077184
A9: GRJ 4 | B9: 654 | C9: Bomb Autolimp. 654 | D9: 0 | E9: =+IF(D9="","",IF(D9-N9>0,0,N9-D9)) -> 3.9216 | F9: =+IFERROR(D9/H9,) -> 0 | H9: 5 | I9: 15 | J9: =+H9*L9 -> 3488.3721 | K9: 0.0215 | L9: =+I9/K9 -> 697.67442 | M9: =IFERROR(VLOOKUP(B9,'Estadistica Madre CH 23-01'!A:C,3,0),+VLOOKUP(B9,'Estadistica Madre LK 23-01 '!A:C,3,0)) -> 912 | N9: =3*M9/L9 -> 3.9216 | P9: Martin | Q9: GRJ7/8 | R9: 506 | S9: Uña LK 506 | T9: A10 | U9: Cpo Uña LK C/M Pint. | V9: =+AC9/Z9 -> 33.83664 | Y9: 0.01796 | Z9: 30 | AA9: =+SUMIFS(E:E,B:$B,R9)*1/4 -> 20.6769 | AB9: =+SUMIFS(L:L,B:B,R9) -> 2733.4852 | AC9: =+(AB9*AA9)*Y9 -> 1015.0992
A10: GRJ 5 | B10: 558 | C10: Bomb. Tradicional 558 | D10: 0 | E10: =+IF(D10="","",IF(D10-N10>0,0,N10-D10)) -> 54.87 | F10: =+IFERROR(D10/H10,) -> 0 | H10: 10 | I10: 1.8 | J10: =+H10*L10 -> 1161.2903 | K10: 0.0155 | L10: =+I10/K10 -> 116.12903 | M10: =IFERROR(VLOOKUP(B10,'Estadistica Madre CH 23-01'!A:C,3,0),+VLOOKUP(B10,'Estadistica Madre LK 23-01 '!A:C,3,0)) -> 2124 | N10: =3*M10/L10 -> 54.87 | P10: Martin | Q10: GRJ7/8 | R10: 506 | S10: Uña LK 506 | T10: C10 | U10: Uñas Zinc. | V10: =+AC10/Z10 -> 6.65052 | Y10: 0.00353 | Z10: 30 | AA10: =+SUMIFS(E:E,B:$B,R10)*1/4 -> 20.6769 | AB10: =+SUMIFS(L:L,B:B,R10) -> 2733.4852 | AC10: =+(AB10*AA10)*Y10 -> 199.5156
A11: GRJ 6 | B11: 557 | C11: Bomb. Tradicional 557 | D11: 0 | E11: =+IF(D11="","",IF(D11-N11>0,0,N11-D11)) -> 37.1 | F11: =+IFERROR(D11/H11,) -> 0 | H11: 1 | I11: 1.8 | J11: =+H11*L11 -> 113.20755 | K11: 0.0159 | L11: =+I11/K11 -> 113.20755 | M11: =IFERROR(VLOOKUP(B11,'Estadistica Madre CH 23-01'!A:C,3,0),+VLOOKUP(B11,'Estadistica Madre LK 23-01 '!A:C,3,0)) -> 1400 | N11: =3*M11/L11 -> 37.1 | P11: Fabrica | Q11: GRJ 4 | R11: 654 | S11: Bomb Autolimp. 654 | V11: =+AC11/Z11 -> #DIV/0! | AA11: =+SUMIFS(E:E,B:$B,R11) -> 3.9216 | AB11: =+SUMIFS(L:L,B:B,R11) -> 697.67442 | AC11: =+(AB11*AA11)*Y11 -> 0
A12: GRJ9 | B12: 510 | C12: Uña Crom 510 | D12: 8 | E12: =+IF(D12="","",IF(D12-N12>0,0,N12-D12)) -> 6.2032 | F12: =+IFERROR(D12/H12,) -> 1 | H12: 8 | I12: 30 | J12: =+H12*L12 -> 10909.091 | K12: 0.022 | L12: =+I12/K12 -> 1363.6364 | M12: =IFERROR(VLOOKUP(B12,'Estadistica Madre CH 23-01'!A:C,3,0),+VLOOKUP(B12,'Estadistica Madre LK 23-01 '!A:C,3,0)) -> 6456 | N12: =3*M12/L12 -> 14.2032 | P12: Fabrica | Q12: GRJ 5 | R12: 558 | S12: Bomb. Tradicional 558 | V12: =+AC12/Z12 -> #DIV/0! | AA12: =+SUMIFS(E:E,B:$B,R12) -> 54.87 | AB12: =+SUMIFS(L:L,B:B,R12) -> 116.12903 | AC12: =+(AB12*AA12)*Y12 -> 0
A13: GJR10 | B13: 544 | C13: Batidor Pera | D13: 30 | E13: =+IF(D13="","",IF(D13-N13>0,0,N13-D13)) -> 109.95 | F13: =+IFERROR(D13/H13,) -> 0.55555556 | H13: 54 | I13: 15.68 | J13: =+H13*L13 -> 8640 | K13: 0.098 | L13: =+I13/K13 -> 160 | M13: =IFERROR(VLOOKUP(B13,'Estadistica Madre CH 23-01'!A:C,3,0),+VLOOKUP(B13,'Estadistica Madre LK 23-01 '!A:C,3,0)) -> 7464 | N13: =3*M13/L13 -> 139.95 | P13: Fabrica | Q13: GRJ 6 | R13: 557 | S13: Bomb. Tradicional 557 | V13: =+AC13/Z13 -> #DIV/0! | AA13: =+SUMIFS(E:E,B:$B,R13) -> 37.1 | AB13: =+SUMIFS(L:L,B:B,R13) -> 113.20755 | AC13: =+(AB13*AA13)*Y13 -> 0
A14: GRJ7/8 | B14: 506 | C14: Uña LK 506 | D14: 0 | E14: =+IF(D14="","",IF(D14-N14>0,0,N14-D14)) -> 41.3538 | F14: =+IFERROR(D14/H14,) -> 0 | H14: 36 | I14: 30 | J14: =+H14*L14 -> 49202.733 | K14: 0.02195 | L14: =+I14/K14 -> 1366.7426 | M14: =IFERROR(VLOOKUP(B14,'Estadistica Madre CH 23-01'!A:C,3,0),+VLOOKUP(B14,'Estadistica Madre LK 23-01 '!A:C,3,0)) -> 18840 | N14: =3*M14/L14 -> 41.3538 | P14: Carlos | Q14: GRJ9 | R14: 510 | S14: Uña Crom 510 | T14: A15 | U14: Cpo Uña Crom. LK C/M | V14: =+AC14/Z14 -> 5.079105 | Y14: 0.018013333 | Z14: 30 | AA14: =+SUMIFS(E:E,B:$B,R14) -> 6.2032 | AB14: =+SUMIFS(L:L,B:B,R14) -> 1363.6364 | AC14: =+(AB14*AA14)*Y14 -> 152.37315
A15: GRJ15 | B15: 530-531-730-731-706-700 | C15: Pintura Azul Mate | D15: 3 | E15: =+IF(D15="","",IF(D15-N15>0,0,N15-D15)) -> 0 | F15: =+IFERROR(D15/H15,) -> 0.15 | H15: 20 | I15: =+H15*J15 -> 400 | J15: 20 | K15: 12.867568 | L15: =+SUMIFS('Consumo '!E:E,'Consumo '!A:A,'Garage 06-02'!A15) -> 9224 | M15: =+K15*1.5 -> 19.301351 | N15: =3*M15/L15 -> 0.0062775427 | P15: Carlos | Q15: GRJ9 | R15: 510 | S15: Uña Crom 510 | T15: C10 | U15: Uñas Zinc. | V15: =+AC15/Z15 -> 0.99533164 | Y15: 0.00353 | Z15: 30 | AA15: =+SUMIFS(E:E,B:$B,R15) -> 6.2032 | AB15: =+SUMIFS(L:L,B:B,R15) -> 1363.6364 | AC15: =+(AB15*AA15)*Y15 -> 29.859949
P16: Carlos | Q16: GJR10 | R16: 544 | S16: Batidor Pera | T16: LL9 | U16: Resorte Batidor Pera | V16: =+AC16/Z16 -> 34.695333 | Y16: 0.0355 | Z16: 18 | AA16: =+SUMIFS(E:E,B:$B,R16) -> 109.95 | AB16: =+SUMIFS(L:L,B:B,R16) -> 160 | AC16: =+(AB16*AA16)*Y16 -> 624.516
P17: Carlos | Q17: GJR10 | R17: 544 | S17: Batidor Pera | T17: LLF7B | U17: Arandela Batidor Pera | V17: =+AC17/Z17 -> 0.8741025 | Y17: 0.00159 | Z17: 32 | AA17: =+SUMIFS(E:E,B:$B,R17) -> 109.95 | AB17: =+SUMIFS(L:L,B:B,R17) -> 160 | AC17: =+(AB17*AA17)*Y17 -> 27.97128
P18: Carlos | Q18: GJR10 | R18: 544 | S18: Batidor Pera | T18: E4 | U18: Fleje Ø2 x 600 | V18: =+AC18/Z18 -> 58.410937 | Y18: 0.046484375 | Z18: 14 | AA18: =+SUMIFS(E:E,B:$B,R18) -> 109.95 | AB18: =+SUMIFS(L:L,B:B,R18) -> 160 | AC18: =+(AB18*AA18)*Y18 -> 817.75312
P19: Carlos | Q19: GJR10 | R19: 544 | S19: Batidor Pera | T19: E5 | U19: Fleje Ø2 x 665 | V19: =+AC19/Z19 -> 27.4875 | Y19: 0.015625 | Z19: 10 | AA19: =+SUMIFS(E:E,B:$B,R19) -> 109.95 | AB19: =+SUMIFS(L:L,B:B,R19) -> 160 | AC19: =+(AB19*AA19)*Y19 -> 274.875
P20: Carlos | Q20: GRJ7/8 | R20: 506 | S20: Uña LK 506 | T20: A10 | U20: Cpo Uña LK C/M Pint. | V20: =+AC20/Z20 -> 101.50992 | Y20: 0.01796 | Z20: 30 | AA20: =+SUMIFS(E:E,B:$B,R20)*3/4 -> 62.0307 | AB20: =+SUMIFS(L:L,B:B,R20) -> 2733.4852 | AC20: =+(AB20*AA20)*Y20 -> 3045.2976
P21: Carlos | Q21: GRJ7/8 | R21: 506 | S21: Uña LK 506 | T21: C10 | U21: Uñas Zinc. | V21: =+AC21/Z21 -> 19.95156 | Y21: 0.00353 | Z21: 30 | AA21: =+SUMIFS(E:E,B:$B,R21)*3/4 -> 62.0307 | AB21: =+SUMIFS(L:L,B:B,R21) -> 2733.4852 | AC21: =+(AB21*AA21)*Y21 -> 598.5468
P22: Jade | Q22: GRJ15 | R22: 530-531-730-731-706-700 | S22: Pintura Azul Mate | V22: =+AC22/Z22 -> #DIV/0! | AA22: =+SUMIFS(E:E,B:$B,R22) -> 0 | AB22: =+SUMIFS(L:L,B:B,R22) -> 9224 | AC22: =+(AB22*AA22)*Y22 -> 0

Sheet Garage Vacio 27-01
C4: =+TODAY() -> 46101
I5: Informacion Cajones Garage | Q5: Cajones a Preparar | Z5: Informacion Partes
A6: Sector | B6: Art | C6: Descripcion | D6: Stock Actual Cajon | E6: KG | F6: Pedido Cajon | G6: % Ocup | I6: Max Entra Caj | J6: Kg x Cajon | K6: Max Uni | L6: KG x Uni | M6: Uni x Cajon | N6: Est Madre Uni | O6: Stock Max Madre 3M | Q6: Taller | R6: Sector Garage | S6: Cod | T6: Descripcion | U6: Sector Parte | V6: Descrip | W6: Cajon/ Paq a Enviar | Z6: Kg x Uni | AA6: Kg x Cajon | AB6: Cajones Pedido | AC6: Uni x Cajon | AD6: Kg a Enviar
A7: GRJ 1 | B7: 500 | C7: Uña 500 LK | F7: =+IF(D7="","",IF(D7-O7>0,0,O7-D7)) | G7: =+IFERROR(D7/I7,) -> 0 | I7: 5 | J7: 30 | K7: =+I7*M7 -> 4552.352 | L7: 0.03295 | M7: =+J7/L7 -> 910.47041 | N7: =IFERROR(VLOOKUP(B7,'Estadistica Madre CH 23-01'!A:C,3,0),+VLOOKUP(B7,'Estadistica Madre LK 23-01 '!A:C,3,0)) -> 1440 | O7: =3*N7/M7 -> 4.7448 | Q7: Martin | R7: GRJ 1 | S7: 500 | T7: Uña 500 LK | U7: C1 | V7: Abrelata Pie Uña Serig | W7: =+AD7/AA7 -> 0 | Z7: 0.029343333 | AA7: 30 | AB7: =+SUMIFS(F:F,B:$B,S7) -> 0 | AC7: =+SUMIFS(M:M,B:B,S7) -> 910.47041 | AD7: =+(AC7*AB7)*Z7 -> 0
A8: GRJ7/8 | B8: 506 | C8: Uña LK 506 | F8: =+IF(D8="","",IF(D8-O8>0,0,O8-D8)) | G8: =+IFERROR(D8/I8,) -> 0 | I8: 36 | J8: 30 | K8: =+I8*M8 -> 49202.733 | L8: 0.02195 | M8: =+J8/L8 -> 1366.7426 | N8: =IFERROR(VLOOKUP(B8,'Estadistica Madre CH 23-01'!A:C,3,0),+VLOOKUP(B8,'Estadistica Madre LK 23-01 '!A:C,3,0)) -> 18840 | O8: =3*N8/M8 -> 41.3538 | Q8: Martin | R8: GRJ 1 | S8: 500 | T8: Uña 500 LK | U8: C10 | V8: Uñas Zinc. | W8: =+AD8/AA8 -> 0 | Z8: 0.00353 | AA8: 30 | AB8: =+SUMIFS(F:F,B:$B,S8) -> 0 | AC8: =+SUMIFS(M:M,B:B,S8) -> 910.47041 | AD8: =+(AC8*AB8)*Z8 -> 0
A9: GRJ 4 | B9: 654 | C9: Bomb Autolimp. 654 | F9: =+IF(D9="","",IF(D9-O9>0,0,O9-D9)) | G9: =+IFERROR(D9/I9,) -> 0 | I9: 5 | J9: 15 | K9: =+I9*M9 -> 3488.3721 | L9: 0.0215 | M9: =+J9/L9 -> 697.67442 | N9: =IFERROR(VLOOKUP(B9,'Estadistica Madre CH 23-01'!A:C,3,0),+VLOOKUP(B9,'Estadistica Madre LK 23-01 '!A:C,3,0)) -> 912 | O9: =3*N9/M9 -> 3.9216 | Q9: Martin | R9: GRJ7/8 | S9: 506 | T9: Uña LK 506 | U9: A10 | V9: Cpo Uña LK C/M Pint. | W9: =+AD9/AA9 -> 0 | Z9: 0.01796 | AA9: 30 | AB9: =+SUMIFS(F:F,B:$B,S9)*1/4 -> 0 | AC9: =+SUMIFS(M:M,B:B,S9) -> 2733.4852 | AD9: =+(AC9*AB9)*Z9 -> 0
A10: GRJ 5 | B10: 558 | C10: Bomb. Tradicional 558 | F10: =+IF(D10="","",IF(D10-O10>0,0,O10-D10)) | G10: =+IFERROR(D10/I10,) -> 0 | I10: 10 | J10: 1.8 | K10: =+I10*M10 -> 1161.2903 | L10: 0.0155 | M10: =+J10/L10 -> 116.12903 | N10: =IFERROR(VLOOKUP(B10,'Estadistica Madre CH 23-01'!A:C,3,0),+VLOOKUP(B10,'Estadistica Madre LK 23-01 '!A:C,3,0)) -> 2124 | O10: =3*N10/M10 -> 54.87 | Q10: Martin | R10: GRJ7/8 | S10: 506 | T10: Uña LK 506 | U10: C10 | V10: Uñas Zinc. | W10: =+AD10/AA10 -> 0 | Z10: 0.00353 | AA10: 30 | AB10: =+SUMIFS(F:F,B:$B,S10)*1/4 -> 0 | AC10: =+SUMIFS(M:M,B:B,S10) -> 2733.4852 | AD10: =+(AC10*AB10)*Z10 -> 0
