Workbook

Sheet Garage
A2: Cod. Art. | B2: Descripción | C2: Un | D2: Talle | F2: Linea
A3: 026 | B3: Colador N°8 | C3: 30 | D3: Telam | F3: LK
A4: 031 | B4: Filtro Cafe | C4: 11 | D4: Poly | F4: LK
A5: 031 | B5: Filtro Cafe | C5: 23 | D5: Poly | F5: LK
A6: 034 | B6: Filtro Cafe Gastr | C6: 23 | D6: Poly | F6: LK
A7: 059 | B7: Cuchillito Untar Plast x2 | C7: 17 | D7: Log/ Fabr | F7: LK
A8: 066 | B8: Abrel Super Marip | C8: 3 | D8: Poly | F8: LK
A9: 102 | B9: Abr Marip Loke | C9: 2 | D9: Poly | F9: LK
A10: 101 | B10: Abrel A Manija Loke | C10: 2 | D10: Rafael | F10: LK
A11: 109 | B11: Sac Zincado Loke | C11: 7 | D11: Martin | F11: LK
A12: 207 | B12: Ñoquera Fresada | C12: 6 | D12: TN | F12: LK
A13: 208 | B13: Cucharita 13cm Azuc Mra | C13: 11 | D13: Pintos | F13: LK
A14: 220 | B14: Cuchara Mra 40 Cm | C14: 11 | D14: Pintos | F14: LK
A15: 221 | B15: Cuchara Mra 45 Cm | C15: 11 | D15: Pintos | F15: LK
A16: 222 | B16: Bate Bife | C16: 11 | D16: Maspoli | F16: LK
A17: 223 | B17: Cuchara Mra 25 Cm | C17: 5 | D17: Pintos | F17: LK
A18: 224 | B18: Cuchara Mra 30 Cm | C18: 10 | D18: Pintos | F18: LK
A19: 225 | B19: Cuchara Mra 35 Cm | C19: 11 | D19: Pintos | F19: LK
A20: 229 | B20: Ñoquera Mra | C20: 3 | D20: TN | F20: LK
... A36: 396 | B36: Enrulador Manteca | C36: 6 | D36: INACTIVO | F36: LK
A37: 398 | B37: Espatula Calada Nylon | C37: 11 | F37: LK
A38: 400 | B38: Cuchara Fios Nylon | C38: 11 | F38: LK
A39: 499 | B39: Llavero stapador Pie Color | C39: 9 | D39: Garcia | F39: LK
A40: 500 | B40: Abrel Uña Pie Color | C40: 8 | D40: Oscar | F40: LK
A41: 501 | B41: Abrel A Manija | C41: 3 | D41: Rafael | F41: LK
A42: 501 Beq | B42: Abrel A Manija | C42: 17 | D42: Rafael | F42: LK
A43: 504 | B43: Afila Cuchillos | C43: 5 | D43: Martin | F43: LK
A44: 505 | B44: Pel Mgo Plast | C44: 2 | D44: Garcia | F44: LK
A45: 505 | B45: Pel Mgo Plast | C45: 5 | D45: Garcia | F45: LK
A46: 507 | B46: Rompenueces | C46: 11 | D46: Martin | F46: LK
A47: 508 | B47: Sacaf Artic | C47: 10 | D47: Martin | F47: LK
A48: 510 | B48: Abrel Uña Crom | C48: 6 | D48: Oscar | F48: LK
A49: 511 | B49: Abrel Uña 3 En 1 | C49: 7 | D49: Martin | F49: LK
A50: 512 | B50: Abrel Marip | C50: 3 | D50: Poly | F50: LK
A51: 512 | B51: Abrel Marip | C51: 10 | D51: Poly | F51: LK
A52: 513 | B52: Pel Mgo Metal | C52: 5 | D52: Poly | F52: LK
A53: 518 | B53: Sacafuente Gastr | C53: 6 | D53: Lucho | F53: LK
A54: 519 | B54: Cuchillo Untar Mgo Mra x2 | C54: 10 | D54: Log/ Fabr | F54: LK
... A59: 525 | B59: Sacac Cabo Mra | C59: 11 | D59: Lucho | F59: LK
A60: 526 | C60: 9 | F60: LK
...

Sheet LK
A2: Loekemeyer
A4: Cod. Art. | B4: Descripción | C4: Un | D4: Salidas | F4: Cod. Art. | H4: Un | I4: Salidas | K4: Cod. Art. | M4: Un | N4: Salidas | P4: Cod. Art. | Q4: Un | R4: Salidas
A5: 026 | B5: Colador N°8 | C5: 30 | D5: =+VLOOKUP(A5,Hoja2!A:B,2,FALSE) -> Colador N°8 | F5: 400 | G5: =+VLOOKUP(F5,Hoja2!A:B,2,FALSE) -> Cuchara de Fideos Nylon Mango Goma OFERTA!!! | H5: 11 | K5: 543 | M5: 9
A6: 031 | B6: Filtro De Cafe | C6: 11 | F6: 499 | G6: =+VLOOKUP(F6,Hoja2!A:B,2,FALSE) -> Llavero Destapador Pie Color | H6: 9 | K6: 543 | M6: 9
A7: 034 | B7: Filtro De Cafe Gastronomico | C7: 23 | F7: 500 | G7: =+VLOOKUP(F7,Hoja2!A:B,2,FALSE) -> Abrelata Uña Pie Color | H7: 8 | K7: 548 | M7: 6
A8: 059 | B8: Cuchillito De Untar Plast x2 | C8: 17 | F8: 501 | G8: =+VLOOKUP(F8,Hoja2!A:B,2,FALSE) -> Abrelatas A Manija | H8: 3 | K8: 548 | M8: 6
A9: 066 | B9: Abrelatas Super Mariposa | C9: 3 | F9: 504 | G9: =+VLOOKUP(F9,Hoja2!A:B,2,FALSE) -> Afila Cuchillos | H9: 3 | K9: 550 | M9: 28
A10: 102 | B10: #N/A | C10: 3 | F10: 505 | G10: =+VLOOKUP(F10,Hoja2!A:B,2,FALSE) -> Pelador Mgo Plastico | H10: 4 | K10: 551 | M10: 8
A11: 101 | B11: Abrelata a Manija Loke | C11: 2 | F11: 505 | G11: =+VLOOKUP(F11,Hoja2!A:B,2,FALSE) -> Pelador Mgo Plastico | H11: 5 | K11: 555 | M11: 15
A12: 109 | B12: #N/A | C12: 7 | F12: 507 | G12: =+VLOOKUP(F12,Hoja2!A:B,2,FALSE) -> Rompenueces | H12: 11 | K12: 556 | M12: 23 | P12: 501 B | Q12: 17
A13: 208 | B13: Cucharita 13cm Azucarera Madera | C13: 11 | F13: 508 | G13: =+VLOOKUP(F13,Hoja2!A:B,2,FALSE) -> Sacafuentes Articulado | H13: 10 | K13: 557 | M13: 5
A14: 220 | B14: Cuchara Madera 40 Cm | C14: 11 | F14: 510 | G14: =+VLOOKUP(F14,Hoja2!A:B,2,FALSE) -> Abrelata Uña Cromado | H14: 6 | K14: 558 | M14: 19
A15: 221 | B15: Cuchara Madera 45 Cm | C15: 11 | F15: 511 | G15: =+VLOOKUP(F15,Hoja2!A:B,2,FALSE) -> Abrelatas Uña 3 En 1 | H15: 7 | K15: 561 | M15: 10
A16: 223 | B16: Cuchara Madera 25 Cm | C16: 5 | F16: 512 | G16: =+VLOOKUP(F16,Hoja2!A:B,2,FALSE) -> Abrelatas Mariposa Capuchon Rojo | H16: 3 | K16: 563 | M16: 10
A17: 224 | B17: Cuchara Madera 30 Cm | C17: 10 | F17: 512 | G17: =+VLOOKUP(F17,Hoja2!A:B,2,FALSE) -> Abrelatas Mariposa Capuchon Rojo | H17: 10 | K17: 564 | M17: 2
A18: 225 | B18: Cuchara Madera 35 Cm | C18: 15 | F18: 513 | G18: =+VLOOKUP(F18,Hoja2!A:B,2,FALSE) -> Pelador Mgo Metalico | H18: 5 | K18: 565 | M18: 11
A19: 229 | B19: Ñoquera Madera | C19: 5 | F19: 518 | G19: =+VLOOKUP(F19,Hoja2!A:B,2,FALSE) -> Sacafuente Gastronomico | H19: 6 | K19: 570 | M19: 23
A20: 248 | B20: Cuchara Nylon | C20: 5 | F20: 519 | G20: =+VLOOKUP(F20,Hoja2!A:B,2,FALSE) -> Cuchillo Untar Mgo Madera x2 | H20: 11 | K20: 573 | M20: 10
A21: 311 | B21: Cuchillo De Torta Ac. Inox | C21: 11 | F21: 519 | G21: =+VLOOKUP(F21,Hoja2!A:B,2,FALSE) -> Cuchillo Untar Mgo Madera x2 | H21: 10 | K21: 574 | M21: 3
A22: 312 | B22: Pala De Torta Acero Inox | C22: 8 | F22: 520 | G22: =+VLOOKUP(F22,Hoja2!A:B,2,FALSE) -> Sacacorcho Tipo Mozo Cromado | H22: 10 | K22: 575 | M22: 5
A23: 315 | B23: Pisa Papas Acero Inox | C23: 4 | F23: 521 | G23: =+VLOOKUP(F23,Hoja2!A:B,2,FALSE) -> Sacacorcho Combinado Cromado | H23: 3 | K23: 577 | M23: 10
A24: 321 | B24: Rallador Cilindrico | C24: 6 | F24: 523 | G24: =+VLOOKUP(F24,Hoja2!A:B,2,FALSE) -> Sacacorcho Doble Aleta Metalico Cuerpo en Nylon Reforzado | H24: 5 | K24: 579 | M24: 10
... A35: 396 | B35: Enrulador De Manteca | C35: 6 | F35: 542 | G35: =+VLOOKUP(F35,Hoja2!A:B,2,FALSE) -> Ahueca Papas | H35: 10 | K35: 823 | M35: 4
A36: 398 | B36: Espatula Calada Nylon | C36: 11

Sheet Hoja2
A1: Cod | B1: Descripcion
A2: 026 | B2: Colador N°8
A3: 027 | B3: Colador N°10
A4: 029 | B4: Colador N°16
A5: 030 | B5: Colador N°20
A6: 031 | B6: Filtro De Cafe
A7: 034 | B7: Filtro De Cafe Gastronomico
A8: 057 | B8: Destapa Corona x1 Cromado
A9: 058 | B9: Cierra Bolsa x2
A10: 059 | B10: Cuchillito De Untar Plast x2
A11: 207 | B11: Ñoquera Madera mango redondo
A12: 208 | B12: Cucharita 13cm Azucarera Madera
A13: 220 | B13: Cuchara Madera 40 Cm
A14: 221 | B14: Cuchara Madera 45 Cm
A15: 222 | B15: Bate Bife Madera
A16: 223 | B16: Cuchara Madera 25 Cm
A17: 224 | B17: Cuchara Madera 30 Cm
A18: 225 | B18: Cuchara Madera 35 Cm
A19: 229 | B19: Ñoquera Madera
A20: 230 | B20: Palo de amasar 30cm
A21: 231 | B21: Palo de amasar 40cm
A22: 233 | B22: Palo de amasar 50cm
... A114: 823 | B114: Exprimidor De Citricos
A115: 328E | B115: Rallador Plano 3 Usos Ac Inox
A116: 360E | B116: Rallador 4 Lados A/L Mgo Plast
A117: 361E | B117: Rallador 4 Lados Ac Inox (20 Cm)
A118: 362E | B118: Rallador 4 Lados Ac Inox (23 Cm)
A119: 363E | B119: Rallador Gourmet Grano Fino
A120: 364E | B120: Rallador Gourmet Grano Medio
A121: 366E | B121: Rallador Conico
A122: 367E | B122: Rallador Hexagonal
A123: 368E | B123: Rallador Hexagonal A/I Con Bas
A124: 369E | B124: Rallador 4 Lados A/L Mgo C/Bas
A125: 478E | B125: Sac. Doble Impulso Pintado
A126: 502E | B126: Abrelata Mariposa Rojo
A127: 503E | B127: Abrelata Doble Engranaje
A128: 525 | B128: Sacacorcho Cabo De Madera
A129: 529E | B129: Sac. Doble Impulso Acero
A130: 574 | B130: Corta Queso Blandos Mango Alambre
A131: 580E | B131: Mini Batidor Pera x1
...

Sheet Ch
A2: Chef
A4: Cod. Art. | B4: Un | C4: Salidas
A5: 099 | B5: 10
A6: 106 | B6: 8
A7: 107 | B7: 12
A8: 108 | B8: 6
A9: 160 | B9: 23
A10: 396 | B10: 6
A11: 609 | B11: 8
A12: 701 | B12: 2
A13: 701 | B13: 3
A14: 702 | B14: 11
A15: 713 Krea | B15: 10
A16: 726 | B16: 10
A17: 731 Krea | B17: 9
A18: 731 | B18: 9
A19: 757 | B19: 91
A20: 771 | B20: 7
A21: 789 | B21: 17
A22: 802 | B22: 8
A23: 845 | B23: 4
A24: 847 | B24: 12
A25: 857 | B25: 12
A26: 878 | B26: 19

Sheet Importado
A2: Importado
A4: Cod. Art. | B4: Un | C4: Salidas | E4: Cod. Art. | F4: Un | G4: Salidas
A5: 035E | B5: 11 | E5: 636E | F5: 8
A6: 361E | B6: 11 | E6: 702E | F6: 11
A7: 367E | B7: 11 | E7: 712E | F7: 18
A8: 439E | B8: 5 | E8: 809E | F8: 11
A9: 440E | B9: 3 | E9: 811E | F9: 3
A10: 503E | B10: 3 | E10: 812E | F10: 4
A11: 521E | B11: 4 | E11: 814E | F11: 11
A12: 538E | B12: 10 | E12: 816E | F12: 7
A13: 541E | B13: 10 | E13: 817E | F13: 10
A14: 574E | B14: 3 | E14: 819E | F14: 8
A15: 585E | B15: 4 | E15: 870E | F15: 3
A16: 598E | B16: 4 | E16: 935E | F16: 7
... A19: 607E | B19: 11 | E19: 955E | F19: 8
E20: 960E | F20: 8

Sheet Hoja1
A3: Limpieza Baño
A5: Fecha | B5: Encargado | C5: Firma
