Workbook

Sheet Hoja1
B2: Cod Art | C2: Descripcion ART | D2: Sect | E2: Parte | F2: Consumo x Mes | G2: E Madre Loeke | H2: E Madre Chef | I2: Tallerista
B3: 511 | C3: 3 En 1 | D3: A1 | E3: =+VLOOKUP(D3,'[1]Consumo x Cod Articulo'!$C$1:$O$65536,7,) -> Plaquita 3 en 1 LK | F3: =+G3+H3 -> 420 | G3: 420 | H3: 0 | I3: Martin C
B4: 315 | C4: Pisa Papas Acero Inox | D4: A10 | E4: =+VLOOKUP(D4,'[1]Consumo x Cod Articulo'!$C$1:$O$65536,7,) -> Capuchon ф 8 | F4: =+G4+H4 -> 1920 | G4: 1920 | H4: 0 | I4: Edwin
B5: 355 | C5: Pisa Papas Nylon Mgo Plas | D5: A10 | E5: =+VLOOKUP(D5,'[1]Consumo x Cod Articulo'!$C$1:$O$65536,7,) -> Capuchon ф 8 | F5: =+G5+H5 -> 480 | G5: 480 | H5: 0 | I5: Edwin
B6: 535 | C6: Cepillo Limpia Vaso Mamad | D6: A10 | E6: =+VLOOKUP(D6,'[1]Consumo x Cod Articulo'!$C$1:$O$65536,7,) -> Capuchon ф 8 | F6: =+G6+H6 -> 996 | G6: 996 | H6: 0 | I6: Juan Farias
B7: 512 | C7: Abrelata Mariposa Plastic | D7: A11 | E7: =+VLOOKUP(D7,'[1]Consumo x Cod Articulo'!$C$1:$O$65536,7,) -> Capuchon Mariposa 512 | F7: =+G7+H7 -> 984 | G7: 984 | H7: 0 | I7: Poly
B8: 501 | C8: Abrelatas A Manija | D8: A12 | E8: =+VLOOKUP(D8,'[1]Consumo x Cod Articulo'!$C$1:$O$65536,7,) -> Pirolo Rojo | F8: =+G8+H8 -> 5040 | G8: 5040 | H8: 0 | I8: Logistica
B9: 515 | C9: Batidor Resorte | D9: A13 | E9: =+VLOOKUP(D9,'[1]Consumo x Cod Articulo'!$C$1:$O$65536,7,) -> Capuchon Batidor LK | F9: =+G9+H9 -> 144 | G9: 144 | H9: 0 | I9: Carlos E
B10: 546 | C10: Corta Queso | D10: A13 | E10: =+VLOOKUP(D10,'[1]Consumo x Cod Articulo'!$C$1:$O$65536,7,) -> Capuchon Batidor LK | F10: =+G10+H10 -> 4800 | G10: 4800 | H10: 0 | I10: Lucho
B11: 548 | C11: Pincel Pastelero | D11: A15 | E11: =+VLOOKUP(D11,'[1]Consumo x Cod Articulo'!$C$1:$O$65536,7,) -> Capuchon ф10 | F11: =+G11+H11 -> 360 | G11: 360 | H11: 0 | I11: Logistica
B12: 548 | C12: Pincel Pastelero | D12: A16 | E12: =+VLOOKUP(D12,'[1]Consumo x Cod Articulo'!$C$1:$O$65536,7,) -> Mangos ф 10 | F12: =+G12+H12 -> 360 | G12: 360 | H12: 0 | I12: Logistica
B13: 312 | C13: Pala De Torta Acero Inox | D13: A17 | E13: =+VLOOKUP(D13,'[1]Consumo x Cod Articulo'!$C$1:$O$65536,7,) -> Mango LK Cuch y P Torta | F13: =+G13+H13 -> 156 | G13: 156 | H13: 0 | I13: Martin C
B14: 332 | C14: Espatula Acero Inox. | D14: A18 | E14: =+VLOOKUP(D14,'[1]Consumo x Cod Articulo'!$C$1:$O$65536,7,) -> Capuchon Espatula LK | F14: =+G14+H14 -> 168 | G14: 168 | H14: 0 | I14: Carlos E
... B157: 818 | C157: Corta Torta Plast | D157: V8 | E157: =+VLOOKUP(D157,'[1]Consumo x Cod Articulo'!$C$1:$O$65536,7,) -> Corta Torta | F157: =+G157+H157 -> 0 | G157: 0 | H157: 0 | I157: Carlos E

Sheet Hoja2
J1: Consumo
A2: N° Orden | B2: Sector | C2: Descripcion | D2: Peso x Pieza | E2: Cambio | F2: Minimo Definido | G2: Peso x Bolsa KG | H2: Uni x Bolsa | I2: Consumo Total | J2: Martin C | K2: Edwin | L2: Juan Farias | M2: Poly | N2: Logistica | O2: Carlos E | P2: Lucho | Q2: Rodar | R2: Oscar
A3: 23 | B3: C1 | C3: Mango 505 P/Calar. | D3: =+VLOOKUP(B3,'[1]Consumo x Cod Articulo'!$C$1:$O$65536,6,) -> 0.0056 | E3: =+IF(F3=H3,"No","si") -> No | F3: =+H3 -> 1800 | G3: =+F3*D3 -> 10.08 | H3: 1800 | I3: =+SUM(J3:R3) -> 42000 | J3: =+IF(SUMIFS(Hoja1!$F:$F,Hoja1!$D:$D,$B3,Hoja1!$I:$I,J$2)>1,SUMIFS(Hoja1!$F:$F,Hoja1!$D:$D,$B3,Hoja1!$I:$I,J$2),"") | K3: =+IF(SUMIFS(Hoja1!$F:$F,Hoja1!$D:$D,$B3,Hoja1!$I:$I,K$2)>1,SUMIFS(Hoja1!$F:$F,Hoja1!$D:$D,$B3,Hoja1!$I:$I,K$2),"") -> 21000 | L3: =+IF(SUMIFS(Hoja1!$F:$F,Hoja1!$D:$D,$B3,Hoja1!$I:$I,L$2)>1,SUMIFS(Hoja1!$F:$F,Hoja1!$D:$D,$B3,Hoja1!$I:$I,L$2),"") | M3: =+IF(SUMIFS(Hoja1!$F:$F,Hoja1!$D:$D,$B3,Hoja1!$I:$I,M$2)>1,SUMIFS(Hoja1!$F:$F,Hoja1!$D:$D,$B3,Hoja1!$I:$I,M$2),"") | N3: =+IF(SUMIFS(Hoja1!$F:$F,Hoja1!$D:$D,$B3,Hoja1!$I:$I,N$2)>1,SUMIFS(Hoja1!$F:$F,Hoja1!$D:$D,$B3,Hoja1!$I:$I,N$2),"") | O3: =+IF(SUMIFS(Hoja1!$F:$F,Hoja1!$D:$D,$B3,Hoja1!$I:$I,O$2)>1,SUMIFS(Hoja1!$F:$F,Hoja1!$D:$D,$B3,Hoja1!$I:$I,O$2),"") | P3: =+IF(SUMIFS(Hoja1!$F:$F,Hoja1!$D:$D,$B3,Hoja1!$I:$I,P$2)>1,SUMIFS(Hoja1!$F:$F,Hoja1!$D:$D,$B3,Hoja1!$I:$I,P$2),"") -> 21000 | Q3: =+IF(SUMIFS(Hoja1!$F:$F,Hoja1!$D:$D,$B3,Hoja1!$I:$I,Q$2)>1,SUMIFS(Hoja1!$F:$F,Hoja1!$D:$D,$B3,Hoja1!$I:$I,Q$2),"") | R3: =+IF(SUMIFS(Hoja1!$F:$F,Hoja1!$D:$D,$B3,Hoja1!$I:$I,R$2)>1,SUMIFS(Hoja1!$F:$F,Hoja1!$D:$D,$B3,Hoja1!$I:$I,R$2),"")
A4: 36 | B4: EP4 | C4: Afila Caladas Azules | D4: =+VLOOKUP(B4,'[1]Consumo x Cod Articulo'!$C$1:$O$65536,6,) -> 0.049 | E4: =+IF(F4=H4,"No","si") -> No | F4: =+H4 -> 150 | G4: =+F4*D4 -> 7.35 | H4: 150 | I4: =+SUM(J4:R4) -> 11650 | J4: =+IF(SUMIFS(Hoja1!$F:$F,Hoja1!$D:$D,$B4,Hoja1!$I:$I,J$2)>1,SUMIFS(Hoja1!$F:$F,Hoja1!$D:$D,$B4,Hoja1!$I:$I,J$2),"") -> 6050 | K4: =+IF(SUMIFS(Hoja1!$F:$F,Hoja1!$D:$D,$B4,Hoja1!$I:$I,K$2)>1,SUMIFS(Hoja1!$F:$F,Hoja1!$D:$D,$B4,Hoja1!$I:$I,K$2),"") -> 5600 | L4: =+IF(SUMIFS(Hoja1!$F:$F,Hoja1!$D:$D,$B4,Hoja1!$I:$I,L$2)>1,SUMIFS(Hoja1!$F:$F,Hoja1!$D:$D,$B4,Hoja1!$I:$I,L$2),"") | M4: =+IF(SUMIFS(Hoja1!$F:$F,Hoja1!$D:$D,$B4,Hoja1!$I:$I,M$2)>1,SUMIFS(Hoja1!$F:$F,Hoja1!$D:$D,$B4,Hoja1!$I:$I,M$2),"") | N4: =+IF(SUMIFS(Hoja1!$F:$F,Hoja1!$D:$D,$B4,Hoja1!$I:$I,N$2)>1,SUMIFS(Hoja1!$F:$F,Hoja1!$D:$D,$B4,Hoja1!$I:$I,N$2),"") | O4: =+IF(SUMIFS(Hoja1!$F:$F,Hoja1!$D:$D,$B4,Hoja1!$I:$I,O$2)>1,SUMIFS(Hoja1!$F:$F,Hoja1!$D:$D,$B4,Hoja1!$I:$I,O$2),"") | P4: =+IF(SUMIFS(Hoja1!$F:$F,Hoja1!$D:$D,$B4,Hoja1!$I:$I,P$2)>1,SUMIFS(Hoja1!$F:$F,Hoja1!$D:$D,$B4,Hoja1!$I:$I,P$2),"") | Q4: =+IF(SUMIFS(Hoja1!$F:$F,Hoja1!$D:$D,$B4,Hoja1!$I:$I,Q$2)>1,SUMIFS(Hoja1!$F:$F,Hoja1!$D:$D,$B4,Hoja1!$I:$I,Q$2),"") | R4: =+IF(SUMIFS(Hoja1!$F:$F,Hoja1!$D:$D,$B4,Hoja1!$I:$I,R$2)>1,SUMIFS(Hoja1!$F:$F,Hoja1!$D:$D,$B4,Hoja1!$I:$I,R$2),"")
A5: 3 | B5: A3 | C5: Muñeco Antiderrame | D5: =+VLOOKUP(B5,'[1]Consumo x Cod Articulo'!$C$1:$O$65536,6,) -> 0.008 | E5: =+IF(F5=H5,"No","si") -> si | F5: 500 | G5: =+F5*D5 -> 4 | H5: 1000 | I5: =+SUM(J5:R5) -> 120 | J5: =+IF(SUMIFS(Hoja1!$F:$F,Hoja1!$D:$D,$B5,Hoja1!$I:$I,J$2)>1,SUMIFS(Hoja1!$F:$F,Hoja1!$D:$D,$B5,Hoja1!$I:$I,J$2),"") | K5: =+IF(SUMIFS(Hoja1!$F:$F,Hoja1!$D:$D,$B5,Hoja1!$I:$I,K$2)>1,SUMIFS(Hoja1!$F:$F,Hoja1!$D:$D,$B5,Hoja1!$I:$I,K$2),"") | L5: =+IF(SUMIFS(Hoja1!$F:$F,Hoja1!$D:$D,$B5,Hoja1!$I:$I,L$2)>1,SUMIFS(Hoja1!$F:$F,Hoja1!$D:$D,$B5,Hoja1!$I:$I,L$2),"") -> 120 | M5: =+IF(SUMIFS(Hoja1!$F:$F,Hoja1!$D:$D,$B5,Hoja1!$I:$I,M$2)>1,SUMIFS(Hoja1!$F:$F,Hoja1!$D:$D,$B5,Hoja1!$I:$I,M$2),"") | N5: =+IF(SUMIFS(Hoja1!$F:$F,Hoja1!$D:$D,$B5,Hoja1!$I:$I,N$2)>1,SUMIFS(Hoja1!$F:$F,Hoja1!$D:$D,$B5,Hoja1!$I:$I,N$2),"") | O5: =+IF(SUMIFS(Hoja1!$F:$F,Hoja1!$D:$D,$B5,Hoja1!$I:$I,O$2)>1,SUMIFS(Hoja1!$F:$F,Hoja1!$D:$D,$B5,Hoja1!$I:$I,O$2),"") | P5: =+IF(SUMIFS(Hoja1!$F:$F,Hoja1!$D:$D,$B5,Hoja1!$I:$I,P$2)>1,SUMIFS(Hoja1!$F:$F,Hoja1!$D:$D,$B5,Hoja1!$I:$I,P$2),"") | Q5: =+IF(SUMIFS(Hoja1!$F:$F,Hoja1!$D:$D,$B5,Hoja1!$I:$I,Q$2)>1,SUMIFS(Hoja1!$F:$F,Hoja1!$D:$D,$B5,Hoja1!$I:$I,Q$2),"") | R5: =+IF(SUMIFS(Hoja1!$F:$F,Hoja1!$D:$D,$B5,Hoja1!$I:$I,R$2)>1,SUMIFS(Hoja1!$F:$F,Hoja1!$D:$D,$B5,Hoja1!$I:$I,R$2),"")
A6: 6 | B6: A8 | C6: Buje Blanco | D6: =+VLOOKUP(B6,'[1]Consumo x Cod Articulo'!$C$1:$O$65536,6,) -> 0.00063 | E6: =+IF(F6=H6,"No","si") -> No | F6: =+H6 -> 2500 | G6: =+F6*D6 -> 1.575 | H6: 2500 | I6: =+SUM(J6:R6) -> 7404 | J6: =+IF(SUMIFS(Hoja1!$F:$F,Hoja1!$D:$D,$B6,Hoja1!$I:$I,J$2)>1,SUMIFS(Hoja1!$F:$F,Hoja1!$D:$D,$B6,Hoja1!$I:$I,J$2),"") | K6: =+IF(SUMIFS(Hoja1!$F:$F,Hoja1!$D:$D,$B6,Hoja1!$I:$I,K$2)>1,SUMIFS(Hoja1!$F:$F,Hoja1!$D:$D,$B6,Hoja1!$I:$I,K$2),"") | L6: =+IF(SUMIFS(Hoja1!$F:$F,Hoja1!$D:$D,$B6,Hoja1!$I:$I,L$2)>1,SUMIFS(Hoja1!$F:$F,Hoja1!$D:$D,$B6,Hoja1!$I:$I,L$2),"") | M6: =+IF(SUMIFS(Hoja1!$F:$F,Hoja1!$D:$D,$B6,Hoja1!$I:$I,M$2)>1,SUMIFS(Hoja1!$F:$F,Hoja1!$D:$D,$B6,Hoja1!$I:$I,M$2),"") -> 7404 | N6: =+IF(SUMIFS(Hoja1!$F:$F,Hoja1!$D:$D,$B6,Hoja1!$I:$I,N$2)>1,SUMIFS(Hoja1!$F:$F,Hoja1!$D:$D,$B6,Hoja1!$I:$I,N$2),"") | O6: =+IF(SUMIFS(Hoja1!$F:$F,Hoja1!$D:$D,$B6,Hoja1!$I:$I,O$2)>1,SUMIFS(Hoja1!$F:$F,Hoja1!$D:$D,$B6,Hoja1!$I:$I,O$2),"") | P6: =+IF(SUMIFS(Hoja1!$F:$F,Hoja1!$D:$D,$B6,Hoja1!$I:$I,P$2)>1,SUMIFS(Hoja1!$F:$F,Hoja1!$D:$D,$B6,Hoja1!$I:$I,P$2),"") | Q6: =+IF(SUMIFS(Hoja1!$F:$F,Hoja1!$D:$D,$B6,Hoja1!$I:$I,Q$2)>1,SUMIFS(Hoja1!$F:$F,Hoja1!$D:$D,$B6,Hoja1!$I:$I,Q$2),"") | R6: =+IF(SUMIFS(Hoja1!$F:$F,Hoja1!$D:$D,$B6,Hoja1!$I:$I,R$2)>1,SUMIFS(Hoja1!$F:$F,Hoja1!$D:$D,$B6,Hoja1!$I:$I,R$2),"")
A7: 30 | B7: C10 | C7: Mango LK Espatula | D7: =+VLOOKUP(B7,'[1]Consumo x Cod Articulo'!$C$1:$O$65536,6,) -> 0.015 | E7: =+IF(F7=H7,"No","si") -> No | F7: =+H7 -> 1000 | G7: =+F7*D7 -> 15 | H7: 1000 | I7: =+SUM(J7:R7) -> 7040 | J7: =+IF(SUMIFS(Hoja1!$F:$F,Hoja1!$D:$D,$B7,Hoja1!$I:$I,J$2)>1,SUMIFS(Hoja1!$F:$F,Hoja1!$D:$D,$B7,Hoja1!$I:$I,J$2),"") -> 1016 | K7: =+IF(SUMIFS(Hoja1!$F:$F,Hoja1!$D:$D,$B7,Hoja1!$I:$I,K$2)>1,SUMIFS(Hoja1!$F:$F,Hoja1!$D:$D,$B7,Hoja1!$I:$I,K$2),"") | L7: =+IF(SUMIFS(Hoja1!$F:$F,Hoja1!$D:$D,$B7,Hoja1!$I:$I,L$2)>1,SUMIFS(Hoja1!$F:$F,Hoja1!$D:$D,$B7,Hoja1!$I:$I,L$2),"") -> 996 | M7: =+IF(SUMIFS(Hoja1!$F:$F,Hoja1!$D:$D,$B7,Hoja1!$I:$I,M$2)>1,SUMIFS(Hoja1!$F:$F,Hoja1!$D:$D,$B7,Hoja1!$I:$I,M$2),"") | N7: =+IF(SUMIFS(Hoja1!$F:$F,Hoja1!$D:$D,$B7,Hoja1!$I:$I,N$2)>1,SUMIFS(Hoja1!$F:$F,Hoja1!$D:$D,$B7,Hoja1!$I:$I,N$2),"") -> 696 | O7: =+IF(SUMIFS(Hoja1!$F:$F,Hoja1!$D:$D,$B7,Hoja1!$I:$I,O$2)>1,SUMIFS(Hoja1!$F:$F,Hoja1!$D:$D,$B7,Hoja1!$I:$I,O$2),"") -> 1572 | P7: =+IF(SUMIFS(Hoja1!$F:$F,Hoja1!$D:$D,$B7,Hoja1!$I:$I,P$2)>1,SUMIFS(Hoja1!$F:$F,Hoja1!$D:$D,$B7,Hoja1!$I:$I,P$2),"") -> 2760 | Q7: =+IF(SUMIFS(Hoja1!$F:$F,Hoja1!$D:$D,$B7,Hoja1!$I:$I,Q$2)>1,SUMIFS(Hoja1!$F:$F,Hoja1!$D:$D,$B7,Hoja1!$I:$I,Q$2),"") | R7: =+IF(SUMIFS(Hoja1!$F:$F,Hoja1!$D:$D,$B7,Hoja1!$I:$I,R$2)>1,SUMIFS(Hoja1!$F:$F,Hoja1!$D:$D,$B7,Hoja1!$I:$I,R$2),"")
A8: 35 | B8: EP2 | C8: Mango Pelador LK 586 S/S | D8: =+VLOOKUP(B8,'[1]Consumo x Cod Articulo'!$C$1:$O$65536,6,) -> 0.0165 | E8: =+IF(F8=H8,"No","si") -> No | F8: =+H8 -> 250 | G8: =+F8*D8 -> 4.125 | H8: 250 | I8: =+SUM(J8:R8) -> 6000 | J8: =+IF(SUMIFS(Hoja1!$F:$F,Hoja1!$D:$D,$B8,Hoja1!$I:$I,J$2)>1,SUMIFS(Hoja1!$F:$F,Hoja1!$D:$D,$B8,Hoja1!$I:$I,J$2),"") | K8: =+IF(SUMIFS(Hoja1!$F:$F,Hoja1!$D:$D,$B8,Hoja1!$I:$I,K$2)>1,SUMIFS(Hoja1!$F:$F,Hoja1!$D:$D,$B8,Hoja1!$I:$I,K$2),"") | L8: =+IF(SUMIFS(Hoja1!$F:$F,Hoja1!$D:$D,$B8,Hoja1!$I:$I,L$2)>1,SUMIFS(Hoja1!$F:$F,Hoja1!$D:$D,$B8,Hoja1!$I:$I,L$2),"") | M8: =+IF(SUMIFS(Hoja1!$F:$F,Hoja1!$D:$D,$B8,Hoja1!$I:$I,M$2)>1,SUMIFS(Hoja1!$F:$F,Hoja1!$D:$D,$B8,Hoja1!$I:$I,M$2),"") | N8: =+IF(SUMIFS(Hoja1!$F:$F,Hoja1!$D:$D,$B8,Hoja1!$I:$I,N$2)>1,SUMIFS(Hoja1!$F:$F,Hoja1!$D:$D,$B8,Hoja1!$I:$I,N$2),"") | O8: =+IF(SUMIFS(Hoja1!$F:$F,Hoja1!$D:$D,$B8,Hoja1!$I:$I,O$2)>1,SUMIFS(Hoja1!$F:$F,Hoja1!$D:$D,$B8,Hoja1!$I:$I,O$2),"") | P8: =+IF(SUMIFS(Hoja1!$F:$F,Hoja1!$D:$D,$B8,Hoja1!$I:$I,P$2)>1,SUMIFS(Hoja1!$F:$F,Hoja1!$D:$D,$B8,Hoja1!$I:$I,P$2),"") -> 6000 | Q8: =+IF(SUMIFS(Hoja1!$F:$F,Hoja1!$D:$D,$B8,Hoja1!$I:$I,Q$2)>1,SUMIFS(Hoja1!$F:$F,Hoja1!$D:$D,$B8,Hoja1!$I:$I,Q$2),"") | R8: =+IF(SUMIFS(Hoja1!$F:$F,Hoja1!$D:$D,$B8,Hoja1!$I:$I,R$2)>1,SUMIFS(Hoja1!$F:$F,Hoja1!$D:$D,$B8,Hoja1!$I:$I,R$2),"")
A9: 16 | B9: B1 | C9: Cilindro Corta Queso | D9: =+VLOOKUP(B9,'[1]Consumo x Cod Articulo'!$C$1:$O$65536,6,) -> 0.0077 | E9: =+IF(F9=H9,"No","si") -> No | F9: =+H9 -> 1000 | G9: =+F9*D9 -> 7.7 | H9: 1000 | I9: =+SUM(J9:R9) -> 5400 | J9: =+IF(SUMIFS(Hoja1!$F:$F,Hoja1!$D:$D,$B9,Hoja1!$I:$I,J$2)>1,SUMIFS(Hoja1!$F:$F,Hoja1!$D:$D,$B9,Hoja1!$I:$I,J$2),"") | K9: =+IF(SUMIFS(Hoja1!$F:$F,Hoja1!$D:$D,$B9,Hoja1!$I:$I,K$2)>1,SUMIFS(Hoja1!$F:$F,Hoja1!$D:$D,$B9,Hoja1!$I:$I,K$2),"") | L9: =+IF(SUMIFS(Hoja1!$F:$F,Hoja1!$D:$D,$B9,Hoja1!$I:$I,L$2)>1,SUMIFS(Hoja1!$F:$F,Hoja1!$D:$D,$B9,Hoja1!$I:$I,L$2),"") | M9: =+IF(SUMIFS(Hoja1!$F:$F,Hoja1!$D:$D,$B9,Hoja1!$I:$I,M$2)>1,SUMIFS(Hoja1!$F:$F,Hoja1!$D:$D,$B9,Hoja1!$I:$I,M$2),"") | N9: =+IF(SUMIFS(Hoja1!$F:$F,Hoja1!$D:$D,$B9,Hoja1!$I:$I,N$2)>1,SUMIFS(Hoja1!$F:$F,Hoja1!$D:$D,$B9,Hoja1!$I:$I,N$2),"") | O9: =+IF(SUMIFS(Hoja1!$F:$F,Hoja1!$D:$D,$B9,Hoja1!$I:$I,O$2)>1,SUMIFS(Hoja1!$F:$F,Hoja1!$D:$D,$B9,Hoja1!$I:$I,O$2),"") | P9: =+IF(SUMIFS(Hoja1!$F:$F,Hoja1!$D:$D,$B9,Hoja1!$I:$I,P$2)>1,SUMIFS(Hoja1!$F:$F,Hoja1!$D:$D,$B9,Hoja1!$I:$I,P$2),"") -> 5400 | Q9: =+IF(SUMIFS(Hoja1!$F:$F,Hoja1!$D:$D,$B9,Hoja1!$I:$I,Q$2)>1,SUMIFS(Hoja1!$F:$F,Hoja1!$D:$D,$B9,Hoja1!$I:$I,Q$2),"") | R9: =+IF(SUMIFS(Hoja1!$F:$F,Hoja1!$D:$D,$B9,Hoja1!$I:$I,R$2)>1,SUMIFS(Hoja1!$F:$F,Hoja1!$D:$D,$B9,Hoja1!$I:$I,R$2),"")
A10: 5 | B10: A5 | C10: Mang Cuch Unt Chef | D10: =+VLOOKUP(B10,'[1]Consumo x Cod Articulo'!$C$1:$O$65536,6,) -> 0.01 | E10: =+IF(F10=H10,"No","si") -> si | F10: 250 | G10: =+F10*D10 -> 2.5 | H10: 1000 | I10: =+SUM(J10:R10) -> 168 | J10: =+IF(SUMIFS(Hoja1!$F:$F,Hoja1!$D:$D,$B10,Hoja1!$I:$I,J$2)>1,SUMIFS(Hoja1!$F:$F,Hoja1!$D:$D,$B10,Hoja1!$I:$I,J$2),"") -> 168 | K10: =+IF(SUMIFS(Hoja1!$F:$F,Hoja1!$D:$D,$B10,Hoja1!$I:$I,K$2)>1,SUMIFS(Hoja1!$F:$F,Hoja1!$D:$D,$B10,Hoja1!$I:$I,K$2),"") | L10: =+IF(SUMIFS(Hoja1!$F:$F,Hoja1!$D:$D,$B10,Hoja1!$I:$I,L$2)>1,SUMIFS(Hoja1!$F:$F,Hoja1!$D:$D,$B10,Hoja1!$I:$I,L$2),"") | M10: =+IF(SUMIFS(Hoja1!$F:$F,Hoja1!$D:$D,$B10,Hoja1!$I:$I,M$2)>1,SUMIFS(Hoja1!$F:$F,Hoja1!$D:$D,$B10,Hoja1!$I:$I,M$2),"") | N10: =+IF(SUMIFS(Hoja1!$F:$F,Hoja1!$D:$D,$B10,Hoja1!$I:$I,N$2)>1,SUMIFS(Hoja1!$F:$F,Hoja1!$D:$D,$B10,Hoja1!$I:$I,N$2),"") | O10: =+IF(SUMIFS(Hoja1!$F:$F,Hoja1!$D:$D,$B10,Hoja1!$I:$I,O$2)>1,SUMIFS(Hoja1!$F:$F,Hoja1!$D:$D,$B10,Hoja1!$I:$I,O$2),"") | P10: =+IF(SUMIFS(Hoja1!$F:$F,Hoja1!$D:$D,$B10,Hoja1!$I:$I,P$2)>1,SUMIFS(Hoja1!$F:$F,Hoja1!$D:$D,$B10,Hoja1!$I:$I,P$2),"") | Q10: =+IF(SUMIFS(Hoja1!$F:$F,Hoja1!$D:$D,$B10,Hoja1!$I:$I,Q$2)>1,SUMIFS(Hoja1!$F:$F,Hoja1!$D:$D,$B10,Hoja1!$I:$I,Q$2),"") | R10: =+IF(SUMIFS(Hoja1!$F:$F,Hoja1!$D:$D,$B10,Hoja1!$I:$I,R$2)>1,SUMIFS(Hoja1!$F:$F,Hoja1!$D:$D,$B10,Hoja1!$I:$I,R$2),"")
A11: 33 | B11: C14 | C11: Manguito Abrelat. Rojo | D11: =+VLOOKUP(B11,'[1]Consumo x Cod Articulo'!$C$1:$O$65536,6,) -> 0.009 | E11: =+IF(F11=H11,"No","si") -> No | F11: 1200 | G11: =+F11*D11 -> 10.8 | H11: 1200 | I11: =+SUM(J11:R11) -> 5040 | J11: =+IF(SUMIFS(Hoja1!$F:$F,Hoja1!$D:$D,$B11,Hoja1!$I:$I,J$2)>1,SUMIFS(Hoja1!$F:$F,Hoja1!$D:$D,$B11,Hoja1!$I:$I,J$2),"") | K11: =+IF(SUMIFS(Hoja1!$F:$F,Hoja1!$D:$D,$B11,Hoja1!$I:$I,K$2)>1,SUMIFS(Hoja1!$F:$F,Hoja1!$D:$D,$B11,Hoja1!$I:$I,K$2),"") | L11: =+IF(SUMIFS(Hoja1!$F:$F,Hoja1!$D:$D,$B11,Hoja1!$I:$I,L$2)>1,SUMIFS(Hoja1!$F:$F,Hoja1!$D:$D,$B11,Hoja1!$I:$I,L$2),"") | M11: =+IF(SUMIFS(Hoja1!$F:$F,Hoja1!$D:$D,$B11,Hoja1!$I:$I,M$2)>1,SUMIFS(Hoja1!$F:$F,Hoja1!$D:$D,$B11,Hoja1!$I:$I,M$2),"") | N11: =+IF(SUMIFS(Hoja1!$F:$F,Hoja1!$D:$D,$B11,Hoja1!$I:$I,N$2)>1,SUMIFS(Hoja1!$F:$F,Hoja1!$D:$D,$B11,Hoja1!$I:$I,N$2),"") -> 5040 | O11: =+IF(SUMIFS(Hoja1!$F:$F,Hoja1!$D:$D,$B11,Hoja1!$I:$I,O$2)>1,SUMIFS(Hoja1!$F:$F,Hoja1!$D:$D,$B11,Hoja1!$I:$I,O$2),"") | P11: =+IF(SUMIFS(Hoja1!$F:$F,Hoja1!$D:$D,$B11,Hoja1!$I:$I,P$2)>1,SUMIFS(Hoja1!$F:$F,Hoja1!$D:$D,$B11,Hoja1!$I:$I,P$2),"") | Q11: =+IF(SUMIFS(Hoja1!$F:$F,Hoja1!$D:$D,$B11,Hoja1!$I:$I,Q$2)>1,SUMIFS(Hoja1!$F:$F,Hoja1!$D:$D,$B11,Hoja1!$I:$I,Q$2),"") | R11: =+IF(SUMIFS(Hoja1!$F:$F,Hoja1!$D:$D,$B11,Hoja1!$I:$I,R$2)>1,SUMIFS(Hoja1!$F:$F,Hoja1!$D:$D,$B11,Hoja1!$I:$I,R$2),"")
A12: 7 | B12: A10 | C12: Capuchon ф 8 | D12: =+VLOOKUP(B12,'[1]Consumo x Cod Articulo'!$C$1:$O$65536,6,) -> 0.0022 | E12: =+IF(F12=H12,"No","si") -> si | F12: 1000 | G12: =+F12*D12 -> 2.2 | H12: =+VLOOKUP(B12,'[1]Relevamiento y OP VACIO'!$C$1:$AH$65536,26,) -> 5000 | I12: =+SUM(J12:R12) -> 3396 | J12: =+IF(SUMIFS(Hoja1!$F:$F,Hoja1!$D:$D,$B12,Hoja1!$I:$I,J$2)>1,SUMIFS(Hoja1!$F:$F,Hoja1!$D:$D,$B12,Hoja1!$I:$I,J$2),"") | K12: =+IF(SUMIFS(Hoja1!$F:$F,Hoja1!$D:$D,$B12,Hoja1!$I:$I,K$2)>1,SUMIFS(Hoja1!$F:$F,Hoja1!$D:$D,$B12,Hoja1!$I:$I,K$2),"") -> 2400 | L12: =+IF(SUMIFS(Hoja1!$F:$F,Hoja1!$D:$D,$B12,Hoja1!$I:$I,L$2)>1,SUMIFS(Hoja1!$F:$F,Hoja1!$D:$D,$B12,Hoja1!$I:$I,L$2),"") -> 996 | M12: =+IF(SUMIFS(Hoja1!$F:$F,Hoja1!$D:$D,$B12,Hoja1!$I:$I,M$2)>1,SUMIFS(Hoja1!$F:$F,Hoja1!$D:$D,$B12,Hoja1!$I:$I,M$2),"") | N12: =+IF(SUMIFS(Hoja1!$F:$F,Hoja1!$D:$D,$B12,Hoja1!$I:$I,N$2)>1,SUMIFS(Hoja1!$F:$F,Hoja1!$D:$D,$B12,Hoja1!$I:$I,N$2),"") | O12: =+IF(SUMIFS(Hoja1!$F:$F,Hoja1!$D:$D,$B12,Hoja1!$I:$I,O$2)>1,SUMIFS(Hoja1!$F:$F,Hoja1!$D:$D,$B12,Hoja1!$I:$I,O$2),"") | P12: =+IF(SUMIFS(Hoja1!$F:$F,Hoja1!$D:$D,$B12,Hoja1!$I:$I,P$2)>1,SUMIFS(Hoja1!$F:$F,Hoja1!$D:$D,$B12,Hoja1!$I:$I,P$2),"") | Q12: =+IF(SUMIFS(Hoja1!$F:$F,Hoja1!$D:$D,$B12,Hoja1!$I:$I,Q$2)>1,SUMIFS(Hoja1!$F:$F,Hoja1!$D:$D,$B12,Hoja1!$I:$I,Q$2),"") | R12: =+IF(SUMIFS(Hoja1!$F:$F,Hoja1!$D:$D,$B12,Hoja1!$I:$I,R$2)>1,SUMIFS(Hoja1!$F:$F,Hoja1!$D:$D,$B12,Hoja1!$I:$I,R$2),"")
A13: 25 | B13: C3 | C13: Mango LK Corta Queso | D13: =+VLOOKUP(B13,'[1]Consumo x Cod Articulo'!$C$1:$O$65536,6,) -> 0.015 | E13: =+IF(F13=H13,"No","si") -> No | F13: 1000 | G13: =+F13*D13 -> 15 | H13: 1000 | I13: =+SUM(J13:R13) -> 4944 | J13: =+IF(SUMIFS(Hoja1!$F:$F,Hoja1!$D:$D,$B13,Hoja1!$I:$I,J$2)>1,SUMIFS(Hoja1!$F:$F,Hoja1!$D:$D,$B13,Hoja1!$I:$I,J$2),"") | K13: =+IF(SUMIFS(Hoja1!$F:$F,Hoja1!$D:$D,$B13,Hoja1!$I:$I,K$2)>1,SUMIFS(Hoja1!$F:$F,Hoja1!$D:$D,$B13,Hoja1!$I:$I,K$2),"") | L13: =+IF(SUMIFS(Hoja1!$F:$F,Hoja1!$D:$D,$B13,Hoja1!$I:$I,L$2)>1,SUMIFS(Hoja1!$F:$F,Hoja1!$D:$D,$B13,Hoja1!$I:$I,L$2),"") | M13: =+IF(SUMIFS(Hoja1!$F:$F,Hoja1!$D:$D,$B13,Hoja1!$I:$I,M$2)>1,SUMIFS(Hoja1!$F:$F,Hoja1!$D:$D,$B13,Hoja1!$I:$I,M$2),"") | N13: =+IF(SUMIFS(Hoja1!$F:$F,Hoja1!$D:$D,$B13,Hoja1!$I:$I,N$2)>1,SUMIFS(Hoja1!$F:$F,Hoja1!$D:$D,$B13,Hoja1!$I:$I,N$2),"") | O13: =+IF(SUMIFS(Hoja1!$F:$F,Hoja1!$D:$D,$B13,Hoja1!$I:$I,O$2)>1,SUMIFS(Hoja1!$F:$F,Hoja1!$D:$D,$B13,Hoja1!$I:$I,O$2),"") -> 144 | P13: =+IF(SUMIFS(Hoja1!$F:$F,Hoja1!$D:$D,$B13,Hoja1!$I:$I,P$2)>1,SUMIFS(Hoja1!$F:$F,Hoja1!$D:$D,$B13,Hoja1!$I:$I,P$2),"") -> 4800 | Q13: =+IF(SUMIFS(Hoja1!$F:$F,Hoja1!$D:$D,$B13,Hoja1!$I:$I,Q$2)>1,SUMIFS(Hoja1!$F:$F,Hoja1!$D:$D,$B13,Hoja1!$I:$I,Q$2),"") | R13: =+IF(SUMIFS(Hoja1!$F:$F,Hoja1!$D:$D,$B13,Hoja1!$I:$I,R$2)>1,SUMIFS(Hoja1!$F:$F,Hoja1!$D:$D,$B13,Hoja1!$I:$I,R$2),"")
A14: 9 | B14: A12 | C14: Pirolo Rojo | D14: =+VLOOKUP(B14,'[1]Consumo x Cod Articulo'!$C$1:$O$65536,6,) -> 0.00056 | E14: =+IF(F14=H14,"No","si") -> si | F14: 5000 | G14: =+F14*D14 -> 2.8 | H14: 25000 | I14: =+SUM(J14:R14) -> 5040 | J14: =+IF(SUMIFS(Hoja1!$F:$F,Hoja1!$D:$D,$B14,Hoja1!$I:$I,J$2)>1,SUMIFS(Hoja1!$F:$F,Hoja1!$D:$D,$B14,Hoja1!$I:$I,J$2),"") | K14: =+IF(SUMIFS(Hoja1!$F:$F,Hoja1!$D:$D,$B14,Hoja1!$I:$I,K$2)>1,SUMIFS(Hoja1!$F:$F,Hoja1!$D:$D,$B14,Hoja1!$I:$I,K$2),"") | L14: =+IF(SUMIFS(Hoja1!$F:$F,Hoja1!$D:$D,$B14,Hoja1!$I:$I,L$2)>1,SUMIFS(Hoja1!$F:$F,Hoja1!$D:$D,$B14,Hoja1!$I:$I,L$2),"") | M14: =+IF(SUMIFS(Hoja1!$F:$F,Hoja1!$D:$D,$B14,Hoja1!$I:$I,M$2)>1,SUMIFS(Hoja1!$F:$F,Hoja1!$D:$D,$B14,Hoja1!$I:$I,M$2),"") | N14: =+IF(SUMIFS(Hoja1!$F:$F,Hoja1!$D:$D,$B14,Hoja1!$I:$I,N$2)>1,SUMIFS(Hoja1!$F:$F,Hoja1!$D:$D,$B14,Hoja1!$I:$I,N$2),"") -> 5040 | O14: =+IF(SUMIFS(Hoja1!$F:$F,Hoja1!$D:$D,$B14,Hoja1!$I:$I,O$2)>1,SUMIFS(Hoja1!$F:$F,Hoja1!$D:$D,$B14,Hoja1!$I:$I,O$2),"") | P14: =+IF(SUMIFS(Hoja1!$F:$F,Hoja1!$D:$D,$B14,Hoja1!$I:$I,P$2)>1,SUMIFS(Hoja1!$F:$F,Hoja1!$D:$D,$B14,Hoja1!$I:$I,P$2),"") | Q14: =+IF(SUMIFS(Hoja1!$F:$F,Hoja1!$D:$D,$B14,Hoja1!$I:$I,Q$2)>1,SUMIFS(Hoja1!$F:$F,Hoja1!$D:$D,$B14,Hoja1!$I:$I,Q$2),"") | R14: =+IF(SUMIFS(Hoja1!$F:$F,Hoja1!$D:$D,$B14,Hoja1!$I:$I,R$2)>1,SUMIFS(Hoja1!$F:$F,Hoja1!$D:$D,$B14,Hoja1!$I:$I,R$2),"")
A15: 31 | B15: C11 | C15: Mango LK ф 8 | D15: =+VLOOKUP(B15,'[1]Consumo x Cod Articulo'!$C$1:$O$65536,6,) -> 0.015 | E15: =+IF(F15=H15,"No","si") -> No | F15: =+H15 -> 1000 | G15: =+F15*D15 -> 15 | H15: 1000 | I15: =+SUM(J15:R15) -> 2400 | J15: =+IF(SUMIFS(Hoja1!$F:$F,Hoja1!$D:$D,$B15,Hoja1!$I:$I,J$2)>1,SUMIFS(Hoja1!$F:$F,Hoja1!$D:$D,$B15,Hoja1!$I:$I,J$2),"") | K15: =+IF(SUMIFS(Hoja1!$F:$F,Hoja1!$D:$D,$B15,Hoja1!$I:$I,K$2)>1,SUMIFS(Hoja1!$F:$F,Hoja1!$D:$D,$B15,Hoja1!$I:$I,K$2),"") -> 2400 | L15: =+IF(SUMIFS(Hoja1!$F:$F,Hoja1!$D:$D,$B15,Hoja1!$I:$I,L$2)>1,SUMIFS(Hoja1!$F:$F,Hoja1!$D:$D,$B15,Hoja1!$I:$I,L$2),"") | M15: =+IF(SUMIFS(Hoja1!$F:$F,Hoja1!$D:$D,$B15,Hoja1!$I:$I,M$2)>1,SUMIFS(Hoja1!$F:$F,Hoja1!$D:$D,$B15,Hoja1!$I:$I,M$2),"") | N15: =+IF(SUMIFS(Hoja1!$F:$F,Hoja1!$D:$D,$B15,Hoja1!$I:$I,N$2)>1,SUMIFS(Hoja1!$F:$F,Hoja1!$D:$D,$B15,Hoja1!$I:$I,N$2),"") | O15: =+IF(SUMIFS(Hoja1!$F:$F,Hoja1!$D:$D,$B15,Hoja1!$I:$I,O$2)>1,SUMIFS(Hoja1!$F:$F,Hoja1!$D:$D,$B15,Hoja1!$I:$I,O$2),"") | P15: =+IF(SUMIFS(Hoja1!$F:$F,Hoja1!$D:$D,$B15,Hoja1!$I:$I,P$2)>1,SUMIFS(Hoja1!$F:$F,Hoja1!$D:$D,$B15,Hoja1!$I:$I,P$2),"") | Q15: =+IF(SUMIFS(Hoja1!$F:$F,Hoja1!$D:$D,$B15,Hoja1!$I:$I,Q$2)>1,SUMIFS(Hoja1!$F:$F,Hoja1!$D:$D,$B15,Hoja1!$I:$I,Q$2),"") | R15: =+IF(SUMIFS(Hoja1!$F:$F,Hoja1!$D:$D,$B15,Hoja1!$I:$I,R$2)>1,SUMIFS(Hoja1!$F:$F,Hoja1!$D:$D,$B15,Hoja1!$I:$I,R$2),"")
A16: 38 | B16: EP6 | C16: Cabo Madera 525 | D16: =+VLOOKUP(B16,'[1]Consumo x Cod Articulo'!$C$1:$O$65536,6,) -> 0.028 | E16: =+IF(F16=H16,"No","si") -> No | G16: =+F16*D16 -> 0 | I16: =+SUM(J16:R16) -> 2280 | J16: =+IF(SUMIFS(Hoja1!$F:$F,Hoja1!$D:$D,$B16,Hoja1!$I:$I,J$2)>1,SUMIFS(Hoja1!$F:$F,Hoja1!$D:$D,$B16,Hoja1!$I:$I,J$2),"") | K16: =+IF(SUMIFS(Hoja1!$F:$F,Hoja1!$D:$D,$B16,Hoja1!$I:$I,K$2)>1,SUMIFS(Hoja1!$F:$F,Hoja1!$D:$D,$B16,Hoja1!$I:$I,K$2),"") | L16: =+IF(SUMIFS(Hoja1!$F:$F,Hoja1!$D:$D,$B16,Hoja1!$I:$I,L$2)>1,SUMIFS(Hoja1!$F:$F,Hoja1!$D:$D,$B16,Hoja1!$I:$I,L$2),"") | M16: =+IF(SUMIFS(Hoja1!$F:$F,Hoja1!$D:$D,$B16,Hoja1!$I:$I,M$2)>1,SUMIFS(Hoja1!$F:$F,Hoja1!$D:$D,$B16,Hoja1!$I:$I,M$2),"") | N16: =+IF(SUMIFS(Hoja1!$F:$F,Hoja1!$D:$D,$B16,Hoja1!$I:$I,N$2)>1,SUMIFS(Hoja1!$F:$F,Hoja1!$D:$D,$B16,Hoja1!$I:$I,N$2),"") -> 1728 | O16: =+IF(SUMIFS(Hoja1!$F:$F,Hoja1!$D:$D,$B16,Hoja1!$I:$I,O$2)>1,SUMIFS(Hoja1!$F:$F,Hoja1!$D:$D,$B16,Hoja1!$I:$I,O$2),"") | P16: =+IF(SUMIFS(Hoja1!$F:$F,Hoja1!$D:$D,$B16,Hoja1!$I:$I,P$2)>1,SUMIFS(Hoja1!$F:$F,Hoja1!$D:$D,$B16,Hoja1!$I:$I,P$2),"") -> 552 | Q16: =+IF(SUMIFS(Hoja1!$F:$F,Hoja1!$D:$D,$B16,Hoja1!$I:$I,Q$2)>1,SUMIFS(Hoja1!$F:$F,Hoja1!$D:$D,$B16,Hoja1!$I:$I,Q$2),"") | R16: =+IF(SUMIFS(Hoja1!$F:$F,Hoja1!$D:$D,$B16,Hoja1!$I:$I,R$2)>1,SUMIFS(Hoja1!$F:$F,Hoja1!$D:$D,$B16,Hoja1!$I:$I,R$2),"")
A17: 10 | B17: A13 | C17: Capuchon Batidor LK | D17: =+VLOOKUP(B17,'[1]Consumo x Cod Articulo'!$C$1:$O$65536,6,) -> 0.0022 | E17: =+IF(F17=H17,"No","si") -> si | F17: 1000 | G17: =+F17*D17 -> 2.2 | H17: 5000 | I17: =+SUM(J17:R17) -> 4944 | J17: =+IF(SUMIFS(Hoja1!$F:$F,Hoja1!$D:$D,$B17,Hoja1!$I:$I,J$2)>1,SUMIFS(Hoja1!$F:$F,Hoja1!$D:$D,$B17,Hoja1!$I:$I,J$2),"") | K17: =+IF(SUMIFS(Hoja1!$F:$F,Hoja1!$D:$D,$B17,Hoja1!$I:$I,K$2)>1,SUMIFS(Hoja1!$F:$F,Hoja1!$D:$D,$B17,Hoja1!$I:$I,K$2),"") | L17: =+IF(SUMIFS(Hoja1!$F:$F,Hoja1!$D:$D,$B17,Hoja1!$I:$I,L$2)>1,SUMIFS(Hoja1!$F:$F,Hoja1!$D:$D,$B17,Hoja1!$I:$I,L$2),"") | M17: =+IF(SUMIFS(Hoja1!$F:$F,Hoja1!$D:$D,$B17,Hoja1!$I:$I,M$2)>1,SUMIFS(Hoja1!$F:$F,Hoja1!$D:$D,$B17,Hoja1!$I:$I,M$2),"") | N17: =+IF(SUMIFS(Hoja1!$F:$F,Hoja1!$D:$D,$B17,Hoja1!$I:$I,N$2)>1,SUMIFS(Hoja1!$F:$F,Hoja1!$D:$D,$B17,Hoja1!$I:$I,N$2),"") | O17: =+IF(SUMIFS(Hoja1!$F:$F,Hoja1!$D:$D,$B17,Hoja1!$I:$I,O$2)>1,SUMIFS(Hoja1!$F:$F,Hoja1!$D:$D,$B17,Hoja1!$I:$I,O$2),"") -> 144 | P17: =+IF(SUMIFS(Hoja1!$F:$F,Hoja1!$D:$D,$B17,Hoja1!$I:$I,P$2)>1,SUMIFS(Hoja1!$F:$F,Hoja1!$D:$D,$B17,Hoja1!$I:$I,P$2),"") -> 4800 | Q17: =+IF(SUMIFS(Hoja1!$F:$F,Hoja1!$D:$D,$B17,Hoja1!$I:$I,Q$2)>1,SUMIFS(Hoja1!$F:$F,Hoja1!$D:$D,$B17,Hoja1!$I:$I,Q$2),"") | R17: =+IF(SUMIFS(Hoja1!$F:$F,Hoja1!$D:$D,$B17,Hoja1!$I:$I,R$2)>1,SUMIFS(Hoja1!$F:$F,Hoja1!$D:$D,$B17,Hoja1!$I:$I,R$2),"")
A18: 11 | B18: A15 | C18: Capuchon ф10 | D18: =+VLOOKUP(B18,'[1]Consumo x Cod Articulo'!$C$1:$O$65536,6,) -> 0.0022 | E18: =+IF(F18=H18,"No","si") -> si | F18: 500 | G18: =+F18*D18 -> 1.1 | H18: 5000 | I18: =+SUM(J18:R18) -> 360 | J18: =+IF(SUMIFS(Hoja1!$F:$F,Hoja1!$D:$D,$B18,Hoja1!$I:$I,J$2)>1,SUMIFS(Hoja1!$F:$F,Hoja1!$D:$D,$B18,Hoja1!$I:$I,J$2),"") | K18: =+IF(SUMIFS(Hoja1!$F:$F,Hoja1!$D:$D,$B18,Hoja1!$I:$I,K$2)>1,SUMIFS(Hoja1!$F:$F,Hoja1!$D:$D,$B18,Hoja1!$I:$I,K$2),"") | L18: =+IF(SUMIFS(Hoja1!$F:$F,Hoja1!$D:$D,$B18,Hoja1!$I:$I,L$2)>1,SUMIFS(Hoja1!$F:$F,Hoja1!$D:$D,$B18,Hoja1!$I:$I,L$2),"") | M18: =+IF(SUMIFS(Hoja1!$F:$F,Hoja1!$D:$D,$B18,Hoja1!$I:$I,M$2)>1,SUMIFS(Hoja1!$F:$F,Hoja1!$D:$D,$B18,Hoja1!$I:$I,M$2),"") | N18: =+IF(SUMIFS(Hoja1!$F:$F,Hoja1!$D:$D,$B18,Hoja1!$I:$I,N$2)>1,SUMIFS(Hoja1!$F:$F,Hoja1!$D:$D,$B18,Hoja1!$I:$I,N$2),"") -> 360 | O18: =+IF(SUMIFS(Hoja1!$F:$F,Hoja1!$D:$D,$B18,Hoja1!$I:$I,O$2)>1,SUMIFS(Hoja1!$F:$F,Hoja1!$D:$D,$B18,Hoja1!$I:$I,O$2),"") | P18: =+IF(SUMIFS(Hoja1!$F:$F,Hoja1!$D:$D,$B18,Hoja1!$I:$I,P$2)>1,SUMIFS(Hoja1!$F:$F,Hoja1!$D:$D,$B18,Hoja1!$I:$I,P$2),"") | Q18: =+IF(SUMIFS(Hoja1!$F:$F,Hoja1!$D:$D,$B18,Hoja1!$I:$I,Q$2)>1,SUMIFS(Hoja1!$F:$F,Hoja1!$D:$D,$B18,Hoja1!$I:$I,Q$2),"") | R18: =+IF(SUMIFS(Hoja1!$F:$F,Hoja1!$D:$D,$B18,Hoja1!$I:$I,R$2)>1,SUMIFS(Hoja1!$F:$F,Hoja1!$D:$D,$B18,Hoja1!$I:$I,R$2),"")
A19: 24 | B19: C2 | C19: Cuerpo Sac Aleta Plast | D19: =+VLOOKUP(B19,'[1]Consumo x Cod Articulo'!$C$1:$O$65536,6,) -> 0.022 | E19: =+IF(F19=H19,"No","si") -> No | F19: =+H19 -> 1000 | G19: =+F19*D19 -> 22 | H19: 1000 | I19: =+SUM(J19:R19) -> 1800 | J19: =+IF(SUMIFS(Hoja1!$F:$F,Hoja1!$D:$D,$B19,Hoja1!$I:$I,J$2)>1,SUMIFS(Hoja1!$F:$F,Hoja1!$D:$D,$B19,Hoja1!$I:$I,J$2),"") | K19: =+IF(SUMIFS(Hoja1!$F:$F,Hoja1!$D:$D,$B19,Hoja1!$I:$I,K$2)>1,SUMIFS(Hoja1!$F:$F,Hoja1!$D:$D,$B19,Hoja1!$I:$I,K$2),"") | L19: =+IF(SUMIFS(Hoja1!$F:$F,Hoja1!$D:$D,$B19,Hoja1!$I:$I,L$2)>1,SUMIFS(Hoja1!$F:$F,Hoja1!$D:$D,$B19,Hoja1!$I:$I,L$2),"") | M19: =+IF(SUMIFS(Hoja1!$F:$F,Hoja1!$D:$D,$B19,Hoja1!$I:$I,M$2)>1,SUMIFS(Hoja1!$F:$F,Hoja1!$D:$D,$B19,Hoja1!$I:$I,M$2),"") | N19: =+IF(SUMIFS(Hoja1!$F:$F,Hoja1!$D:$D,$B19,Hoja1!$I:$I,N$2)>1,SUMIFS(Hoja1!$F:$F,Hoja1!$D:$D,$B19,Hoja1!$I:$I,N$2),"") -> 1800 | O19: =+IF(SUMIFS(Hoja1!$F:$F,Hoja1!$D:$D,$B19,Hoja1!$I:$I,O$2)>1,SUMIFS(Hoja1!$F:$F,Hoja1!$D:$D,$B19,Hoja1!$I:$I,O$2),"") | P19: =+IF(SUMIFS(Hoja1!$F:$F,Hoja1!$D:$D,$B19,Hoja1!$I:$I,P$2)>1,SUMIFS(Hoja1!$F:$F,Hoja1!$D:$D,$B19,Hoja1!$I:$I,P$2),"") | Q19: =+IF(SUMIFS(Hoja1!$F:$F,Hoja1!$D:$D,$B19,Hoja1!$I:$I,Q$2)>1,SUMIFS(Hoja1!$F:$F,Hoja1!$D:$D,$B19,Hoja1!$I:$I,Q$2),"") | R19: =+IF(SUMIFS(Hoja1!$F:$F,Hoja1!$D:$D,$B19,Hoja1!$I:$I,R$2)>1,SUMIFS(Hoja1!$F:$F,Hoja1!$D:$D,$B19,Hoja1!$I:$I,R$2),"")
A20: 34 | B20: EP1 | C20: Mangos Pelador Vde | D20: =+VLOOKUP(B20,'[1]Consumo x Cod Articulo'!$C$1:$O$65536,6,) -> 0.0165 | E20: =+IF(F20=H20,"No","si") -> No | F20: 250 | G20: =+F20*D20 -> 4.125 | H20: 250 | I20: =+SUM(J20:R20) -> 1476 | J20: =+IF(SUMIFS(Hoja1!$F:$F,Hoja1!$D:$D,$B20,Hoja1!$I:$I,J$2)>1,SUMIFS(Hoja1!$F:$F,Hoja1!$D:$D,$B20,Hoja1!$I:$I,J$2),"") | K20: =+IF(SUMIFS(Hoja1!$F:$F,Hoja1!$D:$D,$B20,Hoja1!$I:$I,K$2)>1,SUMIFS(Hoja1!$F:$F,Hoja1!$D:$D,$B20,Hoja1!$I:$I,K$2),"") | L20: =+IF(SUMIFS(Hoja1!$F:$F,Hoja1!$D:$D,$B20,Hoja1!$I:$I,L$2)>1,SUMIFS(Hoja1!$F:$F,Hoja1!$D:$D,$B20,Hoja1!$I:$I,L$2),"") | M20: =+IF(SUMIFS(Hoja1!$F:$F,Hoja1!$D:$D,$B20,Hoja1!$I:$I,M$2)>1,SUMIFS(Hoja1!$F:$F,Hoja1!$D:$D,$B20,Hoja1!$I:$I,M$2),"") | N20: =+IF(SUMIFS(Hoja1!$F:$F,Hoja1!$D:$D,$B20,Hoja1!$I:$I,N$2)>1,SUMIFS(Hoja1!$F:$F,Hoja1!$D:$D,$B20,Hoja1!$I:$I,N$2),"") | O20: =+IF(SUMIFS(Hoja1!$F:$F,Hoja1!$D:$D,$B20,Hoja1!$I:$I,O$2)>1,SUMIFS(Hoja1!$F:$F,Hoja1!$D:$D,$B20,Hoja1!$I:$I,O$2),"") | P20: =+IF(SUMIFS(Hoja1!$F:$F,Hoja1!$D:$D,$B20,Hoja1!$I:$I,P$2)>1,SUMIFS(Hoja1!$F:$F,Hoja1!$D:$D,$B20,Hoja1!$I:$I,P$2),"") -> 1476 | Q20: =+IF(SUMIFS(Hoja1!$F:$F,Hoja1!$D:$D,$B20,Hoja1!$I:$I,Q$2)>1,SUMIFS(Hoja1!$F:$F,Hoja1!$D:$D,$B20,Hoja1!$I:$I,Q$2),"") | R20: =+IF(SUMIFS(Hoja1!$F:$F,Hoja1!$D:$D,$B20,Hoja1!$I:$I,R$2)>1,SUMIFS(Hoja1!$F:$F,Hoja1!$D:$D,$B20,Hoja1!$I:$I,R$2),"")
A21: 13 | B21: A17 | C21: Mango LK Cuch y P Torta | D21: =+VLOOKUP(B21,'[1]Consumo x Cod Articulo'!$C$1:$O$65536,6,) -> 0.015 | E21: =+IF(F21=H21,"No","si") -> si | F21: 250 | G21: =+F21*D21 -> 3.75 | H21: =+VLOOKUP(B21,'[1]Relevamiento y OP VACIO'!$C$1:$AH$65536,26,) -> 1000 | I21: =+SUM(J21:R21) -> 156 | J21: =+IF(SUMIFS(Hoja1!$F:$F,Hoja1!$D:$D,$B21,Hoja1!$I:$I,J$2)>1,SUMIFS(Hoja1!$F:$F,Hoja1!$D:$D,$B21,Hoja1!$I:$I,J$2),"") -> 156 | K21: =+IF(SUMIFS(Hoja1!$F:$F,Hoja1!$D:$D,$B21,Hoja1!$I:$I,K$2)>1,SUMIFS(Hoja1!$F:$F,Hoja1!$D:$D,$B21,Hoja1!$I:$I,K$2),"") | L21: =+IF(SUMIFS(Hoja1!$F:$F,Hoja1!$D:$D,$B21,Hoja1!$I:$I,L$2)>1,SUMIFS(Hoja1!$F:$F,Hoja1!$D:$D,$B21,Hoja1!$I:$I,L$2),"") | M21: =+IF(SUMIFS(Hoja1!$F:$F,Hoja1!$D:$D,$B21,Hoja1!$I:$I,M$2)>1,SUMIFS(Hoja1!$F:$F,Hoja1!$D:$D,$B21,Hoja1!$I:$I,M$2),"") | N21: =+IF(SUMIFS(Hoja1!$F:$F,Hoja1!$D:$D,$B21,Hoja1!$I:$I,N$2)>1,SUMIFS(Hoja1!$F:$F,Hoja1!$D:$D,$B21,Hoja1!$I:$I,N$2),"") | O21: =+IF(SUMIFS(Hoja1!$F:$F,Hoja1!$D:$D,$B21,Hoja1!$I:$I,O$2)>1,SUMIFS(Hoja1!$F:$F,Hoja1!$D:$D,$B21,Hoja1!$I:$I,O$2),"") | P21: =+IF(SUMIFS(Hoja1!$F:$F,Hoja1!$D:$D,$B21,Hoja1!$I:$I,P$2)>1,SUMIFS(Hoja1!$F:$F,Hoja1!$D:$D,$B21,Hoja1!$I:$I,P$2),"") | Q21: =+IF(SUMIFS(Hoja1!$F:$F,Hoja1!$D:$D,$B21,Hoja1!$I:$I,Q$2)>1,SUMIFS(Hoja1!$F:$F,Hoja1!$D:$D,$B21,Hoja1!$I:$I,Q$2),"") | R21: =+IF(SUMIFS(Hoja1!$F:$F,Hoja1!$D:$D,$B21,Hoja1!$I:$I,R$2)>1,SUMIFS(Hoja1!$F:$F,Hoja1!$D:$D,$B21,Hoja1!$I:$I,R$2),"")
A22: 37 | B22: EP5 | C22: Mgo Mad Cuch Untar | D22: =+VLOOKUP(B22,'[1]Consumo x Cod Articulo'!$C$1:$O$65536,6,) -> 0.0063 | E22: =+IF(F22=H22,"No","si") -> No | G22: =+F22*D22 -> 0 | I22: =+SUM(J22:R22) -> 1104 | J22: =+IF(SUMIFS(Hoja1!$F:$F,Hoja1!$D:$D,$B22,Hoja1!$I:$I,J$2)>1,SUMIFS(Hoja1!$F:$F,Hoja1!$D:$D,$B22,Hoja1!$I:$I,J$2),"") | K22: =+IF(SUMIFS(Hoja1!$F:$F,Hoja1!$D:$D,$B22,Hoja1!$I:$I,K$2)>1,SUMIFS(Hoja1!$F:$F,Hoja1!$D:$D,$B22,Hoja1!$I:$I,K$2),"") | L22: =+IF(SUMIFS(Hoja1!$F:$F,Hoja1!$D:$D,$B22,Hoja1!$I:$I,L$2)>1,SUMIFS(Hoja1!$F:$F,Hoja1!$D:$D,$B22,Hoja1!$I:$I,L$2),"") | M22: =+IF(SUMIFS(Hoja1!$F:$F,Hoja1!$D:$D,$B22,Hoja1!$I:$I,M$2)>1,SUMIFS(Hoja1!$F:$F,Hoja1!$D:$D,$B22,Hoja1!$I:$I,M$2),"") | N22: =+IF(SUMIFS(Hoja1!$F:$F,Hoja1!$D:$D,$B22,Hoja1!$I:$I,N$2)>1,SUMIFS(Hoja1!$F:$F,Hoja1!$D:$D,$B22,Hoja1!$I:$I,N$2),"") | O22: =+IF(SUMIFS(Hoja1!$F:$F,Hoja1!$D:$D,$B22,Hoja1!$I:$I,O$2)>1,SUMIFS(Hoja1!$F:$F,Hoja1!$D:$D,$B22,Hoja1!$I:$I,O$2),"") | P22: =+IF(SUMIFS(Hoja1!$F:$F,Hoja1!$D:$D,$B22,Hoja1!$I:$I,P$2)>1,SUMIFS(Hoja1!$F:$F,Hoja1!$D:$D,$B22,Hoja1!$I:$I,P$2),"") -> 1104 | Q22: =+IF(SUMIFS(Hoja1!$F:$F,Hoja1!$D:$D,$B22,Hoja1!$I:$I,Q$2)>1,SUMIFS(Hoja1!$F:$F,Hoja1!$D:$D,$B22,Hoja1!$I:$I,Q$2),"") | R22: =+IF(SUMIFS(Hoja1!$F:$F,Hoja1!$D:$D,$B22,Hoja1!$I:$I,R$2)>1,SUMIFS(Hoja1!$F:$F,Hoja1!$D:$D,$B22,Hoja1!$I:$I,R$2),"")
A23: 29 | B23: C8 | C23: Cachas Azules | D23: =+VLOOKUP(B23,'[1]Consumo x Cod Articulo'!$C$1:$O$65536,6,) -> 0.023 | E23: =+IF(F23=H23,"No","si") -> No | F23: =+H23 -> 500 | G23: =+F23*D23 -> 11.5 | H23: 500 | I23: =+SUM(J23:R23) -> 1032 | J23: =+IF(SUMIFS(Hoja1!$F:$F,Hoja1!$D:$D,$B23,Hoja1!$I:$I,J$2)>1,SUMIFS(Hoja1!$F:$F,Hoja1!$D:$D,$B23,Hoja1!$I:$I,J$2),"") | K23: =+IF(SUMIFS(Hoja1!$F:$F,Hoja1!$D:$D,$B23,Hoja1!$I:$I,K$2)>1,SUMIFS(Hoja1!$F:$F,Hoja1!$D:$D,$B23,Hoja1!$I:$I,K$2),"") | L23: =+IF(SUMIFS(Hoja1!$F:$F,Hoja1!$D:$D,$B23,Hoja1!$I:$I,L$2)>1,SUMIFS(Hoja1!$F:$F,Hoja1!$D:$D,$B23,Hoja1!$I:$I,L$2),"") | M23: =+IF(SUMIFS(Hoja1!$F:$F,Hoja1!$D:$D,$B23,Hoja1!$I:$I,M$2)>1,SUMIFS(Hoja1!$F:$F,Hoja1!$D:$D,$B23,Hoja1!$I:$I,M$2),"") | N23: =+IF(SUMIFS(Hoja1!$F:$F,Hoja1!$D:$D,$B23,Hoja1!$I:$I,N$2)>1,SUMIFS(Hoja1!$F:$F,Hoja1!$D:$D,$B23,Hoja1!$I:$I,N$2),"") | O23: =+IF(SUMIFS(Hoja1!$F:$F,Hoja1!$D:$D,$B23,Hoja1!$I:$I,O$2)>1,SUMIFS(Hoja1!$F:$F,Hoja1!$D:$D,$B23,Hoja1!$I:$I,O$2),"") | P23: =+IF(SUMIFS(Hoja1!$F:$F,Hoja1!$D:$D,$B23,Hoja1!$I:$I,P$2)>1,SUMIFS(Hoja1!$F:$F,Hoja1!$D:$D,$B23,Hoja1!$I:$I,P$2),"") -> 1032 | Q23: =+IF(SUMIFS(Hoja1!$F:$F,Hoja1!$D:$D,$B23,Hoja1!$I:$I,Q$2)>1,SUMIFS(Hoja1!$F:$F,Hoja1!$D:$D,$B23,Hoja1!$I:$I,Q$2),"") | R23: =+IF(SUMIFS(Hoja1!$F:$F,Hoja1!$D:$D,$B23,Hoja1!$I:$I,R$2)>1,SUMIFS(Hoja1!$F:$F,Hoja1!$D:$D,$B23,Hoja1!$I:$I,R$2),"")
A24: 8 | B24: A11 | C24: Capuchon Mariposa 512 | D24: =+VLOOKUP(B24,'[1]Consumo x Cod Articulo'!$C$1:$O$65536,6,) -> 0.0035 | E24: =+IF(F24=H24,"No","si") -> No | F24: =+H24 -> 500 | G24: =+F24*D24 -> 1.75 | H24: 500 | I24: =+SUM(J24:R24) -> 984 | J24: =+IF(SUMIFS(Hoja1!$F:$F,Hoja1!$D:$D,$B24,Hoja1!$I:$I,J$2)>1,SUMIFS(Hoja1!$F:$F,Hoja1!$D:$D,$B24,Hoja1!$I:$I,J$2),"") | K24: =+IF(SUMIFS(Hoja1!$F:$F,Hoja1!$D:$D,$B24,Hoja1!$I:$I,K$2)>1,SUMIFS(Hoja1!$F:$F,Hoja1!$D:$D,$B24,Hoja1!$I:$I,K$2),"") | L24: =+IF(SUMIFS(Hoja1!$F:$F,Hoja1!$D:$D,$B24,Hoja1!$I:$I,L$2)>1,SUMIFS(Hoja1!$F:$F,Hoja1!$D:$D,$B24,Hoja1!$I:$I,L$2),"") | M24: =+IF(SUMIFS(Hoja1!$F:$F,Hoja1!$D:$D,$B24,Hoja1!$I:$I,M$2)>1,SUMIFS(Hoja1!$F:$F,Hoja1!$D:$D,$B24,Hoja1!$I:$I,M$2),"") -> 984 | N24: =+IF(SUMIFS(Hoja1!$F:$F,Hoja1!$D:$D,$B24,Hoja1!$I:$I,N$2)>1,SUMIFS(Hoja1!$F:$F,Hoja1!$D:$D,$B24,Hoja1!$I:$I,N$2),"") | O24: =+IF(SUMIFS(Hoja1!$F:$F,Hoja1!$D:$D,$B24,Hoja1!$I:$I,O$2)>1,SUMIFS(Hoja1!$F:$F,Hoja1!$D:$D,$B24,Hoja1!$I:$I,O$2),"") | P24: =+IF(SUMIFS(Hoja1!$F:$F,Hoja1!$D:$D,$B24,Hoja1!$I:$I,P$2)>1,SUMIFS(Hoja1!$F:$F,Hoja1!$D:$D,$B24,Hoja1!$I:$I,P$2),"") | Q24: =+IF(SUMIFS(Hoja1!$F:$F,Hoja1!$D:$D,$B24,Hoja1!$I:$I,Q$2)>1,SUMIFS(Hoja1!$F:$F,Hoja1!$D:$D,$B24,Hoja1!$I:$I,Q$2),"") | R24: =+IF(SUMIFS(Hoja1!$F:$F,Hoja1!$D:$D,$B24,Hoja1!$I:$I,R$2)>1,SUMIFS(Hoja1!$F:$F,Hoja1!$D:$D,$B24,Hoja1!$I:$I,R$2),"")
A25: 18 | B25: B3 | C25: Cuchara Ny Loeke (Serif.) | D25: =+VLOOKUP(B25,'[1]Consumo x Cod Articulo'!$C$1:$O$65536,6,) -> 0.055 | E25: =+IF(F25=H25,"No","si") -> No | F25: =+H25 -> 150 | G25: =+F25*D25 -> 8.25 | H25: 150 | I25: =+SUM(J25:R25) -> 984 | J25: =+IF(SUMIFS(Hoja1!$F:$F,Hoja1!$D:$D,$B25,Hoja1!$I:$I,J$2)>1,SUMIFS(Hoja1!$F:$F,Hoja1!$D:$D,$B25,Hoja1!$I:$I,J$2),"") | K25: =+IF(SUMIFS(Hoja1!$F:$F,Hoja1!$D:$D,$B25,Hoja1!$I:$I,K$2)>1,SUMIFS(Hoja1!$F:$F,Hoja1!$D:$D,$B25,Hoja1!$I:$I,K$2),"") | L25: =+IF(SUMIFS(Hoja1!$F:$F,Hoja1!$D:$D,$B25,Hoja1!$I:$I,L$2)>1,SUMIFS(Hoja1!$F:$F,Hoja1!$D:$D,$B25,Hoja1!$I:$I,L$2),"") | M25: =+IF(SUMIFS(Hoja1!$F:$F,Hoja1!$D:$D,$B25,Hoja1!$I:$I,M$2)>1,SUMIFS(Hoja1!$F:$F,Hoja1!$D:$D,$B25,Hoja1!$I:$I,M$2),"") | N25: =+IF(SUMIFS(Hoja1!$F:$F,Hoja1!$D:$D,$B25,Hoja1!$I:$I,N$2)>1,SUMIFS(Hoja1!$F:$F,Hoja1!$D:$D,$B25,Hoja1!$I:$I,N$2),"") | O25: =+IF(SUMIFS(Hoja1!$F:$F,Hoja1!$D:$D,$B25,Hoja1!$I:$I,O$2)>1,SUMIFS(Hoja1!$F:$F,Hoja1!$D:$D,$B25,Hoja1!$I:$I,O$2),"") -> 984 | P25: =+IF(SUMIFS(Hoja1!$F:$F,Hoja1!$D:$D,$B25,Hoja1!$I:$I,P$2)>1,SUMIFS(Hoja1!$F:$F,Hoja1!$D:$D,$B25,Hoja1!$I:$I,P$2),"") | Q25: =+IF(SUMIFS(Hoja1!$F:$F,Hoja1!$D:$D,$B25,Hoja1!$I:$I,Q$2)>1,SUMIFS(Hoja1!$F:$F,Hoja1!$D:$D,$B25,Hoja1!$I:$I,Q$2),"") | R25: =+IF(SUMIFS(Hoja1!$F:$F,Hoja1!$D:$D,$B25,Hoja1!$I:$I,R$2)>1,SUMIFS(Hoja1!$F:$F,Hoja1!$D:$D,$B25,Hoja1!$I:$I,R$2),"")
A26: 49 | B26: V14 | C26: Picos Reposteros | D26: =+VLOOKUP(B26,'[1]Consumo x Cod Articulo'!$C$1:$O$65536,6,) -> 0.0011 | E26: =+IF(F26=H26,"No","si") -> No | G26: =+F26*D26 -> 0 | I26: =+SUM(J26:R26) -> 984 | J26: =+IF(SUMIFS(Hoja1!$F:$F,Hoja1!$D:$D,$B26,Hoja1!$I:$I,J$2)>1,SUMIFS(Hoja1!$F:$F,Hoja1!$D:$D,$B26,Hoja1!$I:$I,J$2),"") | K26: =+IF(SUMIFS(Hoja1!$F:$F,Hoja1!$D:$D,$B26,Hoja1!$I:$I,K$2)>1,SUMIFS(Hoja1!$F:$F,Hoja1!$D:$D,$B26,Hoja1!$I:$I,K$2),"") | L26: =+IF(SUMIFS(Hoja1!$F:$F,Hoja1!$D:$D,$B26,Hoja1!$I:$I,L$2)>1,SUMIFS(Hoja1!$F:$F,Hoja1!$D:$D,$B26,Hoja1!$I:$I,L$2),"") | M26: =+IF(SUMIFS(Hoja1!$F:$F,Hoja1!$D:$D,$B26,Hoja1!$I:$I,M$2)>1,SUMIFS(Hoja1!$F:$F,Hoja1!$D:$D,$B26,Hoja1!$I:$I,M$2),"") | N26: =+IF(SUMIFS(Hoja1!$F:$F,Hoja1!$D:$D,$B26,Hoja1!$I:$I,N$2)>1,SUMIFS(Hoja1!$F:$F,Hoja1!$D:$D,$B26,Hoja1!$I:$I,N$2),"") | O26: =+IF(SUMIFS(Hoja1!$F:$F,Hoja1!$D:$D,$B26,Hoja1!$I:$I,O$2)>1,SUMIFS(Hoja1!$F:$F,Hoja1!$D:$D,$B26,Hoja1!$I:$I,O$2),"") | P26: =+IF(SUMIFS(Hoja1!$F:$F,Hoja1!$D:$D,$B26,Hoja1!$I:$I,P$2)>1,SUMIFS(Hoja1!$F:$F,Hoja1!$D:$D,$B26,Hoja1!$I:$I,P$2),"") | Q26: =+IF(SUMIFS(Hoja1!$F:$F,Hoja1!$D:$D,$B26,Hoja1!$I:$I,Q$2)>1,SUMIFS(Hoja1!$F:$F,Hoja1!$D:$D,$B26,Hoja1!$I:$I,Q$2),"") | R26: =+IF(SUMIFS(Hoja1!$F:$F,Hoja1!$D:$D,$B26,Hoja1!$I:$I,R$2)>1,SUMIFS(Hoja1!$F:$F,Hoja1!$D:$D,$B26,Hoja1!$I:$I,R$2),"") -> 984
A27: 39 | B27: EP7 | C27: Mgo Sacafuente Pizzero | D27: =+VLOOKUP(B27,'[1]Consumo x Cod Articulo'!$C$1:$O$65536,6,) -> 0.0745 | E27: =+IF(F27=H27,"No","si") -> No | G27: =+F27*D27 -> 0 | I27: =+SUM(J27:R27) -> 864 | J27: =+IF(SUMIFS(Hoja1!$F:$F,Hoja1!$D:$D,$B27,Hoja1!$I:$I,J$2)>1,SUMIFS(Hoja1!$F:$F,Hoja1!$D:$D,$B27,Hoja1!$I:$I,J$2),"") | K27: =+IF(SUMIFS(Hoja1!$F:$F,Hoja1!$D:$D,$B27,Hoja1!$I:$I,K$2)>1,SUMIFS(Hoja1!$F:$F,Hoja1!$D:$D,$B27,Hoja1!$I:$I,K$2),"") | L27: =+IF(SUMIFS(Hoja1!$F:$F,Hoja1!$D:$D,$B27,Hoja1!$I:$I,L$2)>1,SUMIFS(Hoja1!$F:$F,Hoja1!$D:$D,$B27,Hoja1!$I:$I,L$2),"") | M27: =+IF(SUMIFS(Hoja1!$F:$F,Hoja1!$D:$D,$B27,Hoja1!$I:$I,M$2)>1,SUMIFS(Hoja1!$F:$F,Hoja1!$D:$D,$B27,Hoja1!$I:$I,M$2),"") | N27: =+IF(SUMIFS(Hoja1!$F:$F,Hoja1!$D:$D,$B27,Hoja1!$I:$I,N$2)>1,SUMIFS(Hoja1!$F:$F,Hoja1!$D:$D,$B27,Hoja1!$I:$I,N$2),"") | O27: =+IF(SUMIFS(Hoja1!$F:$F,Hoja1!$D:$D,$B27,Hoja1!$I:$I,O$2)>1,SUMIFS(Hoja1!$F:$F,Hoja1!$D:$D,$B27,Hoja1!$I:$I,O$2),"") | P27: =+IF(SUMIFS(Hoja1!$F:$F,Hoja1!$D:$D,$B27,Hoja1!$I:$I,P$2)>1,SUMIFS(Hoja1!$F:$F,Hoja1!$D:$D,$B27,Hoja1!$I:$I,P$2),"") -> 864 | Q27: =+IF(SUMIFS(Hoja1!$F:$F,Hoja1!$D:$D,$B27,Hoja1!$I:$I,Q$2)>1,SUMIFS(Hoja1!$F:$F,Hoja1!$D:$D,$B27,Hoja1!$I:$I,Q$2),"") | R27: =+IF(SUMIFS(Hoja1!$F:$F,Hoja1!$D:$D,$B27,Hoja1!$I:$I,R$2)>1,SUMIFS(Hoja1!$F:$F,Hoja1!$D:$D,$B27,Hoja1!$I:$I,R$2),"")
A28: 43 | B28: V2 | C28: Cucharon 1 Pz Ny | D28: =+VLOOKUP(B28,'[1]Consumo x Cod Articulo'!$C$1:$O$65536,6,) -> 0.055 | E28: =+IF(F28=H28,"No","si") -> No | G28: =+F28*D28 -> 0 | I28: =+SUM(J28:R28) -> 744 | J28: =+IF(SUMIFS(Hoja1!$F:$F,Hoja1!$D:$D,$B28,Hoja1!$I:$I,J$2)>1,SUMIFS(Hoja1!$F:$F,Hoja1!$D:$D,$B28,Hoja1!$I:$I,J$2),"") | K28: =+IF(SUMIFS(Hoja1!$F:$F,Hoja1!$D:$D,$B28,Hoja1!$I:$I,K$2)>1,SUMIFS(Hoja1!$F:$F,Hoja1!$D:$D,$B28,Hoja1!$I:$I,K$2),"") | L28: =+IF(SUMIFS(Hoja1!$F:$F,Hoja1!$D:$D,$B28,Hoja1!$I:$I,L$2)>1,SUMIFS(Hoja1!$F:$F,Hoja1!$D:$D,$B28,Hoja1!$I:$I,L$2),"") | M28: =+IF(SUMIFS(Hoja1!$F:$F,Hoja1!$D:$D,$B28,Hoja1!$I:$I,M$2)>1,SUMIFS(Hoja1!$F:$F,Hoja1!$D:$D,$B28,Hoja1!$I:$I,M$2),"") | N28: =+IF(SUMIFS(Hoja1!$F:$F,Hoja1!$D:$D,$B28,Hoja1!$I:$I,N$2)>1,SUMIFS(Hoja1!$F:$F,Hoja1!$D:$D,$B28,Hoja1!$I:$I,N$2),"") -> 744 | O28: =+IF(SUMIFS(Hoja1!$F:$F,Hoja1!$D:$D,$B28,Hoja1!$I:$I,O$2)>1,SUMIFS(Hoja1!$F:$F,Hoja1!$D:$D,$B28,Hoja1!$I:$I,O$2),"") | P28: =+IF(SUMIFS(Hoja1!$F:$F,Hoja1!$D:$D,$B28,Hoja1!$I:$I,P$2)>1,SUMIFS(Hoja1!$F:$F,Hoja1!$D:$D,$B28,Hoja1!$I:$I,P$2),"") | Q28: =+IF(SUMIFS(Hoja1!$F:$F,Hoja1!$D:$D,$B28,Hoja1!$I:$I,Q$2)>1,SUMIFS(Hoja1!$F:$F,Hoja1!$D:$D,$B28,Hoja1!$I:$I,Q$2),"") | R28: =+IF(SUMIFS(Hoja1!$F:$F,Hoja1!$D:$D,$B28,Hoja1!$I:$I,R$2)>1,SUMIFS(Hoja1!$F:$F,Hoja1!$D:$D,$B28,Hoja1!$I:$I,R$2),"")
A29: 32 | B29: C13 | C29: Manguito Abrelat. Blanco | D29: =+VLOOKUP(B29,'[1]Consumo x Cod Articulo'!$C$1:$O$65536,6,) -> 0.009 | E29: =+IF(F29=H29,"No","si") -> No | F29: =+H29 -> 1200 | G29: =+F29*D29 -> 10.8 | H29: 1200 | I29: =+SUM(J29:R29) -> 600 | J29: =+IF(SUMIFS(Hoja1!$F:$F,Hoja1!$D:$D,$B29,Hoja1!$I:$I,J$2)>1,SUMIFS(Hoja1!$F:$F,Hoja1!$D:$D,$B29,Hoja1!$I:$I,J$2),"") | K29: =+IF(SUMIFS(Hoja1!$F:$F,Hoja1!$D:$D,$B29,Hoja1!$I:$I,K$2)>1,SUMIFS(Hoja1!$F:$F,Hoja1!$D:$D,$B29,Hoja1!$I:$I,K$2),"") | L29: =+IF(SUMIFS(Hoja1!$F:$F,Hoja1!$D:$D,$B29,Hoja1!$I:$I,L$2)>1,SUMIFS(Hoja1!$F:$F,Hoja1!$D:$D,$B29,Hoja1!$I:$I,L$2),"") | M29: =+IF(SUMIFS(Hoja1!$F:$F,Hoja1!$D:$D,$B29,Hoja1!$I:$I,M$2)>1,SUMIFS(Hoja1!$F:$F,Hoja1!$D:$D,$B29,Hoja1!$I:$I,M$2),"") | N29: =+IF(SUMIFS(Hoja1!$F:$F,Hoja1!$D:$D,$B29,Hoja1!$I:$I,N$2)>1,SUMIFS(Hoja1!$F:$F,Hoja1!$D:$D,$B29,Hoja1!$I:$I,N$2),"") -> 600 | O29: =+IF(SUMIFS(Hoja1!$F:$F,Hoja1!$D:$D,$B29,Hoja1!$I:$I,O$2)>1,SUMIFS(Hoja1!$F:$F,Hoja1!$D:$D,$B29,Hoja1!$I:$I,O$2),"") | P29: =+IF(SUMIFS(Hoja1!$F:$F,Hoja1!$D:$D,$B29,Hoja1!$I:$I,P$2)>1,SUMIFS(Hoja1!$F:$F,Hoja1!$D:$D,$B29,Hoja1!$I:$I,P$2),"") | Q29: =+IF(SUMIFS(Hoja1!$F:$F,Hoja1!$D:$D,$B29,Hoja1!$I:$I,Q$2)>1,SUMIFS(Hoja1!$F:$F,Hoja1!$D:$D,$B29,Hoja1!$I:$I,Q$2),"") | R29: =+IF(SUMIFS(Hoja1!$F:$F,Hoja1!$D:$D,$B29,Hoja1!$I:$I,R$2)>1,SUMIFS(Hoja1!$F:$F,Hoja1!$D:$D,$B29,Hoja1!$I:$I,R$2),"")
A30: 40 | B30: EP8 | C30: Mgo Corta Pizza | D30: =+VLOOKUP(B30,'[1]Consumo x Cod Articulo'!$C$1:$O$65536,6,) -> 0.0745 | E30: =+IF(F30=H30,"No","si") -> No | G30: =+F30*D30 -> 0 | I30: =+SUM(J30:R30) -> 600 | J30: =+IF(SUMIFS(Hoja1!$F:$F,Hoja1!$D:$D,$B30,Hoja1!$I:$I,J$2)>1,SUMIFS(Hoja1!$F:$F,Hoja1!$D:$D,$B30,Hoja1!$I:$I,J$2),"") -> 600 | K30: =+IF(SUMIFS(Hoja1!$F:$F,Hoja1!$D:$D,$B30,Hoja1!$I:$I,K$2)>1,SUMIFS(Hoja1!$F:$F,Hoja1!$D:$D,$B30,Hoja1!$I:$I,K$2),"") | L30: =+IF(SUMIFS(Hoja1!$F:$F,Hoja1!$D:$D,$B30,Hoja1!$I:$I,L$2)>1,SUMIFS(Hoja1!$F:$F,Hoja1!$D:$D,$B30,Hoja1!$I:$I,L$2),"") | M30: =+IF(SUMIFS(Hoja1!$F:$F,Hoja1!$D:$D,$B30,Hoja1!$I:$I,M$2)>1,SUMIFS(Hoja1!$F:$F,Hoja1!$D:$D,$B30,Hoja1!$I:$I,M$2),"") | N30: =+IF(SUMIFS(Hoja1!$F:$F,Hoja1!$D:$D,$B30,Hoja1!$I:$I,N$2)>1,SUMIFS(Hoja1!$F:$F,Hoja1!$D:$D,$B30,Hoja1!$I:$I,N$2),"") | O30: =+IF(SUMIFS(Hoja1!$F:$F,Hoja1!$D:$D,$B30,Hoja1!$I:$I,O$2)>1,SUMIFS(Hoja1!$F:$F,Hoja1!$D:$D,$B30,Hoja1!$I:$I,O$2),"") | P30: =+IF(SUMIFS(Hoja1!$F:$F,Hoja1!$D:$D,$B30,Hoja1!$I:$I,P$2)>1,SUMIFS(Hoja1!$F:$F,Hoja1!$D:$D,$B30,Hoja1!$I:$I,P$2),"") | Q30: =+IF(SUMIFS(Hoja1!$F:$F,Hoja1!$D:$D,$B30,Hoja1!$I:$I,Q$2)>1,SUMIFS(Hoja1!$F:$F,Hoja1!$D:$D,$B30,Hoja1!$I:$I,Q$2),"") | R30: =+IF(SUMIFS(Hoja1!$F:$F,Hoja1!$D:$D,$B30,Hoja1!$I:$I,R$2)>1,SUMIFS(Hoja1!$F:$F,Hoja1!$D:$D,$B30,Hoja1!$I:$I,R$2),"")
A31: 47 | B31: V7 | C31: Espatula Cal. 1 Pz Ny | D31: =+VLOOKUP(B31,'[1]Consumo x Cod Articulo'!$C$1:$O$65536,6,) -> 0.043 | E31: =+IF(F31=H31,"No","si") -> No | G31: =+F31*D31 -> 0 | I31: =+SUM(J31:R31) -> 576 | J31: =+IF(SUMIFS(Hoja1!$F:$F,Hoja1!$D:$D,$B31,Hoja1!$I:$I,J$2)>1,SUMIFS(Hoja1!$F:$F,Hoja1!$D:$D,$B31,Hoja1!$I:$I,J$2),"") | K31: =+IF(SUMIFS(Hoja1!$F:$F,Hoja1!$D:$D,$B31,Hoja1!$I:$I,K$2)>1,SUMIFS(Hoja1!$F:$F,Hoja1!$D:$D,$B31,Hoja1!$I:$I,K$2),"") | L31: =+IF(SUMIFS(Hoja1!$F:$F,Hoja1!$D:$D,$B31,Hoja1!$I:$I,L$2)>1,SUMIFS(Hoja1!$F:$F,Hoja1!$D:$D,$B31,Hoja1!$I:$I,L$2),"") | M31: =+IF(SUMIFS(Hoja1!$F:$F,Hoja1!$D:$D,$B31,Hoja1!$I:$I,M$2)>1,SUMIFS(Hoja1!$F:$F,Hoja1!$D:$D,$B31,Hoja1!$I:$I,M$2),"") | N31: =+IF(SUMIFS(Hoja1!$F:$F,Hoja1!$D:$D,$B31,Hoja1!$I:$I,N$2)>1,SUMIFS(Hoja1!$F:$F,Hoja1!$D:$D,$B31,Hoja1!$I:$I,N$2),"") -> 576 | O31: =+IF(SUMIFS(Hoja1!$F:$F,Hoja1!$D:$D,$B31,Hoja1!$I:$I,O$2)>1,SUMIFS(Hoja1!$F:$F,Hoja1!$D:$D,$B31,Hoja1!$I:$I,O$2),"") | P31: =+IF(SUMIFS(Hoja1!$F:$F,Hoja1!$D:$D,$B31,Hoja1!$I:$I,P$2)>1,SUMIFS(Hoja1!$F:$F,Hoja1!$D:$D,$B31,Hoja1!$I:$I,P$2),"") | Q31: =+IF(SUMIFS(Hoja1!$F:$F,Hoja1!$D:$D,$B31,Hoja1!$I:$I,Q$2)>1,SUMIFS(Hoja1!$F:$F,Hoja1!$D:$D,$B31,Hoja1!$I:$I,Q$2),"") | R31: =+IF(SUMIFS(Hoja1!$F:$F,Hoja1!$D:$D,$B31,Hoja1!$I:$I,R$2)>1,SUMIFS(Hoja1!$F:$F,Hoja1!$D:$D,$B31,Hoja1!$I:$I,R$2),"")
A32: 42 | B32: V1 | C32: Pisa papa Nylon | D32: =+VLOOKUP(B32,'[1]Consumo x Cod Articulo'!$C$1:$O$65536,6,) -> 0.014 | E32: =+IF(F32=H32,"No","si") -> No | G32: =+F32*D32 -> 0 | I32: =+SUM(J32:R32) -> 480 | J32: =+IF(SUMIFS(Hoja1!$F:$F,Hoja1!$D:$D,$B32,Hoja1!$I:$I,J$2)>1,SUMIFS(Hoja1!$F:$F,Hoja1!$D:$D,$B32,Hoja1!$I:$I,J$2),"") | K32: =+IF(SUMIFS(Hoja1!$F:$F,Hoja1!$D:$D,$B32,Hoja1!$I:$I,K$2)>1,SUMIFS(Hoja1!$F:$F,Hoja1!$D:$D,$B32,Hoja1!$I:$I,K$2),"") -> 480 | L32: =+IF(SUMIFS(Hoja1!$F:$F,Hoja1!$D:$D,$B32,Hoja1!$I:$I,L$2)>1,SUMIFS(Hoja1!$F:$F,Hoja1!$D:$D,$B32,Hoja1!$I:$I,L$2),"") | M32: =+IF(SUMIFS(Hoja1!$F:$F,Hoja1!$D:$D,$B32,Hoja1!$I:$I,M$2)>1,SUMIFS(Hoja1!$F:$F,Hoja1!$D:$D,$B32,Hoja1!$I:$I,M$2),"") | N32: =+IF(SUMIFS(Hoja1!$F:$F,Hoja1!$D:$D,$B32,Hoja1!$I:$I,N$2)>1,SUMIFS(Hoja1!$F:$F,Hoja1!$D:$D,$B32,Hoja1!$I:$I,N$2),"") | O32: =+IF(SUMIFS(Hoja1!$F:$F,Hoja1!$D:$D,$B32,Hoja1!$I:$I,O$2)>1,SUMIFS(Hoja1!$F:$F,Hoja1!$D:$D,$B32,Hoja1!$I:$I,O$2),"") | P32: =+IF(SUMIFS(Hoja1!$F:$F,Hoja1!$D:$D,$B32,Hoja1!$I:$I,P$2)>1,SUMIFS(Hoja1!$F:$F,Hoja1!$D:$D,$B32,Hoja1!$I:$I,P$2),"") | Q32: =+IF(SUMIFS(Hoja1!$F:$F,Hoja1!$D:$D,$B32,Hoja1!$I:$I,Q$2)>1,SUMIFS(Hoja1!$F:$F,Hoja1!$D:$D,$B32,Hoja1!$I:$I,Q$2),"") | R32: =+IF(SUMIFS(Hoja1!$F:$F,Hoja1!$D:$D,$B32,Hoja1!$I:$I,R$2)>1,SUMIFS(Hoja1!$F:$F,Hoja1!$D:$D,$B32,Hoja1!$I:$I,R$2),"")
A33: 44 | B33: V3 | C33: Espatula Lisa 1 Pz | D33: =+VLOOKUP(B33,'[1]Consumo x Cod Articulo'!$C$1:$O$65536,6,) -> 0.05 | E33: =+IF(F33=H33,"No","si") -> No | G33: =+F33*D33 -> 0 | I33: =+SUM(J33:R33) -> 480 | J33: =+IF(SUMIFS(Hoja1!$F:$F,Hoja1!$D:$D,$B33,Hoja1!$I:$I,J$2)>1,SUMIFS(Hoja1!$F:$F,Hoja1!$D:$D,$B33,Hoja1!$I:$I,J$2),"") | K33: =+IF(SUMIFS(Hoja1!$F:$F,Hoja1!$D:$D,$B33,Hoja1!$I:$I,K$2)>1,SUMIFS(Hoja1!$F:$F,Hoja1!$D:$D,$B33,Hoja1!$I:$I,K$2),"") | L33: =+IF(SUMIFS(Hoja1!$F:$F,Hoja1!$D:$D,$B33,Hoja1!$I:$I,L$2)>1,SUMIFS(Hoja1!$F:$F,Hoja1!$D:$D,$B33,Hoja1!$I:$I,L$2),"") | M33: =+IF(SUMIFS(Hoja1!$F:$F,Hoja1!$D:$D,$B33,Hoja1!$I:$I,M$2)>1,SUMIFS(Hoja1!$F:$F,Hoja1!$D:$D,$B33,Hoja1!$I:$I,M$2),"") | N33: =+IF(SUMIFS(Hoja1!$F:$F,Hoja1!$D:$D,$B33,Hoja1!$I:$I,N$2)>1,SUMIFS(Hoja1!$F:$F,Hoja1!$D:$D,$B33,Hoja1!$I:$I,N$2),"") -> 480 | O33: =+IF(SUMIFS(Hoja1!$F:$F,Hoja1!$D:$D,$B33,Hoja1!$I:$I,O$2)>1,SUMIFS(Hoja1!$F:$F,Hoja1!$D:$D,$B33,Hoja1!$I:$I,O$2),"") | P33: =+IF(SUMIFS(Hoja1!$F:$F,Hoja1!$D:$D,$B33,Hoja1!$I:$I,P$2)>1,SUMIFS(Hoja1!$F:$F,Hoja1!$D:$D,$B33,Hoja1!$I:$I,P$2),"") | Q33: =+IF(SUMIFS(Hoja1!$F:$F,Hoja1!$D:$D,$B33,Hoja1!$I:$I,Q$2)>1,SUMIFS(Hoja1!$F:$F,Hoja1!$D:$D,$B33,Hoja1!$I:$I,Q$2),"") | R33: =+IF(SUMIFS(Hoja1!$F:$F,Hoja1!$D:$D,$B33,Hoja1!$I:$I,R$2)>1,SUMIFS(Hoja1!$F:$F,Hoja1!$D:$D,$B33,Hoja1!$I:$I,R$2),"")
A34: 1 | B34: A1 | C34: Plaquita 3 en 1 LK | D34: =+VLOOKUP(B34,'[1]Consumo x Cod Articulo'!$C$1:$O$65536,6,) -> 0.002 | E34: =+IF(F34=H34,"No","si") -> No | F34: =+H34 -> 1000 | G34: =+F34*D34 -> 2 | H34: 1000 | I34: =+SUM(J34:R34) -> 420 | J34: =+IF(SUMIFS(Hoja1!$F:$F,Hoja1!$D:$D,$B34,Hoja1!$I:$I,J$2)>1,SUMIFS(Hoja1!$F:$F,Hoja1!$D:$D,$B34,Hoja1!$I:$I,J$2),"") -> 420 | K34: =+IF(SUMIFS(Hoja1!$F:$F,Hoja1!$D:$D,$B34,Hoja1!$I:$I,K$2)>1,SUMIFS(Hoja1!$F:$F,Hoja1!$D:$D,$B34,Hoja1!$I:$I,K$2),"") | L34: =+IF(SUMIFS(Hoja1!$F:$F,Hoja1!$D:$D,$B34,Hoja1!$I:$I,L$2)>1,SUMIFS(Hoja1!$F:$F,Hoja1!$D:$D,$B34,Hoja1!$I:$I,L$2),"") | M34: =+IF(SUMIFS(Hoja1!$F:$F,Hoja1!$D:$D,$B34,Hoja1!$I:$I,M$2)>1,SUMIFS(Hoja1!$F:$F,Hoja1!$D:$D,$B34,Hoja1!$I:$I,M$2),"") | N34: =+IF(SUMIFS(Hoja1!$F:$F,Hoja1!$D:$D,$B34,Hoja1!$I:$I,N$2)>1,SUMIFS(Hoja1!$F:$F,Hoja1!$D:$D,$B34,Hoja1!$I:$I,N$2),"") | O34: =+IF(SUMIFS(Hoja1!$F:$F,Hoja1!$D:$D,$B34,Hoja1!$I:$I,O$2)>1,SUMIFS(Hoja1!$F:$F,Hoja1!$D:$D,$B34,Hoja1!$I:$I,O$2),"") | P34: =+IF(SUMIFS(Hoja1!$F:$F,Hoja1!$D:$D,$B34,Hoja1!$I:$I,P$2)>1,SUMIFS(Hoja1!$F:$F,Hoja1!$D:$D,$B34,Hoja1!$I:$I,P$2),"") | Q34: =+IF(SUMIFS(Hoja1!$F:$F,Hoja1!$D:$D,$B34,Hoja1!$I:$I,Q$2)>1,SUMIFS(Hoja1!$F:$F,Hoja1!$D:$D,$B34,Hoja1!$I:$I,Q$2),"") | R34: =+IF(SUMIFS(Hoja1!$F:$F,Hoja1!$D:$D,$B34,Hoja1!$I:$I,R$2)>1,SUMIFS(Hoja1!$F:$F,Hoja1!$D:$D,$B34,Hoja1!$I:$I,R$2),"")
A35: 4 | B35: A4 | C35: Mang Cuch Unt Rojo | D35: =+VLOOKUP(B35,'[1]Consumo x Cod Articulo'!$C$1:$O$65536,6,) -> 0.01 | E35: =+IF(F35=H35,"No","si") -> No | F35: =+H35 -> 1000 | G35: =+F35*D35 -> 10 | H35: 1000 | I35: =+SUM(J35:R35) -> 360 | J35: =+IF(SUMIFS(Hoja1!$F:$F,Hoja1!$D:$D,$B35,Hoja1!$I:$I,J$2)>1,SUMIFS(Hoja1!$F:$F,Hoja1!$D:$D,$B35,Hoja1!$I:$I,J$2),"") -> 360 | K35: =+IF(SUMIFS(Hoja1!$F:$F,Hoja1!$D:$D,$B35,Hoja1!$I:$I,K$2)>1,SUMIFS(Hoja1!$F:$F,Hoja1!$D:$D,$B35,Hoja1!$I:$I,K$2),"") | L35: =+IF(SUMIFS(Hoja1!$F:$F,Hoja1!$D:$D,$B35,Hoja1!$I:$I,L$2)>1,SUMIFS(Hoja1!$F:$F,Hoja1!$D:$D,$B35,Hoja1!$I:$I,L$2),"") | M35: =+IF(SUMIFS(Hoja1!$F:$F,Hoja1!$D:$D,$B35,Hoja1!$I:$I,M$2)>1,SUMIFS(Hoja1!$F:$F,Hoja1!$D:$D,$B35,Hoja1!$I:$I,M$2),"") | N35: =+IF(SUMIFS(Hoja1!$F:$F,Hoja1!$D:$D,$B35,Hoja1!$I:$I,N$2)>1,SUMIFS(Hoja1!$F:$F,Hoja1!$D:$D,$B35,Hoja1!$I:$I,N$2),"") | O35: =+IF(SUMIFS(Hoja1!$F:$F,Hoja1!$D:$D,$B35,Hoja1!$I:$I,O$2)>1,SUMIFS(Hoja1!$F:$F,Hoja1!$D:$D,$B35,Hoja1!$I:$I,O$2),"") | P35: =+IF(SUMIFS(Hoja1!$F:$F,Hoja1!$D:$D,$B35,Hoja1!$I:$I,P$2)>1,SUMIFS(Hoja1!$F:$F,Hoja1!$D:$D,$B35,Hoja1!$I:$I,P$2),"") | Q35: =+IF(SUMIFS(Hoja1!$F:$F,Hoja1!$D:$D,$B35,Hoja1!$I:$I,Q$2)>1,SUMIFS(Hoja1!$F:$F,Hoja1!$D:$D,$B35,Hoja1!$I:$I,Q$2),"") | R35: =+IF(SUMIFS(Hoja1!$F:$F,Hoja1!$D:$D,$B35,Hoja1!$I:$I,R$2)>1,SUMIFS(Hoja1!$F:$F,Hoja1!$D:$D,$B35,Hoja1!$I:$I,R$2),"")
A36: 14 | B36: A18 | C36: Capuchon Espatula LK | D36: =+VLOOKUP(B36,'[1]Consumo x Cod Articulo'!$C$1:$O$65536,6,) -> 0.0022 | E36: =+IF(F36=H36,"No","si") -> si | F36: 2500 | G36: =+F36*D36 -> 5.5 | H36: =+VLOOKUP(B36,'[1]Relevamiento y OP VACIO'!$C$1:$AH$65536,26,) -> 5000 | I36: =+SUM(J36:R36) -> 11000 | J36: =+IF(SUMIFS(Hoja1!$F:$F,Hoja1!$D:$D,$B36,Hoja1!$I:$I,J$2)>1,SUMIFS(Hoja1!$F:$F,Hoja1!$D:$D,$B36,Hoja1!$I:$I,J$2),"") -> 1172 | K36: =+IF(SUMIFS(Hoja1!$F:$F,Hoja1!$D:$D,$B36,Hoja1!$I:$I,K$2)>1,SUMIFS(Hoja1!$F:$F,Hoja1!$D:$D,$B36,Hoja1!$I:$I,K$2),"") | L36: =+IF(SUMIFS(Hoja1!$F:$F,Hoja1!$D:$D,$B36,Hoja1!$I:$I,L$2)>1,SUMIFS(Hoja1!$F:$F,Hoja1!$D:$D,$B36,Hoja1!$I:$I,L$2),"") | M36: =+IF(SUMIFS(Hoja1!$F:$F,Hoja1!$D:$D,$B36,Hoja1!$I:$I,M$2)>1,SUMIFS(Hoja1!$F:$F,Hoja1!$D:$D,$B36,Hoja1!$I:$I,M$2),"") | N36: =+IF(SUMIFS(Hoja1!$F:$F,Hoja1!$D:$D,$B36,Hoja1!$I:$I,N$2)>1,SUMIFS(Hoja1!$F:$F,Hoja1!$D:$D,$B36,Hoja1!$I:$I,N$2),"") -> 696 | O36: =+IF(SUMIFS(Hoja1!$F:$F,Hoja1!$D:$D,$B36,Hoja1!$I:$I,O$2)>1,SUMIFS(Hoja1!$F:$F,Hoja1!$D:$D,$B36,Hoja1!$I:$I,O$2),"") -> 1572 | P36: =+IF(SUMIFS(Hoja1!$F:$F,Hoja1!$D:$D,$B36,Hoja1!$I:$I,P$2)>1,SUMIFS(Hoja1!$F:$F,Hoja1!$D:$D,$B36,Hoja1!$I:$I,P$2),"") -> 7560 | Q36: =+IF(SUMIFS(Hoja1!$F:$F,Hoja1!$D:$D,$B36,Hoja1!$I:$I,Q$2)>1,SUMIFS(Hoja1!$F:$F,Hoja1!$D:$D,$B36,Hoja1!$I:$I,Q$2),"") | R36: =+IF(SUMIFS(Hoja1!$F:$F,Hoja1!$D:$D,$B36,Hoja1!$I:$I,R$2)>1,SUMIFS(Hoja1!$F:$F,Hoja1!$D:$D,$B36,Hoja1!$I:$I,R$2),"")
A37: 12 | B37: A16 | C37: Mangos ф 10 | D37: =+VLOOKUP(B37,'[1]Consumo x Cod Articulo'!$C$1:$O$65536,6,) -> 0.015 | E37: =+IF(F37=H37,"No","si") -> No | F37: =+H37 -> 1000 | G37: =+F37*D37 -> 15 | H37: =+VLOOKUP(B37,'[1]Relevamiento y OP VACIO'!$C$1:$AH$65536,26,) -> 1000 | I37: =+SUM(J37:R37) -> 360 | J37: =+IF(SUMIFS(Hoja1!$F:$F,Hoja1!$D:$D,$B37,Hoja1!$I:$I,J$2)>1,SUMIFS(Hoja1!$F:$F,Hoja1!$D:$D,$B37,Hoja1!$I:$I,J$2),"") | K37: =+IF(SUMIFS(Hoja1!$F:$F,Hoja1!$D:$D,$B37,Hoja1!$I:$I,K$2)>1,SUMIFS(Hoja1!$F:$F,Hoja1!$D:$D,$B37,Hoja1!$I:$I,K$2),"") | L37: =+IF(SUMIFS(Hoja1!$F:$F,Hoja1!$D:$D,$B37,Hoja1!$I:$I,L$2)>1,SUMIFS(Hoja1!$F:$F,Hoja1!$D:$D,$B37,Hoja1!$I:$I,L$2),"") | M37: =+IF(SUMIFS(Hoja1!$F:$F,Hoja1!$D:$D,$B37,Hoja1!$I:$I,M$2)>1,SUMIFS(Hoja1!$F:$F,Hoja1!$D:$D,$B37,Hoja1!$I:$I,M$2),"") | N37: =+IF(SUMIFS(Hoja1!$F:$F,Hoja1!$D:$D,$B37,Hoja1!$I:$I,N$2)>1,SUMIFS(Hoja1!$F:$F,Hoja1!$D:$D,$B37,Hoja1!$I:$I,N$2),"") -> 360 | O37: =+IF(SUMIFS(Hoja1!$F:$F,Hoja1!$D:$D,$B37,Hoja1!$I:$I,O$2)>1,SUMIFS(Hoja1!$F:$F,Hoja1!$D:$D,$B37,Hoja1!$I:$I,O$2),"") | P37: =+IF(SUMIFS(Hoja1!$F:$F,Hoja1!$D:$D,$B37,Hoja1!$I:$I,P$2)>1,SUMIFS(Hoja1!$F:$F,Hoja1!$D:$D,$B37,Hoja1!$I:$I,P$2),"") | Q37: =+IF(SUMIFS(Hoja1!$F:$F,Hoja1!$D:$D,$B37,Hoja1!$I:$I,Q$2)>1,SUMIFS(Hoja1!$F:$F,Hoja1!$D:$D,$B37,Hoja1!$I:$I,Q$2),"") | R37: =+IF(SUMIFS(Hoja1!$F:$F,Hoja1!$D:$D,$B37,Hoja1!$I:$I,R$2)>1,SUMIFS(Hoja1!$F:$F,Hoja1!$D:$D,$B37,Hoja1!$I:$I,R$2),"")
A38: 26 | B38: C4 | C38: Cierra Bolsas Blanc. | D38: =+VLOOKUP(B38,'[1]Consumo x Cod Articulo'!$C$1:$O$65536,6,) -> 0 | E38: =+IF(F38=H38,"No","si") -> No | F38: =+H38 -> 1000 | G38: =+F38*D38 -> 0 | H38: 1000 | I38: =+SUM(J38:R38) -> 360 | J38: =+IF(SUMIFS(Hoja1!$F:$F,Hoja1!$D:$D,$B38,Hoja1!$I:$I,J$2)>1,SUMIFS(Hoja1!$F:$F,Hoja1!$D:$D,$B38,Hoja1!$I:$I,J$2),"") | K38: =+IF(SUMIFS(Hoja1!$F:$F,Hoja1!$D:$D,$B38,Hoja1!$I:$I,K$2)>1,SUMIFS(Hoja1!$F:$F,Hoja1!$D:$D,$B38,Hoja1!$I:$I,K$2),"") | L38: =+IF(SUMIFS(Hoja1!$F:$F,Hoja1!$D:$D,$B38,Hoja1!$I:$I,L$2)>1,SUMIFS(Hoja1!$F:$F,Hoja1!$D:$D,$B38,Hoja1!$I:$I,L$2),"") | M38: =+IF(SUMIFS(Hoja1!$F:$F,Hoja1!$D:$D,$B38,Hoja1!$I:$I,M$2)>1,SUMIFS(Hoja1!$F:$F,Hoja1!$D:$D,$B38,Hoja1!$I:$I,M$2),"") | N38: =+IF(SUMIFS(Hoja1!$F:$F,Hoja1!$D:$D,$B38,Hoja1!$I:$I,N$2)>1,SUMIFS(Hoja1!$F:$F,Hoja1!$D:$D,$B38,Hoja1!$I:$I,N$2),"") -> 360 | O38: =+IF(SUMIFS(Hoja1!$F:$F,Hoja1!$D:$D,$B38,Hoja1!$I:$I,O$2)>1,SUMIFS(Hoja1!$F:$F,Hoja1!$D:$D,$B38,Hoja1!$I:$I,O$2),"") | P38: =+IF(SUMIFS(Hoja1!$F:$F,Hoja1!$D:$D,$B38,Hoja1!$I:$I,P$2)>1,SUMIFS(Hoja1!$F:$F,Hoja1!$D:$D,$B38,Hoja1!$I:$I,P$2),"") | Q38: =+IF(SUMIFS(Hoja1!$F:$F,Hoja1!$D:$D,$B38,Hoja1!$I:$I,Q$2)>1,SUMIFS(Hoja1!$F:$F,Hoja1!$D:$D,$B38,Hoja1!$I:$I,Q$2),"") | R38: =+IF(SUMIFS(Hoja1!$F:$F,Hoja1!$D:$D,$B38,Hoja1!$I:$I,R$2)>1,SUMIFS(Hoja1!$F:$F,Hoja1!$D:$D,$B38,Hoja1!$I:$I,R$2),"")
A39: 45 | B39: V5 | C39: Cuchara Fideos 1 Pz Ny | D39: =+VLOOKUP(B39,'[1]Consumo x Cod Articulo'!$C$1:$O$65536,6,) -> 0.048 | E39: =+IF(F39=H39,"No","si") -> No | G39: =+F39*D39 -> 0 | I39: =+SUM(J39:R39) -> 360 | J39: =+IF(SUMIFS(Hoja1!$F:$F,Hoja1!$D:$D,$B39,Hoja1!$I:$I,J$2)>1,SUMIFS(Hoja1!$F:$F,Hoja1!$D:$D,$B39,Hoja1!$I:$I,J$2),"") | K39: =+IF(SUMIFS(Hoja1!$F:$F,Hoja1!$D:$D,$B39,Hoja1!$I:$I,K$2)>1,SUMIFS(Hoja1!$F:$F,Hoja1!$D:$D,$B39,Hoja1!$I:$I,K$2),"") | L39: =+IF(SUMIFS(Hoja1!$F:$F,Hoja1!$D:$D,$B39,Hoja1!$I:$I,L$2)>1,SUMIFS(Hoja1!$F:$F,Hoja1!$D:$D,$B39,Hoja1!$I:$I,L$2),"") | M39: =+IF(SUMIFS(Hoja1!$F:$F,Hoja1!$D:$D,$B39,Hoja1!$I:$I,M$2)>1,SUMIFS(Hoja1!$F:$F,Hoja1!$D:$D,$B39,Hoja1!$I:$I,M$2),"") | N39: =+IF(SUMIFS(Hoja1!$F:$F,Hoja1!$D:$D,$B39,Hoja1!$I:$I,N$2)>1,SUMIFS(Hoja1!$F:$F,Hoja1!$D:$D,$B39,Hoja1!$I:$I,N$2),"") -> 360 | O39: =+IF(SUMIFS(Hoja1!$F:$F,Hoja1!$D:$D,$B39,Hoja1!$I:$I,O$2)>1,SUMIFS(Hoja1!$F:$F,Hoja1!$D:$D,$B39,Hoja1!$I:$I,O$2),"") | P39: =+IF(SUMIFS(Hoja1!$F:$F,Hoja1!$D:$D,$B39,Hoja1!$I:$I,P$2)>1,SUMIFS(Hoja1!$F:$F,Hoja1!$D:$D,$B39,Hoja1!$I:$I,P$2),"") | Q39: =+IF(SUMIFS(Hoja1!$F:$F,Hoja1!$D:$D,$B39,Hoja1!$I:$I,Q$2)>1,SUMIFS(Hoja1!$F:$F,Hoja1!$D:$D,$B39,Hoja1!$I:$I,Q$2),"") | R39: =+IF(SUMIFS(Hoja1!$F:$F,Hoja1!$D:$D,$B39,Hoja1!$I:$I,R$2)>1,SUMIFS(Hoja1!$F:$F,Hoja1!$D:$D,$B39,Hoja1!$I:$I,R$2),"")
A40: 15 | B40: A19 | C40: Mangos Chef | D40: =+VLOOKUP(B40,'[1]Consumo x Cod Articulo'!$C$1:$O$65536,6,) -> 0.0137 | E40: =+IF(F40=H40,"No","si") -> si | F40: 500 | G40: =+F40*D40 -> 6.85 | H40: 1000 | I40: =+SUM(J40:R40) -> 1848 | J40: =+IF(SUMIFS(Hoja1!$F:$F,Hoja1!$D:$D,$B40,Hoja1!$I:$I,J$2)>1,SUMIFS(Hoja1!$F:$F,Hoja1!$D:$D,$B40,Hoja1!$I:$I,J$2),"") -> 396 | K40: =+IF(SUMIFS(Hoja1!$F:$F,Hoja1!$D:$D,$B40,Hoja1!$I:$I,K$2)>1,SUMIFS(Hoja1!$F:$F,Hoja1!$D:$D,$B40,Hoja1!$I:$I,K$2),"") -> 840 | L40: =+IF(SUMIFS(Hoja1!$F:$F,Hoja1!$D:$D,$B40,Hoja1!$I:$I,L$2)>1,SUMIFS(Hoja1!$F:$F,Hoja1!$D:$D,$B40,Hoja1!$I:$I,L$2),"") | M40: =+IF(SUMIFS(Hoja1!$F:$F,Hoja1!$D:$D,$B40,Hoja1!$I:$I,M$2)>1,SUMIFS(Hoja1!$F:$F,Hoja1!$D:$D,$B40,Hoja1!$I:$I,M$2),"") | N40: =+IF(SUMIFS(Hoja1!$F:$F,Hoja1!$D:$D,$B40,Hoja1!$I:$I,N$2)>1,SUMIFS(Hoja1!$F:$F,Hoja1!$D:$D,$B40,Hoja1!$I:$I,N$2),"") -> 228 | O40: =+IF(SUMIFS(Hoja1!$F:$F,Hoja1!$D:$D,$B40,Hoja1!$I:$I,O$2)>1,SUMIFS(Hoja1!$F:$F,Hoja1!$D:$D,$B40,Hoja1!$I:$I,O$2),"") -> 384 | P40: =+IF(SUMIFS(Hoja1!$F:$F,Hoja1!$D:$D,$B40,Hoja1!$I:$I,P$2)>1,SUMIFS(Hoja1!$F:$F,Hoja1!$D:$D,$B40,Hoja1!$I:$I,P$2),"") | Q40: =+IF(SUMIFS(Hoja1!$F:$F,Hoja1!$D:$D,$B40,Hoja1!$I:$I,Q$2)>1,SUMIFS(Hoja1!$F:$F,Hoja1!$D:$D,$B40,Hoja1!$I:$I,Q$2),"") | R40: =+IF(SUMIFS(Hoja1!$F:$F,Hoja1!$D:$D,$B40,Hoja1!$I:$I,R$2)>1,SUMIFS(Hoja1!$F:$F,Hoja1!$D:$D,$B40,Hoja1!$I:$I,R$2),"")
...
