Workbook
Name _360EN: #REF!
Name _361EN: #REF!
Name _388EN: #REF!
Name _503EN: #REF!
Name _525EN: #REF!
Name _529EN: #REF!
Name _544EN: #REF!
Name _575D: #REF!
Name _577D: #REF!
Name _585EN: #REF!
Name _811EN: #REF!
Name _812EN: #REF!
Name _813EN: #REF!
Name _814EN: #REF!
Name _816EN: #REF!
Name _817EN: #REF!
Name _819EN: #REF!
Name ALCOHOL: #REF!
Name ALQ_LARRAZABAL: #REF!
Name ANHILINA: #REF!
Name Atriles10x15: #REF!
Name Atriles13x18: #REF!
Name BuiltIn_Print_Area: #REF!
Name BuiltIn_Print_Area___0: #REF!
Name BuiltIn_Print_Titles: #REF!
Name BuiltIn_Print_Titles___0: #REF!
Name CAJAS: #REF!
Name CARTON: #REF!
Name CHAPA: #REF!
Name CHAPADUR: #REF!
Name COLA: #REF!
Name CONTADOR1: #REF!
Name CORCHO: #REF!
Name CORTE_LASER: #REF!
Name CRAYOVAC: #REF!
Name DIOXIDO: #REF!
Name DOLAR: #REF!
Name Dólar: #REF!
Name Estimado: #REF!
Name Gananc._Chef: #REF!
Name GOMALACA: #REF!
Name Griego10x15: #REF!
Name Griego13x18: #REF!
Name Griego15x21: #REF!
Name HORA: #REF!
Name IB_3: #REF!
Name IG_35: #REF!
Name LA_015: #REF!
Name LA_052: #REF!
Name LA_053: #REF!
Name LA_070: #REF!
Name LA_071: #REF!
Name LA_072: #REF!
Name LA_113: #REF!
Name LA_114: #REF!
Name LA_115: #REF!
Name LA_117: #REF!
Name LA_119: #REF!
Name LA_195: #REF!
Name LA_196: #REF!

Sheet O.C. Rueda
A1: Loekemeyer Hnos. S.R.L | F1: Chef SRL
A2: CUIT: | C2: 30-51584245-0 | F2: CUIT: | H2: 30-68575625-7
A3: DIRECCION: | C3: Cervantes 2868 | F3: DIRECCION: | H3: Virgilio 2788
A4: LOCALIDAD: | C4: Villa Devoto, CABA | F4: LOCALIDAD: | H4: Villa Real, CABA
A6: ORDEN DE COMPRA | F6: FECHA PEDIDO: | I6: =+TODAY() -> 46099
A8: RAZON SOCIAL: | C8: RUEDA | D8: COD PROV: | E8: 3372 | F8: ENTREGA EN: | I8: Cervantes 2868
A10: FACTURAR Loekemeyer 70% Chef 30%
A12: ESTE PEDIDO ANULA CUALQUIER PEDIDO ANTERIOR
A13: Cód ISIS | B13: N° Ord | C13: Descripcion Material | D13: Pedido KG | E13: Emp | F13: KG a FC | G13: Fecha Pos Ent | H13: Fecha Ent | I13: Kg Ent | J13: Fecha Ent | K13: Kg Ent | L13: Fecha Ent | M13: Kg Ent
A14: {=+IFERROR(INDEX('Conteo 18-02-26'!$B:$B,MATCH(1,('Conteo 18-02-26'!$E:$E=$B14)*('Conteo 18-02-26'!$A:$A="Rueda"),0)),"")} | B14: 1 | C14: {=+IFERROR(INDEX('Conteo 18-02-26'!$C:$C,MATCH(1,('Conteo 18-02-26'!$E:$E=$B14)*('Conteo 18-02-26'!$A:$A="Rueda"),0)),"")} | D14: {=+IFERROR(INDEX('Conteo 18-02-26'!$D:$D,MATCH(1,('Conteo 18-02-26'!$E:$E=$B14)*('Conteo 18-02-26'!A:A:'Conteo 18-02-26'!$A:$A="Rueda"),0)),"")} | E14: =+IF(E13="LK","CH",IF(D14="","",IF(D14>0,"LK","CH"))) | F14: =+IF(OR(E14="LK"),ROUNDUP(D14*(VLOOKUP(B14,'Conteo 18-02-26'!$E:$AN,35,0))/100,0),IF(E14="CH",D13-F13,""))
E15: =+IF(E14="LK","CH",IF(D15="","",IF(D15>0,"LK","CH"))) | F15: =+IF(OR(E15="LK"),ROUNDUP(D15*(VLOOKUP(B15,'Conteo 18-02-26'!$E:$AN,35,0))/100,0),IF(E15="CH",D14-F14,""))
A16: {=+IFERROR(INDEX('Conteo 18-02-26'!$B:$B,MATCH(1,('Conteo 18-02-26'!$E:$E=$B16)*('Conteo 18-02-26'!$A:$A="Rueda"),0)),"")} | B16: =+B14+1 -> 2 | C16: {=+IFERROR(INDEX('Conteo 18-02-26'!$C:$C,MATCH(1,('Conteo 18-02-26'!$E:$E=$B16)*('Conteo 18-02-26'!$A:$A="Rueda"),0)),"")} | D16: {=+IFERROR(INDEX('Conteo 18-02-26'!$D:$D,MATCH(1,('Conteo 18-02-26'!$E:$E=$B16)*('Conteo 18-02-26'!A:A:'Conteo 18-02-26'!$A:$A="Rueda"),0)),"")} | E16: =+IF(E15="LK","CH",IF(D16="","",IF(D16>0,"LK","CH"))) | F16: =+IF(OR(E16="LK"),ROUNDUP(D16*(VLOOKUP(B16,'Conteo 18-02-26'!$E:$AN,35,0))/100,0),IF(E16="CH",D15-F15,""))
E17: =+IF(E16="LK","CH",IF(D17="","",IF(D17>0,"LK","CH"))) | F17: =+IF(OR(E17="LK"),ROUNDUP(D17*(VLOOKUP(B17,'Conteo 18-02-26'!$E:$AN,35,0))/100,0),IF(E17="CH",D16-F16,""))
A18: {=+IFERROR(INDEX('Conteo 18-02-26'!$B:$B,MATCH(1,('Conteo 18-02-26'!$E:$E=$B18)*('Conteo 18-02-26'!$A:$A="Rueda"),0)),"")} | B18: =+B16+1 -> 3 | C18: {=+IFERROR(INDEX('Conteo 18-02-26'!$C:$C,MATCH(1,('Conteo 18-02-26'!$E:$E=$B18)*('Conteo 18-02-26'!$A:$A="Rueda"),0)),"")} | D18: {=+IFERROR(INDEX('Conteo 18-02-26'!$D:$D,MATCH(1,('Conteo 18-02-26'!$E:$E=$B18)*('Conteo 18-02-26'!A:A:'Conteo 18-02-26'!$A:$A="Rueda"),0)),"")} | E18: =+IF(E17="LK","CH",IF(D18="","",IF(D18>0,"LK","CH"))) | F18: =+IF(OR(E18="LK"),ROUNDUP(D18*(VLOOKUP(B18,'Conteo 18-02-26'!$E:$AN,35,0))/100,0),IF(E18="CH",D17-F17,""))
E19: =+IF(E18="LK","CH",IF(D19="","",IF(D19>0,"LK","CH"))) | F19: =+IF(OR(E19="LK"),ROUNDUP(D19*(VLOOKUP(B19,'Conteo 18-02-26'!$E:$AN,35,0))/100,0),IF(E19="CH",D18-F18,""))
A20: {=+IFERROR(INDEX('Conteo 18-02-26'!$B:$B,MATCH(1,('Conteo 18-02-26'!$E:$E=$B20)*('Conteo 18-02-26'!$A:$A="Rueda"),0)),"")} | B20: =+B18+1 -> 4 | C20: {=+IFERROR(INDEX('Conteo 18-02-26'!$C:$C,MATCH(1,('Conteo 18-02-26'!$E:$E=$B20)*('Conteo 18-02-26'!$A:$A="Rueda"),0)),"")} | D20: {=+IFERROR(INDEX('Conteo 18-02-26'!$D:$D,MATCH(1,('Conteo 18-02-26'!$E:$E=$B20)*('Conteo 18-02-26'!A:A:'Conteo 18-02-26'!$A:$A="Rueda"),0)),"")} | E20: =+IF(E19="LK","CH",IF(D20="","",IF(D20>0,"LK","CH"))) | F20: =+IF(OR(E20="LK"),ROUNDUP(D20*(VLOOKUP(B20,'Conteo 18-02-26'!$E:$AN,35,0))/100,0),IF(E20="CH",D19-F19,""))
E21: =+IF(E20="LK","CH",IF(D21="","",IF(D21>0,"LK","CH"))) | F21: =+IF(OR(E21="LK"),ROUNDUP(D21*(VLOOKUP(B21,'Conteo 18-02-26'!$E:$AN,35,0))/100,0),IF(E21="CH",D20-F20,""))
A22: {=+IFERROR(INDEX('Conteo 18-02-26'!$B:$B,MATCH(1,('Conteo 18-02-26'!$E:$E=$B22)*('Conteo 18-02-26'!$A:$A="Rueda"),0)),"")} | B22: =+B20+1 -> 5 | C22: {=+IFERROR(INDEX('Conteo 18-02-26'!$C:$C,MATCH(1,('Conteo 18-02-26'!$E:$E=$B22)*('Conteo 18-02-26'!$A:$A="Rueda"),0)),"")} | D22: {=+IFERROR(INDEX('Conteo 18-02-26'!$D:$D,MATCH(1,('Conteo 18-02-26'!$E:$E=$B22)*('Conteo 18-02-26'!A:A:'Conteo 18-02-26'!$A:$A="Rueda"),0)),"")} | E22: =+IF(E21="LK","CH",IF(D22="","",IF(D22>0,"LK","CH"))) | F22: =+IF(OR(E22="LK"),ROUNDUP(D22*(VLOOKUP(B22,'Conteo 18-02-26'!$E:$AN,35,0))/100,0),IF(E22="CH",D21-F21,""))
E23: =+IF(E22="LK","CH",IF(D23="","",IF(D23>0,"LK","CH"))) | F23: =+IF(OR(E23="LK"),ROUNDUP(D23*(VLOOKUP(B23,'Conteo 18-02-26'!$E:$AN,35,0))/100,0),IF(E23="CH",D22-F22,""))
A24: {=+IFERROR(INDEX('Conteo 18-02-26'!$B:$B,MATCH(1,('Conteo 18-02-26'!$E:$E=$B24)*('Conteo 18-02-26'!$A:$A="Rueda"),0)),"")} | B24: =+B22+1 -> 6 | C24: {=+IFERROR(INDEX('Conteo 18-02-26'!$C:$C,MATCH(1,('Conteo 18-02-26'!$E:$E=$B24)*('Conteo 18-02-26'!$A:$A="Rueda"),0)),"")} | D24: {=+IFERROR(INDEX('Conteo 18-02-26'!$D:$D,MATCH(1,('Conteo 18-02-26'!$E:$E=$B24)*('Conteo 18-02-26'!A:A:'Conteo 18-02-26'!$A:$A="Rueda"),0)),"")} | E24: =+IF(E23="LK","CH",IF(D24="","",IF(D24>0,"LK","CH"))) | F24: =+IF(OR(E24="LK"),ROUNDUP(D24*(VLOOKUP(B24,'Conteo 18-02-26'!$E:$AN,35,0))/100,0),IF(E24="CH",D23-F23,""))
E25: =+IF(E24="LK","CH",IF(D25="","",IF(D25>0,"LK","CH"))) | F25: =+IF(OR(E25="LK"),ROUNDUP(D25*(VLOOKUP(B25,'Conteo 18-02-26'!$E:$AN,35,0))/100,0),IF(E25="CH",D24-F24,""))
A26: {=+IFERROR(INDEX('Conteo 18-02-26'!$B:$B,MATCH(1,('Conteo 18-02-26'!$E:$E=$B26)*('Conteo 18-02-26'!$A:$A="Rueda"),0)),"")} | B26: =+B24+1 -> 7 | C26: {=+IFERROR(INDEX('Conteo 18-02-26'!$C:$C,MATCH(1,('Conteo 18-02-26'!$E:$E=$B26)*('Conteo 18-02-26'!$A:$A="Rueda"),0)),"")} | D26: {=+IFERROR(INDEX('Conteo 18-02-26'!$D:$D,MATCH(1,('Conteo 18-02-26'!$E:$E=$B26)*('Conteo 18-02-26'!A:A:'Conteo 18-02-26'!$A:$A="Rueda"),0)),"")} | E26: =+IF(E25="LK","CH",IF(D26="","",IF(D26>0,"LK","CH"))) | F26: =+IF(OR(E26="LK"),ROUNDUP(D26*(VLOOKUP(B26,'Conteo 18-02-26'!$E:$AN,35,0))/100,0),IF(E26="CH",D25-F25,""))
E27: =+IF(E26="LK","CH",IF(D27="","",IF(D27>0,"LK","CH"))) | F27: =+IF(OR(E27="LK"),ROUNDUP(D27*(VLOOKUP(B27,'Conteo 18-02-26'!$E:$AN,35,0))/100,0),IF(E27="CH",D26-F26,""))
A28: {=+IFERROR(INDEX('Conteo 18-02-26'!$B:$B,MATCH(1,('Conteo 18-02-26'!$E:$E=$B28)*('Conteo 18-02-26'!$A:$A="Rueda"),0)),"")} | B28: =+B26+1 -> 8 | C28: {=+IFERROR(INDEX('Conteo 18-02-26'!$C:$C,MATCH(1,('Conteo 18-02-26'!$E:$E=$B28)*('Conteo 18-02-26'!$A:$A="Rueda"),0)),"")} | D28: {=+IFERROR(INDEX('Conteo 18-02-26'!$D:$D,MATCH(1,('Conteo 18-02-26'!$E:$E=$B28)*('Conteo 18-02-26'!A:A:'Conteo 18-02-26'!$A:$A="Rueda"),0)),"")} | E28: =+IF(E27="LK","CH",IF(D28="","",IF(D28>0,"LK","CH"))) | F28: =+IF(OR(E28="LK"),ROUNDUP(D28*(VLOOKUP(B28,'Conteo 18-02-26'!$E:$AN,35,0))/100,0),IF(E28="CH",D27-F27,""))
E29: =+IF(E28="LK","CH",IF(D29="","",IF(D29>0,"LK","CH"))) | F29: =+IF(OR(E29="LK"),ROUNDUP(D29*(VLOOKUP(B29,'Conteo 18-02-26'!$E:$AN,35,0))/100,0),IF(E29="CH",D28-F28,""))
A30: {=+IFERROR(INDEX('Conteo 18-02-26'!$B:$B,MATCH(1,('Conteo 18-02-26'!$E:$E=$B30)*('Conteo 18-02-26'!$A:$A="Rueda"),0)),"")} | B30: =+B28+1 -> 9 | C30: {=+IFERROR(INDEX('Conteo 18-02-26'!$C:$C,MATCH(1,('Conteo 18-02-26'!$E:$E=$B30)*('Conteo 18-02-26'!$A:$A="Rueda"),0)),"")} | D30: {=+IFERROR(INDEX('Conteo 18-02-26'!$D:$D,MATCH(1,('Conteo 18-02-26'!$E:$E=$B30)*('Conteo 18-02-26'!A:A:'Conteo 18-02-26'!$A:$A="Rueda"),0)),"")} | E30: =+IF(E29="LK","CH",IF(D30="","",IF(D30>0,"LK","CH"))) | F30: =+IF(OR(E30="LK"),ROUNDUP(D30*(VLOOKUP(B30,'Conteo 18-02-26'!$E:$AN,35,0))/100,0),IF(E30="CH",D29-F29,""))
E31: =+IF(E30="LK","CH",IF(D31="","",IF(D31>0,"LK","CH"))) | F31: =+IF(OR(E31="LK"),ROUNDUP(D31*(VLOOKUP(B31,'Conteo 18-02-26'!$E:$AN,35,0))/100,0),IF(E31="CH",D30-F30,""))
A32: {=+IFERROR(INDEX('Conteo 18-02-26'!$B:$B,MATCH(1,('Conteo 18-02-26'!$E:$E=$B32)*('Conteo 18-02-26'!$A:$A="Rueda"),0)),"")} | B32: =+B30+1 -> 10 | C32: {=+IFERROR(INDEX('Conteo 18-02-26'!$C:$C,MATCH(1,('Conteo 18-02-26'!$E:$E=$B32)*('Conteo 18-02-26'!$A:$A="Rueda"),0)),"")} | D32: {=+IFERROR(INDEX('Conteo 18-02-26'!$D:$D,MATCH(1,('Conteo 18-02-26'!$E:$E=$B32)*('Conteo 18-02-26'!A:A:'Conteo 18-02-26'!$A:$A="Rueda"),0)),"")} | E32: =+IF(E31="LK","CH",IF(D32="","",IF(D32>0,"LK","CH"))) | F32: =+IF(OR(E32="LK"),ROUNDUP(D32*(VLOOKUP(B32,'Conteo 18-02-26'!$E:$AN,35,0))/100,0),IF(E32="CH",D31-F31,""))
E33: =+IF(E32="LK","CH",IF(D33="","",IF(D33>0,"LK","CH"))) | F33: =+IF(OR(E33="LK"),ROUNDUP(D33*(VLOOKUP(B33,'Conteo 18-02-26'!$E:$AN,35,0))/100,0),IF(E33="CH",D32-F32,""))
A34: {=+IFERROR(INDEX('Conteo 18-02-26'!$B:$B,MATCH(1,('Conteo 18-02-26'!$E:$E=$B34)*('Conteo 18-02-26'!$A:$A="Rueda"),0)),"")} | B34: =+B32+1 -> 11 | C34: {=+IFERROR(INDEX('Conteo 18-02-26'!$C:$C,MATCH(1,('Conteo 18-02-26'!$E:$E=$B34)*('Conteo 18-02-26'!$A:$A="Rueda"),0)),"")} | D34: {=+IFERROR(INDEX('Conteo 18-02-26'!$D:$D,MATCH(1,('Conteo 18-02-26'!$E:$E=$B34)*('Conteo 18-02-26'!A:A:'Conteo 18-02-26'!$A:$A="Rueda"),0)),"")} | E34: =+IF(E33="LK","CH",IF(D34="","",IF(D34>0,"LK","CH"))) | F34: =+IF(OR(E34="LK"),ROUNDUP(D34*(VLOOKUP(B34,'Conteo 18-02-26'!$E:$AN,35,0))/100,0),IF(E34="CH",D33-F33,""))
E35: =+IF(E34="LK","CH",IF(D35="","",IF(D35>0,"LK","CH"))) | F35: =+IF(OR(E35="LK"),ROUNDUP(D35*(VLOOKUP(B35,'Conteo 18-02-26'!$E:$AN,35,0))/100,0),IF(E35="CH",D34-F34,""))
A36: {=+IFERROR(INDEX('Conteo 18-02-26'!$B:$B,MATCH(1,('Conteo 18-02-26'!$E:$E=$B36)*('Conteo 18-02-26'!$A:$A="Rueda"),0)),"")} | B36: =+B34+1 -> 12 | C36: {=+IFERROR(INDEX('Conteo 18-02-26'!$C:$C,MATCH(1,('Conteo 18-02-26'!$E:$E=$B36)*('Conteo 18-02-26'!$A:$A="Rueda"),0)),"")} | D36: {=+IFERROR(INDEX('Conteo 18-02-26'!$D:$D,MATCH(1,('Conteo 18-02-26'!$E:$E=$B36)*('Conteo 18-02-26'!A:A:'Conteo 18-02-26'!$A:$A="Rueda"),0)),"")} | E36: =+IF(E35="LK","CH",IF(D36="","",IF(D36>0,"LK","CH"))) | F36: =+IF(OR(E36="LK"),ROUNDUP(D36*(VLOOKUP(B36,'Conteo 18-02-26'!$E:$AN,35,0))/100,0),IF(E36="CH",D35-F35,""))
E37: =+IF(E36="LK","CH",IF(D37="","",IF(D37>0,"LK","CH"))) | F37: =+IF(OR(E37="LK"),ROUNDUP(D37*(VLOOKUP(B37,'Conteo 18-02-26'!$E:$AN,35,0))/100,0),IF(E37="CH",D36-F36,""))
A38: {=+IFERROR(INDEX('Conteo 18-02-26'!$B:$B,MATCH(1,('Conteo 18-02-26'!$E:$E=$B38)*('Conteo 18-02-26'!$A:$A="Rueda"),0)),"")} | B38: =+B36+1 -> 13 | C38: {=+IFERROR(INDEX('Conteo 18-02-26'!$C:$C,MATCH(1,('Conteo 18-02-26'!$E:$E=$B38)*('Conteo 18-02-26'!$A:$A="Rueda"),0)),"")} | D38: {=+IFERROR(INDEX('Conteo 18-02-26'!$D:$D,MATCH(1,('Conteo 18-02-26'!$E:$E=$B38)*('Conteo 18-02-26'!A:A:'Conteo 18-02-26'!$A:$A="Rueda"),0)),"")} | E38: =+IF(E37="LK","CH",IF(D38="","",IF(D38>0,"LK","CH"))) | F38: =+IF(OR(E38="LK"),ROUNDUP(D38*(VLOOKUP(B38,'Conteo 18-02-26'!$E:$AN,35,0))/100,0),IF(E38="CH",D37-F37,""))
E39: =+IF(E38="LK","CH",IF(D39="","",IF(D39>0,"LK","CH"))) | F39: =+IF(OR(E39="LK"),ROUNDUP(D39*(VLOOKUP(B39,'Conteo 18-02-26'!$E:$AN,35,0))/100,0),IF(E39="CH",D38-F38,""))
A40: {=+IFERROR(INDEX('Conteo 18-02-26'!$B:$B,MATCH(1,('Conteo 18-02-26'!$E:$E=$B40)*('Conteo 18-02-26'!$A:$A="Rueda"),0)),"")} | B40: =+B38+1 -> 14 | C40: {=+IFERROR(INDEX('Conteo 18-02-26'!$C:$C,MATCH(1,('Conteo 18-02-26'!$E:$E=$B40)*('Conteo 18-02-26'!$A:$A="Rueda"),0)),"")} | D40: {=+IFERROR(INDEX('Conteo 18-02-26'!$D:$D,MATCH(1,('Conteo 18-02-26'!$E:$E=$B40)*('Conteo 18-02-26'!A:A:'Conteo 18-02-26'!$A:$A="Rueda"),0)),"")} | E40: =+IF(E39="LK","CH",IF(D40="","",IF(D40>0,"LK","CH"))) | F40: =+IF(OR(E40="LK"),ROUNDUP(D40*(VLOOKUP(B40,'Conteo 18-02-26'!$E:$AN,35,0))/100,0),IF(E40="CH",D39-F39,""))
E41: =+IF(E40="LK","CH",IF(D41="","",IF(D41>0,"LK","CH"))) | F41: =+IF(OR(E41="LK"),ROUNDUP(D41*(VLOOKUP(B41,'Conteo 18-02-26'!$E:$AN,35,0))/100,0),IF(E41="CH",D40-F40,""))
A42: {=+IFERROR(INDEX('Conteo 18-02-26'!$B:$B,MATCH(1,('Conteo 18-02-26'!$E:$E=$B42)*('Conteo 18-02-26'!$A:$A="Rueda"),0)),"")} | B42: =+B40+1 -> 15 | C42: {=+IFERROR(INDEX('Conteo 18-02-26'!$C:$C,MATCH(1,('Conteo 18-02-26'!$E:$E=$B42)*('Conteo 18-02-26'!$A:$A="Rueda"),0)),"")} | D42: {=+IFERROR(INDEX('Conteo 18-02-26'!$D:$D,MATCH(1,('Conteo 18-02-26'!$E:$E=$B42)*('Conteo 18-02-26'!A:A:'Conteo 18-02-26'!$A:$A="Rueda"),0)),"")} | E42: =+IF(E41="LK","CH",IF(D42="","",IF(D42>0,"LK","CH"))) | F42: =+IF(OR(E42="LK"),ROUNDUP(D42*(VLOOKUP(B42,'Conteo 18-02-26'!$E:$AN,35,0))/100,0),IF(E42="CH",D41-F41,""))
E43: =+IF(E42="LK","CH",IF(D43="","",IF(D43>0,"LK","CH"))) | F43: =+IF(OR(E43="LK"),ROUNDUP(D43*(VLOOKUP(B43,'Conteo 18-02-26'!$E:$AN,35,0))/100,0),IF(E43="CH",D42-F42,""))

Sheet O.C. Roosevelt
A1: Loekemeyer Hnos. S.R.L | F1: Chef SRL
A2: CUIT: | C2: 30-51584245-0 | F2: CUIT: | H2: 30-68575625-7
A3: DIRECCION: | C3: Cervantes 2868 | F3: DIRECCION: | H3: Virgilio 2788
A4: LOCALIDAD: | C4: Villa Devoto, CABA | F4: LOCALIDAD: | H4: Villa Real, CABA
A6: ORDEN DE COMPRA | F6: FECHA PEDIDO: | I6: =+TODAY() -> 46099
A8: RAZON SOCIAL: | C8: TALLERES ROOSEVELT | D8: COD PROV: | E8: 3085 | F8: ENTREGA EN: | I8: Cervantes 2868
A10: FACTURAR Loekemeyer 70% Chef 30%
A12: ESTE PEDIDO ANULA CUALQUIER PEDIDO ANTERIOR
A13: Cód ISIS | B13: N° Ord | C13: Descripcion Material | D13: Pedido KG | E13: Emp | F13: KG a FC | G13: Fecha Pos Ent | H13: Fecha Ent | I13: Kg Ent | J13: Fecha Ent | K13: Kg Ent | L13: Fecha Ent | M13: Kg Ent
A14: {=+IFERROR(INDEX('Conteo 18-02-26'!$B:$B,MATCH(1,('Conteo 18-02-26'!$E:$E=$B14)*('Conteo 18-02-26'!$A:$A="Roosvelt"),0)),"")} | B14: 1 | C14: {=+IFERROR(INDEX('Conteo 18-02-26'!$C:$C,MATCH(1,('Conteo 18-02-26'!$E:$E=$B14)*('Conteo 18-02-26'!$A:$A="Roosvelt"),0)),"")} | D14: {=+IFERROR(INDEX('Conteo 18-02-26'!$D:$D,MATCH(1,('Conteo 18-02-26'!$E:$E=$B14)*('Conteo 18-02-26'!A:A:'Conteo 18-02-26'!$A:$A="Roosvelt"),0)),"")} | E14: =+IF(E13="LK","CH",IF(D14="","",IF(D14>0,"LK","CH"))) | F14: =+IF(OR(E14="LK"),ROUNDUP(D14*(VLOOKUP(B14,'Conteo 18-02-26'!$E:$AN,35,0))/100,0),IF(E14="CH",D13-F13,""))
E15: =+IF(E14="LK","CH",IF(D15="","",IF(D15>0,"LK","CH"))) | F15: =+IF(OR(E15="LK"),ROUNDUP(D15*(VLOOKUP(B15,'Conteo 18-02-26'!$E:$AN,35,0))/100,0),IF(E15="CH",D14-F14,""))
A16: {=+IFERROR(INDEX('Conteo 18-02-26'!$B:$B,MATCH(1,('Conteo 18-02-26'!$E:$E=$B16)*('Conteo 18-02-26'!$A:$A="Roosvelt"),0)),"")} | B16: =+B14+1 -> 2 | C16: {=+IFERROR(INDEX('Conteo 18-02-26'!$C:$C,MATCH(1,('Conteo 18-02-26'!$E:$E=$B16)*('Conteo 18-02-26'!$A:$A="Roosvelt"),0)),"")} | D16: {=+IFERROR(INDEX('Conteo 18-02-26'!$D:$D,MATCH(1,('Conteo 18-02-26'!$E:$E=$B16)*('Conteo 18-02-26'!A:A:'Conteo 18-02-26'!$A:$A="Roosvelt"),0)),"")} | E16: =+IF(E15="LK","CH",IF(D16="","",IF(D16>0,"LK","CH"))) | F16: =+IF(OR(E16="LK"),ROUNDUP(D16*(VLOOKUP(B16,'Conteo 18-02-26'!$E:$AN,35,0))/100,0),IF(E16="CH",D15-F15,""))
E17: =+IF(E16="LK","CH",IF(D17="","",IF(D17>0,"LK","CH"))) | F17: =+IF(OR(E17="LK"),ROUNDUP(D17*(VLOOKUP(B17,'Conteo 18-02-26'!$E:$AN,35,0))/100,0),IF(E17="CH",D16-F16,""))
A18: {=+IFERROR(INDEX('Conteo 18-02-26'!$B:$B,MATCH(1,('Conteo 18-02-26'!$E:$E=$B18)*('Conteo 18-02-26'!$A:$A="Roosvelt"),0)),"")} | B18: =+B16+1 -> 3 | C18: {=+IFERROR(INDEX('Conteo 18-02-26'!$C:$C,MATCH(1,('Conteo 18-02-26'!$E:$E=$B18)*('Conteo 18-02-26'!$A:$A="Roosvelt"),0)),"")} | D18: {=+IFERROR(INDEX('Conteo 18-02-26'!$D:$D,MATCH(1,('Conteo 18-02-26'!$E:$E=$B18)*('Conteo 18-02-26'!A:A:'Conteo 18-02-26'!$A:$A="Roosvelt"),0)),"")} | E18: =+IF(E17="LK","CH",IF(D18="","",IF(D18>0,"LK","CH"))) | F18: =+IF(OR(E18="LK"),ROUNDUP(D18*(VLOOKUP(B18,'Conteo 18-02-26'!$E:$AN,35,0))/100,0),IF(E18="CH",D17-F17,""))
E19: =+IF(E18="LK","CH",IF(D19="","",IF(D19>0,"LK","CH"))) | F19: =+IF(OR(E19="LK"),ROUNDUP(D19*(VLOOKUP(B19,'Conteo 18-02-26'!$E:$AN,35,0))/100,0),IF(E19="CH",D18-F18,""))
A20: {=+IFERROR(INDEX('Conteo 18-02-26'!$B:$B,MATCH(1,('Conteo 18-02-26'!$E:$E=$B20)*('Conteo 18-02-26'!$A:$A="Roosvelt"),0)),"")} | B20: =+B18+1 -> 4 | C20: {=+IFERROR(INDEX('Conteo 18-02-26'!$C:$C,MATCH(1,('Conteo 18-02-26'!$E:$E=$B20)*('Conteo 18-02-26'!$A:$A="Roosvelt"),0)),"")} | D20: {=+IFERROR(INDEX('Conteo 18-02-26'!$D:$D,MATCH(1,('Conteo 18-02-26'!$E:$E=$B20)*('Conteo 18-02-26'!A:A:'Conteo 18-02-26'!$A:$A="Roosvelt"),0)),"")} | E20: =+IF(E19="LK","CH",IF(D20="","",IF(D20>0,"LK","CH"))) | F20: =+IF(OR(E20="LK"),ROUNDUP(D20*(VLOOKUP(B20,'Conteo 18-02-26'!$E:$AN,35,0))/100,0),IF(E20="CH",D19-F19,""))
E21: =+IF(E20="LK","CH",IF(D21="","",IF(D21>0,"LK","CH"))) | F21: =+IF(OR(E21="LK"),ROUNDUP(D21*(VLOOKUP(B21,'Conteo 18-02-26'!$E:$AN,35,0))/100,0),IF(E21="CH",D20-F20,""))
A22: {=+IFERROR(INDEX('Conteo 18-02-26'!$B:$B,MATCH(1,('Conteo 18-02-26'!$E:$E=$B22)*('Conteo 18-02-26'!$A:$A="Roosvelt"),0)),"")} | B22: =+B20+1 -> 5 | C22: {=+IFERROR(INDEX('Conteo 18-02-26'!$C:$C,MATCH(1,('Conteo 18-02-26'!$E:$E=$B22)*('Conteo 18-02-26'!$A:$A="Roosvelt"),0)),"")} | D22: {=+IFERROR(INDEX('Conteo 18-02-26'!$D:$D,MATCH(1,('Conteo 18-02-26'!$E:$E=$B22)*('Conteo 18-02-26'!A:A:'Conteo 18-02-26'!$A:$A="Roosvelt"),0)),"")} | E22: =+IF(E21="LK","CH",IF(D22="","",IF(D22>0,"LK","CH"))) | F22: =+IF(OR(E22="LK"),ROUNDUP(D22*(VLOOKUP(B22,'Conteo 18-02-26'!$E:$AN,35,0))/100,0),IF(E22="CH",D21-F21,""))
E23: =+IF(E22="LK","CH",IF(D23="","",IF(D23>0,"LK","CH"))) | F23: =+IF(OR(E23="LK"),ROUNDUP(D23*(VLOOKUP(B23,'Conteo 18-02-26'!$E:$AN,35,0))/100,0),IF(E23="CH",D22-F22,""))
A24: {=+IFERROR(INDEX('Conteo 18-02-26'!$B:$B,MATCH(1,('Conteo 18-02-26'!$E:$E=$B24)*('Conteo 18-02-26'!$A:$A="Roosvelt"),0)),"")} | B24: =+B22+1 -> 6 | C24: {=+IFERROR(INDEX('Conteo 18-02-26'!$C:$C,MATCH(1,('Conteo 18-02-26'!$E:$E=$B24)*('Conteo 18-02-26'!$A:$A="Roosvelt"),0)),"")} | D24: {=+IFERROR(INDEX('Conteo 18-02-26'!$D:$D,MATCH(1,('Conteo 18-02-26'!$E:$E=$B24)*('Conteo 18-02-26'!A:A:'Conteo 18-02-26'!$A:$A="Roosvelt"),0)),"")} | E24: =+IF(E23="LK","CH",IF(D24="","",IF(D24>0,"LK","CH"))) | F24: =+IF(OR(E24="LK"),ROUNDUP(D24*(VLOOKUP(B24,'Conteo 18-02-26'!$E:$AN,35,0))/100,0),IF(E24="CH",D23-F23,""))
E25: =+IF(E24="LK","CH",IF(D25="","",IF(D25>0,"LK","CH"))) | F25: =+IF(OR(E25="LK"),ROUNDUP(D25*(VLOOKUP(B25,'Conteo 18-02-26'!$E:$AN,35,0))/100,0),IF(E25="CH",D24-F24,""))
A26: {=+IFERROR(INDEX('Conteo 18-02-26'!$B:$B,MATCH(1,('Conteo 18-02-26'!$E:$E=$B26)*('Conteo 18-02-26'!$A:$A="Roosvelt"),0)),"")} | B26: =+B24+1 -> 7 | C26: {=+IFERROR(INDEX('Conteo 18-02-26'!$C:$C,MATCH(1,('Conteo 18-02-26'!$E:$E=$B26)*('Conteo 18-02-26'!$A:$A="Roosvelt"),0)),"")} | D26: {=+IFERROR(INDEX('Conteo 18-02-26'!$D:$D,MATCH(1,('Conteo 18-02-26'!$E:$E=$B26)*('Conteo 18-02-26'!A:A:'Conteo 18-02-26'!$A:$A="Roosvelt"),0)),"")} | E26: =+IF(E25="LK","CH",IF(D26="","",IF(D26>0,"LK","CH"))) | F26: =+IF(OR(E26="LK"),ROUNDUP(D26*(VLOOKUP(B26,'Conteo 18-02-26'!$E:$AN,35,0))/100,0),IF(E26="CH",D25-F25,""))
E27: =+IF(E26="LK","CH",IF(D27="","",IF(D27>0,"LK","CH"))) | F27: =+IF(OR(E27="LK"),ROUNDUP(D27*(VLOOKUP(B27,'Conteo 18-02-26'!$E:$AN,35,0))/100,0),IF(E27="CH",D26-F26,""))
A28: {=+IFERROR(INDEX('Conteo 18-02-26'!$B:$B,MATCH(1,('Conteo 18-02-26'!$E:$E=$B28)*('Conteo 18-02-26'!$A:$A="Roosvelt"),0)),"")} | B28: =+B26+1 -> 8 | C28: {=+IFERROR(INDEX('Conteo 18-02-26'!$C:$C,MATCH(1,('Conteo 18-02-26'!$E:$E=$B28)*('Conteo 18-02-26'!$A:$A="Roosvelt"),0)),"")} | D28: {=+IFERROR(INDEX('Conteo 18-02-26'!$D:$D,MATCH(1,('Conteo 18-02-26'!$E:$E=$B28)*('Conteo 18-02-26'!A:A:'Conteo 18-02-26'!$A:$A="Roosvelt"),0)),"")} | E28: =+IF(E27="LK","CH",IF(D28="","",IF(D28>0,"LK","CH"))) | F28: =+IF(OR(E28="LK"),ROUNDUP(D28*(VLOOKUP(B28,'Conteo 18-02-26'!$E:$AN,35,0))/100,0),IF(E28="CH",D27-F27,""))
E29: =+IF(E28="LK","CH",IF(D29="","",IF(D29>0,"LK","CH"))) | F29: =+IF(OR(E29="LK"),ROUNDUP(D29*(VLOOKUP(B29,'Conteo 18-02-26'!$E:$AN,35,0))/100,0),IF(E29="CH",D28-F28,""))
A30: {=+IFERROR(INDEX('Conteo 18-02-26'!$B:$B,MATCH(1,('Conteo 18-02-26'!$E:$E=$B30)*('Conteo 18-02-26'!$A:$A="Roosvelt"),0)),"")} | B30: =+B28+1 -> 9 | C30: {=+IFERROR(INDEX('Conteo 18-02-26'!$C:$C,MATCH(1,('Conteo 18-02-26'!$E:$E=$B30)*('Conteo 18-02-26'!$A:$A="Roosvelt"),0)),"")} | D30: {=+IFERROR(INDEX('Conteo 18-02-26'!$D:$D,MATCH(1,('Conteo 18-02-26'!$E:$E=$B30)*('Conteo 18-02-26'!A:A:'Conteo 18-02-26'!$A:$A="Roosvelt"),0)),"")} | E30: =+IF(E29="LK","CH",IF(D30="","",IF(D30>0,"LK","CH"))) | F30: =+IF(OR(E30="LK"),ROUNDUP(D30*(VLOOKUP(B30,'Conteo 18-02-26'!$E:$AN,35,0))/100,0),IF(E30="CH",D29-F29,""))
E31: =+IF(E30="LK","CH",IF(D31="","",IF(D31>0,"LK","CH"))) | F31: =+IF(OR(E31="LK"),ROUNDUP(D31*(VLOOKUP(B31,'Conteo 18-02-26'!$E:$AN,35,0))/100,0),IF(E31="CH",D30-F30,""))
A32: {=+IFERROR(INDEX('Conteo 18-02-26'!$B:$B,MATCH(1,('Conteo 18-02-26'!$E:$E=$B32)*('Conteo 18-02-26'!$A:$A="Roosvelt"),0)),"")} | B32: =+B30+1 -> 10 | C32: {=+IFERROR(INDEX('Conteo 18-02-26'!$C:$C,MATCH(1,('Conteo 18-02-26'!$E:$E=$B32)*('Conteo 18-02-26'!$A:$A="Roosvelt"),0)),"")} | D32: {=+IFERROR(INDEX('Conteo 18-02-26'!$D:$D,MATCH(1,('Conteo 18-02-26'!$E:$E=$B32)*('Conteo 18-02-26'!A:A:'Conteo 18-02-26'!$A:$A="Roosvelt"),0)),"")} | E32: =+IF(E31="LK","CH",IF(D32="","",IF(D32>0,"LK","CH"))) | F32: =+IF(OR(E32="LK"),ROUNDUP(D32*(VLOOKUP(B32,'Conteo 18-02-26'!$E:$AN,35,0))/100,0),IF(E32="CH",D31-F31,""))
E33: =+IF(E32="LK","CH",IF(D33="","",IF(D33>0,"LK","CH"))) | F33: =+IF(OR(E33="LK"),ROUNDUP(D33*(VLOOKUP(B33,'Conteo 18-02-26'!$E:$AN,35,0))/100,0),IF(E33="CH",D32-F32,""))
A34: {=+IFERROR(INDEX('Conteo 18-02-26'!$B:$B,MATCH(1,('Conteo 18-02-26'!$E:$E=$B34)*('Conteo 18-02-26'!$A:$A="Roosvelt"),0)),"")} | B34: =+B32+1 -> 11 | C34: {=+IFERROR(INDEX('Conteo 18-02-26'!$C:$C,MATCH(1,('Conteo 18-02-26'!$E:$E=$B34)*('Conteo 18-02-26'!$A:$A="Roosvelt"),0)),"")} | D34: {=+IFERROR(INDEX('Conteo 18-02-26'!$D:$D,MATCH(1,('Conteo 18-02-26'!$E:$E=$B34)*('Conteo 18-02-26'!A:A:'Conteo 18-02-26'!$A:$A="Roosvelt"),0)),"")} | E34: =+IF(E33="LK","CH",IF(D34="","",IF(D34>0,"LK","CH"))) | F34: =+IF(OR(E34="LK"),ROUNDUP(D34*(VLOOKUP(B34,'Conteo 18-02-26'!$E:$AN,35,0))/100,0),IF(E34="CH",D33-F33,""))
E35: =+IF(E34="LK","CH",IF(D35="","",IF(D35>0,"LK","CH"))) | F35: =+IF(OR(E35="LK"),ROUNDUP(D35*(VLOOKUP(B35,'Conteo 18-02-26'!$E:$AN,35,0))/100,0),IF(E35="CH",D34-F34,""))
A36: {=+IFERROR(INDEX('Conteo 18-02-26'!$B:$B,MATCH(1,('Conteo 18-02-26'!$E:$E=$B36)*('Conteo 18-02-26'!$A:$A="Roosvelt"),0)),"")} | B36: =+B34+1 -> 12 | C36: {=+IFERROR(INDEX('Conteo 18-02-26'!$C:$C,MATCH(1,('Conteo 18-02-26'!$E:$E=$B36)*('Conteo 18-02-26'!$A:$A="Roosvelt"),0)),"")} | D36: {=+IFERROR(INDEX('Conteo 18-02-26'!$D:$D,MATCH(1,('Conteo 18-02-26'!$E:$E=$B36)*('Conteo 18-02-26'!A:A:'Conteo 18-02-26'!$A:$A="Roosvelt"),0)),"")} | E36: =+IF(E35="LK","CH",IF(D36="","",IF(D36>0,"LK","CH"))) | F36: =+IF(OR(E36="LK"),ROUNDUP(D36*(VLOOKUP(B36,'Conteo 18-02-26'!$E:$AN,35,0))/100,0),IF(E36="CH",D35-F35,""))
E37: =+IF(E36="LK","CH",IF(D37="","",IF(D37>0,"LK","CH"))) | F37: =+IF(OR(E37="LK"),ROUNDUP(D37*(VLOOKUP(B37,'Conteo 18-02-26'!$E:$AN,35,0))/100,0),IF(E37="CH",D36-F36,""))
A38: {=+IFERROR(INDEX('Conteo 18-02-26'!$B:$B,MATCH(1,('Conteo 18-02-26'!$E:$E=$B38)*('Conteo 18-02-26'!$A:$A="Roosvelt"),0)),"")} | B38: =+B36+1 -> 13 | C38: {=+IFERROR(INDEX('Conteo 18-02-26'!$C:$C,MATCH(1,('Conteo 18-02-26'!$E:$E=$B38)*('Conteo 18-02-26'!$A:$A="Roosvelt"),0)),"")} | D38: {=+IFERROR(INDEX('Conteo 18-02-26'!$D:$D,MATCH(1,('Conteo 18-02-26'!$E:$E=$B38)*('Conteo 18-02-26'!A:A:'Conteo 18-02-26'!$A:$A="Roosvelt"),0)),"")} | E38: =+IF(E37="LK","CH",IF(D38="","",IF(D38>0,"LK","CH"))) | F38: =+IF(OR(E38="LK"),ROUNDUP(D38*(VLOOKUP(B38,'Conteo 18-02-26'!$E:$AN,35,0))/100,0),IF(E38="CH",D37-F37,""))
E39: =+IF(E38="LK","CH",IF(D39="","",IF(D39>0,"LK","CH"))) | F39: =+IF(OR(E39="LK"),ROUNDUP(D39*(VLOOKUP(B39,'Conteo 18-02-26'!$E:$AN,35,0))/100,0),IF(E39="CH",D38-F38,""))
A40: {=+IFERROR(INDEX('Conteo 18-02-26'!$B:$B,MATCH(1,('Conteo 18-02-26'!$E:$E=$B40)*('Conteo 18-02-26'!$A:$A="Roosvelt"),0)),"")} | B40: =+B38+1 -> 14 | C40: {=+IFERROR(INDEX('Conteo 18-02-26'!$C:$C,MATCH(1,('Conteo 18-02-26'!$E:$E=$B40)*('Conteo 18-02-26'!$A:$A="Roosvelt"),0)),"")} | D40: {=+IFERROR(INDEX('Conteo 18-02-26'!$D:$D,MATCH(1,('Conteo 18-02-26'!$E:$E=$B40)*('Conteo 18-02-26'!A:A:'Conteo 18-02-26'!$A:$A="Roosvelt"),0)),"")} | E40: =+IF(E39="LK","CH",IF(D40="","",IF(D40>0,"LK","CH"))) | F40: =+IF(OR(E40="LK"),ROUNDUP(D40*(VLOOKUP(B40,'Conteo 18-02-26'!$E:$AN,35,0))/100,0),IF(E40="CH",D39-F39,""))
E41: =+IF(E40="LK","CH",IF(D41="","",IF(D41>0,"LK","CH"))) | F41: =+IF(OR(E41="LK"),ROUNDUP(D41*(VLOOKUP(B41,'Conteo 18-02-26'!$E:$AN,35,0))/100,0),IF(E41="CH",D40-F40,""))
A42: {=+IFERROR(INDEX('Conteo 18-02-26'!$B:$B,MATCH(1,('Conteo 18-02-26'!$E:$E=$B42)*('Conteo 18-02-26'!$A:$A="Roosvelt"),0)),"")} | B42: =+B40+1 -> 15 | C42: {=+IFERROR(INDEX('Conteo 18-02-26'!$C:$C,MATCH(1,('Conteo 18-02-26'!$E:$E=$B42)*('Conteo 18-02-26'!$A:$A="Roosvelt"),0)),"")} | D42: {=+IFERROR(INDEX('Conteo 18-02-26'!$D:$D,MATCH(1,('Conteo 18-02-26'!$E:$E=$B42)*('Conteo 18-02-26'!A:A:'Conteo 18-02-26'!$A:$A="Roosvelt"),0)),"")} | E42: =+IF(E41="LK","CH",IF(D42="","",IF(D42>0,"LK","CH"))) | F42: =+IF(OR(E42="LK"),ROUNDUP(D42*(VLOOKUP(B42,'Conteo 18-02-26'!$E:$AN,35,0))/100,0),IF(E42="CH",D41-F41,""))
E43: =+IF(E42="LK","CH",IF(D43="","",IF(D43>0,"LK","CH"))) | F43: =+IF(OR(E43="LK"),ROUNDUP(D43*(VLOOKUP(B43,'Conteo 18-02-26'!$E:$AN,35,0))/100,0),IF(E43="CH",D42-F42,""))

Sheet O.C. Resortes Charcas
A1: Loekemeyer Hnos. S.R.L | F1: Chef SRL
A2: CUIT: | C2: 30-51584245-0 | F2: CUIT: | H2: 30-68575625-7
A3: DIRECCION: | C3: Cervantes 2868 | F3: DIRECCION: | H3: Virgilio 2788
A4: LOCALIDAD: | C4: Villa Devoto, CABA | F4: LOCALIDAD: | H4: Villa Real, CABA
A6: ORDEN DE COMPRA | F6: FECHA PEDIDO: | I6: =+TODAY() -> 46099
A8: RAZON SOCIAL: | C8: BARDONESCHI HERNAN | D8: COD PROV: | E8: 3605 | F8: ENTREGA EN: | I8: Cervantes 2868
A10: FACTURAR Loekemeyer 70% Chef 30%
A12: ESTE PEDIDO ANULA CUALQUIER PEDIDO ANTERIOR
A13: Cód ISIS | B13: N° Ord | C13: Descripcion Material | D13: Pedido KG | E13: Emp | F13: KG a FC | G13: Fecha Pos Ent | H13: Fecha Ent | I13: Kg Ent | J13: Fecha Ent | K13: Kg Ent | L13: Fecha Ent | M13: Kg Ent
A14: {=+IFERROR(INDEX('Conteo 18-02-26'!$B:$B,MATCH(1,('Conteo 18-02-26'!$E:$E=$B14)*('Conteo 18-02-26'!$A:$A="Charcas"),0)),"")} -> 1111500 | B14: 1 | C14: {=+IFERROR(INDEX('Conteo 18-02-26'!$C:$C,MATCH(1,('Conteo 18-02-26'!$E:$E=$B14)*('Conteo 18-02-26'!$A:$A="Charcas"),0)),"")} -> Resorte p/ Bombilla Crudo | D14: {=+IFERROR(INDEX('Conteo 18-02-26'!$D:$D,MATCH(1,('Conteo 18-02-26'!$E:$E=$B14)*('Conteo 18-02-26'!A:A:'Conteo 18-02-26'!$A:$A="Charcas"),0)),"")} -> 20000 | E14: =+IF(E13="LK","CH",IF(D14="","",IF(D14>0,"LK","CH"))) -> LK | F14: =+IF(OR(E14="LK"),ROUNDUP(D14*(VLOOKUP(B14,'Conteo 18-02-26'!$E:$AN,35,0))/100,0),IF(E14="CH",D13-F13,"")) -> 14000
E15: =+IF(E14="LK","CH",IF(D15="","",IF(D15>0,"LK","CH"))) -> CH | F15: =+IF(OR(E15="LK"),ROUNDUP(D15*(VLOOKUP(B15,'Conteo 18-02-26'!$E:$AN,35,0))/100,0),IF(E15="CH",D14-F14,"")) -> 6000
A16: {=+IFERROR(INDEX('Conteo 18-02-26'!$B:$B,MATCH(1,('Conteo 18-02-26'!$E:$E=$B16)*('Conteo 18-02-26'!$A:$A="Charcas"),0)),"")} | B16: =+B14+1 -> 2 | C16: {=+IFERROR(INDEX('Conteo 18-02-26'!$C:$C,MATCH(1,('Conteo 18-02-26'!$E:$E=$B16)*('Conteo 18-02-26'!$A:$A="Charcas"),0)),"")} | D16: {=+IFERROR(INDEX('Conteo 18-02-26'!$D:$D,MATCH(1,('Conteo 18-02-26'!$E:$E=$B16)*('Conteo 18-02-26'!A:A:'Conteo 18-02-26'!$A:$A="Charcas"),0)),"")} | E16: =+IF(E15="LK","CH",IF(D16="","",IF(D16>0,"LK","CH"))) | F16: =+IF(OR(E16="LK"),ROUNDUP(D16*(VLOOKUP(B16,'Conteo 18-02-26'!$E:$AN,35,0))/100,0),IF(E16="CH",D15-F15,""))
E17: =+IF(E16="LK","CH",IF(D17="","",IF(D17>0,"LK","CH"))) | F17: =+IF(OR(E17="LK"),ROUNDUP(D17*(VLOOKUP(B17,'Conteo 18-02-26'!$E:$AN,35,0))/100,0),IF(E17="CH",D16-F16,""))
A18: {=+IFERROR(INDEX('Conteo 18-02-26'!$B:$B,MATCH(1,('Conteo 18-02-26'!$E:$E=$B18)*('Conteo 18-02-26'!$A:$A="Charcas"),0)),"")} | B18: =+B16+1 -> 3 | C18: {=+IFERROR(INDEX('Conteo 18-02-26'!$C:$C,MATCH(1,('Conteo 18-02-26'!$E:$E=$B18)*('Conteo 18-02-26'!$A:$A="Charcas"),0)),"")} | D18: {=+IFERROR(INDEX('Conteo 18-02-26'!$D:$D,MATCH(1,('Conteo 18-02-26'!$E:$E=$B18)*('Conteo 18-02-26'!A:A:'Conteo 18-02-26'!$A:$A="Charcas"),0)),"")} | E18: =+IF(E17="LK","CH",IF(D18="","",IF(D18>0,"LK","CH"))) | F18: =+IF(OR(E18="LK"),ROUNDUP(D18*(VLOOKUP(B18,'Conteo 18-02-26'!$E:$AN,35,0))/100,0),IF(E18="CH",D17-F17,""))
E19: =+IF(E18="LK","CH",IF(D19="","",IF(D19>0,"LK","CH"))) | F19: =+IF(OR(E19="LK"),ROUNDUP(D19*(VLOOKUP(B19,'Conteo 18-02-26'!$E:$AN,35,0))/100,0),IF(E19="CH",D18-F18,""))
A20: {=+IFERROR(INDEX('Conteo 18-02-26'!$B:$B,MATCH(1,('Conteo 18-02-26'!$E:$E=$B20)*('Conteo 18-02-26'!$A:$A="Charcas"),0)),"")} | B20: =+B18+1 -> 4 | C20: {=+IFERROR(INDEX('Conteo 18-02-26'!$C:$C,MATCH(1,('Conteo 18-02-26'!$E:$E=$B20)*('Conteo 18-02-26'!$A:$A="Charcas"),0)),"")} | D20: {=+IFERROR(INDEX('Conteo 18-02-26'!$D:$D,MATCH(1,('Conteo 18-02-26'!$E:$E=$B20)*('Conteo 18-02-26'!A:A:'Conteo 18-02-26'!$A:$A="Charcas"),0)),"")} | E20: =+IF(E19="LK","CH",IF(D20="","",IF(D20>0,"LK","CH"))) | F20: =+IF(OR(E20="LK"),ROUNDUP(D20*(VLOOKUP(B20,'Conteo 18-02-26'!$E:$AN,35,0))/100,0),IF(E20="CH",D19-F19,""))
E21: =+IF(E20="LK","CH",IF(D21="","",IF(D21>0,"LK","CH"))) | F21: =+IF(OR(E21="LK"),ROUNDUP(D21*(VLOOKUP(B21,'Conteo 18-02-26'!$E:$AN,35,0))/100,0),IF(E21="CH",D20-F20,""))
A22: {=+IFERROR(INDEX('Conteo 18-02-26'!$B:$B,MATCH(1,('Conteo 18-02-26'!$E:$E=$B22)*('Conteo 18-02-26'!$A:$A="Charcas"),0)),"")} | B22: =+B20+1 -> 5 | C22: {=+IFERROR(INDEX('Conteo 18-02-26'!$C:$C,MATCH(1,('Conteo 18-02-26'!$E:$E=$B22)*('Conteo 18-02-26'!$A:$A="Charcas"),0)),"")} | D22: {=+IFERROR(INDEX('Conteo 18-02-26'!$D:$D,MATCH(1,('Conteo 18-02-26'!$E:$E=$B22)*('Conteo 18-02-26'!A:A:'Conteo 18-02-26'!$A:$A="Charcas"),0)),"")} | E22: =+IF(E21="LK","CH",IF(D22="","",IF(D22>0,"LK","CH"))) | F22: =+IF(OR(E22="LK"),ROUNDUP(D22*(VLOOKUP(B22,'Conteo 18-02-26'!$E:$AN,35,0))/100,0),IF(E22="CH",D21-F21,""))
E23: =+IF(E22="LK","CH",IF(D23="","",IF(D23>0,"LK","CH"))) | F23: =+IF(OR(E23="LK"),ROUNDUP(D23*(VLOOKUP(B23,'Conteo 18-02-26'!$E:$AN,35,0))/100,0),IF(E23="CH",D22-F22,""))
A24: {=+IFERROR(INDEX('Conteo 18-02-26'!$B:$B,MATCH(1,('Conteo 18-02-26'!$E:$E=$B24)*('Conteo 18-02-26'!$A:$A="Charcas"),0)),"")} | B24: =+B22+1 -> 6 | C24: {=+IFERROR(INDEX('Conteo 18-02-26'!$C:$C,MATCH(1,('Conteo 18-02-26'!$E:$E=$B24)*('Conteo 18-02-26'!$A:$A="Charcas"),0)),"")} | D24: {=+IFERROR(INDEX('Conteo 18-02-26'!$D:$D,MATCH(1,('Conteo 18-02-26'!$E:$E=$B24)*('Conteo 18-02-26'!A:A:'Conteo 18-02-26'!$A:$A="Charcas"),0)),"")} | E24: =+IF(E23="LK","CH",IF(D24="","",IF(D24>0,"LK","CH"))) | F24: =+IF(OR(E24="LK"),ROUNDUP(D24*(VLOOKUP(B24,'Conteo 18-02-26'!$E:$AN,35,0))/100,0),IF(E24="CH",D23-F23,""))
E25: =+IF(E24="LK","CH",IF(D25="","",IF(D25>0,"LK","CH"))) | F25: =+IF(OR(E25="LK"),ROUNDUP(D25*(VLOOKUP(B25,'Conteo 18-02-26'!$E:$AN,35,0))/100,0),IF(E25="CH",D24-F24,""))
A26: {=+IFERROR(INDEX('Conteo 18-02-26'!$B:$B,MATCH(1,('Conteo 18-02-26'!$E:$E=$B26)*('Conteo 18-02-26'!$A:$A="Charcas"),0)),"")} | B26: =+B24+1 -> 7 | C26: {=+IFERROR(INDEX('Conteo 18-02-26'!$C:$C,MATCH(1,('Conteo 18-02-26'!$E:$E=$B26)*('Conteo 18-02-26'!$A:$A="Charcas"),0)),"")} | D26: {=+IFERROR(INDEX('Conteo 18-02-26'!$D:$D,MATCH(1,('Conteo 18-02-26'!$E:$E=$B26)*('Conteo 18-02-26'!A:A:'Conteo 18-02-26'!$A:$A="Charcas"),0)),"")} | E26: =+IF(E25="LK","CH",IF(D26="","",IF(D26>0,"LK","CH"))) | F26: =+IF(OR(E26="LK"),ROUNDUP(D26*(VLOOKUP(B26,'Conteo 18-02-26'!$E:$AN,35,0))/100,0),IF(E26="CH",D25-F25,""))
E27: =+IF(E26="LK","CH",IF(D27="","",IF(D27>0,"LK","CH"))) | F27: =+IF(OR(E27="LK"),ROUNDUP(D27*(VLOOKUP(B27,'Conteo 18-02-26'!$E:$AN,35,0))/100,0),IF(E27="CH",D26-F26,""))
A28: {=+IFERROR(INDEX('Conteo 18-02-26'!$B:$B,MATCH(1,('Conteo 18-02-26'!$E:$E=$B28)*('Conteo 18-02-26'!$A:$A="Charcas"),0)),"")} | B28: =+B26+1 -> 8 | C28: {=+IFERROR(INDEX('Conteo 18-02-26'!$C:$C,MATCH(1,('Conteo 18-02-26'!$E:$E=$B28)*('Conteo 18-02-26'!$A:$A="Charcas"),0)),"")} | D28: {=+IFERROR(INDEX('Conteo 18-02-26'!$D:$D,MATCH(1,('Conteo 18-02-26'!$E:$E=$B28)*('Conteo 18-02-26'!A:A:'Conteo 18-02-26'!$A:$A="Charcas"),0)),"")} | E28: =+IF(E27="LK","CH",IF(D28="","",IF(D28>0,"LK","CH"))) | F28: =+IF(OR(E28="LK"),ROUNDUP(D28*(VLOOKUP(B28,'Conteo 18-02-26'!$E:$AN,35,0))/100,0),IF(E28="CH",D27-F27,""))
E29: =+IF(E28="LK","CH",IF(D29="","",IF(D29>0,"LK","CH"))) | F29: =+IF(OR(E29="LK"),ROUNDUP(D29*(VLOOKUP(B29,'Conteo 18-02-26'!$E:$AN,35,0))/100,0),IF(E29="CH",D28-F28,""))
A30: {=+IFERROR(INDEX('Conteo 18-02-26'!$B:$B,MATCH(1,('Conteo 18-02-26'!$E:$E=$B30)*('Conteo 18-02-26'!$A:$A="Charcas"),0)),"")} | B30: =+B28+1 -> 9 | C30: {=+IFERROR(INDEX('Conteo 18-02-26'!$C:$C,MATCH(1,('Conteo 18-02-26'!$E:$E=$B30)*('Conteo 18-02-26'!$A:$A="Charcas"),0)),"")} | D30: {=+IFERROR(INDEX('Conteo 18-02-26'!$D:$D,MATCH(1,('Conteo 18-02-26'!$E:$E=$B30)*('Conteo 18-02-26'!A:A:'Conteo 18-02-26'!$A:$A="Charcas"),0)),"")} | E30: =+IF(E29="LK","CH",IF(D30="","",IF(D30>0,"LK","CH"))) | F30: =+IF(OR(E30="LK"),ROUNDUP(D30*(VLOOKUP(B30,'Conteo 18-02-26'!$E:$AN,35,0))/100,0),IF(E30="CH",D29-F29,""))
E31: =+IF(E30="LK","CH",IF(D31="","",IF(D31>0,"LK","CH"))) | F31: =+IF(OR(E31="LK"),ROUNDUP(D31*(VLOOKUP(B31,'Conteo 18-02-26'!$E:$AN,35,0))/100,0),IF(E31="CH",D30-F30,""))
A32: {=+IFERROR(INDEX('Conteo 18-02-26'!$B:$B,MATCH(1,('Conteo 18-02-26'!$E:$E=$B32)*('Conteo 18-02-26'!$A:$A="Charcas"),0)),"")} | B32: =+B30+1 -> 10 | C32: {=+IFERROR(INDEX('Conteo 18-02-26'!$C:$C,MATCH(1,('Conteo 18-02-26'!$E:$E=$B32)*('Conteo 18-02-26'!$A:$A="Charcas"),0)),"")} | D32: {=+IFERROR(INDEX('Conteo 18-02-26'!$D:$D,MATCH(1,('Conteo 18-02-26'!$E:$E=$B32)*('Conteo 18-02-26'!A:A:'Conteo 18-02-26'!$A:$A="Charcas"),0)),"")} | E32: =+IF(E31="LK","CH",IF(D32="","",IF(D32>0,"LK","CH"))) | F32: =+IF(OR(E32="LK"),ROUNDUP(D32*(VLOOKUP(B32,'Conteo 18-02-26'!$E:$AN,35,0))/100,0),IF(E32="CH",D31-F31,""))
E33: =+IF(E32="LK","CH",IF(D33="","",IF(D33>0,"LK","CH"))) | F33: =+IF(OR(E33="LK"),ROUNDUP(D33*(VLOOKUP(B33,'Conteo 18-02-26'!$E:$AN,35,0))/100,0),IF(E33="CH",D32-F32,""))
A34: {=+IFERROR(INDEX('Conteo 18-02-26'!$B:$B,MATCH(1,('Conteo 18-02-26'!$E:$E=$B34)*('Conteo 18-02-26'!$A:$A="Charcas"),0)),"")} | B34: =+B32+1 -> 11 | C34: {=+IFERROR(INDEX('Conteo 18-02-26'!$C:$C,MATCH(1,('Conteo 18-02-26'!$E:$E=$B34)*('Conteo 18-02-26'!$A:$A="Charcas"),0)),"")} | D34: {=+IFERROR(INDEX('Conteo 18-02-26'!$D:$D,MATCH(1,('Conteo 18-02-26'!$E:$E=$B34)*('Conteo 18-02-26'!A:A:'Conteo 18-02-26'!$A:$A="Charcas"),0)),"")} | E34: =+IF(E33="LK","CH",IF(D34="","",IF(D34>0,"LK","CH"))) | F34: =+IF(OR(E34="LK"),ROUNDUP(D34*(VLOOKUP(B34,'Conteo 18-02-26'!$E:$AN,35,0))/100,0),IF(E34="CH",D33-F33,""))
E35: =+IF(E34="LK","CH",IF(D35="","",IF(D35>0,"LK","CH"))) | F35: =+IF(OR(E35="LK"),ROUNDUP(D35*(VLOOKUP(B35,'Conteo 18-02-26'!$E:$AN,35,0))/100,0),IF(E35="CH",D34-F34,""))
A36: {=+IFERROR(INDEX('Conteo 18-02-26'!$B:$B,MATCH(1,('Conteo 18-02-26'!$E:$E=$B36)*('Conteo 18-02-26'!$A:$A="Charcas"),0)),"")} | B36: =+B34+1 -> 12 | C36: {=+IFERROR(INDEX('Conteo 18-02-26'!$C:$C,MATCH(1,('Conteo 18-02-26'!$E:$E=$B36)*('Conteo 18-02-26'!$A:$A="Charcas"),0)),"")} | D36: {=+IFERROR(INDEX('Conteo 18-02-26'!$D:$D,MATCH(1,('Conteo 18-02-26'!$E:$E=$B36)*('Conteo 18-02-26'!A:A:'Conteo 18-02-26'!$A:$A="Charcas"),0)),"")} | E36: =+IF(E35="LK","CH",IF(D36="","",IF(D36>0,"LK","CH"))) | F36: =+IF(OR(E36="LK"),ROUNDUP(D36*(VLOOKUP(B36,'Conteo 18-02-26'!$E:$AN,35,0))/100,0),IF(E36="CH",D35-F35,""))
E37: =+IF(E36="LK","CH",IF(D37="","",IF(D37>0,"LK","CH"))) | F37: =+IF(OR(E37="LK"),ROUNDUP(D37*(VLOOKUP(B37,'Conteo 18-02-26'!$E:$AN,35,0))/100,0),IF(E37="CH",D36-F36,""))
A38: {=+IFERROR(INDEX('Conteo 18-02-26'!$B:$B,MATCH(1,('Conteo 18-02-26'!$E:$E=$B38)*('Conteo 18-02-26'!$A:$A="Charcas"),0)),"")} | B38: =+B36+1 -> 13 | C38: {=+IFERROR(INDEX('Conteo 18-02-26'!$C:$C,MATCH(1,('Conteo 18-02-26'!$E:$E=$B38)*('Conteo 18-02-26'!$A:$A="Charcas"),0)),"")} | D38: {=+IFERROR(INDEX('Conteo 18-02-26'!$D:$D,MATCH(1,('Conteo 18-02-26'!$E:$E=$B38)*('Conteo 18-02-26'!A:A:'Conteo 18-02-26'!$A:$A="Charcas"),0)),"")} | E38: =+IF(E37="LK","CH",IF(D38="","",IF(D38>0,"LK","CH"))) | F38: =+IF(OR(E38="LK"),ROUNDUP(D38*(VLOOKUP(B38,'Conteo 18-02-26'!$E:$AN,35,0))/100,0),IF(E38="CH",D37-F37,""))
E39: =+IF(E38="LK","CH",IF(D39="","",IF(D39>0,"LK","CH"))) | F39: =+IF(OR(E39="LK"),ROUNDUP(D39*(VLOOKUP(B39,'Conteo 18-02-26'!$E:$AN,35,0))/100,0),IF(E39="CH",D38-F38,""))
A40: {=+IFERROR(INDEX('Conteo 18-02-26'!$B:$B,MATCH(1,('Conteo 18-02-26'!$E:$E=$B40)*('Conteo 18-02-26'!$A:$A="Charcas"),0)),"")} | B40: =+B38+1 -> 14 | C40: {=+IFERROR(INDEX('Conteo 18-02-26'!$C:$C,MATCH(1,('Conteo 18-02-26'!$E:$E=$B40)*('Conteo 18-02-26'!$A:$A="Charcas"),0)),"")} | D40: {=+IFERROR(INDEX('Conteo 18-02-26'!$D:$D,MATCH(1,('Conteo 18-02-26'!$E:$E=$B40)*('Conteo 18-02-26'!A:A:'Conteo 18-02-26'!$A:$A="Charcas"),0)),"")} | E40: =+IF(E39="LK","CH",IF(D40="","",IF(D40>0,"LK","CH"))) | F40: =+IF(OR(E40="LK"),ROUNDUP(D40*(VLOOKUP(B40,'Conteo 18-02-26'!$E:$AN,35,0))/100,0),IF(E40="CH",D39-F39,""))
E41: =+IF(E40="LK","CH",IF(D41="","",IF(D41>0,"LK","CH"))) | F41: =+IF(OR(E41="LK"),ROUNDUP(D41*(VLOOKUP(B41,'Conteo 18-02-26'!$E:$AN,35,0))/100,0),IF(E41="CH",D40-F40,""))
A42: {=+IFERROR(INDEX('Conteo 18-02-26'!$B:$B,MATCH(1,('Conteo 18-02-26'!$E:$E=$B42)*('Conteo 18-02-26'!$A:$A="Charcas"),0)),"")} | B42: =+B40+1 -> 15 | C42: {=+IFERROR(INDEX('Conteo 18-02-26'!$C:$C,MATCH(1,('Conteo 18-02-26'!$E:$E=$B42)*('Conteo 18-02-26'!$A:$A="Charcas"),0)),"")} | D42: {=+IFERROR(INDEX('Conteo 18-02-26'!$D:$D,MATCH(1,('Conteo 18-02-26'!$E:$E=$B42)*('Conteo 18-02-26'!A:A:'Conteo 18-02-26'!$A:$A="Charcas"),0)),"")} | E42: =+IF(E41="LK","CH",IF(D42="","",IF(D42>0,"LK","CH"))) | F42: =+IF(OR(E42="LK"),ROUNDUP(D42*(VLOOKUP(B42,'Conteo 18-02-26'!$E:$AN,35,0))/100,0),IF(E42="CH",D41-F41,""))
E43: =+IF(E42="LK","CH",IF(D43="","",IF(D43>0,"LK","CH"))) | F43: =+IF(OR(E43="LK"),ROUNDUP(D43*(VLOOKUP(B43,'Conteo 18-02-26'!$E:$AN,35,0))/100,0),IF(E43="CH",D42-F42,""))

Sheet O.C. Colodis Kufo
A1: Loekemeyer Hnos. S.R.L | F1: Chef SRL
A2: CUIT: | C2: 30-51584245-0 | F2: CUIT: | H2: 30-68575625-7
A3: DIRECCION: | C3: Cervantes 2868 | F3: DIRECCION: | H3: Virgilio 2788
A4: LOCALIDAD: | C4: Villa Devoto, CABA | F4: LOCALIDAD: | H4: Villa Real, CABA
A6: ORDEN DE COMPRA | F6: FECHA PEDIDO: | I6: =+TODAY() -> 46099
A8: RAZON SOCIAL: | C8: ALIMENTOS Y BEBIDAS CONGRESO | D8: COD PROV: | E8: 4309 | F8: ENTREGA EN: | I8: Cervantes 2868
A10: FACTURAR Loekemeyer 70% Chef 30%
A12: ESTE PEDIDO ANULA CUALQUIER PEDIDO ANTERIOR
A13: Cód ISIS | B13: N° Ord | C13: Descripcion Material | D13: Pedido KG | E13: Emp | F13: KG a FC | G13: Fecha Pos Ent | H13: Fecha Ent | I13: Kg Ent | J13: Fecha Ent | K13: Kg Ent | L13: Fecha Ent | M13: Kg Ent
A14: {=+IFERROR(INDEX('Conteo 18-02-26'!$B:$B,MATCH(1,('Conteo 18-02-26'!$E:$E=$B14)*('Conteo 18-02-26'!$A:$A="Kufo"),0)),"")} | B14: 1 | C14: {=+IFERROR(INDEX('Conteo 18-02-26'!$C:$C,MATCH(1,('Conteo 18-02-26'!$E:$E=$B14)*('Conteo 18-02-26'!$A:$A="Kufo"),0)),"")} | D14: {=+IFERROR(INDEX('Conteo 18-02-26'!$D:$D,MATCH(1,('Conteo 18-02-26'!$E:$E=$B14)*('Conteo 18-02-26'!A:A:'Conteo 18-02-26'!$A:$A="Kufo"),0)),"")} | E14: =+IF(E13="LK","CH",IF(D14="","",IF(D14>0,"LK","CH"))) | F14: =+IF(OR(E14="LK"),ROUNDUP(D14*(VLOOKUP(B14,'Conteo 18-02-26'!$E:$AN,35,0))/100,0),IF(E14="CH",D13-F13,""))
E15: =+IF(E14="LK","CH",IF(D15="","",IF(D15>0,"LK","CH"))) | F15: =+IF(OR(E15="LK"),ROUNDUP(D15*(VLOOKUP(B15,'Conteo 18-02-26'!$E:$AN,35,0))/100,0),IF(E15="CH",D14-F14,""))
A16: {=+IFERROR(INDEX('Conteo 18-02-26'!$B:$B,MATCH(1,('Conteo 18-02-26'!$E:$E=$B16)*('Conteo 18-02-26'!$A:$A="Kufo"),0)),"")} | B16: =+B14+1 -> 2 | C16: {=+IFERROR(INDEX('Conteo 18-02-26'!$C:$C,MATCH(1,('Conteo 18-02-26'!$E:$E=$B16)*('Conteo 18-02-26'!$A:$A="Kufo"),0)),"")} | D16: {=+IFERROR(INDEX('Conteo 18-02-26'!$D:$D,MATCH(1,('Conteo 18-02-26'!$E:$E=$B16)*('Conteo 18-02-26'!A:A:'Conteo 18-02-26'!$A:$A="Kufo"),0)),"")} | E16: =+IF(E15="LK","CH",IF(D16="","",IF(D16>0,"LK","CH"))) | F16: =+IF(OR(E16="LK"),ROUNDUP(D16*(VLOOKUP(B16,'Conteo 18-02-26'!$E:$AN,35,0))/100,0),IF(E16="CH",D15-F15,""))
E17: =+IF(E16="LK","CH",IF(D17="","",IF(D17>0,"LK","CH"))) | F17: =+IF(OR(E17="LK"),ROUNDUP(D17*(VLOOKUP(B17,'Conteo 18-02-26'!$E:$AN,35,0))/100,0),IF(E17="CH",D16-F16,""))
A18: {=+IFERROR(INDEX('Conteo 18-02-26'!$B:$B,MATCH(1,('Conteo 18-02-26'!$E:$E=$B18)*('Conteo 18-02-26'!$A:$A="Kufo"),0)),"")} | B18: =+B16+1 -> 3 | C18: {=+IFERROR(INDEX('Conteo 18-02-26'!$C:$C,MATCH(1,('Conteo 18-02-26'!$E:$E=$B18)*('Conteo 18-02-26'!$A:$A="Kufo"),0)),"")} | D18: {=+IFERROR(INDEX('Conteo 18-02-26'!$D:$D,MATCH(1,('Conteo 18-02-26'!$E:$E=$B18)*('Conteo 18-02-26'!A:A:'Conteo 18-02-26'!$A:$A="Kufo"),0)),"")} | E18: =+IF(E17="LK","CH",IF(D18="","",IF(D18>0,"LK","CH"))) | F18: =+IF(OR(E18="LK"),ROUNDUP(D18*(VLOOKUP(B18,'Conteo 18-02-26'!$E:$AN,35,0))/100,0),IF(E18="CH",D17-F17,""))
E19: =+IF(E18="LK","CH",IF(D19="","",IF(D19>0,"LK","CH"))) | F19: =+IF(OR(E19="LK"),ROUNDUP(D19*(VLOOKUP(B19,'Conteo 18-02-26'!$E:$AN,35,0))/100,0),IF(E19="CH",D18-F18,""))
A20: {=+IFERROR(INDEX('Conteo 18-02-26'!$B:$B,MATCH(1,('Conteo 18-02-26'!$E:$E=$B20)*('Conteo 18-02-26'!$A:$A="Kufo"),0)),"")} | B20: =+B18+1 -> 4 | C20: {=+IFERROR(INDEX('Conteo 18-02-26'!$C:$C,MATCH(1,('Conteo 18-02-26'!$E:$E=$B20)*('Conteo 18-02-26'!$A:$A="Kufo"),0)),"")} | D20: {=+IFERROR(INDEX('Conteo 18-02-26'!$D:$D,MATCH(1,('Conteo 18-02-26'!$E:$E=$B20)*('Conteo 18-02-26'!A:A:'Conteo 18-02-26'!$A:$A="Kufo"),0)),"")} | E20: =+IF(E19="LK","CH",IF(D20="","",IF(D20>0,"LK","CH"))) | F20: =+IF(OR(E20="LK"),ROUNDUP(D20*(VLOOKUP(B20,'Conteo 18-02-26'!$E:$AN,35,0))/100,0),IF(E20="CH",D19-F19,""))
E21: =+IF(E20="LK","CH",IF(D21="","",IF(D21>0,"LK","CH"))) | F21: =+IF(OR(E21="LK"),ROUNDUP(D21*(VLOOKUP(B21,'Conteo 18-02-26'!$E:$AN,35,0))/100,0),IF(E21="CH",D20-F20,""))
A22: {=+IFERROR(INDEX('Conteo 18-02-26'!$B:$B,MATCH(1,('Conteo 18-02-26'!$E:$E=$B22)*('Conteo 18-02-26'!$A:$A="Kufo"),0)),"")} | B22: =+B20+1 -> 5 | C22: {=+IFERROR(INDEX('Conteo 18-02-26'!$C:$C,MATCH(1,('Conteo 18-02-26'!$E:$E=$B22)*('Conteo 18-02-26'!$A:$A="Kufo"),0)),"")} | D22: {=+IFERROR(INDEX('Conteo 18-02-26'!$D:$D,MATCH(1,('Conteo 18-02-26'!$E:$E=$B22)*('Conteo 18-02-26'!A:A:'Conteo 18-02-26'!$A:$A="Kufo"),0)),"")} | E22: =+IF(E21="LK","CH",IF(D22="","",IF(D22>0,"LK","CH"))) | F22: =+IF(OR(E22="LK"),ROUNDUP(D22*(VLOOKUP(B22,'Conteo 18-02-26'!$E:$AN,35,0))/100,0),IF(E22="CH",D21-F21,""))
E23: =+IF(E22="LK","CH",IF(D23="","",IF(D23>0,"LK","CH"))) | F23: =+IF(OR(E23="LK"),ROUNDUP(D23*(VLOOKUP(B23,'Conteo 18-02-26'!$E:$AN,35,0))/100,0),IF(E23="CH",D22-F22,""))
A24: {=+IFERROR(INDEX('Conteo 18-02-26'!$B:$B,MATCH(1,('Conteo 18-02-26'!$E:$E=$B24)*('Conteo 18-02-26'!$A:$A="Kufo"),0)),"")} | B24: =+B22+1 -> 6 | C24: {=+IFERROR(INDEX('Conteo 18-02-26'!$C:$C,MATCH(1,('Conteo 18-02-26'!$E:$E=$B24)*('Conteo 18-02-26'!$A:$A="Kufo"),0)),"")} | D24: {=+IFERROR(INDEX('Conteo 18-02-26'!$D:$D,MATCH(1,('Conteo 18-02-26'!$E:$E=$B24)*('Conteo 18-02-26'!A:A:'Conteo 18-02-26'!$A:$A="Kufo"),0)),"")} | E24: =+IF(E23="LK","CH",IF(D24="","",IF(D24>0,"LK","CH"))) | F24: =+IF(OR(E24="LK"),ROUNDUP(D24*(VLOOKUP(B24,'Conteo 18-02-26'!$E:$AN,35,0))/100,0),IF(E24="CH",D23-F23,""))
E25: =+IF(E24="LK","CH",IF(D25="","",IF(D25>0,"LK","CH"))) | F25: =+IF(OR(E25="LK"),ROUNDUP(D25*(VLOOKUP(B25,'Conteo 18-02-26'!$E:$AN,35,0))/100,0),IF(E25="CH",D24-F24,""))
A26: {=+IFERROR(INDEX('Conteo 18-02-26'!$B:$B,MATCH(1,('Conteo 18-02-26'!$E:$E=$B26)*('Conteo 18-02-26'!$A:$A="Kufo"),0)),"")} | B26: =+B24+1 -> 7 | C26: {=+IFERROR(INDEX('Conteo 18-02-26'!$C:$C,MATCH(1,('Conteo 18-02-26'!$E:$E=$B26)*('Conteo 18-02-26'!$A:$A="Kufo"),0)),"")} | D26: {=+IFERROR(INDEX('Conteo 18-02-26'!$D:$D,MATCH(1,('Conteo 18-02-26'!$E:$E=$B26)*('Conteo 18-02-26'!A:A:'Conteo 18-02-26'!$A:$A="Kufo"),0)),"")} | E26: =+IF(E25="LK","CH",IF(D26="","",IF(D26>0,"LK","CH"))) | F26: =+IF(OR(E26="LK"),ROUNDUP(D26*(VLOOKUP(B26,'Conteo 18-02-26'!$E:$AN,35,0))/100,0),IF(E26="CH",D25-F25,""))
E27: =+IF(E26="LK","CH",IF(D27="","",IF(D27>0,"LK","CH"))) | F27: =+IF(OR(E27="LK"),ROUNDUP(D27*(VLOOKUP(B27,'Conteo 18-02-26'!$E:$AN,35,0))/100,0),IF(E27="CH",D26-F26,""))
A28: {=+IFERROR(INDEX('Conteo 18-02-26'!$B:$B,MATCH(1,('Conteo 18-02-26'!$E:$E=$B28)*('Conteo 18-02-26'!$A:$A="Kufo"),0)),"")} | B28: =+B26+1 -> 8 | C28: {=+IFERROR(INDEX('Conteo 18-02-26'!$C:$C,MATCH(1,('Conteo 18-02-26'!$E:$E=$B28)*('Conteo 18-02-26'!$A:$A="Kufo"),0)),"")} | D28: {=+IFERROR(INDEX('Conteo 18-02-26'!$D:$D,MATCH(1,('Conteo 18-02-26'!$E:$E=$B28)*('Conteo 18-02-26'!A:A:'Conteo 18-02-26'!$A:$A="Kufo"),0)),"")} | E28: =+IF(E27="LK","CH",IF(D28="","",IF(D28>0,"LK","CH"))) | F28: =+IF(OR(E28="LK"),ROUNDUP(D28*(VLOOKUP(B28,'Conteo 18-02-26'!$E:$AN,35,0))/100,0),IF(E28="CH",D27-F27,""))
E29: =+IF(E28="LK","CH",IF(D29="","",IF(D29>0,"LK","CH"))) | F29: =+IF(OR(E29="LK"),ROUNDUP(D29*(VLOOKUP(B29,'Conteo 18-02-26'!$E:$AN,35,0))/100,0),IF(E29="CH",D28-F28,""))
A30: {=+IFERROR(INDEX('Conteo 18-02-26'!$B:$B,MATCH(1,('Conteo 18-02-26'!$E:$E=$B30)*('Conteo 18-02-26'!$A:$A="Kufo"),0)),"")} | B30: =+B28+1 -> 9 | C30: {=+IFERROR(INDEX('Conteo 18-02-26'!$C:$C,MATCH(1,('Conteo 18-02-26'!$E:$E=$B30)*('Conteo 18-02-26'!$A:$A="Kufo"),0)),"")} | D30: {=+IFERROR(INDEX('Conteo 18-02-26'!$D:$D,MATCH(1,('Conteo 18-02-26'!$E:$E=$B30)*('Conteo 18-02-26'!A:A:'Conteo 18-02-26'!$A:$A="Kufo"),0)),"")} | E30: =+IF(E29="LK","CH",IF(D30="","",IF(D30>0,"LK","CH"))) | F30: =+IF(OR(E30="LK"),ROUNDUP(D30*(VLOOKUP(B30,'Conteo 18-02-26'!$E:$AN,35,0))/100,0),IF(E30="CH",D29-F29,""))
E31: =+IF(E30="LK","CH",IF(D31="","",IF(D31>0,"LK","CH"))) | F31: =+IF(OR(E31="LK"),ROUNDUP(D31*(VLOOKUP(B31,'Conteo 18-02-26'!$E:$AN,35,0))/100,0),IF(E31="CH",D30-F30,""))
A32: {=+IFERROR(INDEX('Conteo 18-02-26'!$B:$B,MATCH(1,('Conteo 18-02-26'!$E:$E=$B32)*('Conteo 18-02-26'!$A:$A="Kufo"),0)),"")} | B32: =+B30+1 -> 10 | C32: {=+IFERROR(INDEX('Conteo 18-02-26'!$C:$C,MATCH(1,('Conteo 18-02-26'!$E:$E=$B32)*('Conteo 18-02-26'!$A:$A="Kufo"),0)),"")} | D32: {=+IFERROR(INDEX('Conteo 18-02-26'!$D:$D,MATCH(1,('Conteo 18-02-26'!$E:$E=$B32)*('Conteo 18-02-26'!A:A:'Conteo 18-02-26'!$A:$A="Kufo"),0)),"")} | E32: =+IF(E31="LK","CH",IF(D32="","",IF(D32>0,"LK","CH"))) | F32: =+IF(OR(E32="LK"),ROUNDUP(D32*(VLOOKUP(B32,'Conteo 18-02-26'!$E:$AN,35,0))/100,0),IF(E32="CH",D31-F31,""))
E33: =+IF(E32="LK","CH",IF(D33="","",IF(D33>0,"LK","CH"))) | F33: =+IF(OR(E33="LK"),ROUNDUP(D33*(VLOOKUP(B33,'Conteo 18-02-26'!$E:$AN,35,0))/100,0),IF(E33="CH",D32-F32,""))
A34: {=+IFERROR(INDEX('Conteo 18-02-26'!$B:$B,MATCH(1,('Conteo 18-02-26'!$E:$E=$B34)*('Conteo 18-02-26'!$A:$A="Kufo"),0)),"")} | B34: =+B32+1 -> 11 | C34: {=+IFERROR(INDEX('Conteo 18-02-26'!$C:$C,MATCH(1,('Conteo 18-02-26'!$E:$E=$B34)*('Conteo 18-02-26'!$A:$A="Kufo"),0)),"")} | D34: {=+IFERROR(INDEX('Conteo 18-02-26'!$D:$D,MATCH(1,('Conteo 18-02-26'!$E:$E=$B34)*('Conteo 18-02-26'!A:A:'Conteo 18-02-26'!$A:$A="Kufo"),0)),"")} | E34: =+IF(E33="LK","CH",IF(D34="","",IF(D34>0,"LK","CH"))) | F34: =+IF(OR(E34="LK"),ROUNDUP(D34*(VLOOKUP(B34,'Conteo 18-02-26'!$E:$AN,35,0))/100,0),IF(E34="CH",D33-F33,""))
E35: =+IF(E34="LK","CH",IF(D35="","",IF(D35>0,"LK","CH"))) | F35: =+IF(OR(E35="LK"),ROUNDUP(D35*(VLOOKUP(B35,'Conteo 18-02-26'!$E:$AN,35,0))/100,0),IF(E35="CH",D34-F34,""))
A36: {=+IFERROR(INDEX('Conteo 18-02-26'!$B:$B,MATCH(1,('Conteo 18-02-26'!$E:$E=$B36)*('Conteo 18-02-26'!$A:$A="Kufo"),0)),"")} | B36: =+B34+1 -> 12 | C36: {=+IFERROR(INDEX('Conteo 18-02-26'!$C:$C,MATCH(1,('Conteo 18-02-26'!$E:$E=$B36)*('Conteo 18-02-26'!$A:$A="Kufo"),0)),"")} | D36: {=+IFERROR(INDEX('Conteo 18-02-26'!$D:$D,MATCH(1,('Conteo 18-02-26'!$E:$E=$B36)*('Conteo 18-02-26'!A:A:'Conteo 18-02-26'!$A:$A="Kufo"),0)),"")} | E36: =+IF(E35="LK","CH",IF(D36="","",IF(D36>0,"LK","CH"))) | F36: =+IF(OR(E36="LK"),ROUNDUP(D36*(VLOOKUP(B36,'Conteo 18-02-26'!$E:$AN,35,0))/100,0),IF(E36="CH",D35-F35,""))
E37: =+IF(E36="LK","CH",IF(D37="","",IF(D37>0,"LK","CH"))) | F37: =+IF(OR(E37="LK"),ROUNDUP(D37*(VLOOKUP(B37,'Conteo 18-02-26'!$E:$AN,35,0))/100,0),IF(E37="CH",D36-F36,""))
A38: {=+IFERROR(INDEX('Conteo 18-02-26'!$B:$B,MATCH(1,('Conteo 18-02-26'!$E:$E=$B38)*('Conteo 18-02-26'!$A:$A="Kufo"),0)),"")} | B38: =+B36+1 -> 13 | C38: {=+IFERROR(INDEX('Conteo 18-02-26'!$C:$C,MATCH(1,('Conteo 18-02-26'!$E:$E=$B38)*('Conteo 18-02-26'!$A:$A="Kufo"),0)),"")} | D38: {=+IFERROR(INDEX('Conteo 18-02-26'!$D:$D,MATCH(1,('Conteo 18-02-26'!$E:$E=$B38)*('Conteo 18-02-26'!A:A:'Conteo 18-02-26'!$A:$A="Kufo"),0)),"")} | E38: =+IF(E37="LK","CH",IF(D38="","",IF(D38>0,"LK","CH"))) | F38: =+IF(OR(E38="LK"),ROUNDUP(D38*(VLOOKUP(B38,'Conteo 18-02-26'!$E:$AN,35,0))/100,0),IF(E38="CH",D37-F37,""))
E39: =+IF(E38="LK","CH",IF(D39="","",IF(D39>0,"LK","CH"))) | F39: =+IF(OR(E39="LK"),ROUNDUP(D39*(VLOOKUP(B39,'Conteo 18-02-26'!$E:$AN,35,0))/100,0),IF(E39="CH",D38-F38,""))
A40: {=+IFERROR(INDEX('Conteo 18-02-26'!$B:$B,MATCH(1,('Conteo 18-02-26'!$E:$E=$B40)*('Conteo 18-02-26'!$A:$A="Kufo"),0)),"")} | B40: =+B38+1 -> 14 | C40: {=+IFERROR(INDEX('Conteo 18-02-26'!$C:$C,MATCH(1,('Conteo 18-02-26'!$E:$E=$B40)*('Conteo 18-02-26'!$A:$A="Kufo"),0)),"")} | D40: {=+IFERROR(INDEX('Conteo 18-02-26'!$D:$D,MATCH(1,('Conteo 18-02-26'!$E:$E=$B40)*('Conteo 18-02-26'!A:A:'Conteo 18-02-26'!$A:$A="Kufo"),0)),"")} | E40: =+IF(E39="LK","CH",IF(D40="","",IF(D40>0,"LK","CH"))) | F40: =+IF(OR(E40="LK"),ROUNDUP(D40*(VLOOKUP(B40,'Conteo 18-02-26'!$E:$AN,35,0))/100,0),IF(E40="CH",D39-F39,""))
E41: =+IF(E40="LK","CH",IF(D41="","",IF(D41>0,"LK","CH"))) | F41: =+IF(OR(E41="LK"),ROUNDUP(D41*(VLOOKUP(B41,'Conteo 18-02-26'!$E:$AN,35,0))/100,0),IF(E41="CH",D40-F40,""))
A42: {=+IFERROR(INDEX('Conteo 18-02-26'!$B:$B,MATCH(1,('Conteo 18-02-26'!$E:$E=$B42)*('Conteo 18-02-26'!$A:$A="Kufo"),0)),"")} | B42: =+B40+1 -> 15 | C42: {=+IFERROR(INDEX('Conteo 18-02-26'!$C:$C,MATCH(1,('Conteo 18-02-26'!$E:$E=$B42)*('Conteo 18-02-26'!$A:$A="Kufo"),0)),"")} | D42: {=+IFERROR(INDEX('Conteo 18-02-26'!$D:$D,MATCH(1,('Conteo 18-02-26'!$E:$E=$B42)*('Conteo 18-02-26'!A:A:'Conteo 18-02-26'!$A:$A="Kufo"),0)),"")} | E42: =+IF(E41="LK","CH",IF(D42="","",IF(D42>0,"LK","CH"))) | F42: =+IF(OR(E42="LK"),ROUNDUP(D42*(VLOOKUP(B42,'Conteo 18-02-26'!$E:$AN,35,0))/100,0),IF(E42="CH",D41-F41,""))
E43: =+IF(E42="LK","CH",IF(D43="","",IF(D43>0,"LK","CH"))) | F43: =+IF(OR(E43="LK"),ROUNDUP(D43*(VLOOKUP(B43,'Conteo 18-02-26'!$E:$AN,35,0))/100,0),IF(E43="CH",D42-F42,""))

Sheet O.C. Melinox
A1: Loekemeyer Hnos. S.R.L | F1: Chef SRL
A2: CUIT: | C2: 30-51584245-0 | F2: CUIT: | H2: 30-68575625-7
A3: DIRECCION: | C3: Cervantes 2868 | F3: DIRECCION: | H3: Virgilio 2788
A4: LOCALIDAD: | C4: Villa Devoto, CABA | F4: LOCALIDAD: | H4: Villa Real, CABA
A6: ORDEN DE COMPRA | F6: FECHA PEDIDO: | I6: =+TODAY() -> 46099
A8: RAZON SOCIAL: | C8: ADOLFO GONZALEZ | D8: COD PROV: | E8: 2593 | F8: ENTREGA EN: | I8: Cervantes 2868
A10: FACTURAR Loekemeyer 70% Chef 30%
A12: ESTE PEDIDO ANULA CUALQUIER PEDIDO ANTERIOR
A13: Cód ISIS | B13: N° Ord | C13: Descripcion Material | D13: Pedido KG | E13: Emp | F13: KG a FC | G13: Fecha Pos Ent | H13: Fecha Ent | I13: Kg Ent | J13: Fecha Ent | K13: Kg Ent | L13: Fecha Ent | M13: Kg Ent
A14: {=+IFERROR(INDEX('Conteo 18-02-26'!$B:$B,MATCH(1,('Conteo 18-02-26'!$E:$E=$B14)*('Conteo 18-02-26'!$A:$A="Melinox"),0)),"")} | B14: 1 | C14: {=+IFERROR(INDEX('Conteo 18-02-26'!$C:$C,MATCH(1,('Conteo 18-02-26'!$E:$E=$B14)*('Conteo 18-02-26'!$A:$A="Melinox"),0)),"")} | D14: {=+IFERROR(INDEX('Conteo 18-02-26'!$D:$D,MATCH(1,('Conteo 18-02-26'!$E:$E=$B14)*('Conteo 18-02-26'!A:A:'Conteo 18-02-26'!$A:$A="Melinox"),0)),"")} | E14: =+IF(E13="LK","CH",IF(D14="","",IF(D14>0,"LK","CH"))) | F14: =+IF(OR(E14="LK"),ROUNDUP(D14*(VLOOKUP(B14,'Conteo 18-02-26'!$E:$AN,35,0))/100,0),IF(E14="CH",D13-F13,""))
E15: =+IF(E14="LK","CH",IF(D15="","",IF(D15>0,"LK","CH"))) | F15: =+IF(OR(E15="LK"),ROUNDUP(D15*(VLOOKUP(B15,'Conteo 18-02-26'!$E:$AN,35,0))/100,0),IF(E15="CH",D14-F14,""))
A16: {=+IFERROR(INDEX('Conteo 18-02-26'!$B:$B,MATCH(1,('Conteo 18-02-26'!$E:$E=$B16)*('Conteo 18-02-26'!$A:$A="Melinox"),0)),"")} | B16: =+B14+1 -> 2 | C16: {=+IFERROR(INDEX('Conteo 18-02-26'!$C:$C,MATCH(1,('Conteo 18-02-26'!$E:$E=$B16)*('Conteo 18-02-26'!$A:$A="Melinox"),0)),"")} | D16: {=+IFERROR(INDEX('Conteo 18-02-26'!$D:$D,MATCH(1,('Conteo 18-02-26'!$E:$E=$B16)*('Conteo 18-02-26'!A:A:'Conteo 18-02-26'!$A:$A="Melinox"),0)),"")} | E16: =+IF(E15="LK","CH",IF(D16="","",IF(D16>0,"LK","CH"))) | F16: =+IF(OR(E16="LK"),ROUNDUP(D16*(VLOOKUP(B16,'Conteo 18-02-26'!$E:$AN,35,0))/100,0),IF(E16="CH",D15-F15,""))
E17: =+IF(E16="LK","CH",IF(D17="","",IF(D17>0,"LK","CH"))) | F17: =+IF(OR(E17="LK"),ROUNDUP(D17*(VLOOKUP(B17,'Conteo 18-02-26'!$E:$AN,35,0))/100,0),IF(E17="CH",D16-F16,""))
A18: {=+IFERROR(INDEX('Conteo 18-02-26'!$B:$B,MATCH(1,('Conteo 18-02-26'!$E:$E=$B18)*('Conteo 18-02-26'!$A:$A="Melinox"),0)),"")} | B18: =+B16+1 -> 3 | C18: {=+IFERROR(INDEX('Conteo 18-02-26'!$C:$C,MATCH(1,('Conteo 18-02-26'!$E:$E=$B18)*('Conteo 18-02-26'!$A:$A="Melinox"),0)),"")} | D18: {=+IFERROR(INDEX('Conteo 18-02-26'!$D:$D,MATCH(1,('Conteo 18-02-26'!$E:$E=$B18)*('Conteo 18-02-26'!A:A:'Conteo 18-02-26'!$A:$A="Melinox"),0)),"")} | E18: =+IF(E17="LK","CH",IF(D18="","",IF(D18>0,"LK","CH"))) | F18: =+IF(OR(E18="LK"),ROUNDUP(D18*(VLOOKUP(B18,'Conteo 18-02-26'!$E:$AN,35,0))/100,0),IF(E18="CH",D17-F17,""))
E19: =+IF(E18="LK","CH",IF(D19="","",IF(D19>0,"LK","CH"))) | F19: =+IF(OR(E19="LK"),ROUNDUP(D19*(VLOOKUP(B19,'Conteo 18-02-26'!$E:$AN,35,0))/100,0),IF(E19="CH",D18-F18,""))
A20: {=+IFERROR(INDEX('Conteo 18-02-26'!$B:$B,MATCH(1,('Conteo 18-02-26'!$E:$E=$B20)*('Conteo 18-02-26'!$A:$A="Melinox"),0)),"")} | B20: =+B18+1 -> 4 | C20: {=+IFERROR(INDEX('Conteo 18-02-26'!$C:$C,MATCH(1,('Conteo 18-02-26'!$E:$E=$B20)*('Conteo 18-02-26'!$A:$A="Melinox"),0)),"")} | D20: {=+IFERROR(INDEX('Conteo 18-02-26'!$D:$D,MATCH(1,('Conteo 18-02-26'!$E:$E=$B20)*('Conteo 18-02-26'!A:A:'Conteo 18-02-26'!$A:$A="Melinox"),0)),"")} | E20: =+IF(E19="LK","CH",IF(D20="","",IF(D20>0,"LK","CH"))) | F20: =+IF(OR(E20="LK"),ROUNDUP(D20*(VLOOKUP(B20,'Conteo 18-02-26'!$E:$AN,35,0))/100,0),IF(E20="CH",D19-F19,""))
E21: =+IF(E20="LK","CH",IF(D21="","",IF(D21>0,"LK","CH"))) | F21: =+IF(OR(E21="LK"),ROUNDUP(D21*(VLOOKUP(B21,'Conteo 18-02-26'!$E:$AN,35,0))/100,0),IF(E21="CH",D20-F20,""))
A22: {=+IFERROR(INDEX('Conteo 18-02-26'!$B:$B,MATCH(1,('Conteo 18-02-26'!$E:$E=$B22)*('Conteo 18-02-26'!$A:$A="Melinox"),0)),"")} | B22: =+B20+1 -> 5 | C22: {=+IFERROR(INDEX('Conteo 18-02-26'!$C:$C,MATCH(1,('Conteo 18-02-26'!$E:$E=$B22)*('Conteo 18-02-26'!$A:$A="Melinox"),0)),"")} | D22: {=+IFERROR(INDEX('Conteo 18-02-26'!$D:$D,MATCH(1,('Conteo 18-02-26'!$E:$E=$B22)*('Conteo 18-02-26'!A:A:'Conteo 18-02-26'!$A:$A="Melinox"),0)),"")} | E22: =+IF(E21="LK","CH",IF(D22="","",IF(D22>0,"LK","CH"))) | F22: =+IF(OR(E22="LK"),ROUNDUP(D22*(VLOOKUP(B22,'Conteo 18-02-26'!$E:$AN,35,0))/100,0),IF(E22="CH",D21-F21,""))
E23: =+IF(E22="LK","CH",IF(D23="","",IF(D23>0,"LK","CH"))) | F23: =+IF(OR(E23="LK"),ROUNDUP(D23*(VLOOKUP(B23,'Conteo 18-02-26'!$E:$AN,35,0))/100,0),IF(E23="CH",D22-F22,""))
A24: {=+IFERROR(INDEX('Conteo 18-02-26'!$B:$B,MATCH(1,('Conteo 18-02-26'!$E:$E=$B24)*('Conteo 18-02-26'!$A:$A="Melinox"),0)),"")} | B24: =+B22+1 -> 6 | C24: {=+IFERROR(INDEX('Conteo 18-02-26'!$C:$C,MATCH(1,('Conteo 18-02-26'!$E:$E=$B24)*('Conteo 18-02-26'!$A:$A="Melinox"),0)),"")} | D24: {=+IFERROR(INDEX('Conteo 18-02-26'!$D:$D,MATCH(1,('Conteo 18-02-26'!$E:$E=$B24)*('Conteo 18-02-26'!A:A:'Conteo 18-02-26'!$A:$A="Melinox"),0)),"")} | E24: =+IF(E23="LK","CH",IF(D24="","",IF(D24>0,"LK","CH"))) | F24: =+IF(OR(E24="LK"),ROUNDUP(D24*(VLOOKUP(B24,'Conteo 18-02-26'!$E:$AN,35,0))/100,0),IF(E24="CH",D23-F23,""))
E25: =+IF(E24="LK","CH",IF(D25="","",IF(D25>0,"LK","CH"))) | F25: =+IF(OR(E25="LK"),ROUNDUP(D25*(VLOOKUP(B25,'Conteo 18-02-26'!$E:$AN,35,0))/100,0),IF(E25="CH",D24-F24,""))
A26: {=+IFERROR(INDEX('Conteo 18-02-26'!$B:$B,MATCH(1,('Conteo 18-02-26'!$E:$E=$B26)*('Conteo 18-02-26'!$A:$A="Melinox"),0)),"")} | B26: =+B24+1 -> 7 | C26: {=+IFERROR(INDEX('Conteo 18-02-26'!$C:$C,MATCH(1,('Conteo 18-02-26'!$E:$E=$B26)*('Conteo 18-02-26'!$A:$A="Melinox"),0)),"")} | D26: {=+IFERROR(INDEX('Conteo 18-02-26'!$D:$D,MATCH(1,('Conteo 18-02-26'!$E:$E=$B26)*('Conteo 18-02-26'!A:A:'Conteo 18-02-26'!$A:$A="Melinox"),0)),"")} | E26: =+IF(E25="LK","CH",IF(D26="","",IF(D26>0,"LK","CH"))) | F26: =+IF(OR(E26="LK"),ROUNDUP(D26*(VLOOKUP(B26,'Conteo 18-02-26'!$E:$AN,35,0))/100,0),IF(E26="CH",D25-F25,""))
E27: =+IF(E26="LK","CH",IF(D27="","",IF(D27>0,"LK","CH"))) | F27: =+IF(OR(E27="LK"),ROUNDUP(D27*(VLOOKUP(B27,'Conteo 18-02-26'!$E:$AN,35,0))/100,0),IF(E27="CH",D26-F26,""))
A28: {=+IFERROR(INDEX('Conteo 18-02-26'!$B:$B,MATCH(1,('Conteo 18-02-26'!$E:$E=$B28)*('Conteo 18-02-26'!$A:$A="Melinox"),0)),"")} | B28: =+B26+1 -> 8 | C28: {=+IFERROR(INDEX('Conteo 18-02-26'!$C:$C,MATCH(1,('Conteo 18-02-26'!$E:$E=$B28)*('Conteo 18-02-26'!$A:$A="Melinox"),0)),"")} | D28: {=+IFERROR(INDEX('Conteo 18-02-26'!$D:$D,MATCH(1,('Conteo 18-02-26'!$E:$E=$B28)*('Conteo 18-02-26'!A:A:'Conteo 18-02-26'!$A:$A="Melinox"),0)),"")} | E28: =+IF(E27="LK","CH",IF(D28="","",IF(D28>0,"LK","CH"))) | F28: =+IF(OR(E28="LK"),ROUNDUP(D28*(VLOOKUP(B28,'Conteo 18-02-26'!$E:$AN,35,0))/100,0),IF(E28="CH",D27-F27,""))
E29: =+IF(E28="LK","CH",IF(D29="","",IF(D29>0,"LK","CH"))) | F29: =+IF(OR(E29="LK"),ROUNDUP(D29*(VLOOKUP(B29,'Conteo 18-02-26'!$E:$AN,35,0))/100,0),IF(E29="CH",D28-F28,""))
A30: {=+IFERROR(INDEX('Conteo 18-02-26'!$B:$B,MATCH(1,('Conteo 18-02-26'!$E:$E=$B30)*('Conteo 18-02-26'!$A:$A="Melinox"),0)),"")} | B30: =+B28+1 -> 9 | C30: {=+IFERROR(INDEX('Conteo 18-02-26'!$C:$C,MATCH(1,('Conteo 18-02-26'!$E:$E=$B30)*('Conteo 18-02-26'!$A:$A="Melinox"),0)),"")} | D30: {=+IFERROR(INDEX('Conteo 18-02-26'!$D:$D,MATCH(1,('Conteo 18-02-26'!$E:$E=$B30)*('Conteo 18-02-26'!A:A:'Conteo 18-02-26'!$A:$A="Melinox"),0)),"")} | E30: =+IF(E29="LK","CH",IF(D30="","",IF(D30>0,"LK","CH"))) | F30: =+IF(OR(E30="LK"),ROUNDUP(D30*(VLOOKUP(B30,'Conteo 18-02-26'!$E:$AN,35,0))/100,0),IF(E30="CH",D29-F29,""))
E31: =+IF(E30="LK","CH",IF(D31="","",IF(D31>0,"LK","CH"))) | F31: =+IF(OR(E31="LK"),ROUNDUP(D31*(VLOOKUP(B31,'Conteo 18-02-26'!$E:$AN,35,0))/100,0),IF(E31="CH",D30-F30,""))
A32: {=+IFERROR(INDEX('Conteo 18-02-26'!$B:$B,MATCH(1,('Conteo 18-02-26'!$E:$E=$B32)*('Conteo 18-02-26'!$A:$A="Melinox"),0)),"")} | B32: =+B30+1 -> 10 | C32: {=+IFERROR(INDEX('Conteo 18-02-26'!$C:$C,MATCH(1,('Conteo 18-02-26'!$E:$E=$B32)*('Conteo 18-02-26'!$A:$A="Melinox"),0)),"")} | D32: {=+IFERROR(INDEX('Conteo 18-02-26'!$D:$D,MATCH(1,('Conteo 18-02-26'!$E:$E=$B32)*('Conteo 18-02-26'!A:A:'Conteo 18-02-26'!$A:$A="Melinox"),0)),"")} | E32: =+IF(E31="LK","CH",IF(D32="","",IF(D32>0,"LK","CH"))) | F32: =+IF(OR(E32="LK"),ROUNDUP(D32*(VLOOKUP(B32,'Conteo 18-02-26'!$E:$AN,35,0))/100,0),IF(E32="CH",D31-F31,""))
E33: =+IF(E32="LK","CH",IF(D33="","",IF(D33>0,"LK","CH"))) | F33: =+IF(OR(E33="LK"),ROUNDUP(D33*(VLOOKUP(B33,'Conteo 18-02-26'!$E:$AN,35,0))/100,0),IF(E33="CH",D32-F32,""))
