Workbook

Sheet O.C. Corrugadora del Plata
A1: Loekemeyer Hnos. S.R.L | F1: Chef SRL
A2: CUIT: | C2: 30-51584245-0 | F2: CUIT: | H2: 30-68575625-7
A3: DIRECCION: | C3: Cervantes 2868 | F3: DIRECCION: | H3: Virgilio 2788
A4: LOCALIDAD: | C4: Villa Devoto, CABA | F4: LOCALIDAD: | H4: Villa Real, CABA
A6: ORDEN DE COMPRA | F6: FECHA PEDIDO: | I6: =+TODAY() -> 46099
A8: RAZON SOCIAL: | C8: CORRUGADORA DEL PLATA | D8: COD PROV: | E8: 69587 | F8: ENTREGA EN: | I8: Cervantes 2868
A10: FACTURAR Loekemeyer 70% Chef 30%
A12: ESTE PEDIDO ANULA CUALQUIER PEDIDO ANTERIOR
A13: Cód ISIS | B13: N° Ord | C13: N° Caja | D13: Pedido Uni | E13: Emp | F13: Uni a FC | G13: Fecha Pos Ent | H13: Fecha Ent | I13: Uni Ent | J13: Fecha Ent | K13: Uni Ent | L13: Fecha Ent | M13: Uni Ent
A14: {=+IFERROR(INDEX('Relevamiento 11-03'!$D:$D,MATCH(1,('Relevamiento 11-03'!$C:$C=$B14)*('Relevamiento 11-03'!$A:$A="Corrugadora"),0)),"")} -> 1104700 | B14: 1 | C14: {=+IFERROR(INDEX('Relevamiento 11-03'!$F:$F,MATCH(1,('Relevamiento 11-03'!$C:$C=$B14)*('Relevamiento 11-03'!$A:$A="Corrugadora"),0)),"")} -> 7 | D14: {=+IFERROR(INDEX('Relevamiento 11-03'!$G:$G,MATCH(1,('Relevamiento 11-03'!$C:$C=$B14)*('Relevamiento 11-03'!$A:$A="Corrugadora"),0)),"")} -> 1000 | E14: =+IF(E13="LK","CH",IF(D14="","",IF(D14>0,"LK","CH"))) -> LK | F14: =+IF(OR(E14="LK"),ROUNDUP(D14*(VLOOKUP(B14,'Relevamiento 11-03'!$C:$AE,29,0))/25,0)*25,IF(E14="CH",D13-F13,"")) -> 700
E15: =+IF(E14="LK","CH",IF(D15="","",IF(D15>0,"LK","CH"))) -> CH | F15: =+IF(OR(E15="LK"),ROUNDUP(D15*(VLOOKUP(B15,'Relevamiento 11-03'!$C:$AE,29,0))/25,0)*25,IF(E15="CH",D14-F14,"")) -> 300
A16: {=+IFERROR(INDEX('Relevamiento 11-03'!$D:$D,MATCH(1,('Relevamiento 11-03'!$C:$C=$B16)*('Relevamiento 11-03'!$A:$A="Corrugadora"),0)),"")} -> 1113700 | B16: =+B14+1 -> 2 | C16: {=+IFERROR(INDEX('Relevamiento 11-03'!$F:$F,MATCH(1,('Relevamiento 11-03'!$C:$C=$B16)*('Relevamiento 11-03'!$A:$A="Corrugadora"),0)),"")} -> 29 | D16: {=+IFERROR(INDEX('Relevamiento 11-03'!$G:$G,MATCH(1,('Relevamiento 11-03'!$C:$C=$B16)*('Relevamiento 11-03'!$A:$A="Corrugadora"),0)),"")} -> 15500 | E16: =+IF(E15="LK","CH",IF(D16="","",IF(D16>0,"LK","CH"))) -> LK | F16: =+IF(OR(E16="LK"),ROUNDUP(D16*(VLOOKUP(B16,'Relevamiento 11-03'!$C:$AE,29,0))/25,0)*25,IF(E16="CH",D15-F15,"")) -> 10850
E17: =+IF(E16="LK","CH",IF(D17="","",IF(D17>0,"LK","CH"))) -> CH | F17: =+IF(OR(E17="LK"),ROUNDUP(D17*(VLOOKUP(B17,'Relevamiento 11-03'!$C:$AE,29,0))/25,0)*25,IF(E17="CH",D16-F16,"")) -> 4650
A18: {=+IFERROR(INDEX('Relevamiento 11-03'!$D:$D,MATCH(1,('Relevamiento 11-03'!$C:$C=$B18)*('Relevamiento 11-03'!$A:$A="Corrugadora"),0)),"")} -> 1101700 | B18: =+B16+1 -> 3 | C18: {=+IFERROR(INDEX('Relevamiento 11-03'!$F:$F,MATCH(1,('Relevamiento 11-03'!$C:$C=$B18)*('Relevamiento 11-03'!$A:$A="Corrugadora"),0)),"")} -> 2 | D18: {=+IFERROR(INDEX('Relevamiento 11-03'!$G:$G,MATCH(1,('Relevamiento 11-03'!$C:$C=$B18)*('Relevamiento 11-03'!$A:$A="Corrugadora"),0)),"")} -> 7000 | E18: =+IF(E17="LK","CH",IF(D18="","",IF(D18>0,"LK","CH"))) -> LK | F18: =+IF(OR(E18="LK"),ROUNDUP(D18*(VLOOKUP(B18,'Relevamiento 11-03'!$C:$AE,29,0))/25,0)*25,IF(E18="CH",D17-F17,"")) -> 4900
E19: =+IF(E18="LK","CH",IF(D19="","",IF(D19>0,"LK","CH"))) -> CH | F19: =+IF(OR(E19="LK"),ROUNDUP(D19*(VLOOKUP(B19,'Relevamiento 11-03'!$C:$AE,29,0))/25,0)*25,IF(E19="CH",D18-F18,"")) -> 2100
A20: {=+IFERROR(INDEX('Relevamiento 11-03'!$D:$D,MATCH(1,('Relevamiento 11-03'!$C:$C=$B20)*('Relevamiento 11-03'!$A:$A="Corrugadora"),0)),"")} -> 1110700 | B20: =+B18+1 -> 4 | C20: {=+IFERROR(INDEX('Relevamiento 11-03'!$F:$F,MATCH(1,('Relevamiento 11-03'!$C:$C=$B20)*('Relevamiento 11-03'!$A:$A="Corrugadora"),0)),"")} -> 22 | D20: {=+IFERROR(INDEX('Relevamiento 11-03'!$G:$G,MATCH(1,('Relevamiento 11-03'!$C:$C=$B20)*('Relevamiento 11-03'!$A:$A="Corrugadora"),0)),"")} -> 10000 | E20: =+IF(E19="LK","CH",IF(D20="","",IF(D20>0,"LK","CH"))) -> LK | F20: =+IF(OR(E20="LK"),ROUNDUP(D20*(VLOOKUP(B20,'Relevamiento 11-03'!$C:$AE,29,0))/25,0)*25,IF(E20="CH",D19-F19,"")) -> 7000
E21: =+IF(E20="LK","CH",IF(D21="","",IF(D21>0,"LK","CH"))) -> CH | F21: =+IF(OR(E21="LK"),ROUNDUP(D21*(VLOOKUP(B21,'Relevamiento 11-03'!$C:$AE,29,0))/25,0)*25,IF(E21="CH",D20-F20,"")) -> 3000
A22: {=+IFERROR(INDEX('Relevamiento 11-03'!$D:$D,MATCH(1,('Relevamiento 11-03'!$C:$C=$B22)*('Relevamiento 11-03'!$A:$A="Corrugadora"),0)),"")} | B22: =+B20+1 -> 5 | C22: {=+IFERROR(INDEX('Relevamiento 11-03'!$F:$F,MATCH(1,('Relevamiento 11-03'!$C:$C=$B22)*('Relevamiento 11-03'!$A:$A="Corrugadora"),0)),"")} | D22: {=+IFERROR(INDEX('Relevamiento 11-03'!$G:$G,MATCH(1,('Relevamiento 11-03'!$C:$C=$B22)*('Relevamiento 11-03'!$A:$A="Corrugadora"),0)),"")} | E22: =+IF(E21="LK","CH",IF(D22="","",IF(D22>0,"LK","CH"))) | F22: =+IF(OR(E22="LK"),ROUNDUP(D22*(VLOOKUP(B22,'Relevamiento 11-03'!$C:$AE,29,0))/25,0)*25,IF(E22="CH",D21-F21,""))
E23: =+IF(E22="LK","CH",IF(D23="","",IF(D23>0,"LK","CH"))) | F23: =+IF(OR(E23="LK"),ROUNDUP(D23*(VLOOKUP(B23,'Relevamiento 11-03'!$C:$AE,29,0))/25,0)*25,IF(E23="CH",D22-F22,""))
A24: {=+IFERROR(INDEX('Relevamiento 11-03'!$D:$D,MATCH(1,('Relevamiento 11-03'!$C:$C=$B24)*('Relevamiento 11-03'!$A:$A="Corrugadora"),0)),"")} | B24: =+B22+1 -> 6 | C24: {=+IFERROR(INDEX('Relevamiento 11-03'!$F:$F,MATCH(1,('Relevamiento 11-03'!$C:$C=$B24)*('Relevamiento 11-03'!$A:$A="Corrugadora"),0)),"")} | D24: {=+IFERROR(INDEX('Relevamiento 11-03'!$G:$G,MATCH(1,('Relevamiento 11-03'!$C:$C=$B24)*('Relevamiento 11-03'!$A:$A="Corrugadora"),0)),"")} | E24: =+IF(E23="LK","CH",IF(D24="","",IF(D24>0,"LK","CH"))) | F24: =+IF(OR(E24="LK"),ROUNDUP(D24*(VLOOKUP(B24,'[1]Pedido VACIO'!$E$1:$AT$65536,42,0))/25,0)*25,IF(E24="CH",D23-F23,""))
E25: =+IF(E24="LK","CH",IF(D25="","",IF(D25>0,"LK","CH"))) | F25: =+IF(OR(E25="LK"),ROUNDUP(D25*(VLOOKUP(B25,'[1]Pedido VACIO'!$E$1:$AT$65536,42,0))/25,0)*25,IF(E25="CH",D24-F24,""))
A26: {=+IFERROR(INDEX('Relevamiento 11-03'!$D:$D,MATCH(1,('Relevamiento 11-03'!$C:$C=$B26)*('Relevamiento 11-03'!$A:$A="Corrugadora"),0)),"")} | B26: =+B24+1 -> 7 | C26: {=+IFERROR(INDEX('Relevamiento 11-03'!$F:$F,MATCH(1,('Relevamiento 11-03'!$C:$C=$B26)*('Relevamiento 11-03'!$A:$A="Corrugadora"),0)),"")} | D26: {=+IFERROR(INDEX('Relevamiento 11-03'!$G:$G,MATCH(1,('Relevamiento 11-03'!$C:$C=$B26)*('Relevamiento 11-03'!$A:$A="Corrugadora"),0)),"")} | E26: =+IF(E25="LK","CH",IF(D26="","",IF(D26>0,"LK","CH"))) | F26: =+IF(OR(E26="LK"),ROUNDUP(D26*(VLOOKUP(B26,'[1]Pedido VACIO'!$E$1:$AT$65536,42,0))/25,0)*25,IF(E26="CH",D25-F25,""))
E27: =+IF(E26="LK","CH",IF(D27="","",IF(D27>0,"LK","CH"))) | F27: =+IF(OR(E27="LK"),ROUNDUP(D27*(VLOOKUP(B27,'[1]Pedido VACIO'!$E$1:$AT$65536,42,0))/25,0)*25,IF(E27="CH",D26-F26,""))
A28: {=+IFERROR(INDEX('Relevamiento 11-03'!$D:$D,MATCH(1,('Relevamiento 11-03'!$C:$C=$B28)*('Relevamiento 11-03'!$A:$A="Corrugadora"),0)),"")} | B28: =+B26+1 -> 8 | C28: {=+IFERROR(INDEX('Relevamiento 11-03'!$F:$F,MATCH(1,('Relevamiento 11-03'!$C:$C=$B28)*('Relevamiento 11-03'!$A:$A="Corrugadora"),0)),"")} | D28: {=+IFERROR(INDEX('Relevamiento 11-03'!$G:$G,MATCH(1,('Relevamiento 11-03'!$C:$C=$B28)*('Relevamiento 11-03'!$A:$A="Corrugadora"),0)),"")} | E28: =+IF(E27="LK","CH",IF(D28="","",IF(D28>0,"LK","CH"))) | F28: =+IF(OR(E28="LK"),ROUNDUP(D28*(VLOOKUP(B28,'[1]Pedido VACIO'!$E$1:$AT$65536,42,0))/25,0)*25,IF(E28="CH",D27-F27,""))
E29: =+IF(E28="LK","CH",IF(D29="","",IF(D29>0,"LK","CH"))) | F29: =+IF(OR(E29="LK"),ROUNDUP(D29*(VLOOKUP(B29,'[1]Pedido VACIO'!$E$1:$AT$65536,42,0))/25,0)*25,IF(E29="CH",D28-F28,""))
A30: {=+IFERROR(INDEX('Relevamiento 11-03'!$D:$D,MATCH(1,('Relevamiento 11-03'!$C:$C=$B30)*('Relevamiento 11-03'!$A:$A="Corrugadora"),0)),"")} | B30: =+B28+1 -> 9 | C30: {=+IFERROR(INDEX('Relevamiento 11-03'!$F:$F,MATCH(1,('Relevamiento 11-03'!$C:$C=$B30)*('Relevamiento 11-03'!$A:$A="Corrugadora"),0)),"")} | D30: {=+IFERROR(INDEX('Relevamiento 11-03'!$G:$G,MATCH(1,('Relevamiento 11-03'!$C:$C=$B30)*('Relevamiento 11-03'!$A:$A="Corrugadora"),0)),"")} | E30: =+IF(E29="LK","CH",IF(D30="","",IF(D30>0,"LK","CH"))) | F30: =+IF(OR(E30="LK"),ROUNDUP(D30*(VLOOKUP(B30,'[1]Pedido VACIO'!$E$1:$AT$65536,42,0))/25,0)*25,IF(E30="CH",D29-F29,""))
E31: =+IF(E30="LK","CH",IF(D31="","",IF(D31>0,"LK","CH"))) | F31: =+IF(OR(E31="LK"),ROUNDUP(D31*(VLOOKUP(B31,'[1]Pedido VACIO'!$E$1:$AT$65536,42,0))/25,0)*25,IF(E31="CH",D30-F30,""))
A32: {=+IFERROR(INDEX('Relevamiento 11-03'!$D:$D,MATCH(1,('Relevamiento 11-03'!$C:$C=$B32)*('Relevamiento 11-03'!$A:$A="Corrugadora"),0)),"")} | B32: =+B30+1 -> 10 | C32: {=+IFERROR(INDEX('Relevamiento 11-03'!$F:$F,MATCH(1,('Relevamiento 11-03'!$C:$C=$B32)*('Relevamiento 11-03'!$A:$A="Corrugadora"),0)),"")} | D32: {=+IFERROR(INDEX('Relevamiento 11-03'!$G:$G,MATCH(1,('Relevamiento 11-03'!$C:$C=$B32)*('Relevamiento 11-03'!$A:$A="Corrugadora"),0)),"")} | E32: =+IF(E31="LK","CH",IF(D32="","",IF(D32>0,"LK","CH"))) | F32: =+IF(OR(E32="LK"),ROUNDUP(D32*(VLOOKUP(B32,'[1]Pedido VACIO'!$E$1:$AT$65536,42,0))/25,0)*25,IF(E32="CH",D31-F31,""))
E33: =+IF(E32="LK","CH",IF(D33="","",IF(D33>0,"LK","CH"))) | F33: =+IF(OR(E33="LK"),ROUNDUP(D33*(VLOOKUP(B33,'[1]Pedido VACIO'!$E$1:$AT$65536,42,0))/25,0)*25,IF(E33="CH",D32-F32,""))
A34: {=+IFERROR(INDEX('Relevamiento 11-03'!$D:$D,MATCH(1,('Relevamiento 11-03'!$C:$C=$B34)*('Relevamiento 11-03'!$A:$A="Corrugadora"),0)),"")} | B34: =+B32+1 -> 11 | C34: {=+IFERROR(INDEX('Relevamiento 11-03'!$F:$F,MATCH(1,('Relevamiento 11-03'!$C:$C=$B34)*('Relevamiento 11-03'!$A:$A="Corrugadora"),0)),"")} | D34: {=+IFERROR(INDEX('Relevamiento 11-03'!$G:$G,MATCH(1,('Relevamiento 11-03'!$C:$C=$B34)*('Relevamiento 11-03'!$A:$A="Corrugadora"),0)),"")} | E34: =+IF(E33="LK","CH",IF(D34="","",IF(D34>0,"LK","CH"))) | F34: =+IF(OR(E34="LK"),ROUNDUP(D34*(VLOOKUP(B34,'[1]Pedido VACIO'!$E$1:$AT$65536,42,0))/25,0)*25,IF(E34="CH",D33-F33,""))
E35: =+IF(E34="LK","CH",IF(D35="","",IF(D35>0,"LK","CH"))) | F35: =+IF(OR(E35="LK"),ROUNDUP(D35*(VLOOKUP(B35,'[1]Pedido VACIO'!$E$1:$AT$65536,42,0))/25,0)*25,IF(E35="CH",D34-F34,""))
A36: {=+IFERROR(INDEX('Relevamiento 11-03'!$D:$D,MATCH(1,('Relevamiento 11-03'!$C:$C=$B36)*('Relevamiento 11-03'!$A:$A="Corrugadora"),0)),"")} | B36: =+B34+1 -> 12 | C36: {=+IFERROR(INDEX('Relevamiento 11-03'!$F:$F,MATCH(1,('Relevamiento 11-03'!$C:$C=$B36)*('Relevamiento 11-03'!$A:$A="Corrugadora"),0)),"")} | D36: {=+IFERROR(INDEX('Relevamiento 11-03'!$G:$G,MATCH(1,('Relevamiento 11-03'!$C:$C=$B36)*('Relevamiento 11-03'!$A:$A="Corrugadora"),0)),"")} | E36: =+IF(E35="LK","CH",IF(D36="","",IF(D36>0,"LK","CH"))) | F36: =+IF(OR(E36="LK"),ROUNDUP(D36*(VLOOKUP(B36,'[1]Pedido VACIO'!$E$1:$AT$65536,42,0))/25,0)*25,IF(E36="CH",D35-F35,""))
E37: =+IF(E36="LK","CH",IF(D37="","",IF(D37>0,"LK","CH"))) | F37: =+IF(OR(E37="LK"),ROUNDUP(D37*(VLOOKUP(B37,'[1]Pedido VACIO'!$E$1:$AT$65536,42,0))/25,0)*25,IF(E37="CH",D36-F36,""))
A38: {=+IFERROR(INDEX('Relevamiento 11-03'!$D:$D,MATCH(1,('Relevamiento 11-03'!$C:$C=$B38)*('Relevamiento 11-03'!$A:$A="Corrugadora"),0)),"")} | B38: =+B36+1 -> 13 | C38: {=+IFERROR(INDEX('Relevamiento 11-03'!$F:$F,MATCH(1,('Relevamiento 11-03'!$C:$C=$B38)*('Relevamiento 11-03'!$A:$A="Corrugadora"),0)),"")} | D38: {=+IFERROR(INDEX('Relevamiento 11-03'!$G:$G,MATCH(1,('Relevamiento 11-03'!$C:$C=$B38)*('Relevamiento 11-03'!$A:$A="Corrugadora"),0)),"")} | E38: =+IF(E37="LK","CH",IF(D38="","",IF(D38>0,"LK","CH"))) | F38: =+IF(OR(E38="LK"),ROUNDUP(D38*(VLOOKUP(B38,'[1]Pedido VACIO'!$E$1:$AT$65536,42,0))/25,0)*25,IF(E38="CH",D37-F37,""))
E39: =+IF(E38="LK","CH",IF(D39="","",IF(D39>0,"LK","CH"))) | F39: =+IF(OR(E39="LK"),ROUNDUP(D39*(VLOOKUP(B39,'[1]Pedido VACIO'!$E$1:$AT$65536,42,0))/25,0)*25,IF(E39="CH",D38-F38,""))
A40: {=+IFERROR(INDEX('Relevamiento 11-03'!$D:$D,MATCH(1,('Relevamiento 11-03'!$C:$C=$B40)*('Relevamiento 11-03'!$A:$A="Corrugadora"),0)),"")} | B40: =+B38+1 -> 14 | C40: {=+IFERROR(INDEX('Relevamiento 11-03'!$F:$F,MATCH(1,('Relevamiento 11-03'!$C:$C=$B40)*('Relevamiento 11-03'!$A:$A="Corrugadora"),0)),"")} | D40: {=+IFERROR(INDEX('Relevamiento 11-03'!$G:$G,MATCH(1,('Relevamiento 11-03'!$C:$C=$B40)*('Relevamiento 11-03'!$A:$A="Corrugadora"),0)),"")} | E40: =+IF(E39="LK","CH",IF(D40="","",IF(D40>0,"LK","CH"))) | F40: =+IF(OR(E40="LK"),ROUNDUP(D40*(VLOOKUP(B40,'[1]Pedido VACIO'!$E$1:$AT$65536,42,0))/25,0)*25,IF(E40="CH",D39-F39,""))
E41: =+IF(E40="LK","CH",IF(D41="","",IF(D41>0,"LK","CH"))) | F41: =+IF(OR(E41="LK"),ROUNDUP(D41*(VLOOKUP(B41,'[1]Pedido VACIO'!$E$1:$AT$65536,42,0))/25,0)*25,IF(E41="CH",D40-F40,""))
A42: {=+IFERROR(INDEX('[1]Pedido VACIO'!$B$1:$B$65536,MATCH(1,('[1]Pedido VACIO'!$E$1:$E$65536=$B42)*('[1]Pedido VACIO'!$A$1:$A$65536="Pat Bet Plast"),0)),"")} | B42: =+B40+1 -> 15 | C42: {=+IFERROR(INDEX('[1]Pedido VACIO'!$C$1:$C$65536,MATCH(1,('[1]Pedido VACIO'!$E$1:$E$65536=$B42)*('[1]Pedido VACIO'!$A$1:$A$65536="Pat Bet Plast"),0)),"")} | D42: {=+IFERROR(INDEX('[1]Pedido VACIO'!$D$1:$D$65536,MATCH(1,('[1]Pedido VACIO'!$E$1:$E$65536=$B42)*('[1]Pedido VACIO'!$A$1:$A$65536="Pat Bet Plast"),0)),"")} | E42: =+IF(E41="LK","CH",IF(D42="","",IF(D42>0,"LK","CH"))) | F42: =+IF(OR(E42="LK"),ROUNDUP(D42*(VLOOKUP(B42,'[1]Pedido VACIO'!$E$1:$AT$65536,42,0))/25,0)*25,IF(E42="CH",D41-F41,""))
E43: =+IF(E42="LK","CH",IF(D43="","",IF(D43>0,"LK","CH"))) | F43: =+IF(OR(E43="LK"),ROUNDUP(D43*(VLOOKUP(B43,'[1]Pedido VACIO'!$E$1:$AT$65536,42,0))/25,0)*25,IF(E43="CH",D42-F42,""))
A44: {=+IFERROR(INDEX('[1]Pedido VACIO'!$B$1:$B$65536,MATCH(1,('[1]Pedido VACIO'!$E$1:$E$65536=$B44)*('[1]Pedido VACIO'!$A$1:$A$65536="Pat Bet Plast"),0)),"")} | B44: =+B42+1 -> 16 | C44: {=+IFERROR(INDEX('[1]Pedido VACIO'!$C$1:$C$65536,MATCH(1,('[1]Pedido VACIO'!$E$1:$E$65536=$B44)*('[1]Pedido VACIO'!$A$1:$A$65536="Pat Bet Plast"),0)),"")} | D44: {=+IFERROR(INDEX('[1]Pedido VACIO'!$D$1:$D$65536,MATCH(1,('[1]Pedido VACIO'!$E$1:$E$65536=$B44)*('[1]Pedido VACIO'!$A$1:$A$65536="Pat Bet Plast"),0)),"")} | E44: =+IF(E43="LK","CH",IF(D44="","",IF(D44>0,"LK","CH"))) | F44: =+IF(OR(E44="LK"),ROUNDUP(D44*(VLOOKUP(B44,'[1]Pedido VACIO'!$E$1:$AT$65536,42,0))/25,0)*25,IF(E44="CH",D43-F43,""))
...

Sheet Envio de Virg a Cerv
A1: Envio de Virg a Cervantes
A2: Cod ISIS | B2: N° Caja | C2: Paq a Enviar | D2: Paq Cerv | E2: Paq Virg | F2: Max Cerv
A3: =+IFERROR(VLOOKUP(ROW()-2,'Relevamiento 11-03'!$B:$AD,3,),"") -> 1100700 | B3: =+IFERROR(VLOOKUP(ROW()-2,'Relevamiento 11-03'!$B:$AD,5,),"") -> 1 | C3: =+IF(D3>F3,0,IF(E3>0,IF(E3<(F3-D3),E3,F3-D3),0)) -> 310 | D3: =+IFERROR(VLOOKUP(ROW()-2,'Relevamiento 11-03'!$B:$AD,12,),0)+IFERROR(VLOOKUP(ROW()-2,'Relevamiento 11-03'!$B:$AD,13,),0)/25 -> 50 | E3: =+IFERROR(VLOOKUP(ROW()-2,'Relevamiento 11-03'!$B:$AD,14,),"")/25 -> 310 | F3: =+IFERROR(VLOOKUP(ROW()-2,'Relevamiento 11-03'!$B:$AD,25,0),0) -> 465
A4: =+IFERROR(VLOOKUP(ROW()-2,'Relevamiento 11-03'!$B:$AD,3,),"") -> 1101700 | B4: =+IFERROR(VLOOKUP(ROW()-2,'Relevamiento 11-03'!$B:$AD,5,),"") -> 2 | C4: =+IF(D4>F4,0,IF(E4>0,IF(E4<(F4-D4),E4,F4-D4),0)) -> 146 | D4: =+IFERROR(VLOOKUP(ROW()-2,'Relevamiento 11-03'!$B:$AD,12,),0)+IFERROR(VLOOKUP(ROW()-2,'Relevamiento 11-03'!$B:$AD,13,),0)/25 -> 68.52 | E4: =+IFERROR(VLOOKUP(ROW()-2,'Relevamiento 11-03'!$B:$AD,14,),"")/25 -> 146 | F4: =+IFERROR(VLOOKUP(ROW()-2,'Relevamiento 11-03'!$B:$AD,25,0),0) -> 576
A5: =+IFERROR(VLOOKUP(ROW()-2,'Relevamiento 11-03'!$B:$AD,3,),"") -> 1103700 | B5: =+IFERROR(VLOOKUP(ROW()-2,'Relevamiento 11-03'!$B:$AD,5,),"") -> 6 | C5: =+IF(D5>F5,0,IF(E5>0,IF(E5<(F5-D5),E5,F5-D5),0)) -> 0 | D5: =+IFERROR(VLOOKUP(ROW()-2,'Relevamiento 11-03'!$B:$AD,12,),0)+IFERROR(VLOOKUP(ROW()-2,'Relevamiento 11-03'!$B:$AD,13,),0)/25 -> 50 | E5: =+IFERROR(VLOOKUP(ROW()-2,'Relevamiento 11-03'!$B:$AD,14,),"")/25 -> 0 | F5: =+IFERROR(VLOOKUP(ROW()-2,'Relevamiento 11-03'!$B:$AD,25,0),0) -> 376
A6: =+IFERROR(VLOOKUP(ROW()-2,'Relevamiento 11-03'!$B:$AD,3,),"") -> 1104700 | B6: =+IFERROR(VLOOKUP(ROW()-2,'Relevamiento 11-03'!$B:$AD,5,),"") -> 7 | C6: =+IF(D6>F6,0,IF(E6>0,IF(E6<(F6-D6),E6,F6-D6),0)) -> 0 | D6: =+IFERROR(VLOOKUP(ROW()-2,'Relevamiento 11-03'!$B:$AD,12,),0)+IFERROR(VLOOKUP(ROW()-2,'Relevamiento 11-03'!$B:$AD,13,),0)/25 -> 11.48 | E6: =+IFERROR(VLOOKUP(ROW()-2,'Relevamiento 11-03'!$B:$AD,14,),"")/25 -> 0 | F6: =+IFERROR(VLOOKUP(ROW()-2,'Relevamiento 11-03'!$B:$AD,25,0),0) -> 95
A7: =+IFERROR(VLOOKUP(ROW()-2,'Relevamiento 11-03'!$B:$AD,3,),"") -> 1105700 | B7: =+IFERROR(VLOOKUP(ROW()-2,'Relevamiento 11-03'!$B:$AD,5,),"") -> 8 | C7: =+IF(D7>F7,0,IF(E7>0,IF(E7<(F7-D7),E7,F7-D7),0)) -> 0 | D7: =+IFERROR(VLOOKUP(ROW()-2,'Relevamiento 11-03'!$B:$AD,12,),0)+IFERROR(VLOOKUP(ROW()-2,'Relevamiento 11-03'!$B:$AD,13,),0)/25 -> 0 | E7: =+IFERROR(VLOOKUP(ROW()-2,'Relevamiento 11-03'!$B:$AD,14,),"")/25 -> 0 | F7: =+IFERROR(VLOOKUP(ROW()-2,'Relevamiento 11-03'!$B:$AD,25,0),0) -> 60
A8: =+IFERROR(VLOOKUP(ROW()-2,'Relevamiento 11-03'!$B:$AD,3,),"") -> 1106700 | B8: =+IFERROR(VLOOKUP(ROW()-2,'Relevamiento 11-03'!$B:$AD,5,),"") -> 10 | C8: =+IF(D8>F8,0,IF(E8>0,IF(E8<(F8-D8),E8,F8-D8),0)) -> 0 | D8: =+IFERROR(VLOOKUP(ROW()-2,'Relevamiento 11-03'!$B:$AD,12,),0)+IFERROR(VLOOKUP(ROW()-2,'Relevamiento 11-03'!$B:$AD,13,),0)/25 -> 80 | E8: =+IFERROR(VLOOKUP(ROW()-2,'Relevamiento 11-03'!$B:$AD,14,),"")/25 -> 0 | F8: =+IFERROR(VLOOKUP(ROW()-2,'Relevamiento 11-03'!$B:$AD,25,0),0) -> 160
A9: =+IFERROR(VLOOKUP(ROW()-2,'Relevamiento 11-03'!$B:$AD,3,),"") -> 1107700 | B9: =+IFERROR(VLOOKUP(ROW()-2,'Relevamiento 11-03'!$B:$AD,5,),"") -> 12 | C9: =+IF(D9>F9,0,IF(E9>0,IF(E9<(F9-D9),E9,F9-D9),0)) -> 0 | D9: =+IFERROR(VLOOKUP(ROW()-2,'Relevamiento 11-03'!$B:$AD,12,),0)+IFERROR(VLOOKUP(ROW()-2,'Relevamiento 11-03'!$B:$AD,13,),0)/25 -> 250 | E9: =+IFERROR(VLOOKUP(ROW()-2,'Relevamiento 11-03'!$B:$AD,14,),"")/25 -> 73.76 | F9: =+IFERROR(VLOOKUP(ROW()-2,'Relevamiento 11-03'!$B:$AD,25,0),0) -> 171
A10: =+IFERROR(VLOOKUP(ROW()-2,'Relevamiento 11-03'!$B:$AD,3,),"") -> 1108700 | B10: =+IFERROR(VLOOKUP(ROW()-2,'Relevamiento 11-03'!$B:$AD,5,),"") -> 13 | C10: =+IF(D10>F10,0,IF(E10>0,IF(E10<(F10-D10),E10,F10-D10),0)) -> 60 | D10: =+IFERROR(VLOOKUP(ROW()-2,'Relevamiento 11-03'!$B:$AD,12,),0)+IFERROR(VLOOKUP(ROW()-2,'Relevamiento 11-03'!$B:$AD,13,),0)/25 -> 5.68 | E10: =+IFERROR(VLOOKUP(ROW()-2,'Relevamiento 11-03'!$B:$AD,14,),"")/25 -> 60 | F10: =+IFERROR(VLOOKUP(ROW()-2,'Relevamiento 11-03'!$B:$AD,25,0),0) -> 105
A11: =+IFERROR(VLOOKUP(ROW()-2,'Relevamiento 11-03'!$B:$AD,3,),"") -> 1114700 | B11: =+IFERROR(VLOOKUP(ROW()-2,'Relevamiento 11-03'!$B:$AD,5,),"") -> 15 | C11: =+IF(D11>F11,0,IF(E11>0,IF(E11<(F11-D11),E11,F11-D11),0)) -> 0 | D11: =+IFERROR(VLOOKUP(ROW()-2,'Relevamiento 11-03'!$B:$AD,12,),0)+IFERROR(VLOOKUP(ROW()-2,'Relevamiento 11-03'!$B:$AD,13,),0)/25 -> 52.4 | E11: =+IFERROR(VLOOKUP(ROW()-2,'Relevamiento 11-03'!$B:$AD,14,),"")/25 -> 0 | F11: =+IFERROR(VLOOKUP(ROW()-2,'Relevamiento 11-03'!$B:$AD,25,0),0) -> 0
A12: =+IFERROR(VLOOKUP(ROW()-2,'Relevamiento 11-03'!$B:$AD,3,),"") -> 1115700 | B12: =+IFERROR(VLOOKUP(ROW()-2,'Relevamiento 11-03'!$B:$AD,5,),"") -> 16 | C12: =+IF(D12>F12,0,IF(E12>0,IF(E12<(F12-D12),E12,F12-D12),0)) -> 0 | D12: =+IFERROR(VLOOKUP(ROW()-2,'Relevamiento 11-03'!$B:$AD,12,),0)+IFERROR(VLOOKUP(ROW()-2,'Relevamiento 11-03'!$B:$AD,13,),0)/25 -> 83 | E12: =+IFERROR(VLOOKUP(ROW()-2,'Relevamiento 11-03'!$B:$AD,14,),"")/25 -> 0 | F12: =+IFERROR(VLOOKUP(ROW()-2,'Relevamiento 11-03'!$B:$AD,25,0),0) -> 0
A13: =+IFERROR(VLOOKUP(ROW()-2,'Relevamiento 11-03'!$B:$AD,3,),"") -> 1110700 | B13: =+IFERROR(VLOOKUP(ROW()-2,'Relevamiento 11-03'!$B:$AD,5,),"") -> 22 | C13: =+IF(D13>F13,0,IF(E13>0,IF(E13<(F13-D13),E13,F13-D13),0)) -> 208 | D13: =+IFERROR(VLOOKUP(ROW()-2,'Relevamiento 11-03'!$B:$AD,12,),0)+IFERROR(VLOOKUP(ROW()-2,'Relevamiento 11-03'!$B:$AD,13,),0)/25 -> 283 | E13: =+IFERROR(VLOOKUP(ROW()-2,'Relevamiento 11-03'!$B:$AD,14,),"")/25 -> 208 | F13: =+IFERROR(VLOOKUP(ROW()-2,'Relevamiento 11-03'!$B:$AD,25,0),0) -> 680
A14: =+IFERROR(VLOOKUP(ROW()-2,'Relevamiento 11-03'!$B:$AD,3,),"") -> 1111700 | B14: =+IFERROR(VLOOKUP(ROW()-2,'Relevamiento 11-03'!$B:$AD,5,),"") -> 27 | C14: =+IF(D14>F14,0,IF(E14>0,IF(E14<(F14-D14),E14,F14-D14),0)) -> 0 | D14: =+IFERROR(VLOOKUP(ROW()-2,'Relevamiento 11-03'!$B:$AD,12,),0)+IFERROR(VLOOKUP(ROW()-2,'Relevamiento 11-03'!$B:$AD,13,),0)/25 -> 42.24 | E14: =+IFERROR(VLOOKUP(ROW()-2,'Relevamiento 11-03'!$B:$AD,14,),"")/25 -> 0 | F14: =+IFERROR(VLOOKUP(ROW()-2,'Relevamiento 11-03'!$B:$AD,25,0),0) -> 43
... A16: =+IFERROR(VLOOKUP(ROW()-2,'Relevamiento 11-03'!$B:$AD,3,),"") -> 1289700 | B16: =+IFERROR(VLOOKUP(ROW()-2,'Relevamiento 11-03'!$B:$AD,5,),"") -> Tira Imp. | C16: =+IF(D16>F16,0,IF(E16>0,IF(E16<(F16-D16),E16,F16-D16),0)) -> 0 | D16: =+IFERROR(VLOOKUP(ROW()-2,'Relevamiento 11-03'!$B:$AD,12,),0)+IFERROR(VLOOKUP(ROW()-2,'Relevamiento 11-03'!$B:$AD,13,),0)/25 -> 43.16 | E16: =+IFERROR(VLOOKUP(ROW()-2,'Relevamiento 11-03'!$B:$AD,14,),"")/25 -> 0 | F16: =+IFERROR(VLOOKUP(ROW()-2,'Relevamiento 11-03'!$B:$AD,25,0),0) -> 50
A17: =+IFERROR(VLOOKUP(ROW()-2,'Relevamiento 11-03'!$B:$AD,3,),"") | B17: =+IFERROR(VLOOKUP(ROW()-2,'Relevamiento 11-03'!$B:$AD,5,),"")
A18: =+IFERROR(VLOOKUP(ROW()-2,'Relevamiento 11-03'!$B:$AD,3,),"") | B18: =+IFERROR(VLOOKUP(ROW()-2,'Relevamiento 11-03'!$B:$AD,5,),"")
A19: =+IFERROR(VLOOKUP(ROW()-2,'Relevamiento 11-03'!$B:$AD,3,),"") | B19: =+IFERROR(VLOOKUP(ROW()-2,'Relevamiento 11-03'!$B:$AD,5,),"")
A20: =+IFERROR(VLOOKUP(ROW()-2,'Relevamiento 11-03'!$B:$AD,3,),"") | B20: =+IFERROR(VLOOKUP(ROW()-2,'Relevamiento 11-03'!$B:$AD,5,),"")
A21: =+IFERROR(VLOOKUP(ROW()-2,'Relevamiento 11-03'!$B:$AD,3,),"") | B21: =+IFERROR(VLOOKUP(ROW()-2,'Relevamiento 11-03'!$B:$AD,5,),"")
A22: =+IFERROR(VLOOKUP(ROW()-2,'Relevamiento 11-03'!$B:$AD,3,),"") | B22: =+IFERROR(VLOOKUP(ROW()-2,'Relevamiento 11-03'!$B:$AD,5,),"")
A23: =+IFERROR(VLOOKUP(ROW()-2,'Relevamiento 11-03'!$B:$AD,3,),"") | B23: =+IFERROR(VLOOKUP(ROW()-2,'Relevamiento 11-03'!$B:$AD,5,),"")
A24: =+IFERROR(VLOOKUP(ROW()-2,'Relevamiento 11-03'!$B:$AD,3,),"") | B24: =+IFERROR(VLOOKUP(ROW()-2,'Relevamiento 11-03'!$B:$AD,5,),"")
A25: =+IFERROR(VLOOKUP(ROW()-2,'Relevamiento 11-03'!$B:$AD,3,),"") | B25: =+IFERROR(VLOOKUP(ROW()-2,'Relevamiento 11-03'!$B:$AD,5,),"")

Sheet Relevamiento 11-03
C1: ORDEN PEDIDO Cajas Corrugadora del Plata Te:1166885428
C3: FECHA: | I3: Uni x Paq | J3: Meses
C5: CORRUGADORA del PLATA | I5: 25 | J5: 4
C7: Antes de mandar, colocar en columna A (Prioridad) el orden en que quieras que entregue | X7: =23*25+10 -> 585
C8: Para definir prioridad, filtrar columna K (solo pedido), ordenar Columna L de Menor a Mayor
C11: Prioridad | D11: codigo ISIS Lk | E11: codigo Isis Ch | F11: N° Caja | G11: Pedido Alan Unidades | I11: Pedido Uni | J11: Max 4 Mes Uni | K11: Stock Total Uni | L11: Sector | M11: Conteo Cerv Paq | N11: Uni Suelta | O11: Conteo Virg Uni | Q11: Pedido Alan | R11: Ocup % | T11: Observacion | V11: Max Paquetes Entra Cerv + Virg | W11: Mes Entra Max | X11: Cons E/Madre Cajas x Mes | Z11: Max Entra Paq Cerv | AA11: Max Entra Uni Cerv | AB11: Max Entra Paq Virg | AC11: Max Entra Uni Virg | AD11: Pedido Minimo
A12: Corrugadora | B12: =+IF(LEN(D12)=7,B11+1,B11) -> 1 | D12: 1100700 | F12: 1 | I12: =+J12-K12 -> 1020 | J12: =+X12*$J$5 -> 10020 | K12: =+M12*$I$5+N12+O12 -> 9000 | L12: A1 | M12: 50 | O12: 7750 | R12: =+IFERROR(K12/(J12),0) -> 0.89820359 | T12: Cuando se pida, agregar firma Loeke | V12: =+AB12+Z12 -> 670 | W12: =V12/X12 -> 0.26746507 | X12: =IFERROR(VLOOKUP(F12,'Datos x Cja LK'!$C$1:$D$15,2,0),0)+IFERROR(VLOOKUP(F12,'Datos x Cja CH'!$C$1:$D$16,2,0),0) -> 2505 | Z12: 465 | AA12: 11625 | AB12: 205 | AC12: 5125 | AD12: 1000 | AE12: 0.7 | AF12: 0.3
A13: Corrugadora | B13: =+IF(LEN(D13)=7,B12+1,B12) -> 2 | C13: 3 | D13: 1101700 | F13: 2 | G13: 7000 | I13: =+J13-K13 -> 7708.8667 | J13: =+X13*$J$5 -> 13071.867 | K13: =+M13*$I$5+N13+O13 -> 5363 | L13: A8 | M13: 67 | N13: 38 | O13: 3650 | R13: =+IFERROR(K13/(J13),0) -> 0.4102704 | V13: =+AB13+Z13 -> 1134 | W13: =V13/X13 -> 0.34700476 | X13: =IFERROR(VLOOKUP(F13,'Datos x Cja LK'!$C$1:$D$15,2,0),0)+IFERROR(VLOOKUP(F13,'Datos x Cja CH'!$C$1:$D$16,2,0),0) -> 3267.9667 | Z13: 576 | AA13: 14400 | AB13: 558 | AC13: 13950 | AD13: 1000 | AE13: 0.7 | AF13: 0.3
A14: Corrugadora | B14: =+IF(LEN(D14)=7,B13+1,B13) -> 3 | D14: 1103700 | F14: 6 | I14: =+J14-K14 -> -502 | J14: =+X14*$J$5 -> 748 | K14: =+M14*$I$5+N14+O14 -> 1250 | L14: A5 | M14: 50 | Q14: 0 | R14: =+IFERROR(K14/(J14),0) -> 1.671123 | V14: =+AB14+Z14 -> 694 | W14: =V14/X14 -> 3.7112299 | X14: =IFERROR(VLOOKUP(F14,'Datos x Cja LK'!$C$1:$D$15,2,0),0)+IFERROR(VLOOKUP(F14,'Datos x Cja CH'!$C$1:$D$16,2,0),0) -> 187 | Z14: 376 | AA14: 9400 | AB14: 318 | AC14: 7950 | AD14: 1000 | AE14: 0.7 | AF14: 0.3
A15: Corrugadora | B15: =+IF(LEN(D15)=7,B14+1,B14) -> 4 | C15: 1 | D15: 1104700 | F15: 7 | G15: 1000 | I15: =+J15-K15 -> 465 | J15: =+X15*$J$5 -> 752 | K15: =+M15*$I$5+N15+O15 -> 287 | L15: A6 | M15: 11 | N15: 12 | R15: =+IFERROR(K15/(J15),0) -> 0.38164894 | V15: =+AB15+Z15 -> 151 | W15: =V15/X15 -> 0.80319149 | X15: =IFERROR(VLOOKUP(F15,'Datos x Cja LK'!$C$1:$D$15,2,0),0)+IFERROR(VLOOKUP(F15,'Datos x Cja CH'!$C$1:$D$16,2,0),0) -> 188 | Z15: 95 | AA15: 2375 | AB15: 56 | AC15: 1400 | AD15: 1000 | AE15: 0.7 | AF15: 0.3
A16: Corrugadora | B16: =+IF(LEN(D16)=7,B15+1,B15) -> 5 | D16: 1105700 | F16: 8 | I16: =+J16-K16 -> 236 | J16: =+X16*$J$5 -> 236 | K16: =+M16*$I$5+N16+O16 -> 0 | L16: A7 | R16: =+IFERROR(K16/(J16),0) -> 0 | V16: =+AB16+Z16 -> 60 | W16: =V16/X16 -> 1.0169492 | X16: =IFERROR(VLOOKUP(F16,'Datos x Cja LK'!$C$1:$D$15,2,0),0)+IFERROR(VLOOKUP(F16,'Datos x Cja CH'!$C$1:$D$16,2,0),0) -> 59 | Z16: 60 | AA16: 1500 | AB16: 0 | AC16: 0 | AD16: 1000 | AE16: 0.7 | AF16: 0.3
A17: Corrugadora | B17: =+IF(LEN(D17)=7,B16+1,B16) -> 6 | D17: 1106700 | F17: 10 | I17: =+J17-K17 -> 568.66667 | J17: =+X17*$J$5 -> 2568.6667 | K17: =+M17*$I$5+N17+O17 -> 2000 | L17: A4 | M17: 80 | R17: =+IFERROR(K17/(J17),0) -> 0.77861407 | V17: =+AB17+Z17 -> 252 | W17: =V17/X17 -> 0.39242149 | X17: =IFERROR(VLOOKUP(F17,'Datos x Cja LK'!$C$1:$D$15,2,0),0)+IFERROR(VLOOKUP(F17,'Datos x Cja CH'!$C$1:$D$16,2,0),0) -> 642.16667 | Z17: 160 | AA17: 4000 | AB17: 92 | AC17: 2300 | AD17: 1000 | AE17: 0.7 | AF17: 0.3
A18: Corrugadora | B18: =+IF(LEN(D18)=7,B17+1,B17) -> 7 | D18: 1107700 | F18: 12 | I18: =+J18-K18 -> -1829.908 | J18: =+X18*$J$5 -> 6264.092 | K18: =+M18*$I$5+N18+O18 -> 8094 | L18: A2 | M18: 250 | O18: 1844 | R18: =+IFERROR(K18/(J18),0) -> 1.2921266 | V18: =+AB18+Z18 -> 244 | W18: =V18/X18 -> 0.1558087 | X18: =IFERROR(VLOOKUP(F18,'Datos x Cja LK'!$C$1:$D$15,2,0),0)+IFERROR(VLOOKUP(F18,'Datos x Cja CH'!$C$1:$D$16,2,0),0) -> 1566.023 | Z18: 171 | AA18: 4275 | AB18: 73 | AC18: 1825 | AD18: 1000 | AE18: 0.7 | AF18: 0.3
A19: Corrugadora | B19: =+IF(LEN(D19)=7,B18+1,B18) -> 8 | D19: 1108700 | F19: 13 | I19: =+J19-K19 -> 586 | J19: =+X19*$J$5 -> 2228 | K19: =+M19*$I$5+N19+O19 -> 1642 | L19: A3 | M19: 5 | N19: 17 | O19: 1500 | R19: =+IFERROR(K19/(J19),0) -> 0.73698384 | V19: =+AB19+Z19 -> 119 | W19: =V19/X19 -> 0.21364452 | X19: =IFERROR(VLOOKUP(F19,'Datos x Cja LK'!$C$1:$D$15,2,0),0)+IFERROR(VLOOKUP(F19,'Datos x Cja CH'!$C$1:$D$16,2,0),0) -> 557 | Z19: 105 | AA19: 2625 | AB19: 14 | AC19: 350 | AD19: 1000
A20: Corrugadora | B20: =+IF(LEN(D20)=7,B19+1,B19) -> 9 | D20: 1114700 | F20: 15 | I20: =+J20-K20 -> -1310 | J20: =+X20*$J$5 -> 0 | K20: =+M20*$I$5+N20+O20 -> 1310 | L20: A9B | M20: 52 | N20: 10 | R20: =+IFERROR(K20/(J20),0) -> 0 | V20: =+AB20+Z20 -> 0 | W20: =V20/X20 -> #DIV/0! | X20: =IFERROR(VLOOKUP(F20,'Datos x Cja LK'!$C$1:$D$15,2,0),0)+IFERROR(VLOOKUP(F20,'Datos x Cja CH'!$C$1:$D$16,2,0),0) -> 0 | AD20: 1000
A21: Corrugadora | B21: =+IF(LEN(D21)=7,B20+1,B20) -> 10 | D21: 1115700 | F21: 16 | I21: =+J21-K21 -> -1967 | J21: =+X21*$J$5 -> 108 | K21: =+M21*$I$5+N21+O21 -> 2075 | L21: A7B | M21: 83 | R21: =+IFERROR(K21/(J21),0) -> 19.212963 | V21: =+AB21+Z21 -> 0 | W21: =V21/X21 -> 0 | X21: =IFERROR(VLOOKUP(F21,'Datos x Cja LK'!$C$1:$D$15,2,0),0)+IFERROR(VLOOKUP(F21,'Datos x Cja CH'!$C$1:$D$16,2,0),0) -> 27 | AD21: 1000
A22: Corrugadora | B22: =+IF(LEN(D22)=7,B21+1,B21) -> 11 | C22: 4 | D22: 1110700 | F22: 22 | G22: 10000 | I22: =+J22-K22 -> 9990.3333 | J22: =+X22*$J$5 -> 22265.333 | K22: =+M22*$I$5+N22+O22 -> 12275 | L22: A9 | M22: 283 | O22: 5200 | R22: =+IFERROR(K22/(J22),0) -> 0.55130547 | V22: =+AB22+Z22 -> 680 | W22: =V22/X22 -> 0.122163 | X22: =IFERROR(VLOOKUP(F22,'Datos x Cja LK'!$C$1:$D$15,2,0),0)+IFERROR(VLOOKUP(F22,'Datos x Cja CH'!$C$1:$D$16,2,0),0) -> 5566.3333 | Z22: 680 | AA22: 17000 | AB22: 0 | AC22: 0 | AD22: 1000 | AE22: 0.7 | AF22: 0.3
A23: Corrugadora | B23: =+IF(LEN(D23)=7,B22+1,B22) -> 12 | D23: 1111700 | F23: 27 | I23: =+J23-K23 -> -620 | J23: =+X23*$J$5 -> 436 | K23: =+M23*$I$5+N23+O23 -> 1056 | L23: Z9 | M23: 40 | N23: 56 | R23: =+IFERROR(K23/(J23),0) -> 2.4220183 | V23: =+AB23+Z23 -> 66 | W23: =V23/X23 -> 0.60550459 | X23: =IFERROR(VLOOKUP(F23,'Datos x Cja LK'!$C$1:$D$15,2,0),0)+IFERROR(VLOOKUP(F23,'Datos x Cja CH'!$C$1:$D$16,2,0),0) -> 109 | Z23: 43 | AA23: 1075 | AB23: 23 | AC23: 575 | AD23: 1000
A24: Corrugadora | B24: =+IF(LEN(D24)=7,B23+1,B23) -> 13 | C24: 2 | D24: 1113700 | F24: 29 | G24: 15500 | I24: =+J24-K24 -> 15323 | J24: =+X24*$J$5 -> 24948 | K24: =+M24*$I$5+N24+O24 -> 9625 | L24: A11 | M24: 19 | N24: 25 | O24: 9125 | R24: =+IFERROR(K24/(J24),0) -> 0.38580247 | V24: =+AB24+Z24 -> 2032 | W24: =V24/X24 -> 0.32579766 | X24: =IFERROR(VLOOKUP(F24,'Datos x Cja LK'!$C$1:$D$15,2,0),0)+IFERROR(VLOOKUP(F24,'Datos x Cja CH'!$C$1:$D$16,2,0),0) -> 6237 | Z24: 1293 | AA24: 32325 | AB24: 739 | AC24: 18475 | AD24: 1000 | AE24: 0.7 | AF24: 0.3
B25: =+IF(LEN(D25)=7,B24+1,B24) -> 14 | D25: 1289700 | F25: Tira Imp. | I25: =+J25-K25 -> -1079 | J25: =+X25*$J$5 -> 0 | K25: =+M25*$I$5+N25+O25 -> 1079 | L25: A10 | M25: 43 | N25: 4 | R25: =+IFERROR(K25/(J25),0) -> 0 | V25: =+AB25+Z25 -> 50 | W25: =V25/X25 -> #DIV/0! | X25: =IFERROR(VLOOKUP(F25,'Datos x Cja LK'!$C$1:$D$15,2,0),0)+IFERROR(VLOOKUP(F25,'Datos x Cja CH'!$C$1:$D$16,2,0),0) -> 0 | Z25: 50 | AA25: =+Z25*15 -> 750 | AD25: 1000
B26: =+IF(LEN(D26)=7,B25+1,B25) -> 14
B27: =+IF(LEN(D27)=7,B26+1,B26) -> 14
B28: =+IF(LEN(D28)=7,B27+1,B27) -> 14 | L28: Z:\AA LOGISTICA Relevamiento y Pedidos\A3 Relevamiento Stock y Pedidos Insumos\Relevamiento\A Relevamientos INSUMOS y Pedido\A Cajas
B29: =+IF(LEN(D29)=7,B28+1,B28) -> 14
B30: =+IF(LEN(D30)=7,B29+1,B29) -> 14
B31: =+IF(LEN(D31)=7,B30+1,B30) -> 14

Sheet Est Madre LK 10-25
A1: Cod Nuevo Isis | B1: Descripcion | C1: E.Madre Uni x Mes | E1: Esta en Consumo?
A2: 505 | B2: Pelador Mgo Plastico | C2: 30000 | E2: =+IF(A2="","",IF(OR(RIGHT(A2,1)="E",RIGHT(A2,1)="H"),"",IF(IFERROR(VLOOKUP(A2,'Datos x Cja LK'!A:A,1,),"Falta en Consumo")=A2,"Ok",IFERROR(VLOOKUP(A2,'Datos x Cja LK'!A:A,1,),"Falta en Consumo")))) -> Ok | G2: 0 | H2: =+C2-G2 -> 30000
A3: 506 | B3: Abrelatas Uña | C3: 18840 | E3: =+IF(A3="","",IF(OR(RIGHT(A3,1)="E",RIGHT(A3,1)="H"),"",IF(IFERROR(VLOOKUP(A3,'Datos x Cja LK'!A:A,1,),"Falta en Consumo")=A3,"Ok",IFERROR(VLOOKUP(A3,'Datos x Cja LK'!A:A,1,),"Falta en Consumo")))) -> Ok | G3: 0 | H3: =+C3-G3 -> 18840
A4: 513 | B4: Pelador Mgo Metalico | C4: 18204 | E4: =+IF(A4="","",IF(OR(RIGHT(A4,1)="E",RIGHT(A4,1)="H"),"",IF(IFERROR(VLOOKUP(A4,'Datos x Cja LK'!A:A,1,),"Falta en Consumo")=A4,"Ok",IFERROR(VLOOKUP(A4,'Datos x Cja LK'!A:A,1,),"Falta en Consumo")))) -> Ok | G4: 0 | H4: =+C4-G4 -> 18204
A5: 31 | B5: Filtro De Cafe | C5: 18192 | E5: =+IF(A5="","",IF(OR(RIGHT(A5,1)="E",RIGHT(A5,1)="H"),"",IF(IFERROR(VLOOKUP(A5,'Datos x Cja LK'!A:A,1,),"Falta en Consumo")=A5,"Ok",IFERROR(VLOOKUP(A5,'Datos x Cja LK'!A:A,1,),"Falta en Consumo")))) -> Ok | G5: 0 | H5: =+C5-G5 -> 18192
A6: 586 | B6: Pelapapas Mgo Ergonomico | C6: 6996 | E6: =+IF(A6="","",IF(OR(RIGHT(A6,1)="E",RIGHT(A6,1)="H"),"",IF(IFERROR(VLOOKUP(A6,'Datos x Cja LK'!A:A,1,),"Falta en Consumo")=A6,"Ok",IFERROR(VLOOKUP(A6,'Datos x Cja LK'!A:A,1,),"Falta en Consumo")))) -> Ok | G6: 0 | H6: =+C6-G6 -> 6996
A7: 530 | B7: Sacacorcho Tipo Mozo Color | C7: 3600 | E7: =+IF(A7="","",IF(OR(RIGHT(A7,1)="E",RIGHT(A7,1)="H"),"",IF(IFERROR(VLOOKUP(A7,'Datos x Cja LK'!A:A,1,),"Falta en Consumo")=A7,"Ok",IFERROR(VLOOKUP(A7,'Datos x Cja LK'!A:A,1,),"Falta en Consumo")))) -> Ok | G7: 0 | H7: =+C7-G7 -> 3600
A8: 546 | B8: Corta Queso | C8: 7200 | E8: =+IF(A8="","",IF(OR(RIGHT(A8,1)="E",RIGHT(A8,1)="H"),"",IF(IFERROR(VLOOKUP(A8,'Datos x Cja LK'!A:A,1,),"Falta en Consumo")=A8,"Ok",IFERROR(VLOOKUP(A8,'Datos x Cja LK'!A:A,1,),"Falta en Consumo")))) -> Ok | G8: 0 | H8: =+C8-G8 -> 7200
A9: 544 | B9: Batidor Pera Alambre | C9: 7464 | E9: =+IF(A9="","",IF(OR(RIGHT(A9,1)="E",RIGHT(A9,1)="H"),"",IF(IFERROR(VLOOKUP(A9,'Datos x Cja LK'!A:A,1,),"Falta en Consumo")=A9,"Ok",IFERROR(VLOOKUP(A9,'Datos x Cja LK'!A:A,1,),"Falta en Consumo")))) -> Ok | G9: 0 | H9: =+C9-G9 -> 7464
A10: 504 | B10: Afila Cuchillos | C10: 6996 | E10: =+IF(A10="","",IF(OR(RIGHT(A10,1)="E",RIGHT(A10,1)="H"),"",IF(IFERROR(VLOOKUP(A10,'Datos x Cja LK'!A:A,1,),"Falta en Consumo")=A10,"Ok",IFERROR(VLOOKUP(A10,'Datos x Cja LK'!A:A,1,),"Falta en Consumo")))) -> Ok | G10: 0 | H10: =+C10-G10 -> 6996
A11: 501 | B11: Abrelatas A Manija | C11: 6912 | E11: =+IF(A11="","",IF(OR(RIGHT(A11,1)="E",RIGHT(A11,1)="H"),"",IF(IFERROR(VLOOKUP(A11,'Datos x Cja LK'!A:A,1,),"Falta en Consumo")=A11,"Ok",IFERROR(VLOOKUP(A11,'Datos x Cja LK'!A:A,1,),"Falta en Consumo")))) -> Ok | G11: 0 | H11: =+C11-G11 -> 6912
A12: 502 | B12: Abrelatas A Mariposa | C12: 5796 | E12: =+IF(A12="","",IF(OR(RIGHT(A12,1)="E",RIGHT(A12,1)="H"),"",IF(IFERROR(VLOOKUP(A12,'Datos x Cja LK'!A:A,1,),"Falta en Consumo")=A12,"Ok",IFERROR(VLOOKUP(A12,'Datos x Cja LK'!A:A,1,),"Falta en Consumo")))) -> Ok | G12: 0 | H12: =+C12-G12 -> 5796
A13: 321 | B13: Rallador Cilindrico | C13: 3120 | E13: =+IF(A13="","",IF(OR(RIGHT(A13,1)="E",RIGHT(A13,1)="H"),"",IF(IFERROR(VLOOKUP(A13,'Datos x Cja LK'!A:A,1,),"Falta en Consumo")=A13,"Ok",IFERROR(VLOOKUP(A13,'Datos x Cja LK'!A:A,1,),"Falta en Consumo")))) -> Ok | G13: 0 | H13: =+C13-G13 -> 3120
... A21: 30 | B21: Colador N°20 | C21: 0 | E21: =+IF(A21="","",IF(OR(RIGHT(A21,1)="E",RIGHT(A21,1)="H"),"",IF(IFERROR(VLOOKUP(A21,'Datos x Cja LK'!A:A,1,),"Falta en Consumo")=A21,"Ok",IFERROR(VLOOKUP(A21,'Datos x Cja LK'!A:A,1,),"Falta en Consumo")))) -> Ok | G21: 0 | H21: =+C21-G21 -> 0
A22: 529E | B22: Sacacorcho Doble Impulso | C22: 4400 | E22: =+IF(A22="","",IF(OR(RIGHT(A22,1)="E",RIGHT(A22,1)="H"),"",IF(IFERROR(VLOOKUP(A22,'Datos x Cja LK'!A:A,1,),"Falta en Consumo")=A22,"Ok",IFERROR(VLOOKUP(A22,'Datos x Cja LK'!A:A,1,),"Falta en Consumo")))) | G22: 0 | H22: =+C22-G22 -> 4400
A23: 224 | B23: Cuchara Madera 30 Cm X 12 | C23: 588 | E23: =+IF(A23="","",IF(OR(RIGHT(A23,1)="E",RIGHT(A23,1)="H"),"",IF(IFERROR(VLOOKUP(A23,'Datos x Cja LK'!A:A,1,),"Falta en Consumo")=A23,"Ok",IFERROR(VLOOKUP(A23,'Datos x Cja LK'!A:A,1,),"Falta en Consumo")))) -> Ok | G23: 0 | H23: =+C23-G23 -> 588
A24: 29 | B24: Colador N°16 | C24: 0 | E24: =+IF(A24="","",IF(OR(RIGHT(A24,1)="E",RIGHT(A24,1)="H"),"",IF(IFERROR(VLOOKUP(A24,'Datos x Cja LK'!A:A,1,),"Falta en Consumo")=A24,"Ok",IFERROR(VLOOKUP(A24,'Datos x Cja LK'!A:A,1,),"Falta en Consumo")))) -> Ok | G24: 0 | H24: =+C24-G24 -> 0
A25: 558 | B25: Bombilla Resorte Tradicio | C25: 2124 | E25: =+IF(A25="","",IF(OR(RIGHT(A25,1)="E",RIGHT(A25,1)="H"),"",IF(IFERROR(VLOOKUP(A25,'Datos x Cja LK'!A:A,1,),"Falta en Consumo")=A25,"Ok",IFERROR(VLOOKUP(A25,'Datos x Cja LK'!A:A,1,),"Falta en Consumo")))) -> Ok | G25: 0 | H25: =+C25-G25 -> 2124
A26: 523 | B26: Sacacorcho Doble Aleta | C26: 2400 | E26: =+IF(A26="","",IF(OR(RIGHT(A26,1)="E",RIGHT(A26,1)="H"),"",IF(IFERROR(VLOOKUP(A26,'Datos x Cja LK'!A:A,1,),"Falta en Consumo")=A26,"Ok",IFERROR(VLOOKUP(A26,'Datos x Cja LK'!A:A,1,),"Falta en Consumo")))) -> Ok | G26: 0 | H26: =+C26-G26 -> 2400
A27: 512 | B27: Abrelata Mariposa Plastic | C27: 1656 | E27: =+IF(A27="","",IF(OR(RIGHT(A27,1)="E",RIGHT(A27,1)="H"),"",IF(IFERROR(VLOOKUP(A27,'Datos x Cja LK'!A:A,1,),"Falta en Consumo")=A27,"Ok",IFERROR(VLOOKUP(A27,'Datos x Cja LK'!A:A,1,),"Falta en Consumo")))) -> Ok | G27: 0 | H27: =+C27-G27 -> 1656
A28: 521 | B28: Sacacorcho Combinado Crom | C28: 2220 | E28: =+IF(A28="","",IF(OR(RIGHT(A28,1)="E",RIGHT(A28,1)="H"),"",IF(IFERROR(VLOOKUP(A28,'Datos x Cja LK'!A:A,1,),"Falta en Consumo")=A28,"Ok",IFERROR(VLOOKUP(A28,'Datos x Cja LK'!A:A,1,),"Falta en Consumo")))) -> Ok | G28: 0 | H28: =+C28-G28 -> 2220
A29: 581 | B29: Sacacorcho Cabo Plastico | C29: 768 | E29: =+IF(A29="","",IF(OR(RIGHT(A29,1)="E",RIGHT(A29,1)="H"),"",IF(IFERROR(VLOOKUP(A29,'Datos x Cja LK'!A:A,1,),"Falta en Consumo")=A29,"Ok",IFERROR(VLOOKUP(A29,'Datos x Cja LK'!A:A,1,),"Falta en Consumo")))) -> Ok | G29: 0 | H29: =+C29-G29 -> 768
A30: 531 | B30: Sacacorcho Combinado Color | C30: 1440 | E30: =+IF(A30="","",IF(OR(RIGHT(A30,1)="E",RIGHT(A30,1)="H"),"",IF(IFERROR(VLOOKUP(A30,'Datos x Cja LK'!A:A,1,),"Falta en Consumo")=A30,"Ok",IFERROR(VLOOKUP(A30,'Datos x Cja LK'!A:A,1,),"Falta en Consumo")))) -> Ok | G30: 0 | H30: =+C30-G30 -> 1440
A31: 248 | B31: Cuchara De Cocina 33 Cm X 12 | C31: 924 | E31: =+IF(A31="","",IF(OR(RIGHT(A31,1)="E",RIGHT(A31,1)="H"),"",IF(IFERROR(VLOOKUP(A31,'Datos x Cja LK'!A:A,1,),"Falta en Consumo")=A31,"Ok",IFERROR(VLOOKUP(A31,'Datos x Cja LK'!A:A,1,),"Falta en Consumo")))) -> Ok | G31: 0 | H31: =+C31-G31 -> 924
A32: 555 | B32: Cepillo Limpia Bombilla | C32: 1800 | E32: =+IF(A32="","",IF(OR(RIGHT(A32,1)="E",RIGHT(A32,1)="H"),"",IF(IFERROR(VLOOKUP(A32,'Datos x Cja LK'!A:A,1,),"Falta en Consumo")=A32,"Ok",IFERROR(VLOOKUP(A32,'Datos x Cja LK'!A:A,1,),"Falta en Consumo")))) -> Ok | G32: 0 | H32: =+C32-G32 -> 1800
A33: 575 | B33: Tapon De Vino/Cerv X1 Negro | C33: 1092 | E33: =+IF(A33="","",IF(OR(RIGHT(A33,1)="E",RIGHT(A33,1)="H"),"",IF(IFERROR(VLOOKUP(A33,'Datos x Cja LK'!A:A,1,),"Falta en Consumo")=A33,"Ok",IFERROR(VLOOKUP(A33,'Datos x Cja LK'!A:A,1,),"Falta en Consumo")))) -> Ok | G33: 0 | H33: =+C33-G33 -> 1092
A34: 66 | B34: Abrelata Super Mariposa | C34: 2100 | E34: =+IF(A34="","",IF(OR(RIGHT(A34,1)="E",RIGHT(A34,1)="H"),"",IF(IFERROR(VLOOKUP(A34,'Datos x Cja LK'!A:A,1,),"Falta en Consumo")=A34,"Ok",IFERROR(VLOOKUP(A34,'Datos x Cja LK'!A:A,1,),"Falta en Consumo")))) -> Ok | G34: 0 | H34: =+C34-G34 -> 2100
... A39: 562 | B39: Corta Pizza Mgo 6cm | C39: 1200 | E39: =+IF(A39="","",IF(OR(RIGHT(A39,1)="E",RIGHT(A39,1)="H"),"",IF(IFERROR(VLOOKUP(A39,'Datos x Cja LK'!A:A,1,),"Falta en Consumo")=A39,"Ok",IFERROR(VLOOKUP(A39,'Datos x Cja LK'!A:A,1,),"Falta en Consumo")))) -> Ok | G39: 0 | H39: =+C39-G39 -> 1200
A40: 816E | B40: Pelador "V" Horizontal | C40: 1872 | E40: =+IF(A40="","",IF(OR(RIGHT(A40,1)="E",RIGHT(A40,1)="H"),"",IF(IFERROR(VLOOKUP(A40,'Datos x Cja LK'!A:A,1,),"Falta en Consumo")=A40,"Ok",IFERROR(VLOOKUP(A40,'Datos x Cja LK'!A:A,1,),"Falta en Consumo")))) | G40: 0 | H40: =+C40-G40 -> 1872
A41: 229 | B41: Ñoquera Madera | C41: 1008 | E41: =+IF(A41="","",IF(OR(RIGHT(A41,1)="E",RIGHT(A41,1)="H"),"",IF(IFERROR(VLOOKUP(A41,'Datos x Cja LK'!A:A,1,),"Falta en Consumo")=A41,"Ok",IFERROR(VLOOKUP(A41,'Datos x Cja LK'!A:A,1,),"Falta en Consumo")))) -> Ok | G41: 0 | H41: =+C41-G41 -> 1008
A42: 500 | B42: Abrelata Uña Pie Color | C42: 1440 | E42: =+IF(A42="","",IF(OR(RIGHT(A42,1)="E",RIGHT(A42,1)="H"),"",IF(IFERROR(VLOOKUP(A42,'Datos x Cja LK'!A:A,1,),"Falta en Consumo")=A42,"Ok",IFERROR(VLOOKUP(A42,'Datos x Cja LK'!A:A,1,),"Falta en Consumo")))) -> Ok | G42: 0 | H42: =+C42-G42 -> 1440
A43: 654 | B43: Bombilla Autolimpiante In | C43: 912 | E43: =+IF(A43="","",IF(OR(RIGHT(A43,1)="E",RIGHT(A43,1)="H"),"",IF(IFERROR(VLOOKUP(A43,'Datos x Cja LK'!A:A,1,),"Falta en Consumo")=A43,"Ok",IFERROR(VLOOKUP(A43,'Datos x Cja LK'!A:A,1,),"Falta en Consumo")))) -> Ok | G43: 0 | H43: =+C43-G43 -> 912
A44: 564 | B44: Corta Pizza Gastronomico | C44: 444 | E44: =+IF(A44="","",IF(OR(RIGHT(A44,1)="E",RIGHT(A44,1)="H"),"",IF(IFERROR(VLOOKUP(A44,'Datos x Cja LK'!A:A,1,),"Falta en Consumo")=A44,"Ok",IFERROR(VLOOKUP(A44,'Datos x Cja LK'!A:A,1,),"Falta en Consumo")))) -> Ok | G44: 0 | H44: =+C44-G44 -> 444
A45: 525E | B45: Sacacorcho Cabo De Madera | C45: 1800 | E45: =+IF(A45="","",IF(OR(RIGHT(A45,1)="E",RIGHT(A45,1)="H"),"",IF(IFERROR(VLOOKUP(A45,'Datos x Cja LK'!A:A,1,),"Falta en Consumo")=A45,"Ok",IFERROR(VLOOKUP(A45,'Datos x Cja LK'!A:A,1,),"Falta en Consumo")))) | G45: 0 | H45: =+C45-G45 -> 1800
A46: 560 | B46: Pinza Chica | C46: 660 | E46: =+IF(A46="","",IF(OR(RIGHT(A46,1)="E",RIGHT(A46,1)="H"),"",IF(IFERROR(VLOOKUP(A46,'Datos x Cja LK'!A:A,1,),"Falta en Consumo")=A46,"Ok",IFERROR(VLOOKUP(A46,'Datos x Cja LK'!A:A,1,),"Falta en Consumo")))) -> Ok | G46: 0 | H46: =+C46-G46 -> 660
A47: 225 | B47: Cuchara Madera 35 Cm X 12 | C47: 2400 | E47: =+IF(A47="","",IF(OR(RIGHT(A47,1)="E",RIGHT(A47,1)="H"),"",IF(IFERROR(VLOOKUP(A47,'Datos x Cja LK'!A:A,1,),"Falta en Consumo")=A47,"Ok",IFERROR(VLOOKUP(A47,'Datos x Cja LK'!A:A,1,),"Falta en Consumo")))) -> Ok | G47: 0 | H47: =+C47-G47 -> 2400
A48: 518 | B48: Sacafuente Gastronomico | C48: 780 | E48: =+IF(A48="","",IF(OR(RIGHT(A48,1)="E",RIGHT(A48,1)="H"),"",IF(IFERROR(VLOOKUP(A48,'Datos x Cja LK'!A:A,1,),"Falta en Consumo")=A48,"Ok",IFERROR(VLOOKUP(A48,'Datos x Cja LK'!A:A,1,),"Falta en Consumo")))) -> Ok | G48: 0 | H48: =+C48-G48 -> 780
A49: 580 | B49: Batidor Mini | C49: 684 | E49: =+IF(A49="","",IF(OR(RIGHT(A49,1)="E",RIGHT(A49,1)="H"),"",IF(IFERROR(VLOOKUP(A49,'Datos x Cja LK'!A:A,1,),"Falta en Consumo")=A49,"Ok",IFERROR(VLOOKUP(A49,'Datos x Cja LK'!A:A,1,),"Falta en Consumo")))) -> Ok | G49: 0 | H49: =+C49-G49 -> 684
A50: 577 | B50: Tapon De Vino/Cerveza Premium | C50: 984 | E50: =+IF(A50="","",IF(OR(RIGHT(A50,1)="E",RIGHT(A50,1)="H"),"",IF(IFERROR(VLOOKUP(A50,'Datos x Cja LK'!A:A,1,),"Falta en Consumo")=A50,"Ok",IFERROR(VLOOKUP(A50,'Datos x Cja LK'!A:A,1,),"Falta en Consumo")))) -> Ok | G50: 0 | H50: =+C50-G50 -> 984
A51: 280 | B51: Manga Repostera + 4 Boqui | C51: 1300 | E51: =+IF(A51="","",IF(OR(RIGHT(A51,1)="E",RIGHT(A51,1)="H"),"",IF(IFERROR(VLOOKUP(A51,'Datos x Cja LK'!A:A,1,),"Falta en Consumo")=A51,"Ok",IFERROR(VLOOKUP(A51,'Datos x Cja LK'!A:A,1,),"Falta en Consumo")))) -> Ok | G51: 0 | H51: =+C51-G51 -> 1300
...

Sheet Est Madre CH 10-25
C3: en uso cajas
A5: Cod.Art. | B5: Descripcion | C5: Est Madre Uni | E5: Esta en Consumo?
A6: 98 | B6: Afila Cuchillo Mgo GE | C6: 0 | E6: =+IF(A6="","",IF(OR(RIGHT(A6,1)="E",RIGHT(A6,1)="H"),"",IF(IFERROR(VLOOKUP(A6,'Datos x Cja CH'!A:A,1,),"Falta en Consumo")=A6,"Ok",IFERROR(VLOOKUP(A6,'Datos x Cja CH'!A:A,1,),"Falta en Consumo")))) -> Ok
A7: 828 | B7: COLADOR 16 CM | C7: 0 | E7: =+IF(A7="","",IF(OR(RIGHT(A7,1)="E",RIGHT(A7,1)="H"),"",IF(IFERROR(VLOOKUP(A7,'Datos x Cja CH'!A:A,1,),"Falta en Consumo")=A7,"Ok",IFERROR(VLOOKUP(A7,'Datos x Cja CH'!A:A,1,),"Falta en Consumo")))) -> Ok
A8: 830 | B8: COLADOR 20 CM | C8: 0 | E8: =+IF(A8="","",IF(OR(RIGHT(A8,1)="E",RIGHT(A8,1)="H"),"",IF(IFERROR(VLOOKUP(A8,'Datos x Cja CH'!A:A,1,),"Falta en Consumo")=A8,"Ok",IFERROR(VLOOKUP(A8,'Datos x Cja CH'!A:A,1,),"Falta en Consumo")))) -> Ok
A9: 977 | B9: PLATOS INDIVIDUALES PIZZA X 6 | C9: 0 | E9: =+IF(A9="","",IF(OR(RIGHT(A9,1)="E",RIGHT(A9,1)="H"),"",IF(IFERROR(VLOOKUP(A9,'Datos x Cja CH'!A:A,1,),"Falta en Consumo")=A9,"Ok",IFERROR(VLOOKUP(A9,'Datos x Cja CH'!A:A,1,),"Falta en Consumo")))) -> Ok
E10: =+IF(A10="","",IF(OR(RIGHT(A10,1)="E",RIGHT(A10,1)="H"),"",IF(IFERROR(VLOOKUP(A10,'Datos x Cja CH'!A:A,1,),"Falta en Consumo")=A10,"Ok",IFERROR(VLOOKUP(A10,'Datos x Cja CH'!A:A,1,),"Falta en Consumo"))))
A11: 706 | B11: Abrelatas Uñas | C11: 3144 | E11: =+IF(A11="","",IF(OR(RIGHT(A11,1)="E",RIGHT(A11,1)="H"),"",IF(IFERROR(VLOOKUP(A11,'Datos x Cja CH'!A:A,1,),"Falta en Consumo")=A11,"Ok",IFERROR(VLOOKUP(A11,'Datos x Cja CH'!A:A,1,),"Falta en Consumo")))) -> Ok
A12: 99 | B12: Pelapapas Mgo Plast Verde | C12: 2976 | E12: =+IF(A12="","",IF(OR(RIGHT(A12,1)="E",RIGHT(A12,1)="H"),"",IF(IFERROR(VLOOKUP(A12,'Datos x Cja CH'!A:A,1,),"Falta en Consumo")=A12,"Ok",IFERROR(VLOOKUP(A12,'Datos x Cja CH'!A:A,1,),"Falta en Consumo")))) -> Ok
A13: 713 | B13: Pelapapas Metalico | C13: 2280 | E13: =+IF(A13="","",IF(OR(RIGHT(A13,1)="E",RIGHT(A13,1)="H"),"",IF(IFERROR(VLOOKUP(A13,'Datos x Cja CH'!A:A,1,),"Falta en Consumo")=A13,"Ok",IFERROR(VLOOKUP(A13,'Datos x Cja CH'!A:A,1,),"Falta en Consumo")))) -> Ok
A14: 702E | B14: Abrelatas Mariposa | C14: 1200 | E14: =+IF(A14="","",IF(OR(RIGHT(A14,1)="E",RIGHT(A14,1)="H"),"",IF(IFERROR(VLOOKUP(A14,'Datos x Cja CH'!A:A,1,),"Falta en Consumo")=A14,"Ok",IFERROR(VLOOKUP(A14,'Datos x Cja CH'!A:A,1,),"Falta en Consumo"))))
A15: 840 | B15: Rallador Cilindrico | C15: 2400 | E15: =+IF(A15="","",IF(OR(RIGHT(A15,1)="E",RIGHT(A15,1)="H"),"",IF(IFERROR(VLOOKUP(A15,'Datos x Cja CH'!A:A,1,),"Falta en Consumo")=A15,"Ok",IFERROR(VLOOKUP(A15,'Datos x Cja CH'!A:A,1,),"Falta en Consumo")))) -> Ok
A16: 809E | B16: Corta Queso Blandos Mango Alambre | C16: 1680 | E16: =+IF(A16="","",IF(OR(RIGHT(A16,1)="E",RIGHT(A16,1)="H"),"",IF(IFERROR(VLOOKUP(A16,'Datos x Cja CH'!A:A,1,),"Falta en Consumo")=A16,"Ok",IFERROR(VLOOKUP(A16,'Datos x Cja CH'!A:A,1,),"Falta en Consumo"))))
A17: 824 | B17: Colador 8 Cm | C17: 1920 | E17: =+IF(A17="","",IF(OR(RIGHT(A17,1)="E",RIGHT(A17,1)="H"),"",IF(IFERROR(VLOOKUP(A17,'Datos x Cja CH'!A:A,1,),"Falta en Consumo")=A17,"Ok",IFERROR(VLOOKUP(A17,'Datos x Cja CH'!A:A,1,),"Falta en Consumo")))) -> Ok
A18: 701 | B18: Abrelatas A Manija | C18: 618 | E18: =+IF(A18="","",IF(OR(RIGHT(A18,1)="E",RIGHT(A18,1)="H"),"",IF(IFERROR(VLOOKUP(A18,'Datos x Cja CH'!A:A,1,),"Falta en Consumo")=A18,"Ok",IFERROR(VLOOKUP(A18,'Datos x Cja CH'!A:A,1,),"Falta en Consumo")))) -> Ok
A19: 97 | B19: Afila Cuchillo Con Base V | C19: 840 | E19: =+IF(A19="","",IF(OR(RIGHT(A19,1)="E",RIGHT(A19,1)="H"),"",IF(IFERROR(VLOOKUP(A19,'Datos x Cja CH'!A:A,1,),"Falta en Consumo")=A19,"Ok",IFERROR(VLOOKUP(A19,'Datos x Cja CH'!A:A,1,),"Falta en Consumo")))) -> Ok
A20: 901 | B20: Cuchara Madera 35 Display X 12 | C20: 1440 | E20: =+IF(A20="","",IF(OR(RIGHT(A20,1)="E",RIGHT(A20,1)="H"),"",IF(IFERROR(VLOOKUP(A20,'Datos x Cja CH'!A:A,1,),"Falta en Consumo")=A20,"Ok",IFERROR(VLOOKUP(A20,'Datos x Cja CH'!A:A,1,),"Falta en Consumo")))) -> Ok
A21: 809 | B21: Corta Queso | C21: 1296 | E21: =+IF(A21="","",IF(OR(RIGHT(A21,1)="E",RIGHT(A21,1)="H"),"",IF(IFERROR(VLOOKUP(A21,'Datos x Cja CH'!A:A,1,),"Falta en Consumo")=A21,"Ok",IFERROR(VLOOKUP(A21,'Datos x Cja CH'!A:A,1,),"Falta en Consumo")))) -> Ok
A22: 836 | B22: Filtro Para Cafe | C22: 2400 | E22: =+IF(A22="","",IF(OR(RIGHT(A22,1)="E",RIGHT(A22,1)="H"),"",IF(IFERROR(VLOOKUP(A22,'Datos x Cja CH'!A:A,1,),"Falta en Consumo")=A22,"Ok",IFERROR(VLOOKUP(A22,'Datos x Cja CH'!A:A,1,),"Falta en Consumo")))) -> Ok
A23: 825 | B23: Colador 10 Cm | C23: 2328 | E23: =+IF(A23="","",IF(OR(RIGHT(A23,1)="E",RIGHT(A23,1)="H"),"",IF(IFERROR(VLOOKUP(A23,'Datos x Cja CH'!A:A,1,),"Falta en Consumo")=A23,"Ok",IFERROR(VLOOKUP(A23,'Datos x Cja CH'!A:A,1,),"Falta en Consumo")))) -> Ok
A24: 702 | B24: Abrelatas Mariposa | C24: 504 | E24: =+IF(A24="","",IF(OR(RIGHT(A24,1)="E",RIGHT(A24,1)="H"),"",IF(IFERROR(VLOOKUP(A24,'Datos x Cja CH'!A:A,1,),"Falta en Consumo")=A24,"Ok",IFERROR(VLOOKUP(A24,'Datos x Cja CH'!A:A,1,),"Falta en Consumo")))) -> Falta en Consumo
A25: 910 | B25: Bate Bife Display | C25: 864 | E25: =+IF(A25="","",IF(OR(RIGHT(A25,1)="E",RIGHT(A25,1)="H"),"",IF(IFERROR(VLOOKUP(A25,'Datos x Cja CH'!A:A,1,),"Falta en Consumo")=A25,"Ok",IFERROR(VLOOKUP(A25,'Datos x Cja CH'!A:A,1,),"Falta en Consumo")))) -> Ok
A26: 733E | B26: Sacacorcho Doble Impulso | C26: 792 | E26: =+IF(A26="","",IF(OR(RIGHT(A26,1)="E",RIGHT(A26,1)="H"),"",IF(IFERROR(VLOOKUP(A26,'Datos x Cja CH'!A:A,1,),"Falta en Consumo")=A26,"Ok",IFERROR(VLOOKUP(A26,'Datos x Cja CH'!A:A,1,),"Falta en Consumo"))))
A27: 922 | B27: Cuchara Madera 25 Display X 12 | C27: 696 | E27: =+IF(A27="","",IF(OR(RIGHT(A27,1)="E",RIGHT(A27,1)="H"),"",IF(IFERROR(VLOOKUP(A27,'Datos x Cja CH'!A:A,1,),"Falta en Consumo")=A27,"Ok",IFERROR(VLOOKUP(A27,'Datos x Cja CH'!A:A,1,),"Falta en Consumo")))) -> Ok
A28: 847 | B28: Espatula Repostera Plasti | C28: 1440 | E28: =+IF(A28="","",IF(OR(RIGHT(A28,1)="E",RIGHT(A28,1)="H"),"",IF(IFERROR(VLOOKUP(A28,'Datos x Cja CH'!A:A,1,),"Falta en Consumo")=A28,"Ok",IFERROR(VLOOKUP(A28,'Datos x Cja CH'!A:A,1,),"Falta en Consumo")))) -> Ok
A29: 802 | B29: Batidor Pera Display | C29: 540 | E29: =+IF(A29="","",IF(OR(RIGHT(A29,1)="E",RIGHT(A29,1)="H"),"",IF(IFERROR(VLOOKUP(A29,'Datos x Cja CH'!A:A,1,),"Falta en Consumo")=A29,"Ok",IFERROR(VLOOKUP(A29,'Datos x Cja CH'!A:A,1,),"Falta en Consumo")))) -> Ok
A30: 727E | B30: Sacacorcho Doble Impulso | C30: 240 | E30: =+IF(A30="","",IF(OR(RIGHT(A30,1)="E",RIGHT(A30,1)="H"),"",IF(IFERROR(VLOOKUP(A30,'Datos x Cja CH'!A:A,1,),"Falta en Consumo")=A30,"Ok",IFERROR(VLOOKUP(A30,'Datos x Cja CH'!A:A,1,),"Falta en Consumo"))))
A31: 817 | B31: Tapon De Gaseosa X 1 Negr | C31: 312 | E31: =+IF(A31="","",IF(OR(RIGHT(A31,1)="E",RIGHT(A31,1)="H"),"",IF(IFERROR(VLOOKUP(A31,'Datos x Cja CH'!A:A,1,),"Falta en Consumo")=A31,"Ok",IFERROR(VLOOKUP(A31,'Datos x Cja CH'!A:A,1,),"Falta en Consumo")))) -> Ok
A32: 725E | B32: Sacacorcho Cabo De Madera | C32: 1080 | E32: =+IF(A32="","",IF(OR(RIGHT(A32,1)="E",RIGHT(A32,1)="H"),"",IF(IFERROR(VLOOKUP(A32,'Datos x Cja CH'!A:A,1,),"Falta en Consumo")=A32,"Ok",IFERROR(VLOOKUP(A32,'Datos x Cja CH'!A:A,1,),"Falta en Consumo"))))
A33: 609 | B33: Pisa Papas | C33: 480 | E33: =+IF(A33="","",IF(OR(RIGHT(A33,1)="E",RIGHT(A33,1)="H"),"",IF(IFERROR(VLOOKUP(A33,'Datos x Cja CH'!A:A,1,),"Falta en Consumo")=A33,"Ok",IFERROR(VLOOKUP(A33,'Datos x Cja CH'!A:A,1,),"Falta en Consumo")))) -> Ok
A34: 731 | B34: Sacacocrcho Combinado Col | C34: 264 | E34: =+IF(A34="","",IF(OR(RIGHT(A34,1)="E",RIGHT(A34,1)="H"),"",IF(IFERROR(VLOOKUP(A34,'Datos x Cja CH'!A:A,1,),"Falta en Consumo")=A34,"Ok",IFERROR(VLOOKUP(A34,'Datos x Cja CH'!A:A,1,),"Falta en Consumo")))) -> Ok
A35: 723 | B35: Sacacorcho Doble Aleta | C35: 372 | E35: =+IF(A35="","",IF(OR(RIGHT(A35,1)="E",RIGHT(A35,1)="H"),"",IF(IFERROR(VLOOKUP(A35,'Datos x Cja CH'!A:A,1,),"Falta en Consumo")=A35,"Ok",IFERROR(VLOOKUP(A35,'Datos x Cja CH'!A:A,1,),"Falta en Consumo")))) -> Ok
A36: 730 | B36: Sacacorcho Tipo Mozo Colo | C36: 600 | E36: =+IF(A36="","",IF(OR(RIGHT(A36,1)="E",RIGHT(A36,1)="H"),"",IF(IFERROR(VLOOKUP(A36,'Datos x Cja CH'!A:A,1,),"Falta en Consumo")=A36,"Ok",IFERROR(VLOOKUP(A36,'Datos x Cja CH'!A:A,1,),"Falta en Consumo")))) -> Ok
A37: 911 | B37: Cuchara Madera 30 Display X 12 | C37: 336 | E37: =+IF(A37="","",IF(OR(RIGHT(A37,1)="E",RIGHT(A37,1)="H"),"",IF(IFERROR(VLOOKUP(A37,'Datos x Cja CH'!A:A,1,),"Falta en Consumo")=A37,"Ok",IFERROR(VLOOKUP(A37,'Datos x Cja CH'!A:A,1,),"Falta en Consumo")))) -> Ok
A38: 789 | B38: Pisa Papa Nylon | C38: 1056 | E38: =+IF(A38="","",IF(OR(RIGHT(A38,1)="E",RIGHT(A38,1)="H"),"",IF(IFERROR(VLOOKUP(A38,'Datos x Cja CH'!A:A,1,),"Falta en Consumo")=A38,"Ok",IFERROR(VLOOKUP(A38,'Datos x Cja CH'!A:A,1,),"Falta en Consumo")))) -> Ok
A39: 909 | B39: Ñoquera Display | C39: 276 | E39: =+IF(A39="","",IF(OR(RIGHT(A39,1)="E",RIGHT(A39,1)="H"),"",IF(IFERROR(VLOOKUP(A39,'Datos x Cja CH'!A:A,1,),"Falta en Consumo")=A39,"Ok",IFERROR(VLOOKUP(A39,'Datos x Cja CH'!A:A,1,),"Falta en Consumo")))) -> Ok
A40: 729E | B40: Sac Doble Aleta Fund Eco | C40: 276 | E40: =+IF(A40="","",IF(OR(RIGHT(A40,1)="E",RIGHT(A40,1)="H"),"",IF(IFERROR(VLOOKUP(A40,'Datos x Cja CH'!A:A,1,),"Falta en Consumo")=A40,"Ok",IFERROR(VLOOKUP(A40,'Datos x Cja CH'!A:A,1,),"Falta en Consumo"))))
A41: 725 | B41: Sacacorcho Cabo De Madera | C41: 480 | E41: =+IF(A41="","",IF(OR(RIGHT(A41,1)="E",RIGHT(A41,1)="H"),"",IF(IFERROR(VLOOKUP(A41,'Datos x Cja CH'!A:A,1,),"Falta en Consumo")=A41,"Ok",IFERROR(VLOOKUP(A41,'Datos x Cja CH'!A:A,1,),"Falta en Consumo")))) -> Ok
A42: 43 | B42: Tres En Uno | C42: 240 | E42: =+IF(A42="","",IF(OR(RIGHT(A42,1)="E",RIGHT(A42,1)="H"),"",IF(IFERROR(VLOOKUP(A42,'Datos x Cja CH'!A:A,1,),"Falta en Consumo")=A42,"Ok",IFERROR(VLOOKUP(A42,'Datos x Cja CH'!A:A,1,),"Falta en Consumo")))) -> Ok
A43: 763 | B43: Bombilla Resorte Tradicio | C43: 480 | E43: =+IF(A43="","",IF(OR(RIGHT(A43,1)="E",RIGHT(A43,1)="H"),"",IF(IFERROR(VLOOKUP(A43,'Datos x Cja CH'!A:A,1,),"Falta en Consumo")=A43,"Ok",IFERROR(VLOOKUP(A43,'Datos x Cja CH'!A:A,1,),"Falta en Consumo")))) -> Ok
...

Sheet Datos x Cja LK
C1: Nº Caja | D1: Cons Mens | E1: Medidas (mm)
C2: 1 | D2: =SUMIFS($E$18:$E$153,$D$18:$D$153,C2) -> 1910 | E2: 240*167*113
C3: 2 | D3: =SUMIFS($E$18:$E$153,$D$18:$D$153,C3) -> 2725.9667 | E3: 270*165*115
C4: 6 | D4: =SUMIFS($E$18:$E$153,$D$18:$D$153,C4) -> 160 | E4: 410*225*145
C5: 7 | D5: =SUMIFS($E$18:$E$153,$D$18:$D$153,C5) -> 188 | E5: 280*247*162
C6: 10 | D6: =SUMIFS($E$18:$E$153,$D$18:$D$153,C6) -> 424.16667 | E6: 405*218*210
C7: 12 | D7: =SUMIFS($E$18:$E$153,$D$18:$D$153,C7) -> 1275.023 | E7: 320*215*100
C8: 13 | D8: =SUMIFS($E$18:$E$153,$D$18:$D$153,C8) -> 472 | E8: 285*170*140
C9: 14 | D9: =SUMIFS($E$18:$E$153,$D$18:$D$153,C9) -> 0 | E9: 325*315*190
C10: 15 | D10: =SUMIFS($E$18:$E$153,$D$18:$D$153,C10) -> 0 | E10: 140*470*150 | G10: 15 | I10: 9.3333333
C11: 16 | D11: =SUMIFS($E$18:$E$153,$D$18:$D$153,C11) -> 27 | E11: 145*370*150
C12: 22 | D12: =SUMIFS($E$18:$E$153,$D$18:$D$153,C12) -> 5112.3333 | E12: 100*165*210
C13: 27 | D13: =SUMIFS($E$18:$E$153,$D$18:$D$153,C13) -> 78 | E13: 540*205*100
C14: 28 | D14: =SUMIFS($E$18:$E$153,$D$18:$D$153,C14) -> 0 | E14: 600*360*270
C15: 29 | D15: =SUMIFS($E$18:$E$153,$D$18:$D$153,C15) -> 5955 | E15: 210*140*80
A17: Cod. Art. | B17: Descripcion Articulo | C17: UxB | D17: N° Caja | E17: Cons 2024
A18: 26 | B18: COLADOR N°8 | C18: 36 | D18: 2 | E18: =+IFERROR(VLOOKUP(A18,'Est Madre LK 10-25'!$A:$C,3,0),0)/C18 -> 201 | G18: =IF(F18="ver",A18,"")
A19: 27 | B19: COLADOR N°10 | C19: 24 | D19: 2 | E19: =+IFERROR(VLOOKUP(A19,'Est Madre LK 10-25'!$A:$C,3,0),0)/C19 -> 188 | G19: =IF(F19="ver",A19,"")
A20: 29 | B20: COLADOR N°16 | C20: 24 | D20: 6 | E20: =+IFERROR(VLOOKUP(A20,'Est Madre LK 10-25'!$A:$C,3,0),0)/C20 -> 0
A21: 30 | B21: COLADOR N°20 | C21: 24 | D21: 10 | E21: =+IFERROR(VLOOKUP(A21,'Est Madre LK 10-25'!$A:$C,3,0),0)/C21 -> 0
A22: 31 | B22: FILTRO DE CAFE | C22: 24 | D22: 22 | E22: =+IFERROR(VLOOKUP(A22,'Est Madre LK 10-25'!$A:$C,3,0),0)/C22 -> 758
A23: 34 | B23: FILTRO DE CAFE GASTRONOMICO | C23: 24 | D23: 2 | E23: =+IFERROR(VLOOKUP(A23,'Est Madre LK 10-25'!$A:$C,3,0),0)/C23 -> 64 | G23: =IF(F23="ver",A23,"")
A24: 57 | B24: DESTAPA CORONA X1 CROMADO | C24: 12 | D24: 29 | E24: =+IFERROR(VLOOKUP(A24,'Est Madre LK 10-25'!$A:$C,3,0),0)/C24 -> 62 | G24: =IF(F24="ver",A24,"")
A25: 58 | B25: CIERRA BOLSA X2 | C25: 12 | D25: 22 | E25: =+IFERROR(VLOOKUP(A25,'Est Madre LK 10-25'!$A:$C,3,0),0)/C25 -> 26 | G25: =IF(F25="ver",A25,"")
A26: 59 | B26: CUCHILLITO DE UNTAR PLAST | C26: 12 | D26: 22 | E26: =+IFERROR(VLOOKUP(A26,'Est Madre LK 10-25'!$A:$C,3,0),0)/C26 -> 12 | G26: =IF(F26="ver",A26,"")
A27: 66 | B27: Abrelata Super Mariposa | C27: 12 | D27: 2 | E27: =+IFERROR(VLOOKUP(A27,'Est Madre LK 10-25'!$A:$C,3,0),0)/C27 -> 175 | G27: =IF(F27="ver",A27,"")
A28: 67 | B28: Sacacorcho Zincado | C28: 60 | D28: 2 | E28: =+IFERROR(VLOOKUP(A28,'Est Madre LK 10-25'!$A:$C,3,0),0)/C28 -> 14 | G28: =IF(F28="ver",A28,"")
A29: 70 | B29: Set de Taper x3 | C29: 4 | D29: 10 | E29: 12 | G29: =IF(F29="ver",A29,"")
A30: 101 | B30: Abr Manija Loke | C30: 12 | D30: 22 | E30: =+IFERROR(VLOOKUP(A30,'Est Madre LK 10-25'!$A:$C,3,0),0)/C30 -> 25 | G30: =IF(F30="ver",A30,"")
A31: 104 | B31: Sac Ergo Loke | C31: 12 | D31: 22 | E31: =+IFERROR(VLOOKUP(A31,'Est Madre LK 10-25'!$A:$C,3,0),0)/C31 -> 95 | G31: =IF(F31="ver",A31,"")
A32: 108 | B32: Pel Mgo Met Loke | C32: 12 | D32: 22 | E32: =+IFERROR(VLOOKUP(A32,'Est Madre LK 10-25'!$A:$C,3,0),0)/C32 -> 34 | G32: =IF(F32="ver",A32,"")
A33: 110 | B33: Colador N° 8 Loke | C33: 36 | D33: 2 | E33: =+IFERROR(VLOOKUP(A33,'Est Madre LK 10-25'!$A:$C,3,0),0)/C33 -> 33.333333 | G33: =IF(F33="ver",A33,"")
A34: 111 | B34: Colador N°10 Loke | C34: 24 | D34: 2 | E34: =+IFERROR(VLOOKUP(A34,'Est Madre LK 10-25'!$A:$C,3,0),0)/C34 -> 23 | G34: =IF(F34="ver",A34,"")
A35: 112 | B35: Ø 16 Env. Loke | C35: 12 | D35: 6 | E35: =+IFERROR(VLOOKUP(A35,'Est Madre LK 10-25'!$A:$C,3,0),0)/C35 -> 30 | G35: =IF(F35="ver",A35,"")
A36: 113 | B36: Colador N°20 Loke | C36: 12 | D36: 10 | E36: =+IFERROR(VLOOKUP(A36,'Est Madre LK 10-25'!$A:$C,3,0),0)/C36 -> 30 | G36: =IF(F36="ver",A36,"")
A37: 114 | B37: Afila Cuch Loke | C37: 6 | D37: 1 | E37: =+IFERROR(VLOOKUP(A37,'Est Madre LK 10-25'!$A:$C,3,0),0)/C37 -> 44 | G37: =IF(F37="ver",A37,"")
A38: 115 | B38: Batidor Pera Loke | C38: 12 | D38: 6 | E38: =+IFERROR(VLOOKUP(A38,'Est Madre LK 10-25'!$A:$C,3,0),0)/C38 -> 26 | G38: =IF(F38="ver",A38,"")
A39: 116 | B39: Corta Pizza Loke | C39: 12 | D39: 2 | E39: =+IFERROR(VLOOKUP(A39,'Est Madre LK 10-25'!$A:$C,3,0),0)/C39 -> 50 | G39: =IF(F39="ver",A39,"")
A40: 119 | B40: Corta Quesos Mgo Alamb Loke | C40: 12 | D40: 1 | E40: =+IFERROR(VLOOKUP(A40,'Est Madre LK 10-25'!$A:$C,3,0),0)/C40 -> 50 | G40: =IF(F40="ver",A40,"")
A41: 121 | B41: Pisa Papas Loke | C41: 12 | D41: 13 | E41: =+IFERROR(VLOOKUP(A41,'Est Madre LK 10-25'!$A:$C,3,0),0)/C41 -> 38 | G41: =IF(F41="ver",A41,"")
...

Sheet Datos x Cja CH
C1: Nº Caja | D1: Cons Mens | I1: CHEF | J1: Uni x Pqte | K1: Paq x Fila | L1: Total Filas | M1: Total Espacio Pqte | N1: Total Uni
C2: 1 | D2: =+SUMIFS($E$18:$E$475,$D$18:$D$475,$C2) -> 595 | J2: 25 | K2: 150 | L2: 1 | M2: =+K2*L2 -> 150 | N2: =+M2*J2 -> 3750
C3: 2 | D3: =+SUMIFS($E$18:$E$475,$D$18:$D$475,$C3) -> 542 | J3: 25 | K3: 80 | L3: 1 | M3: =+K3*L3 -> 80 | N3: =+M3*J3 -> 2000
C4: 5 | D4: =+SUMIFS($E$18:$E$475,$D$18:$D$475,$C4) -> 0 | J4: 25 | K4: 28 | L4: 2 | M4: =+K4*L4 -> 56 | N4: =+M4*J4 -> 1400
C5: 6 | D5: =+SUMIFS($E$18:$E$475,$D$18:$D$475,$C5) -> 27 | J5: 25 | K5: 30 | L5: 1 | M5: =+K5*L5 -> 30 | N5: =+M5*J5 -> 750
C6: 8 | D6: =+SUMIFS($E$18:$E$475,$D$18:$D$475,$C6) -> 59 | J6: 25 | K6: 40 | L6: 1 | M6: =+K6*L6 -> 40 | N6: =+M6*J6 -> 1000
C7: 9 | D7: =+SUMIFS($E$18:$E$475,$D$18:$D$475,$C7) -> 0 | J7: 25 | K7: - | L7: - | M7: - | N7: -
C8: 10 | D8: =+SUMIFS($E$18:$E$475,$D$18:$D$475,$C8) -> 218 | J8: 25 | K8: 50 | L8: 1 | M8: =+K8*L8 -> 50 | N8: =+M8*J8 -> 1250
C9: 12 | D9: =+SUMIFS($E$18:$E$475,$D$18:$D$475,$C9) -> 291 | J9: 25 | K9: 50 | L9: 1 | M9: =+K9*L9 -> 50 | N9: =+M9*J9 -> 1250
C10: 13 | D10: =+SUMIFS($E$18:$E$475,$D$18:$D$475,$C10) -> 85 | J10: 25 | K10: - | L10: - | M10: - | N10: -
C11: 14 | D11: =+SUMIFS($E$18:$E$475,$D$18:$D$475,$C11) -> 0 | J11: 25 | K11: - | L11: - | M11: - | N11: -
C12: 15 | D12: =+SUMIFS($E$18:$E$475,$D$18:$D$475,$C12) -> 0 | J12: 25 | K12: - | L12: - | M12: - | N12: -
C13: 16 | D13: =+SUMIFS($E$18:$E$475,$D$18:$D$475,$C13) -> 0 | J13: 25 | K13: - | L13: - | M13: - | N13: -
C14: 22 | D14: =+SUMIFS($E$18:$E$475,$D$18:$D$475,$C14) -> 454 | J14: 25 | K14: 60 | L14: 1 | M14: =+K14*L14 -> 60 | N14: =+M14*J14 -> 1500
C15: 27 | D15: =+SUMIFS($E$18:$E$475,$D$18:$D$475,$C15) -> 31 | J15: 25 | K15: - | L15: - | M15: - | N15: -
C16: 29 | D16: =+SUMIFS($E$18:$E$475,$D$18:$D$475,$C16) -> 282 | J16: 25 | K16: 60 | L16: 1 | M16: =+K16*L16 -> 60 | N16: =+M16*J16 -> 1500
A18: Cod. Art. | B18: Descripcion Articulo | C18: U x C | D18: N° Caja | E18: Cons 2024
A19: 43 | B19: TRES EN UNO | C19: 12 | D19: 22 | E19: =+IFERROR(VLOOKUP(A19,'Est Madre CH 10-25'!$A:$E,3,0),0)/C19 -> 20
A20: 52 | B20: LAVAVAJILLA C/MGO.ARTE | C20: 12 | D20: 8 | E20: =+IFERROR(VLOOKUP(A20,'Est Madre CH 10-25'!$A:$E,3,0),0)/C20 -> 2
A21: 53 | B21: PINZA DE FIAMBRE*ARTE* | C21: 12 | D21: 12 | E21: =+IFERROR(VLOOKUP(A21,'Est Madre CH 10-25'!$A:$E,3,0),0)/C21 -> 4
A22: 54 | B22: PINZA DE ENSALADAS*ARTE* | C22: 12 | D22: 12 | E22: =+IFERROR(VLOOKUP(A22,'Est Madre CH 10-25'!$A:$E,3,0),0)/C22 -> 2
A23: 55 | B23: PINZA DE FIDEOS*ARTE* | C23: 12 | D23: 12 | E23: =+IFERROR(VLOOKUP(A23,'Est Madre CH 10-25'!$A:$E,3,0),0)/C23 -> 8
A24: 97 | B24: AFILA CUCHILLO CON BASE V | C24: 6 | D24: 1 | E24: =+IFERROR(VLOOKUP(A24,'Est Madre CH 10-25'!$A:$E,3,0),0)/C24 -> 140
A25: 99 | B25: PELAPAPAS MGO PLAST VERDE | C25: 12 | D25: 1 | E25: =+IFERROR(VLOOKUP(A25,'Est Madre CH 10-25'!$A:$E,3,0),0)/C25 -> 248
