Workbook

Sheet Planimetría & Nota de Ped.
B1: Fecha: | F1: Cotado Por:
B2: Listado Cartones Loekemeyer | I2: Stocks | L2: Pedido
B3: Tipo | C3: Ubic | D3: COD. | E3: Lin. | F3: Cartón | G3: ART. | H3: Vta. 2017 | I3: Stock Max | J3: Stock Min | K3: Stock Real | L3: Ped. | M3: Ped Correg
B4: Bolsa | C4: A2 | D4: 031D | E4: Lk | F4: Bolsa | G4: Filtro De Cafe | H4: 12813.714 | I4: =+J4*2 -> 25627.429 | J4: =+H4 -> 12813.714
C5: A2 | D5: 034D | E5: Lk | F5: Bolsa | G5: Filtro De Cafe Gastronomico | H5: 970.28571 | I5: =+J5*2 -> 1940.5714 | J5: =+H5 -> 970.28571
C6: A2 | D6: 516S | E6: Lk | F6: Bolsa | G6: Destapacorona Suelto | H6: 305 | I6: =+J6*2 -> 610 | J6: =+H6 -> 305
C7: A2 | D7: 35 | E7: P.P | F7: Bolsa | G7: Filtro De Cafe | H7: 1356 | I7: =+J7*2 -> 2712 | J7: =+H7 -> 1356
B8: Linea Lkmeyer / Aro | C8: B1 | D8: 324D | E8: Lk | F8: Pliegos Utensilios | G8: Pinche De Choclo X4 | H8: 42
C9: B1 | D9: 322D | E9: Lk | F9: Pliegos Utensilios | G9: Tenedor De Copetin X6 Unid | H9: 130.28571
C10: B1 | E10: Lk | F10: Pliegos Utensilios | H10: =SUM(H8:H9) -> 172.28571 | I10: =+J10*2 -> 344.57143 | J10: =+H10 -> 172.28571
C11: B1 | D11: 552D | E11: Lk | F11: Pliegos x 16 | G11: Bombilla Sup Niq Larga Recta | H11: 258
C12: B1 | D12: 553D | E12: Lk | F12: Pliegos x 16 | G12: Bombilla Super Niq Larga Curva | H12: 244
C13: B1 | D13: 554D | E13: Lk | F13: Pliegos x 16 | G13: Cucharita Matera | H13: 243.42857
C14: B1 | D14: 555D | E14: Lk | F14: Pliegos x 16 | G14: Cepillo Limpia Bombilla | H14: 1163.4286
C15: B1 | D15: 557D | E15: Lk | F15: Pliegos x 16 | G15: Bombilla Resorte Chata | H15: 230.85714
C16: B1 | D16: 558D | E16: Lk | F16: Pliegos x 16 | G16: Bombilla Resorte Tradicio | H16: 208
C17: B1 | D17: 654D | E17: Lk | F17: Pliegos x 16 | G17: Bombilla Autolimpiante Inox | H17: 788.57143
C18: B1 | D18: 657D | E18: Lk | F18: Pliegos x 16 | G18: Bombilla Autolimpiante Niq | H18: 526.28571
C19: B1 | D19: 658D | E19: Lk | F19: Pliegos x 16 | G19: Bombilla Basica Larga Recta | H19: 126.85714
C20: B1 | D20: 659D | E20: Lk | F20: Pliegos x 16 | G20: Bombilla Basica Larga Curva | H20: 248
C21: B1 | D21: 573D | E21: Lk | F21: Pliegos x 16 | G21: Bombilla Colores Metaliza | H21: 277.71429
C22: B1 | E22: Lk | F22: Pliegos x 16 | H22: =SUM(H11:H21) -> 4315.1429 | I22: =+J22*2 -> 8630.2857 | J22: =+H22 -> 4315.1429
C23: B2 | D23: 506D | E23: Lk | F23: Pliego Uña x 12 | G23: Abrelatas Uña | H23: 22355.286 | I23: =+H23 -> 22355.286 | J23: =+I23/2 -> 11177.643
C24: B3 | D24: 537D | E24: Lk | F24: Carton Propio | G24: Pela Y Pica Ajo De Acero | H24: 385.71429 | I24: =+J24*2 -> 771.42857 | J24: =+H24 -> 385.71429
C25: B3 | D25: 542D | E25: Lk | F25: Carton Propio | G25: Ahueca Papas | H25: 462.85714 | I25: =+J25*2 -> 925.71429 | J25: =+H25 -> 462.85714
C26: B3 | D26: 543D | E26: Lk | F26: Cart Prop. | G26: Ahueca Frutas | H26: 368.57143 | I26: =+J26*2 -> 737.14286 | J26: =+H26 -> 368.57143
C27: B4 | D27: 029D | E27: Lk | F27: Corbata Propia | G27: Colador N°16 | H27: 1107.7143 | I27: =+J27*2 -> 2215.4286 | J27: =+H27 -> 1107.7143
C28: B4 | D28: 315D | E28: Lk | F28: Corb. Prop | G28: Pisa Papas Inox | H28: 1563.4286 | I28: =+J28*2 -> 3126.8571 | J28: =+H28 -> 1563.4286
C29: B4 | D29: 325D | E29: Lk | F29: Corb. Prop | G29: Espat. Repost Plast 1 Pza. | H29: 3252 | I29: =+J29*2 -> 6504 | J29: =+H29 -> 3252
C30: B4 | D30: 333D | E30: Lk | F30: Corbata Propia | G30: Espumadera Ac.Inox. | H30: 594.85714 | I30: =+J30*2 -> 1189.7143 | J30: =+H30 -> 594.85714
C31: B5 | D31: 230D | E31: Lk | F31: Bandita | G31: Palo De Amasar 30 Cm
C32: B5 | D32: 231D | E32: Lk | F32: Bandita | G32: Palo De Amasar 40 Cm
C33: B5 | D33: 233D | E33: Lk | F33: Bandita | G33: Palo De Amasar 50 Cm
C34: B5 | D34: 246D | E34: Lk | F34: Bandita | G34: Prensa Matambre | H34: 103.71429
C35: B5 | D35: 247D | E35: Lk | F35: Bandita | G35: Plato De Picada P.P 21 Cm | H35: 51
C36: B5 | D36: 323D | E36: Lk | F36: Bandita | G36: Rallador Cilindrico Chico | H36: 958.28571
C37: B5 | D37: 328D | E37: Lk | F37: Bandita | G37: Rallador 3 Usos Marco Plast | H37: 1150.2857
C38: B5 | D38: 329D | E38: Lk | F38: Bandita | G38: Rallador Queso Marco Plast | H38: 82.285714
C39: B5 | D39: 695D | E39: Lk | F39: Bandita | G39: Posa Pava Alambre | H39: 0
C40: B5 | D40: 36 | E40: P.P | F40: Bandita | G40: Rallador Cilindrico | H40: 384
...

Sheet Planimetría & Nota de Pedido
A1: Listado Cartones Loekemeyer | K1: Stocks
A2: Tipo | B2: Ubic | C2: COD. | D2: Lin. | E2: Tipo Carton | F2: ART. | G2: Ubic | H2: COD. | I2: Vta. 2017 | K2: Stock Max | L2: Stock Min | M2: Stock Actual | N2: Pedido
A3: Bolsa | B3: A2 | C3: 031D | D3: Lk | E3: Bolsa | F3: FILTRO DE CAFE | G3: A2 | H3: 031D | I3: 12813.714 | K3: =+L3*2 -> 25627.429 | L3: =+I3 -> 12813.714 | M3: 18500 | N3: =+K3+K4+K5+K6-M3 -> 12390
B4: A2 | C4: 034D | D4: Lk | E4: Bolsa | F4: FILTRO DE CAFE GASTRONOMICO | G4: A2 | H4: 034D | I4: 970.28571 | K4: =+L4*2 -> 1940.5714 | L4: =+I4 -> 970.28571
B5: A2 | C5: 516S | D5: Lk | E5: Bolsa | F5: DESTAPACORONA SUELTO | G5: A2 | H5: 516S | I5: 305 | K5: =+L5*2 -> 610 | L5: =+I5 -> 305
B6: A2 | C6: 35 | D6: P.P | E6: Bolsa | F6: FILTRO DE CAFE | G6: A2 | H6: 35 | I6: 1356 | K6: =+L6*2 -> 2712 | L6: =+I6 -> 1356
A7: Linea Lkmeyer / Aro | B7: B1 | C7: 324D | D7: Lk | E7: Pliegos Utensilios | F7: PINCHE DE CHOCLO X4 | G7: B1 | H7: 324D | I7: 42
B8: B1 | C8: 322D | D8: Lk | E8: Pliegos Utensilios | F8: TENEDOR DE COPETIN x6 UNID | G8: B1 | H8: 322D | I8: 130.28571
B9: B1 | D9: Lk | E9: Pliegos Utensilios | G9: B1 | I9: =SUM(I7:I8) -> 172.28571 | K9: =+L9*2 -> 344.57143 | L9: =+I9 -> 172.28571 | M9: 2000 | N9: =+K9-M9 -> -1655.4286
B10: B1 | C10: 552D | D10: Lk | E10: Pliegos x 16 | F10: BOMBILLA SUP NIQ LARGA RECTA | G10: B1 | H10: 552D | I10: 258
B11: B1 | C11: 553D | D11: Lk | E11: Pliegos x 16 | F11: BOMBILLA SUPER NIQ LARGA CURVA | G11: B1 | H11: 553D | I11: 244
B12: B1 | C12: 554D | D12: Lk | E12: Pliegos x 16 | F12: CUCHARITA MATERA | G12: B1 | H12: 554D | I12: 243.42857
B13: B1 | C13: 555D | D13: Lk | E13: Pliegos x 16 | F13: CEPILLO LIMPIA BOMBILLA | G13: B1 | H13: 555D | I13: 1163.4286
B14: B1 | C14: 557D | D14: Lk | E14: Pliegos x 16 | F14: BOMBILLA RESORTE CHATA | G14: B1 | H14: 557D | I14: 230.85714
B15: B1 | C15: 558D | D15: Lk | E15: Pliegos x 16 | F15: BOMBILLA RESORTE tradicio | G15: B1 | H15: 558D | I15: 208
B16: B1 | C16: 654D | D16: Lk | E16: Pliegos x 16 | F16: BOMBILLA AUTOLIMPIANTE INOX | G16: B1 | H16: 654D | I16: 788.57143
B17: B1 | C17: 657D | D17: Lk | E17: Pliegos x 16 | F17: BOMBILLA AUTOLIMPIANTE NIQ | G17: B1 | H17: 657D | I17: 526.28571
B18: B1 | C18: 658D | D18: Lk | E18: Pliegos x 16 | F18: BOMBILLA BASICA LARGA RECTA | G18: B1 | H18: 658D | I18: 126.85714
B19: B1 | C19: 659D | D19: Lk | E19: Pliegos x 16 | F19: BOMBILLA BASICA LARGA CURVA | G19: B1 | H19: 659D | I19: 248
B20: B1 | C20: 573D | D20: Lk | E20: Pliegos x 16 | F20: BOMBILLA COLORES METALIZA | G20: B1 | H20: 573D | I20: 277.71429
B21: B1 | D21: Lk | E21: Pliegos x 16 | G21: B1 | I21: =SUM(I10:I20) -> 4315.1429 | K21: =+L21*2 -> 8630.2857 | L21: =+I21 -> 4315.1429 | M21: 12800 | N21: =+K21-M21 -> -4169.7143
B22: B3 | C22: 537D | D22: Lk | E22: Carton Propio | F22: PELA Y PICA AJO DE ACERO | G22: B3 | H22: 537D | I22: 385.71429 | K22: =+L22*2 -> 771.42857 | L22: =+I22 -> 385.71429 | M22: 1100 | N22: =+K22-M22 -> -328.57143
B23: B3 | C23: 542D | D23: Lk | E23: Carton Propio | F23: AHUECA PAPAS | G23: B3 | H23: 542D | I23: 462.85714 | K23: =+L23*2 -> 925.71429 | L23: =+I23 -> 462.85714 | M23: 510 | N23: =+K23-M23 -> 415.71429
B24: B3 | C24: 543D | D24: Lk | E24: Carton Propio | F24: AHUECA FRUTAS | G24: B3 | H24: 543D | I24: 368.57143 | K24: =+L24*2 -> 737.14286 | L24: =+I24 -> 368.57143 | M24: 550 | N24: =+K24-M24 -> 187.14286
B25: B3 | C25: 580D | D25: Lk | E25: Carton Propio | F25: MINI BATIDOR X 1 | G25: B3 | H25: 580D | I25: 185.71429 | K25: =+L25*2 -> 371.42857 | L25: =+I25 -> 185.71429 | M25: 735 | N25: =+K25-M25 -> -363.57143
B26: B4 | C26: 029D | D26: Lk | E26: Corbata Propia | F26: COLADOR N°16 | G26: B4 | H26: 029D | I26: 1107.7143 | K26: =+L26*2 -> 2215.4286 | L26: =+I26 -> 1107.7143 | M26: 500 | N26: =+K26-M26 -> 1715.4286
B27: B4 | C27: 315D | D27: Lk | E27: Corbata Propia | F27: PISA PAPAS ACERO INOX | G27: B4 | H27: 315D | I27: 1563.4286 | K27: =+L27*2 -> 3126.8571 | L27: =+I27 -> 1563.4286 | M27: 100 | N27: =+K27-M27 -> 3026.8571
B28: B4 | C28: 325D | D28: Lk | E28: Corbata Propia | F28: ESPATULA REPOSTERA PLAST 1 PZA | G28: B4 | H28: 325D | I28: 3252 | K28: =+L28*2 -> 6504 | L28: =+I28 -> 3252 | M28: 1569 | N28: =+K28-M28 -> 4935
B29: B4 | C29: 333D | D29: Lk | E29: Corbata Propia | F29: espumadera ac.inox. | G29: B4 | H29: 333D | I29: 594.85714 | K29: =+L29*2 -> 1189.7143 | L29: =+I29 -> 594.85714 | M29: 400 | N29: =+K29-M29 -> 789.71429
B30: B5 | C30: 230D | D30: Lk | E30: Bandita | F30: PALO DE AMASAR 30 CM | G30: B5 | H30: 230D | I30: 147
B31: B5 | C31: 231D | D31: Lk | E31: Bandita | F31: PALO DE AMASAR 40 CM | G31: B5 | H31: 231D | I31: 478.28571
B32: B5 | C32: 233D | D32: Lk | E32: Bandita | F32: PALO DE AMASAR 50 CM | G32: B5 | H32: 233D | I32: 237
B33: B5 | C33: 246D | D33: Lk | E33: Bandita | F33: PRENSA MATAMBRE | G33: B5 | H33: 246D | I33: 103.71429
B34: B5 | C34: 247D | D34: Lk | E34: Bandita | F34: PLATO DE PICADA P.P 21 CM | G34: B5 | H34: 247D | I34: 51
B35: B5 | C35: 323D | D35: Lk | E35: Bandita | F35: RALLADOR CILINDRICO CHICO | G35: B5 | H35: 323D | I35: 958.28571
B36: B5 | C36: 328D | D36: Lk | E36: Bandita | F36: RALLADOR 3 USOS MARCO PLAST | G36: B5 | H36: 328D | I36: 1150.2857
B37: B5 | C37: 329D | D37: Lk | E37: Bandita | F37: RALLADOR QUESO MARCO PLAST | G37: B5 | H37: 329D | I37: 82.285714
B38: B5 | C38: 695D | D38: Lk | E38: Bandita | F38: POSA PAVA ALAMBRE | G38: B5 | H38: 695D | I38: 0
B39: B5 | C39: 36 | D39: P.P | E39: Bandita | F39: RALLADOR CILINDRICO | G39: B5 | H39: 36 | I39: 384
B40: B5 | D40: Lk | E40: Bandita | G40: B5 | I40: =SUM(I30:I39) -> 3591.8571 | K40: =+L40*2 -> 7183.7143 | L40: =+I40 -> 3591.8571 | M40: 48000 | N40: =+K40-M40 -> -40816.286
...

Sheet O.C. Roster
A1: Loekemeyer Hnos. S.R.L | F1: Chef SRL
A2: CUIT: | C2: 30-51584245-0 | F2: CUIT: | H2: 30-68575625-7
A3: DIRECCION: | C3: Cervantes 2868 | F3: DIRECCION: | H3: Virgilio 2788
A4: LOCALIDAD: | C4: Villa Devoto, CABA | F4: LOCALIDAD: | H4: Villa Real, CABA
A6: ORDEN DE COMPRA | F6: FECHA PEDIDO: | I6: =+TODAY() -> 46099
A8: RAZON SORosterL: | C8: ROSTER | D8: COD PROV: | E8: 3847 | F8: ENTREGA EN: | I8: Cervantes 2868
A10: FACTURAR Loekemeyer 70% Chef 30%
A12: ESTE PEDIDO ANULA CUALQUIER PEDIDO ANTERIOR
A13: Cód ISIS | B13: N° Ord | C13: Descripcion Material | D13: Pedido Uni | E13: Emp | F13: Uni a FC | G13: Fecha Pos Ent | H13: Fecha Ent | I13: Uni Ent | J13: Fecha Ent | K13: Uni Ent | L13: Fecha Ent | M13: Uni Ent
A14: {=+IFERROR(INDEX('Pedido VACIO'!$B:$B,MATCH(1,('Pedido VACIO'!$H:$H=$B14)*('Pedido VACIO'!$A:$A="Roster"),0)),"")} | B14: 1 | C14: {=+IFERROR(INDEX('Pedido VACIO'!$F:$F,MATCH(1,('Pedido VACIO'!$H:$H=$B14)*('Pedido VACIO'!$A:$A="Roster"),0)),"")} | D14: {=+IFERROR(INDEX('Pedido VACIO'!$G:$G,MATCH(1,('Pedido VACIO'!$H:$H=$B14)*('Pedido VACIO'!$A:$A="Roster"),0)),"")} | E14: =+IF(E13="LK","CH",IF(D14="","",IF(D14>0,"LK","CH"))) | F14: =+IF(OR(E14="LK"),ROUNDUP(D14*(VLOOKUP(B14,'Pedido VACIO'!$H:$AK,30,0))/70,0)*1,IF(E14="CH",D13-F13,""))
E15: =+IF(E14="LK","CH",IF(D15="","",IF(D15>0,"LK","CH"))) | F15: =+IF(OR(E15="LK"),ROUNDUP(D15*(VLOOKUP(B15,'Pedido VACIO'!$H:$AK,30,0))/70,0)*1,IF(E15="CH",D14-F14,""))
A16: {=+IFERROR(INDEX('Pedido VACIO'!$B:$B,MATCH(1,('Pedido VACIO'!$H:$H=$B16)*('Pedido VACIO'!$A:$A="Roster"),0)),"")} | B16: =+B14+1 -> 2 | C16: {=+IFERROR(INDEX('Pedido VACIO'!$F:$F,MATCH(1,('Pedido VACIO'!$H:$H=$B16)*('Pedido VACIO'!$A:$A="Roster"),0)),"")} | D16: {=+IFERROR(INDEX('Pedido VACIO'!$G:$G,MATCH(1,('Pedido VACIO'!$H:$H=$B16)*('Pedido VACIO'!$A:$A="Roster"),0)),"")} | E16: =+IF(E15="LK","CH",IF(D16="","",IF(D16>0,"LK","CH"))) | F16: =+IF(OR(E16="LK"),ROUNDUP(D16*(VLOOKUP(B16,'Pedido VACIO'!$H:$AK,30,0))/70,0)*1,IF(E16="CH",D15-F15,""))
E17: =+IF(E16="LK","CH",IF(D17="","",IF(D17>0,"LK","CH"))) | F17: =+IF(OR(E17="LK"),ROUNDUP(D17*(VLOOKUP(B17,'Pedido VACIO'!$H:$AK,30,0))/70,0)*1,IF(E17="CH",D16-F16,""))
A18: {=+IFERROR(INDEX('Pedido VACIO'!$B:$B,MATCH(1,('Pedido VACIO'!$H:$H=$B18)*('Pedido VACIO'!$A:$A="Roster"),0)),"")} | B18: =+B16+1 -> 3 | C18: {=+IFERROR(INDEX('Pedido VACIO'!$F:$F,MATCH(1,('Pedido VACIO'!$H:$H=$B18)*('Pedido VACIO'!$A:$A="Roster"),0)),"")} | D18: {=+IFERROR(INDEX('Pedido VACIO'!$G:$G,MATCH(1,('Pedido VACIO'!$H:$H=$B18)*('Pedido VACIO'!$A:$A="Roster"),0)),"")} | E18: =+IF(E17="LK","CH",IF(D18="","",IF(D18>0,"LK","CH"))) | F18: =+IF(OR(E18="LK"),ROUNDUP(D18*(VLOOKUP(B18,'Pedido VACIO'!$H:$AK,30,0))/70,0)*1,IF(E18="CH",D17-F17,""))
E19: =+IF(E18="LK","CH",IF(D19="","",IF(D19>0,"LK","CH"))) | F19: =+IF(OR(E19="LK"),ROUNDUP(D19*(VLOOKUP(B19,'Pedido VACIO'!$H:$AK,30,0))/70,0)*1,IF(E19="CH",D18-F18,""))
A20: {=+IFERROR(INDEX('Pedido VACIO'!$B:$B,MATCH(1,('Pedido VACIO'!$H:$H=$B20)*('Pedido VACIO'!$A:$A="Roster"),0)),"")} | B20: =+B18+1 -> 4 | C20: {=+IFERROR(INDEX('Pedido VACIO'!$F:$F,MATCH(1,('Pedido VACIO'!$H:$H=$B20)*('Pedido VACIO'!$A:$A="Roster"),0)),"")} | D20: {=+IFERROR(INDEX('Pedido VACIO'!$G:$G,MATCH(1,('Pedido VACIO'!$H:$H=$B20)*('Pedido VACIO'!$A:$A="Roster"),0)),"")} | E20: =+IF(E19="LK","CH",IF(D20="","",IF(D20>0,"LK","CH"))) | F20: =+IF(OR(E20="LK"),ROUNDUP(D20*(VLOOKUP(B20,'Pedido VACIO'!$H:$AK,30,0))/70,0)*1,IF(E20="CH",D19-F19,""))
E21: =+IF(E20="LK","CH",IF(D21="","",IF(D21>0,"LK","CH"))) | F21: =+IF(OR(E21="LK"),ROUNDUP(D21*(VLOOKUP(B21,'Pedido VACIO'!$H:$AK,30,0))/70,0)*1,IF(E21="CH",D20-F20,""))
A22: {=+IFERROR(INDEX('Pedido VACIO'!$B:$B,MATCH(1,('Pedido VACIO'!$H:$H=$B22)*('Pedido VACIO'!$A:$A="Roster"),0)),"")} | B22: =+B20+1 -> 5 | C22: {=+IFERROR(INDEX('Pedido VACIO'!$F:$F,MATCH(1,('Pedido VACIO'!$H:$H=$B22)*('Pedido VACIO'!$A:$A="Roster"),0)),"")} | D22: {=+IFERROR(INDEX('Pedido VACIO'!$G:$G,MATCH(1,('Pedido VACIO'!$H:$H=$B22)*('Pedido VACIO'!$A:$A="Roster"),0)),"")} | E22: =+IF(E21="LK","CH",IF(D22="","",IF(D22>0,"LK","CH"))) | F22: =+IF(OR(E22="LK"),ROUNDUP(D22*(VLOOKUP(B22,'Pedido VACIO'!$H:$AK,30,0))/70,0)*1,IF(E22="CH",D21-F21,""))
E23: =+IF(E22="LK","CH",IF(D23="","",IF(D23>0,"LK","CH"))) | F23: =+IF(OR(E23="LK"),ROUNDUP(D23*(VLOOKUP(B23,'Pedido VACIO'!$H:$AK,30,0))/70,0)*1,IF(E23="CH",D22-F22,""))
A24: {=+IFERROR(INDEX('Pedido VACIO'!$B:$B,MATCH(1,('Pedido VACIO'!$H:$H=$B24)*('Pedido VACIO'!$A:$A="Roster"),0)),"")} | B24: =+B22+1 -> 6 | C24: {=+IFERROR(INDEX('Pedido VACIO'!$F:$F,MATCH(1,('Pedido VACIO'!$H:$H=$B24)*('Pedido VACIO'!$A:$A="Roster"),0)),"")} | D24: {=+IFERROR(INDEX('Pedido VACIO'!$G:$G,MATCH(1,('Pedido VACIO'!$H:$H=$B24)*('Pedido VACIO'!$A:$A="Roster"),0)),"")} | E24: =+IF(E23="LK","CH",IF(D24="","",IF(D24>0,"LK","CH"))) | F24: =+IF(OR(E24="LK"),ROUNDUP(D24*(VLOOKUP(B24,'Pedido VACIO'!$H:$AK,30,0))/70,0)*1,IF(E24="CH",D23-F23,""))
E25: =+IF(E24="LK","CH",IF(D25="","",IF(D25>0,"LK","CH"))) | F25: =+IF(OR(E25="LK"),ROUNDUP(D25*(VLOOKUP(B25,'Pedido VACIO'!$H:$AK,30,0))/70,0)*1,IF(E25="CH",D24-F24,""))
A26: {=+IFERROR(INDEX('Pedido VACIO'!$B:$B,MATCH(1,('Pedido VACIO'!$H:$H=$B26)*('Pedido VACIO'!$A:$A="Roster"),0)),"")} | B26: =+B24+1 -> 7 | C26: {=+IFERROR(INDEX('Pedido VACIO'!$F:$F,MATCH(1,('Pedido VACIO'!$H:$H=$B26)*('Pedido VACIO'!$A:$A="Roster"),0)),"")} | D26: {=+IFERROR(INDEX('Pedido VACIO'!$G:$G,MATCH(1,('Pedido VACIO'!$H:$H=$B26)*('Pedido VACIO'!$A:$A="Roster"),0)),"")} | E26: =+IF(E25="LK","CH",IF(D26="","",IF(D26>0,"LK","CH"))) | F26: =+IF(OR(E26="LK"),ROUNDUP(D26*(VLOOKUP(B26,'Pedido VACIO'!$H:$AK,30,0))/70,0)*1,IF(E26="CH",D25-F25,""))
E27: =+IF(E26="LK","CH",IF(D27="","",IF(D27>0,"LK","CH"))) | F27: =+IF(OR(E27="LK"),ROUNDUP(D27*(VLOOKUP(B27,'Pedido VACIO'!$H:$AK,30,0))/70,0)*1,IF(E27="CH",D26-F26,""))
A28: {=+IFERROR(INDEX('Pedido VACIO'!$B:$B,MATCH(1,('Pedido VACIO'!$H:$H=$B28)*('Pedido VACIO'!$A:$A="Roster"),0)),"")} | B28: =+B26+1 -> 8 | C28: {=+IFERROR(INDEX('Pedido VACIO'!$F:$F,MATCH(1,('Pedido VACIO'!$H:$H=$B28)*('Pedido VACIO'!$A:$A="Roster"),0)),"")} | D28: {=+IFERROR(INDEX('Pedido VACIO'!$G:$G,MATCH(1,('Pedido VACIO'!$H:$H=$B28)*('Pedido VACIO'!$A:$A="Roster"),0)),"")} | E28: =+IF(E27="LK","CH",IF(D28="","",IF(D28>0,"LK","CH"))) | F28: =+IF(OR(E28="LK"),ROUNDUP(D28*(VLOOKUP(B28,'Pedido VACIO'!$H:$AK,30,0))/70,0)*1,IF(E28="CH",D27-F27,""))
E29: =+IF(E28="LK","CH",IF(D29="","",IF(D29>0,"LK","CH"))) | F29: =+IF(OR(E29="LK"),ROUNDUP(D29*(VLOOKUP(B29,'Pedido VACIO'!$H:$AK,30,0))/70,0)*1,IF(E29="CH",D28-F28,""))
A30: {=+IFERROR(INDEX('Pedido VACIO'!$B:$B,MATCH(1,('Pedido VACIO'!$H:$H=$B30)*('Pedido VACIO'!$A:$A="Roster"),0)),"")} | B30: =+B28+1 -> 9 | C30: {=+IFERROR(INDEX('Pedido VACIO'!$F:$F,MATCH(1,('Pedido VACIO'!$H:$H=$B30)*('Pedido VACIO'!$A:$A="Roster"),0)),"")} | D30: {=+IFERROR(INDEX('Pedido VACIO'!$G:$G,MATCH(1,('Pedido VACIO'!$H:$H=$B30)*('Pedido VACIO'!$A:$A="Roster"),0)),"")} | E30: =+IF(E29="LK","CH",IF(D30="","",IF(D30>0,"LK","CH"))) | F30: =+IF(OR(E30="LK"),ROUNDUP(D30*(VLOOKUP(B30,'Pedido VACIO'!$H:$AK,30,0))/70,0)*1,IF(E30="CH",D29-F29,""))
E31: =+IF(E30="LK","CH",IF(D31="","",IF(D31>0,"LK","CH"))) | F31: =+IF(OR(E31="LK"),ROUNDUP(D31*(VLOOKUP(B31,'Pedido VACIO'!$H:$AK,30,0))/70,0)*1,IF(E31="CH",D30-F30,""))
A32: {=+IFERROR(INDEX('Pedido VACIO'!$B:$B,MATCH(1,('Pedido VACIO'!$H:$H=$B32)*('Pedido VACIO'!$A:$A="Roster"),0)),"")} | B32: =+B30+1 -> 10 | C32: {=+IFERROR(INDEX('Pedido VACIO'!$F:$F,MATCH(1,('Pedido VACIO'!$H:$H=$B32)*('Pedido VACIO'!$A:$A="Roster"),0)),"")} | D32: {=+IFERROR(INDEX('Pedido VACIO'!$G:$G,MATCH(1,('Pedido VACIO'!$H:$H=$B32)*('Pedido VACIO'!$A:$A="Roster"),0)),"")} | E32: =+IF(E31="LK","CH",IF(D32="","",IF(D32>0,"LK","CH"))) | F32: =+IF(OR(E32="LK"),ROUNDUP(D32*(VLOOKUP(B32,'Pedido VACIO'!$H:$AK,30,0))/70,0)*1,IF(E32="CH",D31-F31,""))
E33: =+IF(E32="LK","CH",IF(D33="","",IF(D33>0,"LK","CH"))) | F33: =+IF(OR(E33="LK"),ROUNDUP(D33*(VLOOKUP(B33,'Pedido VACIO'!$H:$AK,30,0))/70,0)*1,IF(E33="CH",D32-F32,""))
A34: {=+IFERROR(INDEX('Pedido VACIO'!$B:$B,MATCH(1,('Pedido VACIO'!$H:$H=$B34)*('Pedido VACIO'!$A:$A="Roster"),0)),"")} | B34: =+B32+1 -> 11 | C34: {=+IFERROR(INDEX('Pedido VACIO'!$F:$F,MATCH(1,('Pedido VACIO'!$H:$H=$B34)*('Pedido VACIO'!$A:$A="Roster"),0)),"")} | D34: {=+IFERROR(INDEX('Pedido VACIO'!$G:$G,MATCH(1,('Pedido VACIO'!$H:$H=$B34)*('Pedido VACIO'!$A:$A="Roster"),0)),"")} | E34: =+IF(E33="LK","CH",IF(D34="","",IF(D34>0,"LK","CH"))) | F34: =+IF(OR(E34="LK"),ROUNDUP(D34*(VLOOKUP(B34,'Pedido VACIO'!$H:$AK,30,0))/70,0)*1,IF(E34="CH",D33-F33,""))
E35: =+IF(E34="LK","CH",IF(D35="","",IF(D35>0,"LK","CH"))) | F35: =+IF(OR(E35="LK"),ROUNDUP(D35*(VLOOKUP(B35,'Pedido VACIO'!$H:$AK,30,0))/70,0)*1,IF(E35="CH",D34-F34,""))
A36: {=+IFERROR(INDEX('Pedido VACIO'!$B:$B,MATCH(1,('Pedido VACIO'!$H:$H=$B36)*('Pedido VACIO'!$A:$A="Roster"),0)),"")} | B36: =+B34+1 -> 12 | C36: {=+IFERROR(INDEX('Pedido VACIO'!$F:$F,MATCH(1,('Pedido VACIO'!$H:$H=$B36)*('Pedido VACIO'!$A:$A="Roster"),0)),"")} | D36: {=+IFERROR(INDEX('Pedido VACIO'!$G:$G,MATCH(1,('Pedido VACIO'!$H:$H=$B36)*('Pedido VACIO'!$A:$A="Roster"),0)),"")} | E36: =+IF(E35="LK","CH",IF(D36="","",IF(D36>0,"LK","CH"))) | F36: =+IF(OR(E36="LK"),ROUNDUP(D36*(VLOOKUP(B36,'Pedido VACIO'!$H:$AK,30,0))/70,0)*1,IF(E36="CH",D35-F35,""))
E37: =+IF(E36="LK","CH",IF(D37="","",IF(D37>0,"LK","CH"))) | F37: =+IF(OR(E37="LK"),ROUNDUP(D37*(VLOOKUP(B37,'Pedido VACIO'!$H:$AK,30,0))/70,0)*1,IF(E37="CH",D36-F36,""))
A38: {=+IFERROR(INDEX('Pedido VACIO'!$B:$B,MATCH(1,('Pedido VACIO'!$H:$H=$B38)*('Pedido VACIO'!$A:$A="Roster"),0)),"")} | B38: =+B36+1 -> 13 | C38: {=+IFERROR(INDEX('Pedido VACIO'!$F:$F,MATCH(1,('Pedido VACIO'!$H:$H=$B38)*('Pedido VACIO'!$A:$A="Roster"),0)),"")} | D38: {=+IFERROR(INDEX('Pedido VACIO'!$G:$G,MATCH(1,('Pedido VACIO'!$H:$H=$B38)*('Pedido VACIO'!$A:$A="Roster"),0)),"")} | E38: =+IF(E37="LK","CH",IF(D38="","",IF(D38>0,"LK","CH"))) | F38: =+IF(OR(E38="LK"),ROUNDUP(D38*(VLOOKUP(B38,'Pedido VACIO'!$H:$AK,30,0))/70,0)*1,IF(E38="CH",D37-F37,""))
E39: =+IF(E38="LK","CH",IF(D39="","",IF(D39>0,"LK","CH"))) | F39: =+IF(OR(E39="LK"),ROUNDUP(D39*(VLOOKUP(B39,'Pedido VACIO'!$H:$AK,30,0))/70,0)*1,IF(E39="CH",D38-F38,""))
A40: {=+IFERROR(INDEX('Pedido VACIO'!$B:$B,MATCH(1,('Pedido VACIO'!$H:$H=$B40)*('Pedido VACIO'!$A:$A="Roster"),0)),"")} | B40: =+B38+1 -> 14 | C40: {=+IFERROR(INDEX('Pedido VACIO'!$F:$F,MATCH(1,('Pedido VACIO'!$H:$H=$B40)*('Pedido VACIO'!$A:$A="Roster"),0)),"")} | D40: {=+IFERROR(INDEX('Pedido VACIO'!$G:$G,MATCH(1,('Pedido VACIO'!$H:$H=$B40)*('Pedido VACIO'!$A:$A="Roster"),0)),"")} | E40: =+IF(E39="LK","CH",IF(D40="","",IF(D40>0,"LK","CH"))) | F40: =+IF(OR(E40="LK"),ROUNDUP(D40*(VLOOKUP(B40,'Pedido VACIO'!$H:$AK,30,0))/70,0)*1,IF(E40="CH",D39-F39,""))
E41: =+IF(E40="LK","CH",IF(D41="","",IF(D41>0,"LK","CH"))) | F41: =+IF(OR(E41="LK"),ROUNDUP(D41*(VLOOKUP(B41,'Pedido VACIO'!$H:$AK,30,0))/70,0)*1,IF(E41="CH",D40-F40,""))
A42: {=+IFERROR(INDEX('Pedido VACIO'!$B:$B,MATCH(1,('Pedido VACIO'!$H:$H=$B42)*('Pedido VACIO'!$A:$A="Roster"),0)),"")} | B42: =+B40+1 -> 15 | C42: {=+IFERROR(INDEX('Pedido VACIO'!$F:$F,MATCH(1,('Pedido VACIO'!$H:$H=$B42)*('Pedido VACIO'!$A:$A="Roster"),0)),"")} | D42: {=+IFERROR(INDEX('Pedido VACIO'!$G:$G,MATCH(1,('Pedido VACIO'!$H:$H=$B42)*('Pedido VACIO'!$A:$A="Roster"),0)),"")} | E42: =+IF(E41="LK","CH",IF(D42="","",IF(D42>0,"LK","CH"))) | F42: =+IF(OR(E42="LK"),ROUNDUP(D42*(VLOOKUP(B42,'Pedido VACIO'!$H:$AK,30,0))/70,0)*1,IF(E42="CH",D41-F41,""))
E43: =+IF(E42="LK","CH",IF(D43="","",IF(D43>0,"LK","CH"))) | F43: =+IF(OR(E43="LK"),ROUNDUP(D43*(VLOOKUP(B43,'Pedido VACIO'!$H:$AK,30,0))/70,0)*1,IF(E43="CH",D42-F42,""))

Sheet O.C. Cia Integral Etiquetas
A1: Loekemeyer Hnos. S.R.L | F1: Chef SRL
A2: CUIT: | C2: 30-51584245-0 | F2: CUIT: | H2: 30-68575625-7
A3: DIRECCION: | C3: Cervantes 2868 | F3: DIRECCION: | H3: Virgilio 2788
A4: LOCALIDAD: | C4: Villa Devoto, CABA | F4: LOCALIDAD: | H4: Villa Real, CABA
A6: ORDEN DE COMPRA | F6: FECHA PEDIDO: | I6: =+TODAY() -> 46099
A8: RAZON SOCIAL: | C8: CIA INTEGRAL ETIQUETAS | D8: COD PROV: | E8: 3183 | F8: ENTREGA EN: | I8: Cervantes 2868
A10: FACTURAR Loekemeyer 70% Chef 30%
A12: ESTE PEDIDO ANULA CUALQUIER PEDIDO ANTERIOR
A13: Cód ISIS | B13: N° Ord | C13: Descripcion Material | D13: Pedido Uni | E13: Emp | F13: Uni a FC | G13: Fecha Pos Ent | H13: Fecha Ent | I13: Uni Ent | J13: Fecha Ent | K13: Uni Ent | L13: Fecha Ent | M13: Uni Ent
A14: {=+IFERROR(INDEX('Pedido VACIO'!$B:$B,MATCH(1,('Pedido VACIO'!$H:$H=$B14)*('Pedido VACIO'!$A:$A="Cia"),0)),"")} | B14: 1 | C14: {=+IFERROR(INDEX('Pedido VACIO'!$F:$F,MATCH(1,('Pedido VACIO'!$H:$H=$B14)*('Pedido VACIO'!$A:$A="Cia"),0)),"")} | D14: {=+IFERROR(INDEX('Pedido VACIO'!$G:$G,MATCH(1,('Pedido VACIO'!$H:$H=$B14)*('Pedido VACIO'!$A:$A="Cia"),0)),"")} | E14: =+IF(E13="LK","CH",IF(D14="","",IF(D14>0,"LK","CH"))) | F14: =+IF(OR(E14="LK"),ROUNDUP(D14*(VLOOKUP(B14,'Pedido VACIO'!$H:$AK,30,0))/70,0)*1,IF(E14="CH",D13-F13,""))
E15: =+IF(E14="LK","CH",IF(D15="","",IF(D15>0,"LK","CH"))) | F15: =+IF(OR(E15="LK"),ROUNDUP(D15*(VLOOKUP(B15,'Pedido VACIO'!$H:$AK,30,0))/70,0)*1,IF(E15="CH",D14-F14,""))
A16: {=+IFERROR(INDEX('Pedido VACIO'!$B:$B,MATCH(1,('Pedido VACIO'!$H:$H=$B16)*('Pedido VACIO'!$A:$A="Cia"),0)),"")} | B16: =+B14+1 -> 2 | C16: {=+IFERROR(INDEX('Pedido VACIO'!$F:$F,MATCH(1,('Pedido VACIO'!$H:$H=$B16)*('Pedido VACIO'!$A:$A="Cia"),0)),"")} | D16: {=+IFERROR(INDEX('Pedido VACIO'!$G:$G,MATCH(1,('Pedido VACIO'!$H:$H=$B16)*('Pedido VACIO'!$A:$A="Cia"),0)),"")} | E16: =+IF(E15="LK","CH",IF(D16="","",IF(D16>0,"LK","CH"))) | F16: =+IF(OR(E16="LK"),ROUNDUP(D16*(VLOOKUP(B16,'Pedido VACIO'!$H:$AK,30,0))/70,0)*1,IF(E16="CH",D15-F15,""))
E17: =+IF(E16="LK","CH",IF(D17="","",IF(D17>0,"LK","CH"))) | F17: =+IF(OR(E17="LK"),ROUNDUP(D17*(VLOOKUP(B17,'Pedido VACIO'!$H:$AK,30,0))/70,0)*1,IF(E17="CH",D16-F16,""))
A18: {=+IFERROR(INDEX('Pedido VACIO'!$B:$B,MATCH(1,('Pedido VACIO'!$H:$H=$B18)*('Pedido VACIO'!$A:$A="Cia"),0)),"")} | B18: =+B16+1 -> 3 | C18: {=+IFERROR(INDEX('Pedido VACIO'!$F:$F,MATCH(1,('Pedido VACIO'!$H:$H=$B18)*('Pedido VACIO'!$A:$A="Cia"),0)),"")} | D18: {=+IFERROR(INDEX('Pedido VACIO'!$G:$G,MATCH(1,('Pedido VACIO'!$H:$H=$B18)*('Pedido VACIO'!$A:$A="Cia"),0)),"")} | E18: =+IF(E17="LK","CH",IF(D18="","",IF(D18>0,"LK","CH"))) | F18: =+IF(OR(E18="LK"),ROUNDUP(D18*(VLOOKUP(B18,'Pedido VACIO'!$H:$AK,30,0))/70,0)*1,IF(E18="CH",D17-F17,""))
E19: =+IF(E18="LK","CH",IF(D19="","",IF(D19>0,"LK","CH"))) | F19: =+IF(OR(E19="LK"),ROUNDUP(D19*(VLOOKUP(B19,'Pedido VACIO'!$H:$AK,30,0))/70,0)*1,IF(E19="CH",D18-F18,""))
A20: {=+IFERROR(INDEX('Pedido VACIO'!$B:$B,MATCH(1,('Pedido VACIO'!$H:$H=$B20)*('Pedido VACIO'!$A:$A="Cia"),0)),"")} | B20: =+B18+1 -> 4 | C20: {=+IFERROR(INDEX('Pedido VACIO'!$F:$F,MATCH(1,('Pedido VACIO'!$H:$H=$B20)*('Pedido VACIO'!$A:$A="Cia"),0)),"")} | D20: {=+IFERROR(INDEX('Pedido VACIO'!$G:$G,MATCH(1,('Pedido VACIO'!$H:$H=$B20)*('Pedido VACIO'!$A:$A="Cia"),0)),"")} | E20: =+IF(E19="LK","CH",IF(D20="","",IF(D20>0,"LK","CH"))) | F20: =+IF(OR(E20="LK"),ROUNDUP(D20*(VLOOKUP(B20,'Pedido VACIO'!$H:$AK,30,0))/70,0)*1,IF(E20="CH",D19-F19,""))
E21: =+IF(E20="LK","CH",IF(D21="","",IF(D21>0,"LK","CH"))) | F21: =+IF(OR(E21="LK"),ROUNDUP(D21*(VLOOKUP(B21,'Pedido VACIO'!$H:$AK,30,0))/70,0)*1,IF(E21="CH",D20-F20,""))
A22: {=+IFERROR(INDEX('Pedido VACIO'!$B:$B,MATCH(1,('Pedido VACIO'!$H:$H=$B22)*('Pedido VACIO'!$A:$A="Cia"),0)),"")} | B22: =+B20+1 -> 5 | C22: {=+IFERROR(INDEX('Pedido VACIO'!$F:$F,MATCH(1,('Pedido VACIO'!$H:$H=$B22)*('Pedido VACIO'!$A:$A="Cia"),0)),"")} | D22: {=+IFERROR(INDEX('Pedido VACIO'!$G:$G,MATCH(1,('Pedido VACIO'!$H:$H=$B22)*('Pedido VACIO'!$A:$A="Cia"),0)),"")} | E22: =+IF(E21="LK","CH",IF(D22="","",IF(D22>0,"LK","CH"))) | F22: =+IF(OR(E22="LK"),ROUNDUP(D22*(VLOOKUP(B22,'Pedido VACIO'!$H:$AK,30,0))/70,0)*1,IF(E22="CH",D21-F21,""))
E23: =+IF(E22="LK","CH",IF(D23="","",IF(D23>0,"LK","CH"))) | F23: =+IF(OR(E23="LK"),ROUNDUP(D23*(VLOOKUP(B23,'Pedido VACIO'!$H:$AK,30,0))/70,0)*1,IF(E23="CH",D22-F22,""))
A24: {=+IFERROR(INDEX('Pedido VACIO'!$B:$B,MATCH(1,('Pedido VACIO'!$H:$H=$B24)*('Pedido VACIO'!$A:$A="Cia"),0)),"")} | B24: =+B22+1 -> 6 | C24: {=+IFERROR(INDEX('Pedido VACIO'!$F:$F,MATCH(1,('Pedido VACIO'!$H:$H=$B24)*('Pedido VACIO'!$A:$A="Cia"),0)),"")} | D24: {=+IFERROR(INDEX('Pedido VACIO'!$G:$G,MATCH(1,('Pedido VACIO'!$H:$H=$B24)*('Pedido VACIO'!$A:$A="Cia"),0)),"")} | E24: =+IF(E23="LK","CH",IF(D24="","",IF(D24>0,"LK","CH"))) | F24: =+IF(OR(E24="LK"),ROUNDUP(D24*(VLOOKUP(B24,'Pedido VACIO'!$H:$AK,30,0))/70,0)*1,IF(E24="CH",D23-F23,""))
E25: =+IF(E24="LK","CH",IF(D25="","",IF(D25>0,"LK","CH"))) | F25: =+IF(OR(E25="LK"),ROUNDUP(D25*(VLOOKUP(B25,'Pedido VACIO'!$H:$AK,30,0))/70,0)*1,IF(E25="CH",D24-F24,""))
A26: {=+IFERROR(INDEX('Pedido VACIO'!$B:$B,MATCH(1,('Pedido VACIO'!$H:$H=$B26)*('Pedido VACIO'!$A:$A="Cia"),0)),"")} | B26: =+B24+1 -> 7 | C26: {=+IFERROR(INDEX('Pedido VACIO'!$F:$F,MATCH(1,('Pedido VACIO'!$H:$H=$B26)*('Pedido VACIO'!$A:$A="Cia"),0)),"")} | D26: {=+IFERROR(INDEX('Pedido VACIO'!$G:$G,MATCH(1,('Pedido VACIO'!$H:$H=$B26)*('Pedido VACIO'!$A:$A="Cia"),0)),"")} | E26: =+IF(E25="LK","CH",IF(D26="","",IF(D26>0,"LK","CH"))) | F26: =+IF(OR(E26="LK"),ROUNDUP(D26*(VLOOKUP(B26,'Pedido VACIO'!$H:$AK,30,0))/70,0)*1,IF(E26="CH",D25-F25,""))
E27: =+IF(E26="LK","CH",IF(D27="","",IF(D27>0,"LK","CH"))) | F27: =+IF(OR(E27="LK"),ROUNDUP(D27*(VLOOKUP(B27,'Pedido VACIO'!$H:$AK,30,0))/70,0)*1,IF(E27="CH",D26-F26,""))
A28: {=+IFERROR(INDEX('Pedido VACIO'!$B:$B,MATCH(1,('Pedido VACIO'!$H:$H=$B28)*('Pedido VACIO'!$A:$A="Cia"),0)),"")} | B28: =+B26+1 -> 8 | C28: {=+IFERROR(INDEX('Pedido VACIO'!$F:$F,MATCH(1,('Pedido VACIO'!$H:$H=$B28)*('Pedido VACIO'!$A:$A="Cia"),0)),"")} | D28: {=+IFERROR(INDEX('Pedido VACIO'!$G:$G,MATCH(1,('Pedido VACIO'!$H:$H=$B28)*('Pedido VACIO'!$A:$A="Cia"),0)),"")} | E28: =+IF(E27="LK","CH",IF(D28="","",IF(D28>0,"LK","CH"))) | F28: =+IF(OR(E28="LK"),ROUNDUP(D28*(VLOOKUP(B28,'Pedido VACIO'!$H:$AK,30,0))/70,0)*1,IF(E28="CH",D27-F27,""))
E29: =+IF(E28="LK","CH",IF(D29="","",IF(D29>0,"LK","CH"))) | F29: =+IF(OR(E29="LK"),ROUNDUP(D29*(VLOOKUP(B29,'Pedido VACIO'!$H:$AK,30,0))/70,0)*1,IF(E29="CH",D28-F28,""))
A30: {=+IFERROR(INDEX('Pedido VACIO'!$B:$B,MATCH(1,('Pedido VACIO'!$H:$H=$B30)*('Pedido VACIO'!$A:$A="Cia"),0)),"")} | B30: =+B28+1 -> 9 | C30: {=+IFERROR(INDEX('Pedido VACIO'!$F:$F,MATCH(1,('Pedido VACIO'!$H:$H=$B30)*('Pedido VACIO'!$A:$A="Cia"),0)),"")} | D30: {=+IFERROR(INDEX('Pedido VACIO'!$G:$G,MATCH(1,('Pedido VACIO'!$H:$H=$B30)*('Pedido VACIO'!$A:$A="Cia"),0)),"")} | E30: =+IF(E29="LK","CH",IF(D30="","",IF(D30>0,"LK","CH"))) | F30: =+IF(OR(E30="LK"),ROUNDUP(D30*(VLOOKUP(B30,'Pedido VACIO'!$H:$AK,30,0))/70,0)*1,IF(E30="CH",D29-F29,""))
E31: =+IF(E30="LK","CH",IF(D31="","",IF(D31>0,"LK","CH"))) | F31: =+IF(OR(E31="LK"),ROUNDUP(D31*(VLOOKUP(B31,'Pedido VACIO'!$H:$AK,30,0))/70,0)*1,IF(E31="CH",D30-F30,""))
A32: {=+IFERROR(INDEX('Pedido VACIO'!$B:$B,MATCH(1,('Pedido VACIO'!$H:$H=$B32)*('Pedido VACIO'!$A:$A="Cia"),0)),"")} | B32: =+B30+1 -> 10 | C32: {=+IFERROR(INDEX('Pedido VACIO'!$F:$F,MATCH(1,('Pedido VACIO'!$H:$H=$B32)*('Pedido VACIO'!$A:$A="Cia"),0)),"")} | D32: {=+IFERROR(INDEX('Pedido VACIO'!$G:$G,MATCH(1,('Pedido VACIO'!$H:$H=$B32)*('Pedido VACIO'!$A:$A="Cia"),0)),"")} | E32: =+IF(E31="LK","CH",IF(D32="","",IF(D32>0,"LK","CH"))) | F32: =+IF(OR(E32="LK"),ROUNDUP(D32*(VLOOKUP(B32,'Pedido VACIO'!$H:$AK,30,0))/70,0)*1,IF(E32="CH",D31-F31,""))
E33: =+IF(E32="LK","CH",IF(D33="","",IF(D33>0,"LK","CH"))) | F33: =+IF(OR(E33="LK"),ROUNDUP(D33*(VLOOKUP(B33,'Pedido VACIO'!$H:$AK,30,0))/70,0)*1,IF(E33="CH",D32-F32,""))
A34: {=+IFERROR(INDEX('Pedido VACIO'!$B:$B,MATCH(1,('Pedido VACIO'!$H:$H=$B34)*('Pedido VACIO'!$A:$A="Cia"),0)),"")} | B34: =+B32+1 -> 11 | C34: {=+IFERROR(INDEX('Pedido VACIO'!$F:$F,MATCH(1,('Pedido VACIO'!$H:$H=$B34)*('Pedido VACIO'!$A:$A="Cia"),0)),"")} | D34: {=+IFERROR(INDEX('Pedido VACIO'!$G:$G,MATCH(1,('Pedido VACIO'!$H:$H=$B34)*('Pedido VACIO'!$A:$A="Cia"),0)),"")} | E34: =+IF(E33="LK","CH",IF(D34="","",IF(D34>0,"LK","CH"))) | F34: =+IF(OR(E34="LK"),ROUNDUP(D34*(VLOOKUP(B34,'Pedido VACIO'!$H:$AK,30,0))/70,0)*1,IF(E34="CH",D33-F33,""))
E35: =+IF(E34="LK","CH",IF(D35="","",IF(D35>0,"LK","CH"))) | F35: =+IF(OR(E35="LK"),ROUNDUP(D35*(VLOOKUP(B35,'Pedido VACIO'!$H:$AK,30,0))/70,0)*1,IF(E35="CH",D34-F34,""))
A36: {=+IFERROR(INDEX('Pedido VACIO'!$B:$B,MATCH(1,('Pedido VACIO'!$H:$H=$B36)*('Pedido VACIO'!$A:$A="Cia"),0)),"")} | B36: =+B34+1 -> 12 | C36: {=+IFERROR(INDEX('Pedido VACIO'!$F:$F,MATCH(1,('Pedido VACIO'!$H:$H=$B36)*('Pedido VACIO'!$A:$A="Cia"),0)),"")} | D36: {=+IFERROR(INDEX('Pedido VACIO'!$G:$G,MATCH(1,('Pedido VACIO'!$H:$H=$B36)*('Pedido VACIO'!$A:$A="Cia"),0)),"")} | E36: =+IF(E35="LK","CH",IF(D36="","",IF(D36>0,"LK","CH"))) | F36: =+IF(OR(E36="LK"),ROUNDUP(D36*(VLOOKUP(B36,'Pedido VACIO'!$H:$AK,30,0))/70,0)*1,IF(E36="CH",D35-F35,""))
E37: =+IF(E36="LK","CH",IF(D37="","",IF(D37>0,"LK","CH"))) | F37: =+IF(OR(E37="LK"),ROUNDUP(D37*(VLOOKUP(B37,'Pedido VACIO'!$H:$AK,30,0))/70,0)*1,IF(E37="CH",D36-F36,""))
A38: {=+IFERROR(INDEX('Pedido VACIO'!$B:$B,MATCH(1,('Pedido VACIO'!$H:$H=$B38)*('Pedido VACIO'!$A:$A="Cia"),0)),"")} | B38: =+B36+1 -> 13 | C38: {=+IFERROR(INDEX('Pedido VACIO'!$F:$F,MATCH(1,('Pedido VACIO'!$H:$H=$B38)*('Pedido VACIO'!$A:$A="Cia"),0)),"")} | D38: {=+IFERROR(INDEX('Pedido VACIO'!$G:$G,MATCH(1,('Pedido VACIO'!$H:$H=$B38)*('Pedido VACIO'!$A:$A="Cia"),0)),"")} | E38: =+IF(E37="LK","CH",IF(D38="","",IF(D38>0,"LK","CH"))) | F38: =+IF(OR(E38="LK"),ROUNDUP(D38*(VLOOKUP(B38,'Pedido VACIO'!$H:$AK,30,0))/70,0)*1,IF(E38="CH",D37-F37,""))
E39: =+IF(E38="LK","CH",IF(D39="","",IF(D39>0,"LK","CH"))) | F39: =+IF(OR(E39="LK"),ROUNDUP(D39*(VLOOKUP(B39,'Pedido VACIO'!$H:$AK,30,0))/70,0)*1,IF(E39="CH",D38-F38,""))
A40: {=+IFERROR(INDEX('Pedido VACIO'!$B:$B,MATCH(1,('Pedido VACIO'!$H:$H=$B40)*('Pedido VACIO'!$A:$A="Cia"),0)),"")} | B40: =+B38+1 -> 14 | C40: {=+IFERROR(INDEX('Pedido VACIO'!$F:$F,MATCH(1,('Pedido VACIO'!$H:$H=$B40)*('Pedido VACIO'!$A:$A="Cia"),0)),"")} | D40: {=+IFERROR(INDEX('Pedido VACIO'!$G:$G,MATCH(1,('Pedido VACIO'!$H:$H=$B40)*('Pedido VACIO'!$A:$A="Cia"),0)),"")} | E40: =+IF(E39="LK","CH",IF(D40="","",IF(D40>0,"LK","CH"))) | F40: =+IF(OR(E40="LK"),ROUNDUP(D40*(VLOOKUP(B40,'Pedido VACIO'!$H:$AK,30,0))/70,0)*1,IF(E40="CH",D39-F39,""))
E41: =+IF(E40="LK","CH",IF(D41="","",IF(D41>0,"LK","CH"))) | F41: =+IF(OR(E41="LK"),ROUNDUP(D41*(VLOOKUP(B41,'Pedido VACIO'!$H:$AK,30,0))/70,0)*1,IF(E41="CH",D40-F40,""))
A42: {=+IFERROR(INDEX('Pedido VACIO'!$B:$B,MATCH(1,('Pedido VACIO'!$H:$H=$B42)*('Pedido VACIO'!$A:$A="Cia"),0)),"")} | B42: =+B40+1 -> 15 | C42: {=+IFERROR(INDEX('Pedido VACIO'!$F:$F,MATCH(1,('Pedido VACIO'!$H:$H=$B42)*('Pedido VACIO'!$A:$A="Cia"),0)),"")} | D42: {=+IFERROR(INDEX('Pedido VACIO'!$G:$G,MATCH(1,('Pedido VACIO'!$H:$H=$B42)*('Pedido VACIO'!$A:$A="Cia"),0)),"")} | E42: =+IF(E41="LK","CH",IF(D42="","",IF(D42>0,"LK","CH"))) | F42: =+IF(OR(E42="LK"),ROUNDUP(D42*(VLOOKUP(B42,'Pedido VACIO'!$H:$AK,30,0))/70,0)*1,IF(E42="CH",D41-F41,""))
E43: =+IF(E42="LK","CH",IF(D43="","",IF(D43>0,"LK","CH"))) | F43: =+IF(OR(E43="LK"),ROUNDUP(D43*(VLOOKUP(B43,'Pedido VACIO'!$H:$AK,30,0))/70,0)*1,IF(E43="CH",D42-F42,""))

Sheet O.C. Sumatik
A1: Loekemeyer Hnos. S.R.L | F1: Chef SRL
A2: CUIT: | C2: 30-51584245-0 | F2: CUIT: | H2: 30-68575625-7
A3: DIRECCION: | C3: Cervantes 2868 | F3: DIRECCION: | H3: Virgilio 2788
A4: LOCALIDAD: | C4: Villa Devoto, CABA | F4: LOCALIDAD: | H4: Villa Real, CABA
A6: ORDEN DE COMPRA | F6: FECHA PEDIDO: | I6: =+TODAY() -> 46099
A8: RAZON SOCIAL: | C8: SUMATIK | D8: COD PROV: | F8: ENTREGA EN: | I8: Cervantes 2868
A10: FACTURAR Loekemeyer 70% Chef 30%
A12: ESTE PEDIDO ANULA CUALQUIER PEDIDO ANTERIOR
A13: Cód ISIS | B13: N° Ord | C13: Descripcion Material | D13: Pedido KG | E13: Emp | F13: KG a FC | G13: Fecha Pos Ent | H13: Fecha Ent | I13: KG Ent | J13: Fecha Ent | K13: KG Ent | L13: Fecha Ent | M13: KG Ent
A14: {=+IFERROR(INDEX('Pedido VACIO'!$B:$B,MATCH(1,('Pedido VACIO'!$H:$H=$B14)*('Pedido VACIO'!$A:$A="Sumatik"),0)),"")} | B14: 1 | C14: {=+IFERROR(INDEX('Pedido VACIO'!$F:$F,MATCH(1,('Pedido VACIO'!$H:$H=$B14)*('Pedido VACIO'!$A:$A="Sumatik"),0)),"")} | D14: {=+IFERROR(INDEX('Pedido VACIO'!$G:$G,MATCH(1,('Pedido VACIO'!$H:$H=$B14)*('Pedido VACIO'!$A:$A="Sumatik"),0)),"")} | E14: =+IF(E13="LK","CH",IF(D14="","",IF(D14>0,"LK","CH"))) | F14: =+IF(OR(E14="LK"),ROUNDUP(D14*0.7/25,0)*25,IF(E14="CH",D13-F13,""))
E15: =+IF(E14="LK","CH",IF(D15="","",IF(D15>0,"LK","CH"))) | F15: =+IF(OR(E15="LK"),ROUNDUP(D15*0.7/25,0)*25,IF(E15="CH",D14-F14,""))
A16: {=+IFERROR(INDEX('Pedido VACIO'!$B:$B,MATCH(1,('Pedido VACIO'!$H:$H=$B16)*('Pedido VACIO'!$A:$A="Sumatik"),0)),"")} | B16: =+B14+1 -> 2 | C16: {=+IFERROR(INDEX('Pedido VACIO'!$F:$F,MATCH(1,('Pedido VACIO'!$H:$H=$B16)*('Pedido VACIO'!$A:$A="Sumatik"),0)),"")} | D16: {=+IFERROR(INDEX('Pedido VACIO'!$G:$G,MATCH(1,('Pedido VACIO'!$H:$H=$B16)*('Pedido VACIO'!$A:$A="Sumatik"),0)),"")} | E16: =+IF(E15="LK","CH",IF(D16="","",IF(D16>0,"LK","CH"))) | F16: =+IF(OR(E16="LK"),ROUNDUP(D16*0.7/25,0)*25,IF(E16="CH",D15-F15,""))
E17: =+IF(E16="LK","CH",IF(D17="","",IF(D17>0,"LK","CH"))) | F17: =+IF(OR(E17="LK"),ROUNDUP(D17*0.7/25,0)*25,IF(E17="CH",D16-F16,""))
A18: {=+IFERROR(INDEX('Pedido VACIO'!$B:$B,MATCH(1,('Pedido VACIO'!$H:$H=$B18)*('Pedido VACIO'!$A:$A="Sumatik"),0)),"")} | B18: =+B16+1 -> 3 | C18: {=+IFERROR(INDEX('Pedido VACIO'!$F:$F,MATCH(1,('Pedido VACIO'!$H:$H=$B18)*('Pedido VACIO'!$A:$A="Sumatik"),0)),"")} | D18: {=+IFERROR(INDEX('Pedido VACIO'!$G:$G,MATCH(1,('Pedido VACIO'!$H:$H=$B18)*('Pedido VACIO'!$A:$A="Sumatik"),0)),"")} | E18: =+IF(E17="LK","CH",IF(D18="","",IF(D18>0,"LK","CH"))) | F18: =+IF(OR(E18="LK"),ROUNDUP(D18*0.7/25,0)*25,IF(E18="CH",D17-F17,""))
E19: =+IF(E18="LK","CH",IF(D19="","",IF(D19>0,"LK","CH"))) | F19: =+IF(OR(E19="LK"),ROUNDUP(D19*0.7/25,0)*25,IF(E19="CH",D18-F18,""))
A20: {=+IFERROR(INDEX('Pedido VACIO'!$B:$B,MATCH(1,('Pedido VACIO'!$H:$H=$B20)*('Pedido VACIO'!$A:$A="Sumatik"),0)),"")} | B20: =+B18+1 -> 4 | C20: {=+IFERROR(INDEX('Pedido VACIO'!$F:$F,MATCH(1,('Pedido VACIO'!$H:$H=$B20)*('Pedido VACIO'!$A:$A="Sumatik"),0)),"")} | D20: {=+IFERROR(INDEX('Pedido VACIO'!$G:$G,MATCH(1,('Pedido VACIO'!$H:$H=$B20)*('Pedido VACIO'!$A:$A="Sumatik"),0)),"")} | E20: =+IF(E19="LK","CH",IF(D20="","",IF(D20>0,"LK","CH"))) | F20: =+IF(OR(E20="LK"),ROUNDUP(D20*0.7/25,0)*25,IF(E20="CH",D19-F19,""))
E21: =+IF(E20="LK","CH",IF(D21="","",IF(D21>0,"LK","CH"))) | F21: =+IF(OR(E21="LK"),ROUNDUP(D21*0.7/25,0)*25,IF(E21="CH",D20-F20,""))
A22: {=+IFERROR(INDEX('Pedido VACIO'!$B:$B,MATCH(1,('Pedido VACIO'!$H:$H=$B22)*('Pedido VACIO'!$A:$A="Sumatik"),0)),"")} | B22: =+B20+1 -> 5 | C22: {=+IFERROR(INDEX('Pedido VACIO'!$F:$F,MATCH(1,('Pedido VACIO'!$H:$H=$B22)*('Pedido VACIO'!$A:$A="Sumatik"),0)),"")} | D22: {=+IFERROR(INDEX('Pedido VACIO'!$G:$G,MATCH(1,('Pedido VACIO'!$H:$H=$B22)*('Pedido VACIO'!$A:$A="Sumatik"),0)),"")} | E22: =+IF(E21="LK","CH",IF(D22="","",IF(D22>0,"LK","CH"))) | F22: =+IF(OR(E22="LK"),ROUNDUP(D22*0.7/25,0)*25,IF(E22="CH",D21-F21,""))
E23: =+IF(E22="LK","CH",IF(D23="","",IF(D23>0,"LK","CH"))) | F23: =+IF(OR(E23="LK"),ROUNDUP(D23*0.7/25,0)*25,IF(E23="CH",D22-F22,""))
A24: {=+IFERROR(INDEX('Pedido VACIO'!$B:$B,MATCH(1,('Pedido VACIO'!$H:$H=$B24)*('Pedido VACIO'!$A:$A="Sumatik"),0)),"")} | B24: =+B22+1 -> 6 | C24: {=+IFERROR(INDEX('Pedido VACIO'!$F:$F,MATCH(1,('Pedido VACIO'!$H:$H=$B24)*('Pedido VACIO'!$A:$A="Sumatik"),0)),"")} | D24: {=+IFERROR(INDEX('Pedido VACIO'!$G:$G,MATCH(1,('Pedido VACIO'!$H:$H=$B24)*('Pedido VACIO'!$A:$A="Sumatik"),0)),"")} | E24: =+IF(E23="LK","CH",IF(D24="","",IF(D24>0,"LK","CH"))) | F24: =+IF(OR(E24="LK"),ROUNDUP(D24*0.7/25,0)*25,IF(E24="CH",D23-F23,""))
E25: =+IF(E24="LK","CH",IF(D25="","",IF(D25>0,"LK","CH"))) | F25: =+IF(OR(E25="LK"),ROUNDUP(D25*0.7/25,0)*25,IF(E25="CH",D24-F24,""))
A26: {=+IFERROR(INDEX('Pedido VACIO'!$B:$B,MATCH(1,('Pedido VACIO'!$H:$H=$B26)*('Pedido VACIO'!$A:$A="Sumatik"),0)),"")} | B26: =+B24+1 -> 7 | C26: {=+IFERROR(INDEX('Pedido VACIO'!$F:$F,MATCH(1,('Pedido VACIO'!$H:$H=$B26)*('Pedido VACIO'!$A:$A="Sumatik"),0)),"")} | D26: {=+IFERROR(INDEX('Pedido VACIO'!$G:$G,MATCH(1,('Pedido VACIO'!$H:$H=$B26)*('Pedido VACIO'!$A:$A="Sumatik"),0)),"")} | E26: =+IF(E25="LK","CH",IF(D26="","",IF(D26>0,"LK","CH"))) | F26: =+IF(OR(E26="LK"),ROUNDUP(D26*0.7/25,0)*25,IF(E26="CH",D25-F25,""))
E27: =+IF(E26="LK","CH",IF(D27="","",IF(D27>0,"LK","CH"))) | F27: =+IF(OR(E27="LK"),ROUNDUP(D27*0.7/25,0)*25,IF(E27="CH",D26-F26,""))
A28: {=+IFERROR(INDEX('Pedido VACIO'!$B:$B,MATCH(1,('Pedido VACIO'!$H:$H=$B28)*('Pedido VACIO'!$A:$A="Sumatik"),0)),"")} | B28: =+B26+1 -> 8 | C28: {=+IFERROR(INDEX('Pedido VACIO'!$F:$F,MATCH(1,('Pedido VACIO'!$H:$H=$B28)*('Pedido VACIO'!$A:$A="Sumatik"),0)),"")} | D28: {=+IFERROR(INDEX('Pedido VACIO'!$G:$G,MATCH(1,('Pedido VACIO'!$H:$H=$B28)*('Pedido VACIO'!$A:$A="Sumatik"),0)),"")} | E28: =+IF(E27="LK","CH",IF(D28="","",IF(D28>0,"LK","CH"))) | F28: =+IF(OR(E28="LK"),ROUNDUP(D28*0.7/25,0)*25,IF(E28="CH",D27-F27,""))
E29: =+IF(E28="LK","CH",IF(D29="","",IF(D29>0,"LK","CH"))) | F29: =+IF(OR(E29="LK"),ROUNDUP(D29*0.7/25,0)*25,IF(E29="CH",D28-F28,""))
A30: {=+IFERROR(INDEX('Pedido VACIO'!$B:$B,MATCH(1,('Pedido VACIO'!$H:$H=$B30)*('Pedido VACIO'!$A:$A="Sumatik"),0)),"")} | B30: =+B28+1 -> 9 | C30: {=+IFERROR(INDEX('Pedido VACIO'!$F:$F,MATCH(1,('Pedido VACIO'!$H:$H=$B30)*('Pedido VACIO'!$A:$A="Sumatik"),0)),"")} | D30: {=+IFERROR(INDEX('Pedido VACIO'!$G:$G,MATCH(1,('Pedido VACIO'!$H:$H=$B30)*('Pedido VACIO'!$A:$A="Sumatik"),0)),"")} | E30: =+IF(E29="LK","CH",IF(D30="","",IF(D30>0,"LK","CH"))) | F30: =+IF(OR(E30="LK"),ROUNDUP(D30*0.7/25,0)*25,IF(E30="CH",D29-F29,""))
E31: =+IF(E30="LK","CH",IF(D31="","",IF(D31>0,"LK","CH"))) | F31: =+IF(OR(E31="LK"),ROUNDUP(D31*0.7/25,0)*25,IF(E31="CH",D30-F30,""))
A32: {=+IFERROR(INDEX('Pedido VACIO'!$B:$B,MATCH(1,('Pedido VACIO'!$H:$H=$B32)*('Pedido VACIO'!$A:$A="Sumatik"),0)),"")} | B32: =+B30+1 -> 10 | C32: {=+IFERROR(INDEX('Pedido VACIO'!$F:$F,MATCH(1,('Pedido VACIO'!$H:$H=$B32)*('Pedido VACIO'!$A:$A="Sumatik"),0)),"")} | D32: {=+IFERROR(INDEX('Pedido VACIO'!$G:$G,MATCH(1,('Pedido VACIO'!$H:$H=$B32)*('Pedido VACIO'!$A:$A="Sumatik"),0)),"")} | E32: =+IF(E31="LK","CH",IF(D32="","",IF(D32>0,"LK","CH"))) | F32: =+IF(OR(E32="LK"),ROUNDUP(D32*0.7/25,0)*25,IF(E32="CH",D31-F31,""))
E33: =+IF(E32="LK","CH",IF(D33="","",IF(D33>0,"LK","CH"))) | F33: =+IF(OR(E33="LK"),ROUNDUP(D33*0.7/25,0)*25,IF(E33="CH",D32-F32,""))
A34: {=+IFERROR(INDEX('Pedido VACIO'!$B:$B,MATCH(1,('Pedido VACIO'!$H:$H=$B34)*('Pedido VACIO'!$A:$A="Sumatik"),0)),"")} | B34: =+B32+1 -> 11 | C34: {=+IFERROR(INDEX('Pedido VACIO'!$F:$F,MATCH(1,('Pedido VACIO'!$H:$H=$B34)*('Pedido VACIO'!$A:$A="Sumatik"),0)),"")} | D34: {=+IFERROR(INDEX('Pedido VACIO'!$G:$G,MATCH(1,('Pedido VACIO'!$H:$H=$B34)*('Pedido VACIO'!$A:$A="Sumatik"),0)),"")} | E34: =+IF(E33="LK","CH",IF(D34="","",IF(D34>0,"LK","CH"))) | F34: =+IF(OR(E34="LK"),ROUNDUP(D34*0.7/25,0)*25,IF(E34="CH",D33-F33,""))
E35: =+IF(E34="LK","CH",IF(D35="","",IF(D35>0,"LK","CH"))) | F35: =+IF(OR(E35="LK"),ROUNDUP(D35*0.7/25,0)*25,IF(E35="CH",D34-F34,""))
A36: {=+IFERROR(INDEX('Pedido VACIO'!$B:$B,MATCH(1,('Pedido VACIO'!$H:$H=$B36)*('Pedido VACIO'!$A:$A="Sumatik"),0)),"")} | B36: =+B34+1 -> 12 | C36: {=+IFERROR(INDEX('Pedido VACIO'!$F:$F,MATCH(1,('Pedido VACIO'!$H:$H=$B36)*('Pedido VACIO'!$A:$A="Sumatik"),0)),"")} | D36: {=+IFERROR(INDEX('Pedido VACIO'!$G:$G,MATCH(1,('Pedido VACIO'!$H:$H=$B36)*('Pedido VACIO'!$A:$A="Sumatik"),0)),"")} | E36: =+IF(E35="LK","CH",IF(D36="","",IF(D36>0,"LK","CH"))) | F36: =+IF(OR(E36="LK"),ROUNDUP(D36*0.7/25,0)*25,IF(E36="CH",D35-F35,""))
E37: =+IF(E36="LK","CH",IF(D37="","",IF(D37>0,"LK","CH"))) | F37: =+IF(OR(E37="LK"),ROUNDUP(D37*0.7/25,0)*25,IF(E37="CH",D36-F36,""))
A38: {=+IFERROR(INDEX('Pedido VACIO'!$B:$B,MATCH(1,('Pedido VACIO'!$H:$H=$B38)*('Pedido VACIO'!$A:$A="Sumatik"),0)),"")} | B38: =+B36+1 -> 13 | C38: {=+IFERROR(INDEX('Pedido VACIO'!$F:$F,MATCH(1,('Pedido VACIO'!$H:$H=$B38)*('Pedido VACIO'!$A:$A="Sumatik"),0)),"")} | D38: {=+IFERROR(INDEX('Pedido VACIO'!$G:$G,MATCH(1,('Pedido VACIO'!$H:$H=$B38)*('Pedido VACIO'!$A:$A="Sumatik"),0)),"")} | E38: =+IF(E37="LK","CH",IF(D38="","",IF(D38>0,"LK","CH"))) | F38: =+IF(OR(E38="LK"),ROUNDUP(D38*0.7/25,0)*25,IF(E38="CH",D37-F37,""))
E39: =+IF(E38="LK","CH",IF(D39="","",IF(D39>0,"LK","CH"))) | F39: =+IF(OR(E39="LK"),ROUNDUP(D39*0.7/25,0)*25,IF(E39="CH",D38-F38,""))
A40: {=+IFERROR(INDEX('Pedido VACIO'!$B:$B,MATCH(1,('Pedido VACIO'!$H:$H=$B40)*('Pedido VACIO'!$A:$A="Sumatik"),0)),"")} | B40: =+B38+1 -> 14 | C40: {=+IFERROR(INDEX('Pedido VACIO'!$F:$F,MATCH(1,('Pedido VACIO'!$H:$H=$B40)*('Pedido VACIO'!$A:$A="Sumatik"),0)),"")} | D40: {=+IFERROR(INDEX('Pedido VACIO'!$G:$G,MATCH(1,('Pedido VACIO'!$H:$H=$B40)*('Pedido VACIO'!$A:$A="Sumatik"),0)),"")} | E40: =+IF(E39="LK","CH",IF(D40="","",IF(D40>0,"LK","CH"))) | F40: =+IF(OR(E40="LK"),ROUNDUP(D40*0.7/25,0)*25,IF(E40="CH",D39-F39,""))
E41: =+IF(E40="LK","CH",IF(D41="","",IF(D41>0,"LK","CH"))) | F41: =+IF(OR(E41="LK"),ROUNDUP(D41*0.7/25,0)*25,IF(E41="CH",D40-F40,""))
A42: {=+IFERROR(INDEX('Pedido VACIO'!$B:$B,MATCH(1,('Pedido VACIO'!$H:$H=$B42)*('Pedido VACIO'!$A:$A="Sumatik"),0)),"")} | B42: =+B40+1 -> 15 | C42: {=+IFERROR(INDEX('Pedido VACIO'!$F:$F,MATCH(1,('Pedido VACIO'!$H:$H=$B42)*('Pedido VACIO'!$A:$A="Sumatik"),0)),"")} | D42: {=+IFERROR(INDEX('Pedido VACIO'!$G:$G,MATCH(1,('Pedido VACIO'!$H:$H=$B42)*('Pedido VACIO'!$A:$A="Sumatik"),0)),"")} | E42: =+IF(E41="LK","CH",IF(D42="","",IF(D42>0,"LK","CH"))) | F42: =+IF(OR(E42="LK"),ROUNDUP(D42*0.7/25,0)*25,IF(E42="CH",D41-F41,""))
E43: =+IF(E42="LK","CH",IF(D43="","",IF(D43>0,"LK","CH"))) | F43: =+IF(OR(E43="LK"),ROUNDUP(D43*0.7/25,0)*25,IF(E43="CH",D42-F42,""))

Sheet O.C. Packaging y Servicio
A1: Loekemeyer Hnos. S.R.L | F1: Chef SRL
A2: CUIT: | C2: 30-51584245-0 | F2: CUIT: | H2: 30-68575625-7
A3: DIRECCION: | C3: Cervantes 2868 | F3: DIRECCION: | H3: Virgilio 2788
A4: LOCALIDAD: | C4: Villa Devoto, CABA | F4: LOCALIDAD: | H4: Villa Real, CABA
A6: ORDEN DE COMPRA | F6: FECHA PEDIDO: | I6: =+TODAY() -> 46099
A8: RAZON SOCIAL: | C8: PACKAGING Y SERVICIO | D8: COD PROV: | E8: 2983 | F8: ENTREGA EN: | I8: Virgilio 2788
A10: FACTURAR Loekemeyer 70% Chef 30%
A12: ESTE PEDIDO ANULA CUALQUIER PEDIDO ANTERIOR
A13: Cód ISIS | B13: N° Ord | C13: Descripcion Material | D13: Pedido KG | E13: Emp | F13: KG a FC | G13: Fecha Pos Ent | H13: Fecha Ent | I13: KG Ent | J13: Fecha Ent | K13: KG Ent | L13: Fecha Ent | M13: KG Ent
A14: {=+IFERROR(INDEX('Pedido VACIO'!$B:$B,MATCH(1,('Pedido VACIO'!$H:$H=$B14)*('Pedido VACIO'!$A:$A="Packaging y Serv"),0)),"")} | B14: 1 | C14: {=+IFERROR(INDEX('Pedido VACIO'!$F:$F,MATCH(1,('Pedido VACIO'!$H:$H=$B14)*('Pedido VACIO'!$A:$A="Packaging y Serv"),0)),"")} | D14: {=+IFERROR(INDEX('Pedido VACIO'!$G:$G,MATCH(1,('Pedido VACIO'!$H:$H=$B14)*('Pedido VACIO'!$A:$A="Packaging y Serv"),0)),"")} | E14: =+IF(E13="LK","CH",IF(D14="","",IF(D14>0,"LK","CH"))) | F14: =+IF(OR(E14="LK"),ROUNDUP(D14*0.7/25,0)*25,IF(E14="CH",D13-F13,""))
E15: =+IF(E14="LK","CH",IF(D15="","",IF(D15>0,"LK","CH"))) | F15: =+IF(OR(E15="LK"),ROUNDUP(D15*0.7/25,0)*25,IF(E15="CH",D14-F14,""))
A16: {=+IFERROR(INDEX('Pedido VACIO'!$B:$B,MATCH(1,('Pedido VACIO'!$H:$H=$B16)*('Pedido VACIO'!$A:$A="Packaging y Serv"),0)),"")} | B16: =+B14+1 -> 2 | C16: {=+IFERROR(INDEX('Pedido VACIO'!$F:$F,MATCH(1,('Pedido VACIO'!$H:$H=$B16)*('Pedido VACIO'!$A:$A="Packaging y Serv"),0)),"")} | D16: {=+IFERROR(INDEX('Pedido VACIO'!$G:$G,MATCH(1,('Pedido VACIO'!$H:$H=$B16)*('Pedido VACIO'!$A:$A="Packaging y Serv"),0)),"")} | E16: =+IF(E15="LK","CH",IF(D16="","",IF(D16>0,"LK","CH"))) | F16: =+IF(OR(E16="LK"),ROUNDUP(D16*0.7/25,0)*25,IF(E16="CH",D15-F15,""))
E17: =+IF(E16="LK","CH",IF(D17="","",IF(D17>0,"LK","CH"))) | F17: =+IF(OR(E17="LK"),ROUNDUP(D17*0.7/25,0)*25,IF(E17="CH",D16-F16,""))
A18: {=+IFERROR(INDEX('Pedido VACIO'!$B:$B,MATCH(1,('Pedido VACIO'!$H:$H=$B18)*('Pedido VACIO'!$A:$A="Packaging y Serv"),0)),"")} | B18: =+B16+1 -> 3 | C18: {=+IFERROR(INDEX('Pedido VACIO'!$F:$F,MATCH(1,('Pedido VACIO'!$H:$H=$B18)*('Pedido VACIO'!$A:$A="Packaging y Serv"),0)),"")} | D18: {=+IFERROR(INDEX('Pedido VACIO'!$G:$G,MATCH(1,('Pedido VACIO'!$H:$H=$B18)*('Pedido VACIO'!$A:$A="Packaging y Serv"),0)),"")} | E18: =+IF(E17="LK","CH",IF(D18="","",IF(D18>0,"LK","CH"))) | F18: =+IF(OR(E18="LK"),ROUNDUP(D18*0.7/25,0)*25,IF(E18="CH",D17-F17,""))
E19: =+IF(E18="LK","CH",IF(D19="","",IF(D19>0,"LK","CH"))) | F19: =+IF(OR(E19="LK"),ROUNDUP(D19*0.7/25,0)*25,IF(E19="CH",D18-F18,""))
A20: {=+IFERROR(INDEX('Pedido VACIO'!$B:$B,MATCH(1,('Pedido VACIO'!$H:$H=$B20)*('Pedido VACIO'!$A:$A="Packaging y Serv"),0)),"")} | B20: =+B18+1 -> 4 | C20: {=+IFERROR(INDEX('Pedido VACIO'!$F:$F,MATCH(1,('Pedido VACIO'!$H:$H=$B20)*('Pedido VACIO'!$A:$A="Packaging y Serv"),0)),"")} | D20: {=+IFERROR(INDEX('Pedido VACIO'!$G:$G,MATCH(1,('Pedido VACIO'!$H:$H=$B20)*('Pedido VACIO'!$A:$A="Packaging y Serv"),0)),"")} | E20: =+IF(E19="LK","CH",IF(D20="","",IF(D20>0,"LK","CH"))) | F20: =+IF(OR(E20="LK"),ROUNDUP(D20*0.7/25,0)*25,IF(E20="CH",D19-F19,""))
E21: =+IF(E20="LK","CH",IF(D21="","",IF(D21>0,"LK","CH"))) | F21: =+IF(OR(E21="LK"),ROUNDUP(D21*0.7/25,0)*25,IF(E21="CH",D20-F20,""))
A22: {=+IFERROR(INDEX('Pedido VACIO'!$B:$B,MATCH(1,('Pedido VACIO'!$H:$H=$B22)*('Pedido VACIO'!$A:$A="Packaging y Serv"),0)),"")} | B22: =+B20+1 -> 5 | C22: {=+IFERROR(INDEX('Pedido VACIO'!$F:$F,MATCH(1,('Pedido VACIO'!$H:$H=$B22)*('Pedido VACIO'!$A:$A="Packaging y Serv"),0)),"")} | D22: {=+IFERROR(INDEX('Pedido VACIO'!$G:$G,MATCH(1,('Pedido VACIO'!$H:$H=$B22)*('Pedido VACIO'!$A:$A="Packaging y Serv"),0)),"")} | E22: =+IF(E21="LK","CH",IF(D22="","",IF(D22>0,"LK","CH"))) | F22: =+IF(OR(E22="LK"),ROUNDUP(D22*0.7/25,0)*25,IF(E22="CH",D21-F21,""))
E23: =+IF(E22="LK","CH",IF(D23="","",IF(D23>0,"LK","CH"))) | F23: =+IF(OR(E23="LK"),ROUNDUP(D23*0.7/25,0)*25,IF(E23="CH",D22-F22,""))
A24: {=+IFERROR(INDEX('Pedido VACIO'!$B:$B,MATCH(1,('Pedido VACIO'!$H:$H=$B24)*('Pedido VACIO'!$A:$A="Packaging y Serv"),0)),"")} | B24: =+B22+1 -> 6 | C24: {=+IFERROR(INDEX('Pedido VACIO'!$F:$F,MATCH(1,('Pedido VACIO'!$H:$H=$B24)*('Pedido VACIO'!$A:$A="Packaging y Serv"),0)),"")} | D24: {=+IFERROR(INDEX('Pedido VACIO'!$G:$G,MATCH(1,('Pedido VACIO'!$H:$H=$B24)*('Pedido VACIO'!$A:$A="Packaging y Serv"),0)),"")} | E24: =+IF(E23="LK","CH",IF(D24="","",IF(D24>0,"LK","CH"))) | F24: =+IF(OR(E24="LK"),ROUNDUP(D24*0.7/25,0)*25,IF(E24="CH",D23-F23,""))
E25: =+IF(E24="LK","CH",IF(D25="","",IF(D25>0,"LK","CH"))) | F25: =+IF(OR(E25="LK"),ROUNDUP(D25*0.7/25,0)*25,IF(E25="CH",D24-F24,""))
A26: {=+IFERROR(INDEX('Pedido VACIO'!$B:$B,MATCH(1,('Pedido VACIO'!$H:$H=$B26)*('Pedido VACIO'!$A:$A="Packaging y Serv"),0)),"")} | B26: =+B24+1 -> 7 | C26: {=+IFERROR(INDEX('Pedido VACIO'!$F:$F,MATCH(1,('Pedido VACIO'!$H:$H=$B26)*('Pedido VACIO'!$A:$A="Packaging y Serv"),0)),"")} | D26: {=+IFERROR(INDEX('Pedido VACIO'!$G:$G,MATCH(1,('Pedido VACIO'!$H:$H=$B26)*('Pedido VACIO'!$A:$A="Packaging y Serv"),0)),"")} | E26: =+IF(E25="LK","CH",IF(D26="","",IF(D26>0,"LK","CH"))) | F26: =+IF(OR(E26="LK"),ROUNDUP(D26*0.7/25,0)*25,IF(E26="CH",D25-F25,""))
E27: =+IF(E26="LK","CH",IF(D27="","",IF(D27>0,"LK","CH"))) | F27: =+IF(OR(E27="LK"),ROUNDUP(D27*0.7/25,0)*25,IF(E27="CH",D26-F26,""))
A28: {=+IFERROR(INDEX('Pedido VACIO'!$B:$B,MATCH(1,('Pedido VACIO'!$H:$H=$B28)*('Pedido VACIO'!$A:$A="Packaging y Serv"),0)),"")} | B28: =+B26+1 -> 8 | C28: {=+IFERROR(INDEX('Pedido VACIO'!$F:$F,MATCH(1,('Pedido VACIO'!$H:$H=$B28)*('Pedido VACIO'!$A:$A="Packaging y Serv"),0)),"")} | D28: {=+IFERROR(INDEX('Pedido VACIO'!$G:$G,MATCH(1,('Pedido VACIO'!$H:$H=$B28)*('Pedido VACIO'!$A:$A="Packaging y Serv"),0)),"")} | E28: =+IF(E27="LK","CH",IF(D28="","",IF(D28>0,"LK","CH"))) | F28: =+IF(OR(E28="LK"),ROUNDUP(D28*0.7/25,0)*25,IF(E28="CH",D27-F27,""))
E29: =+IF(E28="LK","CH",IF(D29="","",IF(D29>0,"LK","CH"))) | F29: =+IF(OR(E29="LK"),ROUNDUP(D29*0.7/25,0)*25,IF(E29="CH",D28-F28,""))
A30: {=+IFERROR(INDEX('Pedido VACIO'!$B:$B,MATCH(1,('Pedido VACIO'!$H:$H=$B30)*('Pedido VACIO'!$A:$A="Packaging y Serv"),0)),"")} | B30: =+B28+1 -> 9 | C30: {=+IFERROR(INDEX('Pedido VACIO'!$F:$F,MATCH(1,('Pedido VACIO'!$H:$H=$B30)*('Pedido VACIO'!$A:$A="Packaging y Serv"),0)),"")} | D30: {=+IFERROR(INDEX('Pedido VACIO'!$G:$G,MATCH(1,('Pedido VACIO'!$H:$H=$B30)*('Pedido VACIO'!$A:$A="Packaging y Serv"),0)),"")} | E30: =+IF(E29="LK","CH",IF(D30="","",IF(D30>0,"LK","CH"))) | F30: =+IF(OR(E30="LK"),ROUNDUP(D30*0.7/25,0)*25,IF(E30="CH",D29-F29,""))
E31: =+IF(E30="LK","CH",IF(D31="","",IF(D31>0,"LK","CH"))) | F31: =+IF(OR(E31="LK"),ROUNDUP(D31*0.7/25,0)*25,IF(E31="CH",D30-F30,""))
A32: {=+IFERROR(INDEX('Pedido VACIO'!$B:$B,MATCH(1,('Pedido VACIO'!$H:$H=$B32)*('Pedido VACIO'!$A:$A="Packaging y Serv"),0)),"")} | B32: =+B30+1 -> 10 | C32: {=+IFERROR(INDEX('Pedido VACIO'!$F:$F,MATCH(1,('Pedido VACIO'!$H:$H=$B32)*('Pedido VACIO'!$A:$A="Packaging y Serv"),0)),"")} | D32: {=+IFERROR(INDEX('Pedido VACIO'!$G:$G,MATCH(1,('Pedido VACIO'!$H:$H=$B32)*('Pedido VACIO'!$A:$A="Packaging y Serv"),0)),"")} | E32: =+IF(E31="LK","CH",IF(D32="","",IF(D32>0,"LK","CH"))) | F32: =+IF(OR(E32="LK"),ROUNDUP(D32*0.7/25,0)*25,IF(E32="CH",D31-F31,""))
E33: =+IF(E32="LK","CH",IF(D33="","",IF(D33>0,"LK","CH"))) | F33: =+IF(OR(E33="LK"),ROUNDUP(D33*0.7/25,0)*25,IF(E33="CH",D32-F32,""))
A34: {=+IFERROR(INDEX('Pedido VACIO'!$B:$B,MATCH(1,('Pedido VACIO'!$H:$H=$B34)*('Pedido VACIO'!$A:$A="Packaging y Serv"),0)),"")} | B34: =+B32+1 -> 11 | C34: {=+IFERROR(INDEX('Pedido VACIO'!$F:$F,MATCH(1,('Pedido VACIO'!$H:$H=$B34)*('Pedido VACIO'!$A:$A="Packaging y Serv"),0)),"")} | D34: {=+IFERROR(INDEX('Pedido VACIO'!$G:$G,MATCH(1,('Pedido VACIO'!$H:$H=$B34)*('Pedido VACIO'!$A:$A="Packaging y Serv"),0)),"")} | E34: =+IF(E33="LK","CH",IF(D34="","",IF(D34>0,"LK","CH"))) | F34: =+IF(OR(E34="LK"),ROUNDUP(D34*0.7/25,0)*25,IF(E34="CH",D33-F33,""))
E35: =+IF(E34="LK","CH",IF(D35="","",IF(D35>0,"LK","CH"))) | F35: =+IF(OR(E35="LK"),ROUNDUP(D35*0.7/25,0)*25,IF(E35="CH",D34-F34,""))
A36: {=+IFERROR(INDEX('Pedido VACIO'!$B:$B,MATCH(1,('Pedido VACIO'!$H:$H=$B36)*('Pedido VACIO'!$A:$A="Packaging y Serv"),0)),"")} | B36: =+B34+1 -> 12 | C36: {=+IFERROR(INDEX('Pedido VACIO'!$F:$F,MATCH(1,('Pedido VACIO'!$H:$H=$B36)*('Pedido VACIO'!$A:$A="Packaging y Serv"),0)),"")} | D36: {=+IFERROR(INDEX('Pedido VACIO'!$G:$G,MATCH(1,('Pedido VACIO'!$H:$H=$B36)*('Pedido VACIO'!$A:$A="Packaging y Serv"),0)),"")} | E36: =+IF(E35="LK","CH",IF(D36="","",IF(D36>0,"LK","CH"))) | F36: =+IF(OR(E36="LK"),ROUNDUP(D36*0.7/25,0)*25,IF(E36="CH",D35-F35,""))
E37: =+IF(E36="LK","CH",IF(D37="","",IF(D37>0,"LK","CH"))) | F37: =+IF(OR(E37="LK"),ROUNDUP(D37*0.7/25,0)*25,IF(E37="CH",D36-F36,""))
A38: {=+IFERROR(INDEX('Pedido VACIO'!$B:$B,MATCH(1,('Pedido VACIO'!$H:$H=$B38)*('Pedido VACIO'!$A:$A="Packaging y Serv"),0)),"")} | B38: =+B36+1 -> 13 | C38: {=+IFERROR(INDEX('Pedido VACIO'!$F:$F,MATCH(1,('Pedido VACIO'!$H:$H=$B38)*('Pedido VACIO'!$A:$A="Packaging y Serv"),0)),"")} | D38: {=+IFERROR(INDEX('Pedido VACIO'!$G:$G,MATCH(1,('Pedido VACIO'!$H:$H=$B38)*('Pedido VACIO'!$A:$A="Packaging y Serv"),0)),"")} | E38: =+IF(E37="LK","CH",IF(D38="","",IF(D38>0,"LK","CH"))) | F38: =+IF(OR(E38="LK"),ROUNDUP(D38*0.7/25,0)*25,IF(E38="CH",D37-F37,""))
E39: =+IF(E38="LK","CH",IF(D39="","",IF(D39>0,"LK","CH"))) | F39: =+IF(OR(E39="LK"),ROUNDUP(D39*0.7/25,0)*25,IF(E39="CH",D38-F38,""))
A40: {=+IFERROR(INDEX('Pedido VACIO'!$B:$B,MATCH(1,('Pedido VACIO'!$H:$H=$B40)*('Pedido VACIO'!$A:$A="Packaging y Serv"),0)),"")} | B40: =+B38+1 -> 14 | C40: {=+IFERROR(INDEX('Pedido VACIO'!$F:$F,MATCH(1,('Pedido VACIO'!$H:$H=$B40)*('Pedido VACIO'!$A:$A="Packaging y Serv"),0)),"")} | D40: {=+IFERROR(INDEX('Pedido VACIO'!$G:$G,MATCH(1,('Pedido VACIO'!$H:$H=$B40)*('Pedido VACIO'!$A:$A="Packaging y Serv"),0)),"")} | E40: =+IF(E39="LK","CH",IF(D40="","",IF(D40>0,"LK","CH"))) | F40: =+IF(OR(E40="LK"),ROUNDUP(D40*0.7/25,0)*25,IF(E40="CH",D39-F39,""))
E41: =+IF(E40="LK","CH",IF(D41="","",IF(D41>0,"LK","CH"))) | F41: =+IF(OR(E41="LK"),ROUNDUP(D41*0.7/25,0)*25,IF(E41="CH",D40-F40,""))
A42: {=+IFERROR(INDEX('Pedido VACIO'!$B:$B,MATCH(1,('Pedido VACIO'!$H:$H=$B42)*('Pedido VACIO'!$A:$A="Packaging y Serv"),0)),"")} | B42: =+B40+1 -> 15 | C42: {=+IFERROR(INDEX('Pedido VACIO'!$F:$F,MATCH(1,('Pedido VACIO'!$H:$H=$B42)*('Pedido VACIO'!$A:$A="Packaging y Serv"),0)),"")} | D42: {=+IFERROR(INDEX('Pedido VACIO'!$G:$G,MATCH(1,('Pedido VACIO'!$H:$H=$B42)*('Pedido VACIO'!$A:$A="Packaging y Serv"),0)),"")} | E42: =+IF(E41="LK","CH",IF(D42="","",IF(D42>0,"LK","CH"))) | F42: =+IF(OR(E42="LK"),ROUNDUP(D42*0.7/25,0)*25,IF(E42="CH",D41-F41,""))
E43: =+IF(E42="LK","CH",IF(D43="","",IF(D43>0,"LK","CH"))) | F43: =+IF(OR(E43="LK"),ROUNDUP(D43*0.7/25,0)*25,IF(E43="CH",D42-F42,""))

Sheet O.C. Precinter
A1: Loekemeyer Hnos. S.R.L | F1: Chef SRL
A2: CUIT: | C2: 30-51584245-0 | F2: CUIT: | H2: 30-68575625-7
A3: DIRECCION: | C3: Cervantes 2868 | F3: DIRECCION: | H3: Virgilio 2788
A4: LOCALIDAD: | C4: Villa Devoto, CABA | F4: LOCALIDAD: | H4: Villa Real, CABA
A6: ORDEN DE COMPRA | F6: FECHA PEDIDO: | I6: =+TODAY() -> 46099
A8: RAZON SOCIAL: | C8: PRECINTER | D8: COD PROV: | E8: 4227 | F8: ENTREGA EN: | I8: Cervantes 2868
A10: FACTURAR Loekemeyer 70% Chef 30%
A12: ESTE PEDIDO ANULA CUALQUIER PEDIDO ANTERIOR
A13: Cód ISIS | B13: N° Ord | C13: Descripcion Material | D13: Pedido Uni | E13: Emp | F13: Uni a FC | G13: Fecha Pos Ent | H13: Fecha Ent | I13: Uni Ent | J13: Fecha Ent | K13: Uni Ent | L13: Fecha Ent | M13: Uni Ent
A14: {=+IFERROR(INDEX('Pedido VACIO'!$B:$B,MATCH(1,('Pedido VACIO'!$H:$H=$B14)*('Pedido VACIO'!$A:$A="Precinter"),0)),"")} | B14: 1 | C14: {=+IFERROR(INDEX('Pedido VACIO'!$F:$F,MATCH(1,('Pedido VACIO'!$H:$H=$B14)*('Pedido VACIO'!$A:$A="Precinter"),0)),"")} | D14: {=+IFERROR(INDEX('Pedido VACIO'!$G:$G,MATCH(1,('Pedido VACIO'!$H:$H=$B14)*('Pedido VACIO'!$A:$A="Precinter"),0)),"")} | E14: =+IF(E13="LK","CH",IF(D14="","",IF(D14>0,"LK","CH"))) | F14: =+IF(OR(E14="LK"),ROUNDUP(D14*0.7/25,0)*25,IF(E14="CH",D13-F13,""))
E15: =+IF(E14="LK","CH",IF(D15="","",IF(D15>0,"LK","CH"))) | F15: =+IF(OR(E15="LK"),ROUNDUP(D15*0.7/25,0)*25,IF(E15="CH",D14-F14,""))
A16: {=+IFERROR(INDEX('Pedido VACIO'!$B:$B,MATCH(1,('Pedido VACIO'!$H:$H=$B16)*('Pedido VACIO'!$A:$A="Precinter"),0)),"")} | B16: =+B14+1 -> 2 | C16: {=+IFERROR(INDEX('Pedido VACIO'!$F:$F,MATCH(1,('Pedido VACIO'!$H:$H=$B16)*('Pedido VACIO'!$A:$A="Precinter"),0)),"")} | D16: {=+IFERROR(INDEX('Pedido VACIO'!$G:$G,MATCH(1,('Pedido VACIO'!$H:$H=$B16)*('Pedido VACIO'!$A:$A="Precinter"),0)),"")} | E16: =+IF(E15="LK","CH",IF(D16="","",IF(D16>0,"LK","CH"))) | F16: =+IF(OR(E16="LK"),ROUNDUP(D16*0.7/25,0)*25,IF(E16="CH",D15-F15,""))
E17: =+IF(E16="LK","CH",IF(D17="","",IF(D17>0,"LK","CH"))) | F17: =+IF(OR(E17="LK"),ROUNDUP(D17*0.7/25,0)*25,IF(E17="CH",D16-F16,""))
A18: {=+IFERROR(INDEX('Pedido VACIO'!$B:$B,MATCH(1,('Pedido VACIO'!$H:$H=$B18)*('Pedido VACIO'!$A:$A="Precinter"),0)),"")} | B18: =+B16+1 -> 3 | C18: {=+IFERROR(INDEX('Pedido VACIO'!$F:$F,MATCH(1,('Pedido VACIO'!$H:$H=$B18)*('Pedido VACIO'!$A:$A="Precinter"),0)),"")} | D18: {=+IFERROR(INDEX('Pedido VACIO'!$G:$G,MATCH(1,('Pedido VACIO'!$H:$H=$B18)*('Pedido VACIO'!$A:$A="Precinter"),0)),"")} | E18: =+IF(E17="LK","CH",IF(D18="","",IF(D18>0,"LK","CH"))) | F18: =+IF(OR(E18="LK"),ROUNDUP(D18*0.7/25,0)*25,IF(E18="CH",D17-F17,""))
E19: =+IF(E18="LK","CH",IF(D19="","",IF(D19>0,"LK","CH"))) | F19: =+IF(OR(E19="LK"),ROUNDUP(D19*0.7/25,0)*25,IF(E19="CH",D18-F18,""))
A20: {=+IFERROR(INDEX('Pedido VACIO'!$B:$B,MATCH(1,('Pedido VACIO'!$H:$H=$B20)*('Pedido VACIO'!$A:$A="Precinter"),0)),"")} | B20: =+B18+1 -> 4 | C20: {=+IFERROR(INDEX('Pedido VACIO'!$F:$F,MATCH(1,('Pedido VACIO'!$H:$H=$B20)*('Pedido VACIO'!$A:$A="Precinter"),0)),"")} | D20: {=+IFERROR(INDEX('Pedido VACIO'!$G:$G,MATCH(1,('Pedido VACIO'!$H:$H=$B20)*('Pedido VACIO'!$A:$A="Precinter"),0)),"")} | E20: =+IF(E19="LK","CH",IF(D20="","",IF(D20>0,"LK","CH"))) | F20: =+IF(OR(E20="LK"),ROUNDUP(D20*0.7/25,0)*25,IF(E20="CH",D19-F19,""))
E21: =+IF(E20="LK","CH",IF(D21="","",IF(D21>0,"LK","CH"))) | F21: =+IF(OR(E21="LK"),ROUNDUP(D21*0.7/25,0)*25,IF(E21="CH",D20-F20,""))
A22: {=+IFERROR(INDEX('Pedido VACIO'!$B:$B,MATCH(1,('Pedido VACIO'!$H:$H=$B22)*('Pedido VACIO'!$A:$A="Precinter"),0)),"")} | B22: =+B20+1 -> 5 | C22: {=+IFERROR(INDEX('Pedido VACIO'!$F:$F,MATCH(1,('Pedido VACIO'!$H:$H=$B22)*('Pedido VACIO'!$A:$A="Precinter"),0)),"")} | D22: {=+IFERROR(INDEX('Pedido VACIO'!$G:$G,MATCH(1,('Pedido VACIO'!$H:$H=$B22)*('Pedido VACIO'!$A:$A="Precinter"),0)),"")} | E22: =+IF(E21="LK","CH",IF(D22="","",IF(D22>0,"LK","CH"))) | F22: =+IF(OR(E22="LK"),ROUNDUP(D22*0.7/25,0)*25,IF(E22="CH",D21-F21,""))
E23: =+IF(E22="LK","CH",IF(D23="","",IF(D23>0,"LK","CH"))) | F23: =+IF(OR(E23="LK"),ROUNDUP(D23*0.7/25,0)*25,IF(E23="CH",D22-F22,""))
A24: {=+IFERROR(INDEX('Pedido VACIO'!$B:$B,MATCH(1,('Pedido VACIO'!$H:$H=$B24)*('Pedido VACIO'!$A:$A="Precinter"),0)),"")} | B24: =+B22+1 -> 6 | C24: {=+IFERROR(INDEX('Pedido VACIO'!$F:$F,MATCH(1,('Pedido VACIO'!$H:$H=$B24)*('Pedido VACIO'!$A:$A="Precinter"),0)),"")} | D24: {=+IFERROR(INDEX('Pedido VACIO'!$G:$G,MATCH(1,('Pedido VACIO'!$H:$H=$B24)*('Pedido VACIO'!$A:$A="Precinter"),0)),"")} | E24: =+IF(E23="LK","CH",IF(D24="","",IF(D24>0,"LK","CH"))) | F24: =+IF(OR(E24="LK"),ROUNDUP(D24*0.7/25,0)*25,IF(E24="CH",D23-F23,""))
E25: =+IF(E24="LK","CH",IF(D25="","",IF(D25>0,"LK","CH"))) | F25: =+IF(OR(E25="LK"),ROUNDUP(D25*0.7/25,0)*25,IF(E25="CH",D24-F24,""))
