Workbook

Sheet Flejes
A1: Orden | B1: Sector | C1: N° Fleje | D1: Descripción Material | E1: Medida mm | F1: Max 3 Mes KG | G1: Max 6 Mes KG | H1: Max 3 Mes Rollo Correct | I1: Max 3 Mes Rollo Actual | K1: Kg x Rollo | L1: Ubi
A2: 1 | B2: A1/2 | C2: 13 | D2: Cuerpo Uña Laminado | E2: 84 x 1,75 | F2: 0 | H2: =F2/K2 -> 0 | I2: 6 | K2: 71 | L2: +
A3: 2 | B3: A3 | C3: 1 | D3: Mgo Plano Manija | E3: 19 x 2,1 | F3: 849.01582 | G3: 1698.0316 | H3: =F3/K3 -> 10.612698 | I3: 11 | K3: 80 | L3: + | P3: C y Faltantes quedan pendientes
A4: 3 | B4: A4 | D4: Vacio | L4: +
A5: 4 | B5: A5 | C5: 39 | D5: Pinza De Fideos | E5: 136 x 0,8 | F5: 52.113083 | G5: 104.22617 | H5: =F5/K5 -> 0.56035573 | I5: 1 | K5: 93 | L5: +
A6: 5 | B6: A6 | C6: 29 | D6: Patita | E6: 91 x 1,75 | F6: 396.38243 | G6: 792.76486 | H6: =F6/K6 -> 3.9638243 | I6: 4 | K6: 100
A7: 6 | B7: A7 | C7: 26 | D7: Resorte p/ Pinza | E7: 92 x 1,25 | F7: 61.566437 | G7: 123.13287 | H7: =F7/K7 -> 0.70766019 | I7: 1 | K7: 87 | L7: +
A8: 7 | B8: A8 | C8: 36 | D8: Arandela Base | E8: 40 x 1,5 | F8: 67.825512 | G8: 135.65102 | H8: =F8/K8 -> 1.2797266 | I8: 2 | K8: 53 | L8: +
A9: 8 | B9: A9 | C9: 76 | D9: Esses | E9: 19 x 0.8 | F9: 39.018599 | G9: 78.037199 | H9: =F9/K9 -> 3.5471454 | I9: 3 | K9: 11 | L9: +
A10: 9 | B10: A10 | C10: 85 | D10: Cuchilla Pelador Inox (NO USA) | E10: 13.6 x 0.8 | F10: 0 | G10: 0 | H10: =F10/K10 -> 0 | I10: 17 | K10: 25
A11: 10 | B11: A11 | C11: 8 | D11: Engranaje Chico | E11: 33 x 2 | F11: 101.94257 | G11: 203.88513 | H11: =F11/K11 -> 1.9604339 | I11: 2 | K11: 52
A12: 11 | B12: A12 | C12: 23 | D12: Piruli y Cuchufli | E12: 20 x 2,8 | F12: 223.47539 | G12: 446.95079 | H12: =F12/K12 -> 2.9796719 | I12: 3 | K12: 75 | L12: -
A13: 12 | B13: B1 | C13: 84 | D13: Mango Pelador Inox | E13: 11 x 0.8 | F13: 0 | G13: 0 | H13: =F13/K13 -> 0 | I13: 31 | K13: 30 | L13: +
A14: 13 | B14: B2 | C14: 41 | D14: Disc Pisa-Gde C Pizza-Hoja C Untar Mad | E14: 84 x 1 | F14: 467.48161 | G14: 934.96322 | H14: =F14/K14 -> 7.7913602 | I14: 10 | K14: 60
A15: 14 | B15: B3 | C15: 6 | D15: Mgo Plano Marip | E15: 18,5 x 1,9 | F15: 1092.6293 | G15: 2185.2586 | H15: =F15/K15 -> 18.210488 | I15: 18 | K15: 60 | L15: -
A16: 15 | B16: B4 | C16: 57 | D16: Uñas Nuevo | E16: 66 x 1.2 | F16: 456.04669 | G16: 912.09338 | H16: =F16/K16 -> 6.3339818 | I16: 6 | K16: 72 | L16: -
A17: 16 | B17: B5 | C17: 7 | D17: Marip De Abrelatas | E17: 60 x 2,1 | F17: 389.23525 | G17: 778.4705 | H17: =F17/K17 -> 3.4445597 | I17: 3 | K17: 113
A18: 17 | B18: B6 | C18: 24 | D18: Cabezales | E18: 42 x 1,5 | F18: 747.4346 | G18: 1494.8692 | H18: =F18/K18 -> 11.15574 | I18: 11 | K18: 67
A19: 18 | B19: B7 | C19: 59 | D19: Vast. C Pizza/ Flech. Ahueca | E19: 60 x 2 | F19: 34.124976 | G19: 68.249952 | H19: =F19/K19 -> 0.34821404 | I19: 1 | K19: 98
A20: 19 | B20: B8 | C20: 3 | D20: Engranaje Grande | E20: 40 X 1,9 | F20: 151.60997 | G20: 303.21994 | H20: =F20/K20 -> 1.7836467 | I20: 1 | K20: 85
B21: C1 | C21: 25 | D21: Sacatapitas | E21: 76,5 x 2,8 | F21: 348.17938 | G21: 696.35876 | H21: =F21/K21 -> 4.4638382 | I21: 4 | K21: 78 | L21: -
B22: C2 | C22: 2 | D22: Cuchilla De Abrelatas | E22: 65 x 1,25 | F22: 662.31799 | G22: 1324.636 | H22: =F22/K22 -> 5.8612211 | I22: 5 | K22: 113 | L22: +
B23: C6 | C23: 77 | D23: Hoja Cuchillo Untar Mgo Plast | E23: 64 x 1 | F23: 0 | H23: =F23/K23 -> 0 | I23: Discon | K23: 45 | L23: +
B24: C7 | C24: 4 | D24: Buje De Manija | E24: 46 x 2,1 | F24: 59.952433 | G24: 119.90487 | H24: =F24/K24 -> 0.98282677 | I24: 1 | K24: 61 | L24: +
B25: C8 | C25: 62 | D25: Vast. C Pizza Gastr. | E25: 75.5 x 2 | F25: 57.066128 | G25: 114.13226 | H25: =F25/K25 -> 0.7133266 | I25: 1 | K25: 80 | L25: +
B26: P1 | C26: 85 | D26: Cuchilla Pelador | E26: 13.6 x 0.8 | F26: 0 | G26: 0 | H26: =F26/K26 -> 0 | I26: 17 | K26: 33
B27: P1 | D27: Vacio
B28: P12/13 | C28: 12 | D28: Cuerpo Uña | E28: 84 x 1,75Cha | F28: 1541.1408 | G28: 3082.2816 | H28: =F28/K28 -> 19.26426 | I28: 10 | K28: 80 | L28: +
B29: P2 | C29: 44 | D29: Cucharon. Inox | E29: 130 x 0,9 | F29: 84.752179 | G29: 169.50436 | H29: =F29/K29 -> 1.0865664 | I29: 1 | K29: 78
B30: P3 | C30: 16 | D30: Pieza Gde Sacaf. | E30: 77 x 1,40 | F30: 140.00917 | G30: 280.01835 | H30: =F30/K30 -> 1.9719602 | I30: 2 | K30: 71
B31: P4 | D31: Rollos en Desuso
B32: P5 | C32: 43 | D32: Cuchara y Espatula. Inox | E32: 123 x 0,8 | F32: 120.39427 | G32: 240.78855 | H32: =F32/K32 -> 1.4332652 | I32: 1 | K32: 84
B33: P6 | D33: Vacio
B34: P7 | C34: 45 | D34: Pinza Ensalada | E34: 117 x 0,8 | F34: 121.69883 | G34: 243.39766 | H34: =F34/K34 -> 1.5212354 | I34: 2 | K34: 80
B35: P8 | C35: 17 | D35: Pieza Chica Sacaf | E35: 95 x 1,4 | F35: 54.192499 | G35: 108.385 | H35: =F35/K35 -> 0.54192499 | I35: 1 | K35: 100 | L35: +
B36: P9/10 | C36: 22 | D36: Cpo Sacacorchos | E36: 121 x 1,20 | F36: 1221.5217 | G36: 2443.0434 | H36: =F36/K36 -> 17.45031 | I36: 17 | K36: 70
C37: 5 | D37: Arandela Fina Manija | E37: 38 x 0,55 | F37: 25.710524 | G37: 51.421047 | H37: =F37/K37 -> 0.40810355 | K37: 63 | L37: +
C38: 9 | D38: Arandela Fina Marip. | E38: 33 x 0,6 | F38: 28.671346 | G38: 57.342693 | H38: =F38/K38 -> 0.44798979 | K38: 64
C39: 10 | D39: Arandela Gde/Chica Afila | E39: 77 x 1,25 | F39: 112.58173 | G39: 225.16345 | H39: =F39/K39 -> 1.4072716 | K39: 80 | L39: +
C40: 15 | D40: Rompenueces | E40: 190 x 1,25 | F40: 191.12533 | G40: 382.25066 | K40: 0
...

Sheet Carteles Sector Provisorio
A3: A1/2 | D3: N° | E3: =+VLOOKUP(A3,Flejes!B:H,2,) -> 13 | H3: C4 | K3: A | O3: C5 | R3: A
A11: =+VLOOKUP(A3,Flejes!B:H,4,) -> 84 x 1,75 | E11: =+VLOOKUP(A3,Flejes!B:L,11) -> + | H11: Pinza Corta | L11: =+VLOOKUP(H3,Flejes!B:L,11) -> + | O11: Bocha Cruda Ahuecafruta | S11: =+VLOOKUP(O3,Flejes!I:S,11) -> #N/A
A17: Max Rollo: | C17: =+VLOOKUP(A3,Flejes!B:H,7,) -> 0 | H17: Max : | J17: =2 -> 2 | O17: Max : | Q17: =2 -> 2
A23: A3 | D23: N° | E23: =+VLOOKUP(A23,Flejes!B:H,2,) -> 1 | H23: C4 | K23: B | O23: C5 | R23: B
A31: =+VLOOKUP(A23,Flejes!B:H,4,) -> 19 x 2,1 | E31: =+VLOOKUP(A23,Flejes!B:L,11) -> + | H31: Pinza Larga | L31: =+VLOOKUP(H23,Flejes!B:L,11) -> + | O31: Bocha Cruda Ahuecapapa | S31: =+VLOOKUP(O23,Flejes!I:S,11) -> #N/A
A37: Max Rollo: | C37: =+VLOOKUP(A23,Flejes!B:H,7,) -> 10.612698 | H37: Max : | J37: =2 -> 2 | O37: Max : | Q37: =2 -> 2
A43: A4 | D43: N° | E43: =+VLOOKUP(A43,Flejes!B:H,2,) -> 0 | H43: A11 | K43: N° | L43: =+VLOOKUP(H43,Flejes!B:H,2,) -> 8 | O43: C6
A51: =+VLOOKUP(A43,Flejes!B:H,4,) -> 0 | E51: =+VLOOKUP(A43,Flejes!B:L,11) -> + | H51: =+VLOOKUP(H43,Flejes!B:H,4,) -> 33 x 2 | L51: =+VLOOKUP(H43,Flejes!B:L,11) -> + | O51: Flechita Cruda Estampada | S51: =+VLOOKUP(O43,Flejes!I:S,11) -> #N/A
A57: Max Rollo: | C57: =+VLOOKUP(A43,Flejes!B:H,7,) -> 0 | H57: Max Rollo: | J57: =+VLOOKUP(H43,Flejes!B:H,7,) -> 1.9604339 | O57: Max : | Q57: 4
A63: A5 | D63: N° | E63: =+VLOOKUP(A63,Flejes!B:H,2,) -> 39 | H63: A12 | K63: N° | L63: =+VLOOKUP(H63,Flejes!B:H,2,) -> 23 | O63: D1
A71: =+VLOOKUP(A63,Flejes!B:H,4,) -> 136 x 0,8 | E71: =+VLOOKUP(A63,Flejes!B:L,11) -> + | H71: =+VLOOKUP(H63,Flejes!B:H,4,) -> 20 x 2,8 | L71: =+VLOOKUP(H63,Flejes!B:L,11) -> + | O71: Ahuecafruta p/Cromar | S71: =+VLOOKUP(O63,Flejes!I:S,11) -> #N/A
A77: Max Rollo: | C77: =+VLOOKUP(A63,Flejes!B:H,7,) -> 0.56035573 | H77: Max Rollo: | J77: =+VLOOKUP(H63,Flejes!B:H,7,) -> 2.9796719 | O77: Max : | Q77: 2
A83: A6 | D83: N° | E83: =+VLOOKUP(A83,Flejes!B:H,2,) -> 29 | H83: B1 | K83: N° | L83: =+VLOOKUP(H83,Flejes!B:H,2,) -> 84 | O83: D2
A91: =+VLOOKUP(A83,Flejes!B:H,4,) -> 91 x 1,75 | E91: =+VLOOKUP(A83,Flejes!B:L,11) -> 0 | H91: =+VLOOKUP(H83,Flejes!B:H,4,) -> 11 x 0.8 | L91: =+VLOOKUP(H83,Flejes!B:L,11) -> + | O91: Ahuecapapa p/Cromar | S91: =+VLOOKUP(O83,Flejes!I:S,11) -> #N/A
A97: Max Rollo: | C97: =+VLOOKUP(A83,Flejes!B:H,7,) -> 3.9638243 | H97: Max Rollo: | J97: =+VLOOKUP(H83,Flejes!B:H,7,) -> 0 | O97: Max : | Q97: 2
A103: A7 | D103: N° | E103: =+VLOOKUP(A103,Flejes!B:H,2,) -> 26 | H103: B2 | K103: N° | L103: =+VLOOKUP(H103,Flejes!B:H,2,) -> 41
A111: =+VLOOKUP(A103,Flejes!B:H,4,) -> 92 x 1,25 | E111: =+VLOOKUP(A103,Flejes!B:L,11) -> + | H111: =+VLOOKUP(H103,Flejes!B:H,4,) -> 84 x 1 | L111: =+VLOOKUP(H103,Flejes!B:L,11) -> 0 | O111: Alambre Filtro Café | S111: =+VLOOKUP(O103,Flejes!I:S,11) -> #N/A
A117: Max Rollo: | C117: =+VLOOKUP(A103,Flejes!B:H,7,) -> 0.70766019 | H117: Max Rollo: | J117: =+VLOOKUP(H103,Flejes!B:H,7,) -> 7.7913602 | O117: Max : | Q117: 6
A123: A8 | D123: N° | E123: =+VLOOKUP(A123,Flejes!B:H,2,) -> 36 | H123: B3 | K123: N° | L123: =+VLOOKUP(H123,Flejes!B:H,2,) -> 6
A131: =+VLOOKUP(A123,Flejes!B:H,4,) -> 40 x 1,5 | E131: =+VLOOKUP(A123,Flejes!B:L,11) -> + | H131: =+VLOOKUP(H123,Flejes!B:H,4,) -> 18,5 x 1,9 | L131: =+VLOOKUP(H123,Flejes!B:L,11) -> -
A137: Max Rollo: | C137: =+VLOOKUP(A123,Flejes!B:H,7,) -> 1.2797266 | H137: Max Rollo: | J137: =+VLOOKUP(H123,Flejes!B:H,7,) -> 18.210488

Sheet Carteles
A3: A1/2 | D3: N° | E3: =+VLOOKUP(A3,Flejes!B:H,2,) -> 13 | H3: A9 | K3: N° | L3: =+VLOOKUP(H3,Flejes!B:H,2,) -> 76
A11: =+VLOOKUP(A3,Flejes!B:H,4,) -> 84 x 1,75 | E11: =+VLOOKUP(A3,Flejes!B:L,11) -> + | H11: =+VLOOKUP(H3,Flejes!B:H,4,) -> 19 x 0.8 | L11: =+VLOOKUP(H3,Flejes!B:L,11) -> -
A17: Max Rollo: | C17: =+VLOOKUP(A3,Flejes!B:H,7,) -> 0 | H17: Max Rollo: | J17: =+VLOOKUP(H3,Flejes!B:H,7,) -> 3.5471454
A23: A3 | D23: N° | E23: =+VLOOKUP(A23,Flejes!B:H,2,) -> 1 | H23: A10 | K23: N° | L23: =+VLOOKUP(H23,Flejes!B:H,2,) -> 85
A31: =+VLOOKUP(A23,Flejes!B:H,4,) -> 19 x 2,1 | E31: =+VLOOKUP(A23,Flejes!B:L,11) -> + | H31: =+VLOOKUP(H23,Flejes!B:H,4,) -> 13.6 x 0.8 | L31: =+VLOOKUP(H23,Flejes!B:L,11) -> +
A37: Max Rollo: | C37: =+VLOOKUP(A23,Flejes!B:H,7,) -> 10.612698 | H37: Max Rollo: | J37: =+VLOOKUP(H23,Flejes!B:H,7,) -> 0
A43: A4 | D43: N° | E43: =+VLOOKUP(A43,Flejes!B:H,2,) -> 0 | H43: A11 | K43: N° | L43: =+VLOOKUP(H43,Flejes!B:H,2,) -> 8
A51: =+VLOOKUP(A43,Flejes!B:H,4,) -> 0 | E51: =+VLOOKUP(A43,Flejes!B:L,11) -> + | H51: =+VLOOKUP(H43,Flejes!B:H,4,) -> 33 x 2 | L51: =+VLOOKUP(H43,Flejes!B:L,11) -> +
A57: Max Rollo: | C57: =+VLOOKUP(A43,Flejes!B:H,7,) -> 0 | H57: Max Rollo: | J57: =+VLOOKUP(H43,Flejes!B:H,7,) -> 1.9604339
A63: A5 | D63: N° | E63: =+VLOOKUP(A63,Flejes!B:H,2,) -> 39 | H63: A12 | K63: N° | L63: =+VLOOKUP(H63,Flejes!B:H,2,) -> 23
A71: =+VLOOKUP(A63,Flejes!B:H,4,) -> 136 x 0,8 | E71: =+VLOOKUP(A63,Flejes!B:L,11) -> + | H71: =+VLOOKUP(H63,Flejes!B:H,4,) -> 20 x 2,8 | L71: =+VLOOKUP(H63,Flejes!B:L,11) -> +
A77: Max Rollo: | C77: =+VLOOKUP(A63,Flejes!B:H,7,) -> 0.56035573 | H77: Max Rollo: | J77: =+VLOOKUP(H63,Flejes!B:H,7,) -> 2.9796719
A83: A6 | D83: N° | E83: =+VLOOKUP(A83,Flejes!B:H,2,) -> 29 | H83: B1 | K83: N° | L83: =+VLOOKUP(H83,Flejes!B:H,2,) -> 84
A91: =+VLOOKUP(A83,Flejes!B:H,4,) -> 91 x 1,75 | E91: =+VLOOKUP(A83,Flejes!B:L,11) -> 0 | H91: =+VLOOKUP(H83,Flejes!B:H,4,) -> 11 x 0.8 | L91: =+VLOOKUP(H83,Flejes!B:L,11) -> +
A97: Max Rollo: | C97: =+VLOOKUP(A83,Flejes!B:H,7,) -> 3.9638243 | H97: Max Rollo: | J97: =+VLOOKUP(H83,Flejes!B:H,7,) -> 0
A103: A7 | D103: N° | E103: =+VLOOKUP(A103,Flejes!B:H,2,) -> 26 | H103: B2 | K103: N° | L103: =+VLOOKUP(H103,Flejes!B:H,2,) -> 41
A111: =+VLOOKUP(A103,Flejes!B:H,4,) -> 92 x 1,25 | E111: =+VLOOKUP(A103,Flejes!B:L,11) -> + | H111: =+VLOOKUP(H103,Flejes!B:H,4,) -> 84 x 1 | L111: =+VLOOKUP(H103,Flejes!B:L,11) -> 0
A117: Max Rollo: | C117: =+VLOOKUP(A103,Flejes!B:H,7,) -> 0.70766019 | H117: Max Rollo: | J117: =+VLOOKUP(H103,Flejes!B:H,7,) -> 7.7913602
A123: A8 | D123: N° | E123: =+VLOOKUP(A123,Flejes!B:H,2,) -> 36 | H123: B3 | K123: N° | L123: =+VLOOKUP(H123,Flejes!B:H,2,) -> 6
A131: =+VLOOKUP(A123,Flejes!B:H,4,) -> 40 x 1,5 | E131: =+VLOOKUP(A123,Flejes!B:L,11) -> + | H131: =+VLOOKUP(H123,Flejes!B:H,4,) -> 18,5 x 1,9 | L131: =+VLOOKUP(H123,Flejes!B:L,11) -> -
A137: Max Rollo: | C137: =+VLOOKUP(A123,Flejes!B:H,7,) -> 1.2797266 | H137: Max Rollo: | J137: =+VLOOKUP(H123,Flejes!B:H,7,) -> 18.210488
